Workbook

Sheet Instances
B1: coomsuite-1.1.0/incremental-exponential_clingo_2 | D1: coomsuite-1.1.0/incremental-exponential_clingo_3 | F1: coomsuite-1.1.0/incremental-exponential_clingo_4 | H1: coomsuite-1.1.0/incremental-exponential_flingo_2 | J1: coomsuite-1.1.0/incremental-exponential_flingo_3 | L1: coomsuite-1.1.0/incremental-exponential_flingo_4 | N1: coomsuite-1.1.0/incremental-linear_clingo_1 | P1: coomsuite-1.1.0/incremental-linear_clingo_16 | R1: coomsuite-1.1.0/incremental-linear_clingo_2 | T1: coomsuite-1.1.0/incremental-linear_clingo_4 | V1: coomsuite-1.1.0/incremental-linear_clingo_8 | X1: coomsuite-1.1.0/incremental-linear_flingo_1 | Z1: coomsuite-1.1.0/incremental-linear_flingo_16 | AB1: coomsuite-1.1.0/incremental-linear_flingo_2 | AD1: coomsuite-1.1.0/incremental-linear_flingo_4 | AF1: coomsuite-1.1.0/incremental-linear_flingo_8 | AH1: coomsuite-1.1.0/multishot-exponential_2 | AJ1: coomsuite-1.1.0/multishot-exponential_3 | AL1: coomsuite-1.1.0/multishot-exponential_4 | AN1: coomsuite-1.1.0/multishot-linear_1 | AP1: coomsuite-1.1.0/multishot-linear_16 | AR1: coomsuite-1.1.0/multishot-linear_2 | AT1: coomsuite-1.1.0/multishot-linear_4 | AV1: coomsuite-1.1.0/multishot-linear_8 | AX1: coomsuite-1.1.0/singleshot_clingo | AZ1: coomsuite-1.1.0/singleshot_flingo | BB1: min | BD1: median | BF1: max
B2: time | C2: timeout | D2: time | E2: timeout | F2: time | G2: timeout | H2: time | I2: timeout | J2: time | K2: timeout | L2: time | M2: timeout | N2: time | O2: timeout | P2: time | Q2: timeout | R2: time | S2: timeout | T2: time | U2: timeout | V2: time | W2: timeout | X2: time | Y2: timeout | Z2: time | AA2: timeout | AB2: time | AC2: timeout | AD2: time | AE2: timeout | AF2: time | AG2: timeout | AH2: time | AI2: timeout | AJ2: time | AK2: timeout | AL2: time | AM2: timeout | AN2: time | AO2: timeout | AP2: time | AQ2: timeout | AR2: time | AS2: timeout | AT2: time | AU2: timeout | AV2: time | AW2: timeout | AX2: time | AY2: timeout | AZ2: time | BA2: timeout | BB2: time | BC2: timeout | BD2: time | BE2: timeout | BF2: time | BG2: timeout
A3: ./citybike-max100_user-input-n100 | B3: 4.64 | C3: 0 | D3: 4.49 | E3: 0 | F3: 4.53 | G3: 0 | H3: 23.38 | I3: 0 | J3: 23.58 | K3: 0 | L3: 23.92 | M3: 0 | N3: 4.52 | O3: 0 | P3: 4.4 | Q3: 0 | R3: 4.38 | S3: 0 | T3: 4.77 | U3: 0 | V3: 4.63 | W3: 0 | X3: 23.98 | Y3: 0 | Z3: 23.69 | AA3: 0 | AB3: 24.05 | AC3: 0 | AD3: 25.87 | AE3: 0 | AF3: 23.92 | AG3: 0 | AH3: 4.72 | AI3: 0 | AJ3: 4.79 | AK3: 0 | AL3: 4.75 | AM3: 0 | AN3: 4.91 | AO3: 0 | AP3: 4.99 | AQ3: 0 | AR3: 4.99 | AS3: 0 | AT3: 4.96 | AU3: 0 | AV3: 4.7 | AW3: 0 | AX3: 4.33 | AY3: 0 | AZ3: 28.12 | BA3: 0 | BB3: =MIN($B3,$D3,$F3,$H3,$J3,$L3,$N3,$P3,$R3,$T3,$V3,$X3,$Z3,$AB3,$AD3,$AF3,$AH3,$AJ3,$AL3,$AN3,$AP3,$AR3,$AT3,$AV3,$AX3,$AZ3) -> 0 | BC3: =MIN($C3,$E3,$G3,$I3,$K3,$M3,$O3,$Q3,$S3,$U3,$W3,$Y3,$AA3,$AC3,$AE3,$AG3,$AI3,$AK3,$AM3,$AO3,$AQ3,$AS3,$AU3,$AW3,$AY3,$BA3) -> 0 | BD3: =MEDIAN($B3,$D3,$F3,$H3,$J3,$L3,$N3,$P3,$R3,$T3,$V3,$X3,$Z3,$AB3,$AD3,$AF3,$AH3,$AJ3,$AL3,$AN3,$AP3,$AR3,$AT3,$AV3,$AX3,$AZ3) -> 0 | BE3: =MEDIAN($C3,$E3,$G3,$I3,$K3,$M3,$O3,$Q3,$S3,$U3,$W3,$Y3,$AA3,$AC3,$AE3,$AG3,$AI3,$AK3,$AM3,$AO3,$AQ3,$AS3,$AU3,$AW3,$AY3,$BA3) -> 0 | BF3: =MAX($B3,$D3,$F3,$H3,$J3,$L3,$N3,$P3,$R3,$T3,$V3,$X3,$Z3,$AB3,$AD3,$AF3,$AH3,$AJ3,$AL3,$AN3,$AP3,$AR3,$AT3,$AV3,$AX3,$AZ3) -> 0 | BG3: =MAX($C3,$E3,$G3,$I3,$K3,$M3,$O3,$Q3,$S3,$U3,$W3,$Y3,$AA3,$AC3,$AE3,$AG3,$AI3,$AK3,$AM3,$AO3,$AQ3,$AS3,$AU3,$AW3,$AY3,$BA3) -> 0
A4: ./citybike-max100_user-input-n25 | B4: 0.79 | C4: 0 | D4: 0.81 | E4: 0 | F4: 0.81 | G4: 0 | H4: 5.29 | I4: 0 | J4: 4.99 | K4: 0 | L4: 5.1 | M4: 0 | N4: 0.72 | O4: 0 | P4: 0.99 | Q4: 0 | R4: 1.03 | S4: 0 | T4: 0.98 | U4: 0 | V4: 0.83 | W4: 0 | X4: 5.1 | Y4: 0 | Z4: 5.14 | AA4: 0 | AB4: 5.03 | AC4: 0 | AD4: 5.47 | AE4: 0 | AF4: 5.16 | AG4: 0 | AH4: 0.76 | AI4: 0 | AJ4: 0.77 | AK4: 0 | AL4: 0.76 | AM4: 0 | AN4: 0.77 | AO4: 0 | AP4: 1.2 | AQ4: 0 | AR4: 0.99 | AS4: 0 | AT4: 0.94 | AU4: 0 | AV4: 0.89 | AW4: 0 | AX4: 4.51 | AY4: 0 | AZ4: 29.84 | BA4: 0 | BB4: =MIN($B4,$D4,$F4,$H4,$J4,$L4,$N4,$P4,$R4,$T4,$V4,$X4,$Z4,$AB4,$AD4,$AF4,$AH4,$AJ4,$AL4,$AN4,$AP4,$AR4,$AT4,$AV4,$AX4,$AZ4) -> 0 | BC4: =MIN($C4,$E4,$G4,$I4,$K4,$M4,$O4,$Q4,$S4,$U4,$W4,$Y4,$AA4,$AC4,$AE4,$AG4,$AI4,$AK4,$AM4,$AO4,$AQ4,$AS4,$AU4,$AW4,$AY4,$BA4) -> 0 | BD4: =MEDIAN($B4,$D4,$F4,$H4,$J4,$L4,$N4,$P4,$R4,$T4,$V4,$X4,$Z4,$AB4,$AD4,$AF4,$AH4,$AJ4,$AL4,$AN4,$AP4,$AR4,$AT4,$AV4,$AX4,$AZ4) -> 0 | BE4: =MEDIAN($C4,$E4,$G4,$I4,$K4,$M4,$O4,$Q4,$S4,$U4,$W4,$Y4,$AA4,$AC4,$AE4,$AG4,$AI4,$AK4,$AM4,$AO4,$AQ4,$AS4,$AU4,$AW4,$AY4,$BA4) -> 0 | BF4: =MAX($B4,$D4,$F4,$H4,$J4,$L4,$N4,$P4,$R4,$T4,$V4,$X4,$Z4,$AB4,$AD4,$AF4,$AH4,$AJ4,$AL4,$AN4,$AP4,$AR4,$AT4,$AV4,$AX4,$AZ4) -> 0 | BG4: =MAX($C4,$E4,$G4,$I4,$K4,$M4,$O4,$Q4,$S4,$U4,$W4,$Y4,$AA4,$AC4,$AE4,$AG4,$AI4,$AK4,$AM4,$AO4,$AQ4,$AS4,$AU4,$AW4,$AY4,$BA4) -> 0
A5: ./citybike-max100_user-input-n33 | B5: 1.21 | C5: 0 | D5: 0.96 | E5: 0 | F5: 0.92 | G5: 0 | H5: 6.75 | I5: 0 | J5: 6.78 | K5: 0 | L5: 6.72 | M5: 0 | N5: 0.93 | O5: 0 | P5: 0.91 | Q5: 0 | R5: 0.9 | S5: 0 | T5: 0.99 | U5: 0 | V5: 0.89 | W5: 0 | X5: 6.8 | Y5: 0 | Z5: 6.75 | AA5: 0 | AB5: 6.72 | AC5: 0 | AD5: 6.75 | AE5: 0 | AF5: 6.7 | AG5: 0 | AH5: 1.06 | AI5: 0 | AJ5: 1.01 | AK5: 0 | AL5: 1.02 | AM5: 0 | AN5: 1.07 | AO5: 0 | AP5: 1.11 | AQ5: 0 | AR5: 1.09 | AS5: 0 | AT5: 1.08 | AU5: 0 | AV5: 1.13 | AW5: 0 | AX5: 4.34 | AY5: 0 | AZ5: 29.63 | BA5: 0 | BB5: =MIN($B5,$D5,$F5,$H5,$J5,$L5,$N5,$P5,$R5,$T5,$V5,$X5,$Z5,$AB5,$AD5,$AF5,$AH5,$AJ5,$AL5,$AN5,$AP5,$AR5,$AT5,$AV5,$AX5,$AZ5) -> 0 | BC5: =MIN($C5,$E5,$G5,$I5,$K5,$M5,$O5,$Q5,$S5,$U5,$W5,$Y5,$AA5,$AC5,$AE5,$AG5,$AI5,$AK5,$AM5,$AO5,$AQ5,$AS5,$AU5,$AW5,$AY5,$BA5) -> 0 | BD5: =MEDIAN($B5,$D5,$F5,$H5,$J5,$L5,$N5,$P5,$R5,$T5,$V5,$X5,$Z5,$AB5,$AD5,$AF5,$AH5,$AJ5,$AL5,$AN5,$AP5,$AR5,$AT5,$AV5,$AX5,$AZ5) -> 0 | BE5: =MEDIAN($C5,$E5,$G5,$I5,$K5,$M5,$O5,$Q5,$S5,$U5,$W5,$Y5,$AA5,$AC5,$AE5,$AG5,$AI5,$AK5,$AM5,$AO5,$AQ5,$AS5,$AU5,$AW5,$AY5,$BA5) -> 0 | BF5: =MAX($B5,$D5,$F5,$H5,$J5,$L5,$N5,$P5,$R5,$T5,$V5,$X5,$Z5,$AB5,$AD5,$AF5,$AH5,$AJ5,$AL5,$AN5,$AP5,$AR5,$AT5,$AV5,$AX5,$AZ5) -> 0 | BG5: =MAX($C5,$E5,$G5,$I5,$K5,$M5,$O5,$Q5,$S5,$U5,$W5,$Y5,$AA5,$AC5,$AE5,$AG5,$AI5,$AK5,$AM5,$AO5,$AQ5,$AS5,$AU5,$AW5,$AY5,$BA5) -> 0
A6: ./citybike-max100_user-input-n50 | B6: 1.59 | C6: 0 | D6: 2.29 | E6: 0 | F6: 1.61 | G6: 0 | H6: 11.91 | I6: 0 | J6: 11.32 | K6: 0 | L6: 10.55 | M6: 0 | N6: 1.64 | O6: 0 | P6: 1.53 | Q6: 0 | R6: 1.56 | S6: 0 | T6: 1.78 | U6: 0 | V6: 1.61 | W6: 0 | X6: 11.46 | Y6: 0 | Z6: 10.86 | AA6: 0 | AB6: 10.16 | AC6: 0 | AD6: 10.75 | AE6: 0 | AF6: 10.62 | AG6: 0 | AH6: 1.84 | AI6: 0 | AJ6: 1.82 | AK6: 0 | AL6: 1.86 | AM6: 0 | AN6: 1.78 | AO6: 0 | AP6: 2.14 | AQ6: 0 | AR6: 1.91 | AS6: 0 | AT6: 2.49 | AU6: 0 | AV6: 1.85 | AW6: 0 | AX6: 4.3 | AY6: 0 | AZ6: 23.3 | BA6: 0 | BB6: =MIN($B6,$D6,$F6,$H6,$J6,$L6,$N6,$P6,$R6,$T6,$V6,$X6,$Z6,$AB6,$AD6,$AF6,$AH6,$AJ6,$AL6,$AN6,$AP6,$AR6,$AT6,$AV6,$AX6,$AZ6) -> 0 | BC6: =MIN($C6,$E6,$G6,$I6,$K6,$M6,$O6,$Q6,$S6,$U6,$W6,$Y6,$AA6,$AC6,$AE6,$AG6,$AI6,$AK6,$AM6,$AO6,$AQ6,$AS6,$AU6,$AW6,$AY6,$BA6) -> 0 | BD6: =MEDIAN($B6,$D6,$F6,$H6,$J6,$L6,$N6,$P6,$R6,$T6,$V6,$X6,$Z6,$AB6,$AD6,$AF6,$AH6,$AJ6,$AL6,$AN6,$AP6,$AR6,$AT6,$AV6,$AX6,$AZ6) -> 0 | BE6: =MEDIAN($C6,$E6,$G6,$I6,$K6,$M6,$O6,$Q6,$S6,$U6,$W6,$Y6,$AA6,$AC6,$AE6,$AG6,$AI6,$AK6,$AM6,$AO6,$AQ6,$AS6,$AU6,$AW6,$AY6,$BA6) -> 0 | BF6: =MAX($B6,$D6,$F6,$H6,$J6,$L6,$N6,$P6,$R6,$T6,$V6,$X6,$Z6,$AB6,$AD6,$AF6,$AH6,$AJ6,$AL6,$AN6,$AP6,$AR6,$AT6,$AV6,$AX6,$AZ6) -> 0 | BG6: =MAX($C6,$E6,$G6,$I6,$K6,$M6,$O6,$Q6,$S6,$U6,$W6,$Y6,$AA6,$AC6,$AE6,$AG6,$AI6,$AK6,$AM6,$AO6,$AQ6,$AS6,$AU6,$AW6,$AY6,$BA6) -> 0
A7: ./citybike-max150_user-input-n150 | B7: 8.65 | C7: 0 | D7: 9.76 | E7: 0 | F7: 9.04 | G7: 0 | H7: 45.07 | I7: 0 | J7: 39.68 | K7: 0 | L7: 39.28 | M7: 0 | N7: 9.19 | O7: 0 | P7: 9.44 | Q7: 0 | R7: 9.12 | S7: 0 | T7: 11.88 | U7: 0 | V7: 11.39 | W7: 0 | X7: 41.02 | Y7: 0 | Z7: 40.98 | AA7: 0 | AB7: 39.14 | AC7: 0 | AD7: 41.73 | AE7: 0 | AF7: 43.12 | AG7: 0 | AH7: 9.05 | AI7: 0 | AJ7: 9.13 | AK7: 0 | AL7: 9.34 | AM7: 0 | AN7: 9.31 | AO7: 0 | AP7: 9.28 | AQ7: 0 | AR7: 10.89 | AS7: 0 | AT7: 9.92 | AU7: 0 | AV7: 9.96 | AW7: 0 | AX7: 8.76 | AY7: 0 | AZ7: 39.45 | BA7: 0 | BB7: =MIN($B7,$D7,$F7,$H7,$J7,$L7,$N7,$P7,$R7,$T7,$V7,$X7,$Z7,$AB7,$AD7,$AF7,$AH7,$AJ7,$AL7,$AN7,$AP7,$AR7,$AT7,$AV7,$AX7,$AZ7) -> 0 | BC7: =MIN($C7,$E7,$G7,$I7,$K7,$M7,$O7,$Q7,$S7,$U7,$W7,$Y7,$AA7,$AC7,$AE7,$AG7,$AI7,$AK7,$AM7,$AO7,$AQ7,$AS7,$AU7,$AW7,$AY7,$BA7) -> 0 | BD7: =MEDIAN($B7,$D7,$F7,$H7,$J7,$L7,$N7,$P7,$R7,$T7,$V7,$X7,$Z7,$AB7,$AD7,$AF7,$AH7,$AJ7,$AL7,$AN7,$AP7,$AR7,$AT7,$AV7,$AX7,$AZ7) -> 0 | BE7: =MEDIAN($C7,$E7,$G7,$I7,$K7,$M7,$O7,$Q7,$S7,$U7,$W7,$Y7,$AA7,$AC7,$AE7,$AG7,$AI7,$AK7,$AM7,$AO7,$AQ7,$AS7,$AU7,$AW7,$AY7,$BA7) -> 0 | BF7: =MAX($B7,$D7,$F7,$H7,$J7,$L7,$N7,$P7,$R7,$T7,$V7,$X7,$Z7,$AB7,$AD7,$AF7,$AH7,$AJ7,$AL7,$AN7,$AP7,$AR7,$AT7,$AV7,$AX7,$AZ7) -> 0 | BG7: =MAX($C7,$E7,$G7,$I7,$K7,$M7,$O7,$Q7,$S7,$U7,$W7,$Y7,$AA7,$AC7,$AE7,$AG7,$AI7,$AK7,$AM7,$AO7,$AQ7,$AS7,$AU7,$AW7,$AY7,$BA7) -> 0
A8: ./citybike-max150_user-input-n37 | B8: 1.43 | C8: 0 | D8: 1.18 | E8: 0 | F8: 1.15 | G8: 0 | H8: 7.55 | I8: 0 | J8: 7.67 | K8: 0 | L8: 7.74 | M8: 0 | N8: 1.22 | O8: 0 | P8: 1.04 | Q8: 0 | R8: 1.04 | S8: 0 | T8: 1.35 | U8: 0 | V8: 1.17 | W8: 0 | X8: 7.73 | Y8: 0 | Z8: 7.54 | AA8: 0 | AB8: 8.24 | AC8: 0 | AD8: 9.77 | AE8: 0 | AF8: 7.83 | AG8: 0 | AH8: 1.66 | AI8: 0 | AJ8: 1.38 | AK8: 0 | AL8: 1.37 | AM8: 0 | AN8: 1.52 | AO8: 0 | AP8: 1.39 | AQ8: 0 | AR8: 1.28 | AS8: 0 | AT8: 1.3 | AU8: 0 | AV8: 1.36 | AW8: 0 | AX8: 11.37 | AY8: 0 | AZ8: 37.7 | BA8: 0 | BB8: =MIN($B8,$D8,$F8,$H8,$J8,$L8,$N8,$P8,$R8,$T8,$V8,$X8,$Z8,$AB8,$AD8,$AF8,$AH8,$AJ8,$AL8,$AN8,$AP8,$AR8,$AT8,$AV8,$AX8,$AZ8) -> 0 | BC8: =MIN($C8,$E8,$G8,$I8,$K8,$M8,$O8,$Q8,$S8,$U8,$W8,$Y8,$AA8,$AC8,$AE8,$AG8,$AI8,$AK8,$AM8,$AO8,$AQ8,$AS8,$AU8,$AW8,$AY8,$BA8) -> 0 | BD8: =MEDIAN($B8,$D8,$F8,$H8,$J8,$L8,$N8,$P8,$R8,$T8,$V8,$X8,$Z8,$AB8,$AD8,$AF8,$AH8,$AJ8,$AL8,$AN8,$AP8,$AR8,$AT8,$AV8,$AX8,$AZ8) -> 0 | BE8: =MEDIAN($C8,$E8,$G8,$I8,$K8,$M8,$O8,$Q8,$S8,$U8,$W8,$Y8,$AA8,$AC8,$AE8,$AG8,$AI8,$AK8,$AM8,$AO8,$AQ8,$AS8,$AU8,$AW8,$AY8,$BA8) -> 0 | BF8: =MAX($B8,$D8,$F8,$H8,$J8,$L8,$N8,$P8,$R8,$T8,$V8,$X8,$Z8,$AB8,$AD8,$AF8,$AH8,$AJ8,$AL8,$AN8,$AP8,$AR8,$AT8,$AV8,$AX8,$AZ8) -> 0 | BG8: =MAX($C8,$E8,$G8,$I8,$K8,$M8,$O8,$Q8,$S8,$U8,$W8,$Y8,$AA8,$AC8,$AE8,$AG8,$AI8,$AK8,$AM8,$AO8,$AQ8,$AS8,$AU8,$AW8,$AY8,$BA8) -> 0
A9: ./citybike-max150_user-input-n50 | B9: 1.58 | C9: 0 | D9: 1.6 | E9: 0 | F9: 1.53 | G9: 0 | H9: 11.41 | I9: 0 | J9: 10.48 | K9: 0 | L9: 10.51 | M9: 0 | N9: 1.54 | O9: 0 | P9: 1.51 | Q9: 0 | R9: 1.53 | S9: 0 | T9: 1.55 | U9: 0 | V9: 1.54 | W9: 0 | X9: 10.56 | Y9: 0 | Z9: 10.6 | AA9: 0 | AB9: 10.48 | AC9: 0 | AD9: 12.28 | AE9: 0 | AF9: 10.46 | AG9: 0 | AH9: 1.68 | AI9: 0 | AJ9: 1.67 | AK9: 0 | AL9: 1.66 | AM9: 0 | AN9: 1.7 | AO9: 0 | AP9: 1.75 | AQ9: 0 | AR9: 1.94 | AS9: 0 | AT9: 1.8 | AU9: 0 | AV9: 1.66 | AW9: 0 | AX9: 8.71 | AY9: 0 | AZ9: 52.33 | BA9: 0 | BB9: =MIN($B9,$D9,$F9,$H9,$J9,$L9,$N9,$P9,$R9,$T9,$V9,$X9,$Z9,$AB9,$AD9,$AF9,$AH9,$AJ9,$AL9,$AN9,$AP9,$AR9,$AT9,$AV9,$AX9,$AZ9) -> 0 | BC9: =MIN($C9,$E9,$G9,$I9,$K9,$M9,$O9,$Q9,$S9,$U9,$W9,$Y9,$AA9,$AC9,$AE9,$AG9,$AI9,$AK9,$AM9,$AO9,$AQ9,$AS9,$AU9,$AW9,$AY9,$BA9) -> 0 | BD9: =MEDIAN($B9,$D9,$F9,$H9,$J9,$L9,$N9,$P9,$R9,$T9,$V9,$X9,$Z9,$AB9,$AD9,$AF9,$AH9,$AJ9,$AL9,$AN9,$AP9,$AR9,$AT9,$AV9,$AX9,$AZ9) -> 0 | BE9: =MEDIAN($C9,$E9,$G9,$I9,$K9,$M9,$O9,$Q9,$S9,$U9,$W9,$Y9,$AA9,$AC9,$AE9,$AG9,$AI9,$AK9,$AM9,$AO9,$AQ9,$AS9,$AU9,$AW9,$AY9,$BA9) -> 0 | BF9: =MAX($B9,$D9,$F9,$H9,$J9,$L9,$N9,$P9,$R9,$T9,$V9,$X9,$Z9,$AB9,$AD9,$AF9,$AH9,$AJ9,$AL9,$AN9,$AP9,$AR9,$AT9,$AV9,$AX9,$AZ9) -> 0 | BG9: =MAX($C9,$E9,$G9,$I9,$K9,$M9,$O9,$Q9,$S9,$U9,$W9,$Y9,$AA9,$AC9,$AE9,$AG9,$AI9,$AK9,$AM9,$AO9,$AQ9,$AS9,$AU9,$AW9,$AY9,$BA9) -> 0
A10: ./citybike-max150_user-input-n75 | B10: 2.95 | C10: 0 | D10: 2.98 | E10: 0 | F10: 2.96 | G10: 0 | H10: 18.25 | I10: 0 | J10: 16.94 | K10: 0 | L10: 16.4 | M10: 0 | N10: 2.95 | O10: 0 | P10: 2.9 | Q10: 0 | R10: 2.87 | S10: 0 | T10: 2.91 | U10: 0 | V10: 2.99 | W10: 0 | X10: 17 | Y10: 0 | Z10: 16.69 | AA10: 0 | AB10: 16.65 | AC10: 0 | AD10: 18.54 | AE10: 0 | AF10: 16.89 | AG10: 0 | AH10: 3.17 | AI10: 0 | AJ10: 3.15 | AK10: 0 | AL10: 3.16 | AM10: 0 | AN10: 3.13 | AO10: 0 | AP10: 3.2 | AQ10: 0 | AR10: 3.3 | AS10: 0 | AT10: 3.3 | AU10: 0 | AV10: 3.07 | AW10: 0 | AX10: 8.84 | AY10: 0 | AZ10: 52.57 | BA10: 0 | BB10: =MIN($B10,$D10,$F10,$H10,$J10,$L10,$N10,$P10,$R10,$T10,$V10,$X10,$Z10,$AB10,$AD10,$AF10,$AH10,$AJ10,$AL10,$AN10,$AP10,$AR10,$AT10,$AV10,$AX10,$AZ10) -> 0 | BC10: =MIN($C10,$E10,$G10,$I10,$K10,$M10,$O10,$Q10,$S10,$U10,$W10,$Y10,$AA10,$AC10,$AE10,$AG10,$AI10,$AK10,$AM10,$AO10,$AQ10,$AS10,$AU10,$AW10,$AY10,$BA10) -> 0 | BD10: =MEDIAN($B10,$D10,$F10,$H10,$J10,$L10,$N10,$P10,$R10,$T10,$V10,$X10,$Z10,$AB10,$AD10,$AF10,$AH10,$AJ10,$AL10,$AN10,$AP10,$AR10,$AT10,$AV10,$AX10,$AZ10) -> 0 | BE10: =MEDIAN($C10,$E10,$G10,$I10,$K10,$M10,$O10,$Q10,$S10,$U10,$W10,$Y10,$AA10,$AC10,$AE10,$AG10,$AI10,$AK10,$AM10,$AO10,$AQ10,$AS10,$AU10,$AW10,$AY10,$BA10) -> 0 | BF10: =MAX($B10,$D10,$F10,$H10,$J10,$L10,$N10,$P10,$R10,$T10,$V10,$X10,$Z10,$AB10,$AD10,$AF10,$AH10,$AJ10,$AL10,$AN10,$AP10,$AR10,$AT10,$AV10,$AX10,$AZ10) -> 0 | BG10: =MAX($C10,$E10,$G10,$I10,$K10,$M10,$O10,$Q10,$S10,$U10,$W10,$Y10,$AA10,$AC10,$AE10,$AG10,$AI10,$AK10,$AM10,$AO10,$AQ10,$AS10,$AU10,$AW10,$AY10,$BA10) -> 0
A11: ./citybike-max200_user-input-n100 | B11: 5.44 | C11: 0 | D11: 4.68 | E11: 0 | F11: 4.79 | G11: 0 | H11: 23.81 | I11: 0 | J11: 23.75 | K11: 0 | L11: 23.83 | M11: 0 | N11: 4.68 | O11: 0 | P11: 4.56 | Q11: 0 | R11: 4.57 | S11: 0 | T11: 5.54 | U11: 0 | V11: 4.69 | W11: 0 | X11: 24.12 | Y11: 0 | Z11: 23.63 | AA11: 0 | AB11: 23.56 | AC11: 0 | AD11: 24.17 | AE11: 0 | AF11: 24.83 | AG11: 0 | AH11: 4.66 | AI11: 0 | AJ11: 4.89 | AK11: 0 | AL11: 4.9 | AM11: 0 | AN11: 4.91 | AO11: 0 | AP11: 5.11 | AQ11: 0 | AR11: 5.1 | AS11: 0 | AT11: 5.06 | AU11: 0 | AV11: 4.73 | AW11: 0 | AX11: 14.74 | AY11: 0 | AZ11: 68.51 | BA11: 0 | BB11: =MIN($B11,$D11,$F11,$H11,$J11,$L11,$N11,$P11,$R11,$T11,$V11,$X11,$Z11,$AB11,$AD11,$AF11,$AH11,$AJ11,$AL11,$AN11,$AP11,$AR11,$AT11,$AV11,$AX11,$AZ11) -> 0 | BC11: =MIN($C11,$E11,$G11,$I11,$K11,$M11,$O11,$Q11,$S11,$U11,$W11,$Y11,$AA11,$AC11,$AE11,$AG11,$AI11,$AK11,$AM11,$AO11,$AQ11,$AS11,$AU11,$AW11,$AY11,$BA11) -> 0 | BD11: =MEDIAN($B11,$D11,$F11,$H11,$J11,$L11,$N11,$P11,$R11,$T11,$V11,$X11,$Z11,$AB11,$AD11,$AF11,$AH11,$AJ11,$AL11,$AN11,$AP11,$AR11,$AT11,$AV11,$AX11,$AZ11) -> 0 | BE11: =MEDIAN($C11,$E11,$G11,$I11,$K11,$M11,$O11,$Q11,$S11,$U11,$W11,$Y11,$AA11,$AC11,$AE11,$AG11,$AI11,$AK11,$AM11,$AO11,$AQ11,$AS11,$AU11,$AW11,$AY11,$BA11) -> 0 | BF11: =MAX($B11,$D11,$F11,$H11,$J11,$L11,$N11,$P11,$R11,$T11,$V11,$X11,$Z11,$AB11,$AD11,$AF11,$AH11,$AJ11,$AL11,$AN11,$AP11,$AR11,$AT11,$AV11,$AX11,$AZ11) -> 0 | BG11: =MAX($C11,$E11,$G11,$I11,$K11,$M11,$O11,$Q11,$S11,$U11,$W11,$Y11,$AA11,$AC11,$AE11,$AG11,$AI11,$AK11,$AM11,$AO11,$AQ11,$AS11,$AU11,$AW11,$AY11,$BA11) -> 0
A12: ./citybike-max200_user-input-n200 | B12: 17.67 | C12: 0 | D12: 14.61 | E12: 0 | F12: 14.88 | G12: 0 | H12: 58.34 | I12: 0 | J12: 60.12 | K12: 0 | L12: 58.78 | M12: 0 | N12: 15.42 | O12: 0 | P12: 15.16 | Q12: 0 | R12: 14.67 | S12: 0 | T12: 19.02 | U12: 0 | V12: 14.75 | W12: 0 | X12: 61.07 | Y12: 0 | Z12: 59.66 | AA12: 0 | AB12: 71.79 | AC12: 0 | AD12: 64.7 | AE12: 0 | AF12: 61.58 | AG12: 0 | AH12: 20.85 | AI12: 0 | AJ12: 17.69 | AK12: 0 | AL12: 17.33 | AM12: 0 | AN12: 15.45 | AO12: 0 | AP12: 17.21 | AQ12: 0 | AR12: 17.15 | AS12: 0 | AT12: 15.37 | AU12: 0 | AV12: 15.49 | AW12: 0 | AX12: 19.68 | AY12: 0 | AZ12: 59.25 | BA12: 0 | BB12: =MIN($B12,$D12,$F12,$H12,$J12,$L12,$N12,$P12,$R12,$T12,$V12,$X12,$Z12,$AB12,$AD12,$AF12,$AH12,$AJ12,$AL12,$AN12,$AP12,$AR12,$AT12,$AV12,$AX12,$AZ12) -> 0 | BC12: =MIN($C12,$E12,$G12,$I12,$K12,$M12,$O12,$Q12,$S12,$U12,$W12,$Y12,$AA12,$AC12,$AE12,$AG12,$AI12,$AK12,$AM12,$AO12,$AQ12,$AS12,$AU12,$AW12,$AY12,$BA12) -> 0 | BD12: =MEDIAN($B12,$D12,$F12,$H12,$J12,$L12,$N12,$P12,$R12,$T12,$V12,$X12,$Z12,$AB12,$AD12,$AF12,$AH12,$AJ12,$AL12,$AN12,$AP12,$AR12,$AT12,$AV12,$AX12,$AZ12) -> 0 | BE12: =MEDIAN($C12,$E12,$G12,$I12,$K12,$M12,$O12,$Q12,$S12,$U12,$W12,$Y12,$AA12,$AC12,$AE12,$AG12,$AI12,$AK12,$AM12,$AO12,$AQ12,$AS12,$AU12,$AW12,$AY12,$BA12) -> 0 | BF12: =MAX($B12,$D12,$F12,$H12,$J12,$L12,$N12,$P12,$R12,$T12,$V12,$X12,$Z12,$AB12,$AD12,$AF12,$AH12,$AJ12,$AL12,$AN12,$AP12,$AR12,$AT12,$AV12,$AX12,$AZ12) -> 0 | BG12: =MAX($C12,$E12,$G12,$I12,$K12,$M12,$O12,$Q12,$S12,$U12,$W12,$Y12,$AA12,$AC12,$AE12,$AG12,$AI12,$AK12,$AM12,$AO12,$AQ12,$AS12,$AU12,$AW12,$AY12,$BA12) -> 0
A13: ./citybike-max200_user-input-n50 | B13: 1.77 | C13: 0 | D13: 1.65 | E13: 0 | F13: 2.1 | G13: 0 | H13: 11.27 | I13: 0 | J13: 10.68 | K13: 0 | L13: 10.58 | M13: 0 | N13: 1.68 | O13: 0 | P13: 1.65 | Q13: 0 | R13: 2.13 | S13: 0 | T13: 2.15 | U13: 0 | V13: 1.72 | W13: 0 | X13: 10.51 | Y13: 0 | Z13: 10.66 | AA13: 0 | AB13: 10.15 | AC13: 0 | AD13: 10.75 | AE13: 0 | AF13: 12.11 | AG13: 0 | AH13: 1.81 | AI13: 0 | AJ13: 1.66 | AK13: 0 | AL13: 1.82 | AM13: 0 | AN13: 1.84 | AO13: 0 | AP13: 2.24 | AQ13: 0 | AR13: 2.42 | AS13: 0 | AT13: 2.31 | AU13: 0 | AV13: 1.81 | AW13: 0 | AX13: 14.68 | AY13: 0 | AZ13: 55.82 | BA13: 0 | BB13: =MIN($B13,$D13,$F13,$H13,$J13,$L13,$N13,$P13,$R13,$T13,$V13,$X13,$Z13,$AB13,$AD13,$AF13,$AH13,$AJ13,$AL13,$AN13,$AP13,$AR13,$AT13,$AV13,$AX13,$AZ13) -> 0 | BC13: =MIN($C13,$E13,$G13,$I13,$K13,$M13,$O13,$Q13,$S13,$U13,$W13,$Y13,$AA13,$AC13,$AE13,$AG13,$AI13,$AK13,$AM13,$AO13,$AQ13,$AS13,$AU13,$AW13,$AY13,$BA13) -> 0 | BD13: =MEDIAN($B13,$D13,$F13,$H13,$J13,$L13,$N13,$P13,$R13,$T13,$V13,$X13,$Z13,$AB13,$AD13,$AF13,$AH13,$AJ13,$AL13,$AN13,$AP13,$AR13,$AT13,$AV13,$AX13,$AZ13) -> 0 | BE13: =MEDIAN($C13,$E13,$G13,$I13,$K13,$M13,$O13,$Q13,$S13,$U13,$W13,$Y13,$AA13,$AC13,$AE13,$AG13,$AI13,$AK13,$AM13,$AO13,$AQ13,$AS13,$AU13,$AW13,$AY13,$BA13) -> 0 | BF13: =MAX($B13,$D13,$F13,$H13,$J13,$L13,$N13,$P13,$R13,$T13,$V13,$X13,$Z13,$AB13,$AD13,$AF13,$AH13,$AJ13,$AL13,$AN13,$AP13,$AR13,$AT13,$AV13,$AX13,$AZ13) -> 0 | BG13: =MAX($C13,$E13,$G13,$I13,$K13,$M13,$O13,$Q13,$S13,$U13,$W13,$Y13,$AA13,$AC13,$AE13,$AG13,$AI13,$AK13,$AM13,$AO13,$AQ13,$AS13,$AU13,$AW13,$AY13,$BA13) -> 0
A14: ./citybike-max200_user-input-n66 | B14: 2.37 | C14: 0 | D14: 2.29 | E14: 0 | F14: 2.31 | G14: 0 | H14: 15.29 | I14: 0 | J14: 14.6 | K14: 0 | L14: 14.47 | M14: 0 | N14: 2.58 | O14: 0 | P14: 2.87 | Q14: 0 | R14: 2.33 | S14: 0 | T14: 2.62 | U14: 0 | V14: 2.35 | W14: 0 | X14: 14.76 | Y14: 0 | Z14: 14.49 | AA14: 0 | AB14: 14.53 | AC14: 0 | AD14: 15.75 | AE14: 0 | AF14: 15.89 | AG14: 0 | AH14: 2.57 | AI14: 0 | AJ14: 2.5 | AK14: 0 | AL14: 2.49 | AM14: 0 | AN14: 2.66 | AO14: 0 | AP14: 2.63 | AQ14: 0 | AR14: 2.52 | AS14: 0 | AT14: 2.85 | AU14: 0 | AV14: 2.54 | AW14: 0 | AX14: 14.63 | AY14: 0 | AZ14: 56.41 | BA14: 0 | BB14: =MIN($B14,$D14,$F14,$H14,$J14,$L14,$N14,$P14,$R14,$T14,$V14,$X14,$Z14,$AB14,$AD14,$AF14,$AH14,$AJ14,$AL14,$AN14,$AP14,$AR14,$AT14,$AV14,$AX14,$AZ14) -> 0 | BC14: =MIN($C14,$E14,$G14,$I14,$K14,$M14,$O14,$Q14,$S14,$U14,$W14,$Y14,$AA14,$AC14,$AE14,$AG14,$AI14,$AK14,$AM14,$AO14,$AQ14,$AS14,$AU14,$AW14,$AY14,$BA14) -> 0 | BD14: =MEDIAN($B14,$D14,$F14,$H14,$J14,$L14,$N14,$P14,$R14,$T14,$V14,$X14,$Z14,$AB14,$AD14,$AF14,$AH14,$AJ14,$AL14,$AN14,$AP14,$AR14,$AT14,$AV14,$AX14,$AZ14) -> 0 | BE14: =MEDIAN($C14,$E14,$G14,$I14,$K14,$M14,$O14,$Q14,$S14,$U14,$W14,$Y14,$AA14,$AC14,$AE14,$AG14,$AI14,$AK14,$AM14,$AO14,$AQ14,$AS14,$AU14,$AW14,$AY14,$BA14) -> 0 | BF14: =MAX($B14,$D14,$F14,$H14,$J14,$L14,$N14,$P14,$R14,$T14,$V14,$X14,$Z14,$AB14,$AD14,$AF14,$AH14,$AJ14,$AL14,$AN14,$AP14,$AR14,$AT14,$AV14,$AX14,$AZ14) -> 0 | BG14: =MAX($C14,$E14,$G14,$I14,$K14,$M14,$O14,$Q14,$S14,$U14,$W14,$Y14,$AA14,$AC14,$AE14,$AG14,$AI14,$AK14,$AM14,$AO14,$AQ14,$AS14,$AU14,$AW14,$AY14,$BA14) -> 0
... A53: ./travelbike-max5_user-input-p496-v356 | B53: 61.04 | C53: 0 | D53: 498.33 | E53: 0 | F53: 71.19 | G53: 0 | H53: 5.74 | I53: 0 | J53: 13.24 | K53: 0 | L53: 5.07 | M53: 0 | N53: 75.33 | O53: 0 | P53: 1200 | Q53: 1 | R53: 58.03 | S53: 0 | T53: 77.55 | U53: 0 | V53: 281.53 | W53: 0 | X53: 5.06 | Y53: 0 | Z53: 1200 | AA53: 1 | AB53: 4.44 | AC53: 0 | AD53: 4.53 | AE53: 0 | AF53: 9.3 | AG53: 0 | AH53: 212.63 | AI53: 0 | AJ53: 1200 | AK53: 1 | AL53: 1200 | AM53: 1 | AN53: 180.66 | AO53: 0 | AP53: 1200 | AQ53: 1 | AR53: 246.04 | AS53: 0 | AT53: 1200 | AU53: 1 | AV53: 1200 | AW53: 1 | AX53: 54.52 | AY53: 0 | AZ53: 2.55 | BA53: 0 | BB53: =MIN($B53,$D53,$F53,$H53,$J53,$L53,$N53,$P53,$R53,$T53,$V53,$X53,$Z53,$AB53,$AD53,$AF53,$AH53,$AJ53,$AL53,$AN53,$AP53,$AR53,$AT53,$AV53,$AX53,$AZ53) -> 0 | BC53: =MIN($C53,$E53,$G53,$I53,$K53,$M53,$O53,$Q53,$S53,$U53,$W53,$Y53,$AA53,$AC53,$AE53,$AG53,$AI53,$AK53,$AM53,$AO53,$AQ53,$AS53,$AU53,$AW53,$AY53,$BA53) -> 0 | BD53: =MEDIAN($B53,$D53,$F53,$H53,$J53,$L53,$N53,$P53,$R53,$T53,$V53,$X53,$Z53,$AB53,$AD53,$AF53,$AH53,$AJ53,$AL53,$AN53,$AP53,$AR53,$AT53,$AV53,$AX53,$AZ53) -> 0 | BE53: =MEDIAN($C53,$E53,$G53,$I53,$K53,$M53,$O53,$Q53,$S53,$U53,$W53,$Y53,$AA53,$AC53,$AE53,$AG53,$AI53,$AK53,$AM53,$AO53,$AQ53,$AS53,$AU53,$AW53,$AY53,$BA53) -> 0 | BF53: =MAX($B53,$D53,$F53,$H53,$J53,$L53,$N53,$P53,$R53,$T53,$V53,$X53,$Z53,$AB53,$AD53,$AF53,$AH53,$AJ53,$AL53,$AN53,$AP53,$AR53,$AT53,$AV53,$AX53,$AZ53) -> 0 | BG53: =MAX($C53,$E53,$G53,$I53,$K53,$M53,$O53,$Q53,$S53,$U53,$W53,$Y53,$AA53,$AC53,$AE53,$AG53,$AI53,$AK53,$AM53,$AO53,$AQ53,$AS53,$AU53,$AW53,$AY53,$BA53) -> 0
A54: ./cargobike-100_user-input-0 | B54: 0.61 | C54: 0 | D54: 0.36 | E54: 0 | F54: 0.48 | G54: 0 | H54: 1 | I54: 0 | J54: 0.7 | K54: 0 | L54: 1 | M54: 0 | N54: 0.49 | O54: 0 | P54: 574.2 | Q54: 0 | R54: 0.39 | S54: 0 | T54: 0.61 | U54: 0 | V54: 0.51 | W54: 0 | X54: 0.83 | Y54: 0 | Z54: 1.95 | AA54: 0 | AB54: 0.82 | AC54: 0 | AD54: 0.87 | AE54: 0 | AF54: 1.19 | AG54: 0 | AH54: 0.37 | AI54: 0 | AJ54: 0.38 | AK54: 0 | AL54: 0.35 | AM54: 0 | AN54: 0.3 | AO54: 0 | AP54: 0.95 | AQ54: 0 | AR54: 0.35 | AS54: 0 | AT54: 0.49 | AU54: 0 | AV54: 0.62 | AW54: 0 | BB54: =MIN($B54,$D54,$F54,$H54,$J54,$L54,$N54,$P54,$R54,$T54,$V54,$X54,$Z54,$AB54,$AD54,$AF54,$AH54,$AJ54,$AL54,$AN54,$AP54,$AR54,$AT54,$AV54,$AX54,$AZ54) -> 0 | BC54: =MIN($C54,$E54,$G54,$I54,$K54,$M54,$O54,$Q54,$S54,$U54,$W54,$Y54,$AA54,$AC54,$AE54,$AG54,$AI54,$AK54,$AM54,$AO54,$AQ54,$AS54,$AU54,$AW54,$AY54,$BA54) -> 0 | BD54: =MEDIAN($B54,$D54,$F54,$H54,$J54,$L54,$N54,$P54,$R54,$T54,$V54,$X54,$Z54,$AB54,$AD54,$AF54,$AH54,$AJ54,$AL54,$AN54,$AP54,$AR54,$AT54,$AV54,$AX54,$AZ54) -> 0 | BE54: =MEDIAN($C54,$E54,$G54,$I54,$K54,$M54,$O54,$Q54,$S54,$U54,$W54,$Y54,$AA54,$AC54,$AE54,$AG54,$AI54,$AK54,$AM54,$AO54,$AQ54,$AS54,$AU54,$AW54,$AY54,$BA54) -> 0 | BF54: =MAX($B54,$D54,$F54,$H54,$J54,$L54,$N54,$P54,$R54,$T54,$V54,$X54,$Z54,$AB54,$AD54,$AF54,$AH54,$AJ54,$AL54,$AN54,$AP54,$AR54,$AT54,$AV54,$AX54,$AZ54) -> 0 | BG54: =MAX($C54,$E54,$G54,$I54,$K54,$M54,$O54,$Q54,$S54,$U54,$W54,$Y54,$AA54,$AC54,$AE54,$AG54,$AI54,$AK54,$AM54,$AO54,$AQ54,$AS54,$AU54,$AW54,$AY54,$BA54) -> 0
A55: ./cargobike-100_user-input-1 | B55: 0.49 | C55: 0 | D55: 0.44 | E55: 0 | F55: 0.37 | G55: 0 | H55: 0.88 | I55: 0 | J55: 1.44 | K55: 0 | L55: 0.91 | M55: 0 | N55: 0.37 | O55: 0 | P55: 1200 | Q55: 1 | R55: 0.34 | S55: 0 | T55: 0.33 | U55: 0 | V55: 0.41 | W55: 0 | X55: 1.22 | Y55: 0 | Z55: 1.79 | AA55: 0 | AB55: 0.81 | AC55: 0 | AD55: 0.77 | AE55: 0 | AF55: 1.26 | AG55: 0 | AH55: 0.37 | AI55: 0 | AJ55: 0.58 | AK55: 0 | AL55: 0.33 | AM55: 0 | AN55: 0.34 | AO55: 0 | AP55: 0.97 | AQ55: 0 | AR55: 0.45 | AS55: 0 | AT55: 0.33 | AU55: 0 | AV55: 0.56 | AW55: 0 | BB55: =MIN($B55,$D55,$F55,$H55,$J55,$L55,$N55,$P55,$R55,$T55,$V55,$X55,$Z55,$AB55,$AD55,$AF55,$AH55,$AJ55,$AL55,$AN55,$AP55,$AR55,$AT55,$AV55,$AX55,$AZ55) -> 0 | BC55: =MIN($C55,$E55,$G55,$I55,$K55,$M55,$O55,$Q55,$S55,$U55,$W55,$Y55,$AA55,$AC55,$AE55,$AG55,$AI55,$AK55,$AM55,$AO55,$AQ55,$AS55,$AU55,$AW55,$AY55,$BA55) -> 0 | BD55: =MEDIAN($B55,$D55,$F55,$H55,$J55,$L55,$N55,$P55,$R55,$T55,$V55,$X55,$Z55,$AB55,$AD55,$AF55,$AH55,$AJ55,$AL55,$AN55,$AP55,$AR55,$AT55,$AV55,$AX55,$AZ55) -> 0 | BE55: =MEDIAN($C55,$E55,$G55,$I55,$K55,$M55,$O55,$Q55,$S55,$U55,$W55,$Y55,$AA55,$AC55,$AE55,$AG55,$AI55,$AK55,$AM55,$AO55,$AQ55,$AS55,$AU55,$AW55,$AY55,$BA55) -> 0 | BF55: =MAX($B55,$D55,$F55,$H55,$J55,$L55,$N55,$P55,$R55,$T55,$V55,$X55,$Z55,$AB55,$AD55,$AF55,$AH55,$AJ55,$AL55,$AN55,$AP55,$AR55,$AT55,$AV55,$AX55,$AZ55) -> 0 | BG55: =MAX($C55,$E55,$G55,$I55,$K55,$M55,$O55,$Q55,$S55,$U55,$W55,$Y55,$AA55,$AC55,$AE55,$AG55,$AI55,$AK55,$AM55,$AO55,$AQ55,$AS55,$AU55,$AW55,$AY55,$BA55) -> 0
A56: ./cargobike-100_user-input-2 | B56: 0.37 | C56: 0 | D56: 0.57 | E56: 0 | F56: 0.48 | G56: 0 | H56: 0.88 | I56: 0 | J56: 1.5 | K56: 0 | L56: 0.88 | M56: 0 | N56: 0.36 | O56: 0 | P56: 646.07 | Q56: 0 | R56: 0.34 | S56: 0 | T56: 0.34 | U56: 0 | V56: 0.42 | W56: 0 | X56: 0.88 | Y56: 0 | Z56: 1.83 | AA56: 0 | AB56: 0.84 | AC56: 0 | AD56: 0.81 | AE56: 0 | AF56: 1.61 | AG56: 0 | AH56: 0.33 | AI56: 0 | AJ56: 0.93 | AK56: 0 | AL56: 0.34 | AM56: 0 | AN56: 0.33 | AO56: 0 | AP56: 0.98 | AQ56: 0 | AR56: 0.33 | AS56: 0 | AT56: 0.33 | AU56: 0 | AV56: 0.67 | AW56: 0 | BB56: =MIN($B56,$D56,$F56,$H56,$J56,$L56,$N56,$P56,$R56,$T56,$V56,$X56,$Z56,$AB56,$AD56,$AF56,$AH56,$AJ56,$AL56,$AN56,$AP56,$AR56,$AT56,$AV56,$AX56,$AZ56) -> 0 | BC56: =MIN($C56,$E56,$G56,$I56,$K56,$M56,$O56,$Q56,$S56,$U56,$W56,$Y56,$AA56,$AC56,$AE56,$AG56,$AI56,$AK56,$AM56,$AO56,$AQ56,$AS56,$AU56,$AW56,$AY56,$BA56) -> 0 | BD56: =MEDIAN($B56,$D56,$F56,$H56,$J56,$L56,$N56,$P56,$R56,$T56,$V56,$X56,$Z56,$AB56,$AD56,$AF56,$AH56,$AJ56,$AL56,$AN56,$AP56,$AR56,$AT56,$AV56,$AX56,$AZ56) -> 0 | BE56: =MEDIAN($C56,$E56,$G56,$I56,$K56,$M56,$O56,$Q56,$S56,$U56,$W56,$Y56,$AA56,$AC56,$AE56,$AG56,$AI56,$AK56,$AM56,$AO56,$AQ56,$AS56,$AU56,$AW56,$AY56,$BA56) -> 0 | BF56: =MAX($B56,$D56,$F56,$H56,$J56,$L56,$N56,$P56,$R56,$T56,$V56,$X56,$Z56,$AB56,$AD56,$AF56,$AH56,$AJ56,$AL56,$AN56,$AP56,$AR56,$AT56,$AV56,$AX56,$AZ56) -> 0 | BG56: =MAX($C56,$E56,$G56,$I56,$K56,$M56,$O56,$Q56,$S56,$U56,$W56,$Y56,$AA56,$AC56,$AE56,$AG56,$AI56,$AK56,$AM56,$AO56,$AQ56,$AS56,$AU56,$AW56,$AY56,$BA56) -> 0
A57: ./cargobike-100_user-input-3 | B57: 0.86 | C57: 0 | D57: 0.59 | E57: 0 | F57: 1200 | G57: 1 | H57: 1.69 | I57: 0 | J57: 1.84 | K57: 0 | L57: 2.49 | M57: 0 | N57: 0.54 | O57: 0 | P57: 1200 | Q57: 1 | R57: 0.75 | S57: 0 | T57: 0.53 | U57: 0 | V57: 0.55 | W57: 0 | X57: 1.27 | Y57: 0 | Z57: 2.16 | AA57: 0 | AB57: 1.2 | AC57: 0 | AD57: 1.43 | AE57: 0 | AF57: 1.55 | AG57: 0 | AH57: 0.5 | AI57: 0 | AJ57: 0.54 | AK57: 0 | AL57: 1.08 | AM57: 0 | AN57: 0.4 | AO57: 0 | AP57: 1.09 | AQ57: 0 | AR57: 0.53 | AS57: 0 | AT57: 0.53 | AU57: 0 | AV57: 0.61 | AW57: 0 | BB57: =MIN($B57,$D57,$F57,$H57,$J57,$L57,$N57,$P57,$R57,$T57,$V57,$X57,$Z57,$AB57,$AD57,$AF57,$AH57,$AJ57,$AL57,$AN57,$AP57,$AR57,$AT57,$AV57,$AX57,$AZ57) -> 0 | BC57: =MIN($C57,$E57,$G57,$I57,$K57,$M57,$O57,$Q57,$S57,$U57,$W57,$Y57,$AA57,$AC57,$AE57,$AG57,$AI57,$AK57,$AM57,$AO57,$AQ57,$AS57,$AU57,$AW57,$AY57,$BA57) -> 0 | BD57: =MEDIAN($B57,$D57,$F57,$H57,$J57,$L57,$N57,$P57,$R57,$T57,$V57,$X57,$Z57,$AB57,$AD57,$AF57,$AH57,$AJ57,$AL57,$AN57,$AP57,$AR57,$AT57,$AV57,$AX57,$AZ57) -> 0 | BE57: =MEDIAN($C57,$E57,$G57,$I57,$K57,$M57,$O57,$Q57,$S57,$U57,$W57,$Y57,$AA57,$AC57,$AE57,$AG57,$AI57,$AK57,$AM57,$AO57,$AQ57,$AS57,$AU57,$AW57,$AY57,$BA57) -> 0 | BF57: =MAX($B57,$D57,$F57,$H57,$J57,$L57,$N57,$P57,$R57,$T57,$V57,$X57,$Z57,$AB57,$AD57,$AF57,$AH57,$AJ57,$AL57,$AN57,$AP57,$AR57,$AT57,$AV57,$AX57,$AZ57) -> 0 | BG57: =MAX($C57,$E57,$G57,$I57,$K57,$M57,$O57,$Q57,$S57,$U57,$W57,$Y57,$AA57,$AC57,$AE57,$AG57,$AI57,$AK57,$AM57,$AO57,$AQ57,$AS57,$AU57,$AW57,$AY57,$BA57) -> 0
A58: ./cargobike-100_user-input-4 | B58: 0.49 | C58: 0 | D58: 0.48 | E58: 0 | F58: 170.62 | G58: 0 | H58: 1.64 | I58: 0 | J58: 1.7 | K58: 0 | L58: 2.85 | M58: 0 | N58: 0.41 | O58: 0 | P58: 150.38 | Q58: 0 | R58: 0.4 | S58: 0 | T58: 0.42 | U58: 0 | V58: 0.42 | W58: 0 | X58: 1.15 | Y58: 0 | Z58: 2.13 | AA58: 0 | AB58: 1.16 | AC58: 0 | AD58: 1.41 | AE58: 0 | AF58: 1.43 | AG58: 0 | AH58: 0.5 | AI58: 0 | AJ58: 0.52 | AK58: 0 | AL58: 1 | AM58: 0 | AN58: 0.4 | AO58: 0 | AP58: 0.96 | AQ58: 0 | AR58: 0.39 | AS58: 0 | AT58: 0.5 | AU58: 0 | AV58: 0.66 | AW58: 0 | BB58: =MIN($B58,$D58,$F58,$H58,$J58,$L58,$N58,$P58,$R58,$T58,$V58,$X58,$Z58,$AB58,$AD58,$AF58,$AH58,$AJ58,$AL58,$AN58,$AP58,$AR58,$AT58,$AV58,$AX58,$AZ58) -> 0 | BC58: =MIN($C58,$E58,$G58,$I58,$K58,$M58,$O58,$Q58,$S58,$U58,$W58,$Y58,$AA58,$AC58,$AE58,$AG58,$AI58,$AK58,$AM58,$AO58,$AQ58,$AS58,$AU58,$AW58,$AY58,$BA58) -> 0 | BD58: =MEDIAN($B58,$D58,$F58,$H58,$J58,$L58,$N58,$P58,$R58,$T58,$V58,$X58,$Z58,$AB58,$AD58,$AF58,$AH58,$AJ58,$AL58,$AN58,$AP58,$AR58,$AT58,$AV58,$AX58,$AZ58) -> 0 | BE58: =MEDIAN($C58,$E58,$G58,$I58,$K58,$M58,$O58,$Q58,$S58,$U58,$W58,$Y58,$AA58,$AC58,$AE58,$AG58,$AI58,$AK58,$AM58,$AO58,$AQ58,$AS58,$AU58,$AW58,$AY58,$BA58) -> 0 | BF58: =MAX($B58,$D58,$F58,$H58,$J58,$L58,$N58,$P58,$R58,$T58,$V58,$X58,$Z58,$AB58,$AD58,$AF58,$AH58,$AJ58,$AL58,$AN58,$AP58,$AR58,$AT58,$AV58,$AX58,$AZ58) -> 0 | BG58: =MAX($C58,$E58,$G58,$I58,$K58,$M58,$O58,$Q58,$S58,$U58,$W58,$Y58,$AA58,$AC58,$AE58,$AG58,$AI58,$AK58,$AM58,$AO58,$AQ58,$AS58,$AU58,$AW58,$AY58,$BA58) -> 0
A59: ./cargobike-200_user-input-0 | B59: 1.18 | C59: 0 | D59: 1.15 | E59: 0 | F59: 1.22 | G59: 0 | H59: 1.65 | I59: 0 | J59: 1.73 | K59: 0 | L59: 2.32 | M59: 0 | N59: 1 | O59: 0 | P59: 1.01 | Q59: 0 | R59: 0.89 | S59: 0 | T59: 1.12 | U59: 0 | V59: 0.79 | W59: 0 | X59: 1.47 | Y59: 0 | Z59: 2.1 | AA59: 0 | AB59: 1.18 | AC59: 0 | AD59: 1.41 | AE59: 0 | AF59: 1.61 | AG59: 0 | AH59: 0.63 | AI59: 0 | AJ59: 0.63 | AK59: 0 | AL59: 1.02 | AM59: 0 | AN59: 0.62 | AO59: 0 | AP59: 1.1 | AQ59: 0 | AR59: 0.55 | AS59: 0 | AT59: 0.55 | AU59: 0 | AV59: 0.72 | AW59: 0 | BB59: =MIN($B59,$D59,$F59,$H59,$J59,$L59,$N59,$P59,$R59,$T59,$V59,$X59,$Z59,$AB59,$AD59,$AF59,$AH59,$AJ59,$AL59,$AN59,$AP59,$AR59,$AT59,$AV59,$AX59,$AZ59) -> 0 | BC59: =MIN($C59,$E59,$G59,$I59,$K59,$M59,$O59,$Q59,$S59,$U59,$W59,$Y59,$AA59,$AC59,$AE59,$AG59,$AI59,$AK59,$AM59,$AO59,$AQ59,$AS59,$AU59,$AW59,$AY59,$BA59) -> 0 | BD59: =MEDIAN($B59,$D59,$F59,$H59,$J59,$L59,$N59,$P59,$R59,$T59,$V59,$X59,$Z59,$AB59,$AD59,$AF59,$AH59,$AJ59,$AL59,$AN59,$AP59,$AR59,$AT59,$AV59,$AX59,$AZ59) -> 0 | BE59: =MEDIAN($C59,$E59,$G59,$I59,$K59,$M59,$O59,$Q59,$S59,$U59,$W59,$Y59,$AA59,$AC59,$AE59,$AG59,$AI59,$AK59,$AM59,$AO59,$AQ59,$AS59,$AU59,$AW59,$AY59,$BA59) -> 0 | BF59: =MAX($B59,$D59,$F59,$H59,$J59,$L59,$N59,$P59,$R59,$T59,$V59,$X59,$Z59,$AB59,$AD59,$AF59,$AH59,$AJ59,$AL59,$AN59,$AP59,$AR59,$AT59,$AV59,$AX59,$AZ59) -> 0 | BG59: =MAX($C59,$E59,$G59,$I59,$K59,$M59,$O59,$Q59,$S59,$U59,$W59,$Y59,$AA59,$AC59,$AE59,$AG59,$AI59,$AK59,$AM59,$AO59,$AQ59,$AS59,$AU59,$AW59,$AY59,$BA59) -> 0
A60: ./cargobike-200_user-input-1 | B60: 1.03 | C60: 0 | D60: 0.92 | E60: 0 | F60: 1.49 | G60: 0 | H60: 1.72 | I60: 0 | J60: 1.66 | K60: 0 | L60: 2.62 | M60: 0 | N60: 1.14 | O60: 0 | P60: 1.23 | Q60: 0 | R60: 0.96 | S60: 0 | T60: 0.81 | U60: 0 | V60: 0.83 | W60: 0 | X60: 1.78 | Y60: 0 | Z60: 2.15 | AA60: 0 | AB60: 1.63 | AC60: 0 | AD60: 1.5 | AE60: 0 | AF60: 1.42 | AG60: 0 | AH60: 0.58 | AI60: 0 | AJ60: 0.61 | AK60: 0 | AL60: 1.09 | AM60: 0 | AN60: 0.54 | AO60: 0 | AP60: 1.07 | AQ60: 0 | AR60: 0.6 | AS60: 0 | AT60: 0.57 | AU60: 0 | AV60: 0.78 | AW60: 0 | BB60: =MIN($B60,$D60,$F60,$H60,$J60,$L60,$N60,$P60,$R60,$T60,$V60,$X60,$Z60,$AB60,$AD60,$AF60,$AH60,$AJ60,$AL60,$AN60,$AP60,$AR60,$AT60,$AV60,$AX60,$AZ60) -> 0 | BC60: =MIN($C60,$E60,$G60,$I60,$K60,$M60,$O60,$Q60,$S60,$U60,$W60,$Y60,$AA60,$AC60,$AE60,$AG60,$AI60,$AK60,$AM60,$AO60,$AQ60,$AS60,$AU60,$AW60,$AY60,$BA60) -> 0 | BD60: =MEDIAN($B60,$D60,$F60,$H60,$J60,$L60,$N60,$P60,$R60,$T60,$V60,$X60,$Z60,$AB60,$AD60,$AF60,$AH60,$AJ60,$AL60,$AN60,$AP60,$AR60,$AT60,$AV60,$AX60,$AZ60) -> 0 | BE60: =MEDIAN($C60,$E60,$G60,$I60,$K60,$M60,$O60,$Q60,$S60,$U60,$W60,$Y60,$AA60,$AC60,$AE60,$AG60,$AI60,$AK60,$AM60,$AO60,$AQ60,$AS60,$AU60,$AW60,$AY60,$BA60) -> 0 | BF60: =MAX($B60,$D60,$F60,$H60,$J60,$L60,$N60,$P60,$R60,$T60,$V60,$X60,$Z60,$AB60,$AD60,$AF60,$AH60,$AJ60,$AL60,$AN60,$AP60,$AR60,$AT60,$AV60,$AX60,$AZ60) -> 0 | BG60: =MAX($C60,$E60,$G60,$I60,$K60,$M60,$O60,$Q60,$S60,$U60,$W60,$Y60,$AA60,$AC60,$AE60,$AG60,$AI60,$AK60,$AM60,$AO60,$AQ60,$AS60,$AU60,$AW60,$AY60,$BA60) -> 0
A61: ./cargobike-200_user-input-2 | B61: 1.11 | C61: 0 | D61: 1.28 | E61: 0 | F61: 1.2 | G61: 0 | H61: 1.68 | I61: 0 | J61: 2.17 | K61: 0 | L61: 2.42 | M61: 0 | N61: 1.34 | O61: 0 | P61: 1.08 | Q61: 0 | R61: 1.01 | S61: 0 | T61: 0.89 | U61: 0 | V61: 0.86 | W61: 0 | X61: 2.13 | Y61: 0 | Z61: 2.17 | AA61: 0 | AB61: 1.6 | AC61: 0 | AD61: 1.46 | AE61: 0 | AF61: 1.46 | AG61: 0 | AH61: 0.59 | AI61: 0 | AJ61: 0.68 | AK61: 0 | AL61: 1.12 | AM61: 0 | AN61: 0.57 | AO61: 0 | AP61: 1.14 | AQ61: 0 | AR61: 0.56 | AS61: 0 | AT61: 0.56 | AU61: 0 | AV61: 0.79 | AW61: 0 | BB61: =MIN($B61,$D61,$F61,$H61,$J61,$L61,$N61,$P61,$R61,$T61,$V61,$X61,$Z61,$AB61,$AD61,$AF61,$AH61,$AJ61,$AL61,$AN61,$AP61,$AR61,$AT61,$AV61,$AX61,$AZ61) -> 0 | BC61: =MIN($C61,$E61,$G61,$I61,$K61,$M61,$O61,$Q61,$S61,$U61,$W61,$Y61,$AA61,$AC61,$AE61,$AG61,$AI61,$AK61,$AM61,$AO61,$AQ61,$AS61,$AU61,$AW61,$AY61,$BA61) -> 0 | BD61: =MEDIAN($B61,$D61,$F61,$H61,$J61,$L61,$N61,$P61,$R61,$T61,$V61,$X61,$Z61,$AB61,$AD61,$AF61,$AH61,$AJ61,$AL61,$AN61,$AP61,$AR61,$AT61,$AV61,$AX61,$AZ61) -> 0 | BE61: =MEDIAN($C61,$E61,$G61,$I61,$K61,$M61,$O61,$Q61,$S61,$U61,$W61,$Y61,$AA61,$AC61,$AE61,$AG61,$AI61,$AK61,$AM61,$AO61,$AQ61,$AS61,$AU61,$AW61,$AY61,$BA61) -> 0 | BF61: =MAX($B61,$D61,$F61,$H61,$J61,$L61,$N61,$P61,$R61,$T61,$V61,$X61,$Z61,$AB61,$AD61,$AF61,$AH61,$AJ61,$AL61,$AN61,$AP61,$AR61,$AT61,$AV61,$AX61,$AZ61) -> 0 | BG61: =MAX($C61,$E61,$G61,$I61,$K61,$M61,$O61,$Q61,$S61,$U61,$W61,$Y61,$AA61,$AC61,$AE61,$AG61,$AI61,$AK61,$AM61,$AO61,$AQ61,$AS61,$AU61,$AW61,$AY61,$BA61) -> 0
A62: ./cargobike-200_user-input-3 | B62: 1.81 | C62: 0 | D62: 1.48 | E62: 0 | F62: 1.66 | G62: 0 | H62: 3.27 | I62: 0 | J62: 2.83 | K62: 0 | L62: 2.83 | M62: 0 | N62: 1.88 | O62: 0 | P62: 1.41 | Q62: 0 | R62: 1.63 | S62: 0 | T62: 1.38 | U62: 0 | V62: 1.42 | W62: 0 | X62: 2.57 | Y62: 0 | Z62: 2.74 | AA62: 0 | AB62: 2.15 | AC62: 0 | AD62: 2.22 | AE62: 0 | AF62: 2.73 | AG62: 0 | AH62: 1.04 | AI62: 0 | AJ62: 0.64 | AK62: 0 | AL62: 1.12 | AM62: 0 | AN62: 0.61 | AO62: 0 | AP62: 1.13 | AQ62: 0 | AR62: 0.66 | AS62: 0 | AT62: 1.12 | AU62: 0 | AV62: 1.25 | AW62: 0 | BB62: =MIN($B62,$D62,$F62,$H62,$J62,$L62,$N62,$P62,$R62,$T62,$V62,$X62,$Z62,$AB62,$AD62,$AF62,$AH62,$AJ62,$AL62,$AN62,$AP62,$AR62,$AT62,$AV62,$AX62,$AZ62) -> 0 | BC62: =MIN($C62,$E62,$G62,$I62,$K62,$M62,$O62,$Q62,$S62,$U62,$W62,$Y62,$AA62,$AC62,$AE62,$AG62,$AI62,$AK62,$AM62,$AO62,$AQ62,$AS62,$AU62,$AW62,$AY62,$BA62) -> 0 | BD62: =MEDIAN($B62,$D62,$F62,$H62,$J62,$L62,$N62,$P62,$R62,$T62,$V62,$X62,$Z62,$AB62,$AD62,$AF62,$AH62,$AJ62,$AL62,$AN62,$AP62,$AR62,$AT62,$AV62,$AX62,$AZ62) -> 0 | BE62: =MEDIAN($C62,$E62,$G62,$I62,$K62,$M62,$O62,$Q62,$S62,$U62,$W62,$Y62,$AA62,$AC62,$AE62,$AG62,$AI62,$AK62,$AM62,$AO62,$AQ62,$AS62,$AU62,$AW62,$AY62,$BA62) -> 0 | BF62: =MAX($B62,$D62,$F62,$H62,$J62,$L62,$N62,$P62,$R62,$T62,$V62,$X62,$Z62,$AB62,$AD62,$AF62,$AH62,$AJ62,$AL62,$AN62,$AP62,$AR62,$AT62,$AV62,$AX62,$AZ62) -> 0 | BG62: =MAX($C62,$E62,$G62,$I62,$K62,$M62,$O62,$Q62,$S62,$U62,$W62,$Y62,$AA62,$AC62,$AE62,$AG62,$AI62,$AK62,$AM62,$AO62,$AQ62,$AS62,$AU62,$AW62,$AY62,$BA62) -> 0
A63: ./cargobike-200_user-input-4 | B63: 2.08 | C63: 0 | D63: 1200 | E63: 1 | F63: 1.99 | G63: 0 | H63: 3.14 | I63: 0 | J63: 4.6 | K63: 0 | L63: 2.86 | M63: 0 | N63: 2.25 | O63: 0 | P63: 1.73 | Q63: 0 | R63: 1.8 | S63: 0 | T63: 1.65 | U63: 0 | V63: 1.87 | W63: 0 | X63: 3.04 | Y63: 0 | Z63: 2.71 | AA63: 0 | AB63: 2.11 | AC63: 0 | AD63: 2.23 | AE63: 0 | AF63: 3.12 | AG63: 0 | AH63: 1.06 | AI63: 0 | AJ63: 2.4 | AK63: 0 | AL63: 1.04 | AM63: 0 | AN63: 0.68 | AO63: 0 | AP63: 1.12 | AQ63: 0 | AR63: 0.85 | AS63: 0 | AT63: 0.75 | AU63: 0 | AV63: 1.45 | AW63: 0 | BB63: =MIN($B63,$D63,$F63,$H63,$J63,$L63,$N63,$P63,$R63,$T63,$V63,$X63,$Z63,$AB63,$AD63,$AF63,$AH63,$AJ63,$AL63,$AN63,$AP63,$AR63,$AT63,$AV63,$AX63,$AZ63) -> 0 | BC63: =MIN($C63,$E63,$G63,$I63,$K63,$M63,$O63,$Q63,$S63,$U63,$W63,$Y63,$AA63,$AC63,$AE63,$AG63,$AI63,$AK63,$AM63,$AO63,$AQ63,$AS63,$AU63,$AW63,$AY63,$BA63) -> 0 | BD63: =MEDIAN($B63,$D63,$F63,$H63,$J63,$L63,$N63,$P63,$R63,$T63,$V63,$X63,$Z63,$AB63,$AD63,$AF63,$AH63,$AJ63,$AL63,$AN63,$AP63,$AR63,$AT63,$AV63,$AX63,$AZ63) -> 0 | BE63: =MEDIAN($C63,$E63,$G63,$I63,$K63,$M63,$O63,$Q63,$S63,$U63,$W63,$Y63,$AA63,$AC63,$AE63,$AG63,$AI63,$AK63,$AM63,$AO63,$AQ63,$AS63,$AU63,$AW63,$AY63,$BA63) -> 0 | BF63: =MAX($B63,$D63,$F63,$H63,$J63,$L63,$N63,$P63,$R63,$T63,$V63,$X63,$Z63,$AB63,$AD63,$AF63,$AH63,$AJ63,$AL63,$AN63,$AP63,$AR63,$AT63,$AV63,$AX63,$AZ63) -> 0 | BG63: =MAX($C63,$E63,$G63,$I63,$K63,$M63,$O63,$Q63,$S63,$U63,$W63,$Y63,$AA63,$AC63,$AE63,$AG63,$AI63,$AK63,$AM63,$AO63,$AQ63,$AS63,$AU63,$AW63,$AY63,$BA63) -> 0
A64: ./cargobike-300_user-input-0 | B64: 3.2 | C64: 0 | D64: 3.36 | E64: 0 | F64: 3.42 | G64: 0 | H64: 1.72 | I64: 0 | J64: 2.09 | K64: 0 | L64: 2.62 | M64: 0 | N64: 4.16 | O64: 0 | P64: 3 | Q64: 0 | R64: 2.99 | S64: 0 | T64: 2.51 | U64: 0 | V64: 2.69 | W64: 0 | X64: 2.12 | Y64: 0 | Z64: 2.17 | AA64: 0 | AB64: 1.58 | AC64: 0 | AD64: 1.47 | AE64: 0 | AF64: 1.64 | AG64: 0 | AH64: 0.88 | AI64: 0 | AJ64: 1.07 | AK64: 0 | AL64: 1.37 | AM64: 0 | AN64: 0.87 | AO64: 0 | AP64: 1.42 | AQ64: 0 | AR64: 0.92 | AS64: 0 | AT64: 0.91 | AU64: 0 | AV64: 1.23 | AW64: 0 | BB64: =MIN($B64,$D64,$F64,$H64,$J64,$L64,$N64,$P64,$R64,$T64,$V64,$X64,$Z64,$AB64,$AD64,$AF64,$AH64,$AJ64,$AL64,$AN64,$AP64,$AR64,$AT64,$AV64,$AX64,$AZ64) -> 0 | BC64: =MIN($C64,$E64,$G64,$I64,$K64,$M64,$O64,$Q64,$S64,$U64,$W64,$Y64,$AA64,$AC64,$AE64,$AG64,$AI64,$AK64,$AM64,$AO64,$AQ64,$AS64,$AU64,$AW64,$AY64,$BA64) -> 0 | BD64: =MEDIAN($B64,$D64,$F64,$H64,$J64,$L64,$N64,$P64,$R64,$T64,$V64,$X64,$Z64,$AB64,$AD64,$AF64,$AH64,$AJ64,$AL64,$AN64,$AP64,$AR64,$AT64,$AV64,$AX64,$AZ64) -> 0 | BE64: =MEDIAN($C64,$E64,$G64,$I64,$K64,$M64,$O64,$Q64,$S64,$U64,$W64,$Y64,$AA64,$AC64,$AE64,$AG64,$AI64,$AK64,$AM64,$AO64,$AQ64,$AS64,$AU64,$AW64,$AY64,$BA64) -> 0 | BF64: =MAX($B64,$D64,$F64,$H64,$J64,$L64,$N64,$P64,$R64,$T64,$V64,$X64,$Z64,$AB64,$AD64,$AF64,$AH64,$AJ64,$AL64,$AN64,$AP64,$AR64,$AT64,$AV64,$AX64,$AZ64) -> 0 | BG64: =MAX($C64,$E64,$G64,$I64,$K64,$M64,$O64,$Q64,$S64,$U64,$W64,$Y64,$AA64,$AC64,$AE64,$AG64,$AI64,$AK64,$AM64,$AO64,$AQ64,$AS64,$AU64,$AW64,$AY64,$BA64) -> 0
A65: ./cargobike-300_user-input-1 | B65: 4.91 | C65: 0 | D65: 4.96 | E65: 0 | F65: 4.62 | G65: 0 | H65: 3.18 | I65: 0 | J65: 4.48 | K65: 0 | L65: 2.93 | M65: 0 | N65: 7.24 | O65: 0 | P65: 3.78 | Q65: 0 | R65: 3.94 | S65: 0 | T65: 3.61 | U65: 0 | V65: 3.76 | W65: 0 | X65: 3.01 | Y65: 0 | Z65: 2.69 | AA65: 0 | AB65: 2.13 | AC65: 0 | AD65: 2.17 | AE65: 0 | AF65: 3 | AG65: 0 | AH65: 1.39 | AI65: 0 | AJ65: 2.38 | AK65: 0 | AL65: 1.4 | AM65: 0 | AN65: 0.95 | AO65: 0 | AP65: 1.46 | AQ65: 0 | AR65: 0.99 | AS65: 0 | AT65: 1.08 | AU65: 0 | AV65: 1.93 | AW65: 0 | BB65: =MIN($B65,$D65,$F65,$H65,$J65,$L65,$N65,$P65,$R65,$T65,$V65,$X65,$Z65,$AB65,$AD65,$AF65,$AH65,$AJ65,$AL65,$AN65,$AP65,$AR65,$AT65,$AV65,$AX65,$AZ65) -> 0 | BC65: =MIN($C65,$E65,$G65,$I65,$K65,$M65,$O65,$Q65,$S65,$U65,$W65,$Y65,$AA65,$AC65,$AE65,$AG65,$AI65,$AK65,$AM65,$AO65,$AQ65,$AS65,$AU65,$AW65,$AY65,$BA65) -> 0 | BD65: =MEDIAN($B65,$D65,$F65,$H65,$J65,$L65,$N65,$P65,$R65,$T65,$V65,$X65,$Z65,$AB65,$AD65,$AF65,$AH65,$AJ65,$AL65,$AN65,$AP65,$AR65,$AT65,$AV65,$AX65,$AZ65) -> 0 | BE65: =MEDIAN($C65,$E65,$G65,$I65,$K65,$M65,$O65,$Q65,$S65,$U65,$W65,$Y65,$AA65,$AC65,$AE65,$AG65,$AI65,$AK65,$AM65,$AO65,$AQ65,$AS65,$AU65,$AW65,$AY65,$BA65) -> 0 | BF65: =MAX($B65,$D65,$F65,$H65,$J65,$L65,$N65,$P65,$R65,$T65,$V65,$X65,$Z65,$AB65,$AD65,$AF65,$AH65,$AJ65,$AL65,$AN65,$AP65,$AR65,$AT65,$AV65,$AX65,$AZ65) -> 0 | BG65: =MAX($C65,$E65,$G65,$I65,$K65,$M65,$O65,$Q65,$S65,$U65,$W65,$Y65,$AA65,$AC65,$AE65,$AG65,$AI65,$AK65,$AM65,$AO65,$AQ65,$AS65,$AU65,$AW65,$AY65,$BA65) -> 0
... A103: ./cargobike-nested-500_user-input-4 | B103: 1200 | C103: 1 | D103: 1200 | E103: 1 | F103: 1200 | G103: 1 | H103: 101.3 | I103: 0 | J103: 69.93 | K103: 0 | L103: 231.6 | M103: 0 | N103: 1200 | O103: 1 | P103: 1200 | Q103: 1 | R103: 1200 | S103: 1 | T103: 1200 | U103: 1 | V103: 1200 | W103: 1 | X103: 136.24 | Y103: 0 | Z103: 91.13 | AA103: 0 | AB103: 95.37 | AC103: 0 | AD103: 83.04 | AE103: 0 | AF103: 93.49 | AG103: 0 | AH103: 23.5 | AI103: 0 | AJ103: 15 | AK103: 0 | AL103: 207.3 | AM103: 0 | AN103: 11.05 | AO103: 0 | AP103: 21.95 | AQ103: 0 | AR103: 12.17 | AS103: 0 | AT103: 23.2 | AU103: 0 | AV103: 24.75 | AW103: 0 | BB103: =MIN($B103,$D103,$F103,$H103,$J103,$L103,$N103,$P103,$R103,$T103,$V103,$X103,$Z103,$AB103,$AD103,$AF103,$AH103,$AJ103,$AL103,$AN103,$AP103,$AR103,$AT103,$AV103,$AX103,$AZ103) -> 0 | BC103: =MIN($C103,$E103,$G103,$I103,$K103,$M103,$O103,$Q103,$S103,$U103,$W103,$Y103,$AA103,$AC103,$AE103,$AG103,$AI103,$AK103,$AM103,$AO103,$AQ103,$AS103,$AU103,$AW103,$AY103,$BA103) -> 0 | BD103: =MEDIAN($B103,$D103,$F103,$H103,$J103,$L103,$N103,$P103,$R103,$T103,$V103,$X103,$Z103,$AB103,$AD103,$AF103,$AH103,$AJ103,$AL103,$AN103,$AP103,$AR103,$AT103,$AV103,$AX103,$AZ103) -> 0 | BE103: =MEDIAN($C103,$E103,$G103,$I103,$K103,$M103,$O103,$Q103,$S103,$U103,$W103,$Y103,$AA103,$AC103,$AE103,$AG103,$AI103,$AK103,$AM103,$AO103,$AQ103,$AS103,$AU103,$AW103,$AY103,$BA103) -> 0 | BF103: =MAX($B103,$D103,$F103,$H103,$J103,$L103,$N103,$P103,$R103,$T103,$V103,$X103,$Z103,$AB103,$AD103,$AF103,$AH103,$AJ103,$AL103,$AN103,$AP103,$AR103,$AT103,$AV103,$AX103,$AZ103) -> 0 | BG103: =MAX($C103,$E103,$G103,$I103,$K103,$M103,$O103,$Q103,$S103,$U103,$W103,$Y103,$AA103,$AC103,$AE103,$AG103,$AI103,$AK103,$AM103,$AO103,$AQ103,$AS103,$AU103,$AW103,$AY103,$BA103) -> 0
A105: SUM | B105: =SUM(B$3:B$103) -> 0 | C105: =SUM(C$3:C$103) -> 0 | D105: =SUM(D$3:D$103) -> 0 | E105: =SUM(E$3:E$103) -> 0 | F105: =SUM(F$3:F$103) -> 0 | G105: =SUM(G$3:G$103) -> 0 | H105: =SUM(H$3:H$103) -> 0 | I105: =SUM(I$3:I$103) -> 0 | ... BG105: =SUM(BG$3:BG$103) -> 0
A106: AVG | B106: =AVERAGE(B$3:B$103) -> 0 | C106: =AVERAGE(C$3:C$103) -> 0 | D106: =AVERAGE(D$3:D$103) -> 0 | E106: =AVERAGE(E$3:E$103) -> 0 | F106: =AVERAGE(F$3:F$103) -> 0 | G106: =AVERAGE(G$3:G$103) -> 0 | H106: =AVERAGE(H$3:H$103) -> 0 | I106: =AVERAGE(I$3:I$103) -> 0 | ... BG106: =AVERAGE(BG$3:BG$103) -> 0
A107: DEV | B107: =STDEV(B$3:B$103) -> 0 | C107: =STDEV(C$3:C$103) -> 0 | D107: =STDEV(D$3:D$103) -> 0 | E107: =STDEV(E$3:E$103) -> 0 | F107: =STDEV(F$3:F$103) -> 0 | G107: =STDEV(G$3:G$103) -> 0 | H107: =STDEV(H$3:H$103) -> 0 | I107: =STDEV(I$3:I$103) -> 0 | ... BG107: =STDEV(BG$3:BG$103) -> 0
A108: DST | B108: =SUMPRODUCT(--(B$3:B$103-$BB$3:$BB$103)^2)^0.5 -> 0 | C108: =SUMPRODUCT(--(C$3:C$103-$BC$3:$BC$103)^2)^0.5 -> 0 | D108: =SUMPRODUCT(--(D$3:D$103-$BB$3:$BB$103)^2)^0.5 -> 0 | E108: =SUMPRODUCT(--(E$3:E$103-$BC$3:$BC$103)^2)^0.5 -> 0 | F108: =SUMPRODUCT(--(F$3:F$103-$BB$3:$BB$103)^2)^0.5 -> 0 | G108: =SUMPRODUCT(--(G$3:G$103-$BC$3:$BC$103)^2)^0.5 -> 0 | H108: =SUMPRODUCT(--(H$3:H$103-$BB$3:$BB$103)^2)^0.5 -> 0 | I108: =SUMPRODUCT(--(I$3:I$103-$BC$3:$BC$103)^2)^0.5 -> 0 | J108: =SUMPRODUCT(--(J$3:J$103-$BB$3:$BB$103)^2)^0.5 -> 0 | K108: =SUMPRODUCT(--(K$3:K$103-$BC$3:$BC$103)^2)^0.5 -> 0 | L108: =SUMPRODUCT(--(L$3:L$103-$BB$3:$BB$103)^2)^0.5 -> 0 | M108: =SUMPRODUCT(--(M$3:M$103-$BC$3:$BC$103)^2)^0.5 -> 0 | N108: =SUMPRODUCT(--(N$3:N$103-$BB$3:$BB$103)^2)^0.5 -> 0 | O108: =SUMPRODUCT(--(O$3:O$103-$BC$3:$BC$103)^2)^0.5 -> 0 | P108: =SUMPRODUCT(--(P$3:P$103-$BB$3:$BB$103)^2)^0.5 -> 0 | Q108: =SUMPRODUCT(--(Q$3:Q$103-$BC$3:$BC$103)^2)^0.5 -> 0 | R108: =SUMPRODUCT(--(R$3:R$103-$BB$3:$BB$103)^2)^0.5 -> 0 | S108: =SUMPRODUCT(--(S$3:S$103-$BC$3:$BC$103)^2)^0.5 -> 0 | T108: =SUMPRODUCT(--(T$3:T$103-$BB$3:$BB$103)^2)^0.5 -> 0 | U108: =SUMPRODUCT(--(U$3:U$103-$BC$3:$BC$103)^2)^0.5 -> 0 | V108: =SUMPRODUCT(--(V$3:V$103-$BB$3:$BB$103)^2)^0.5 -> 0 | W108: =SUMPRODUCT(--(W$3:W$103-$BC$3:$BC$103)^2)^0.5 -> 0 | X108: =SUMPRODUCT(--(X$3:X$103-$BB$3:$BB$103)^2)^0.5 -> 0 | Y108: =SUMPRODUCT(--(Y$3:Y$103-$BC$3:$BC$103)^2)^0.5 -> 0 | Z108: =SUMPRODUCT(--(Z$3:Z$103-$BB$3:$BB$103)^2)^0.5 -> 0 | AA108: =SUMPRODUCT(--(AA$3:AA$103-$BC$3:$BC$103)^2)^0.5 -> 0 | AB108: =SUMPRODUCT(--(AB$3:AB$103-$BB$3:$BB$103)^2)^0.5 -> 0 | AC108: =SUMPRODUCT(--(AC$3:AC$103-$BC$3:$BC$103)^2)^0.5 -> 0 | AD108: =SUMPRODUCT(--(AD$3:AD$103-$BB$3:$BB$103)^2)^0.5 -> 0 | AE108: =SUMPRODUCT(--(AE$3:AE$103-$BC$3:$BC$103)^2)^0.5 -> 0 | AF108: =SUMPRODUCT(--(AF$3:AF$103-$BB$3:$BB$103)^2)^0.5 -> 0 | AG108: =SUMPRODUCT(--(AG$3:AG$103-$BC$3:$BC$103)^2)^0.5 -> 0 | AH108: =SUMPRODUCT(--(AH$3:AH$103-$BB$3:$BB$103)^2)^0.5 -> 0 | AI108: =SUMPRODUCT(--(AI$3:AI$103-$BC$3:$BC$103)^2)^0.5 -> 0 | AJ108: =SUMPRODUCT(--(AJ$3:AJ$103-$BB$3:$BB$103)^2)^0.5 -> 0 | AK108: =SUMPRODUCT(--(AK$3:AK$103-$BC$3:$BC$103)^2)^0.5 -> 0 | AL108: =SUMPRODUCT(--(AL$3:AL$103-$BB$3:$BB$103)^2)^0.5 -> 0 | AM108: =SUMPRODUCT(--(AM$3:AM$103-$BC$3:$BC$103)^2)^0.5 -> 0 | AN108: =SUMPRODUCT(--(AN$3:AN$103-$BB$3:$BB$103)^2)^0.5 -> 0 | AO108: =SUMPRODUCT(--(AO$3:AO$103-$BC$3:$BC$103)^2)^0.5 -> 0 | AP108: =SUMPRODUCT(--(AP$3:AP$103-$BB$3:$BB$103)^2)^0.5 -> 0 | AQ108: =SUMPRODUCT(--(AQ$3:AQ$103-$BC$3:$BC$103)^2)^0.5 -> 0 | AR108: =SUMPRODUCT(--(AR$3:AR$103-$BB$3:$BB$103)^2)^0.5 -> 0 | AS108: =SUMPRODUCT(--(AS$3:AS$103-$BC$3:$BC$103)^2)^0.5 -> 0 | AT108: =SUMPRODUCT(--(AT$3:AT$103-$BB$3:$BB$103)^2)^0.5 -> 0 | AU108: =SUMPRODUCT(--(AU$3:AU$103-$BC$3:$BC$103)^2)^0.5 -> 0 | AV108: =SUMPRODUCT(--(AV$3:AV$103-$BB$3:$BB$103)^2)^0.5 -> 0 | AW108: =SUMPRODUCT(--(AW$3:AW$103-$BC$3:$BC$103)^2)^0.5 -> 0 | AX108: =SUMPRODUCT(--(AX$3:AX$103-$BB$3:$BB$103)^2)^0.5 -> 0 | AY108: =SUMPRODUCT(--(AY$3:AY$103-$BC$3:$BC$103)^2)^0.5 -> 0 | AZ108: =SUMPRODUCT(--(AZ$3:AZ$103-$BB$3:$BB$103)^2)^0.5 -> 0 | BA108: =SUMPRODUCT(--(BA$3:BA$103-$BC$3:$BC$103)^2)^0.5 -> 0
A109: BEST | B109: =SUMPRODUCT(NOT(ISBLANK(B$3:B$103))*(B$3:B$103=$BB$3:$BB$103)) -> 0 | C109: =SUMPRODUCT(NOT(ISBLANK(C$3:C$103))*(C$3:C$103=$BC$3:$BC$103)) -> 0 | D109: =SUMPRODUCT(NOT(ISBLANK(D$3:D$103))*(D$3:D$103=$BB$3:$BB$103)) -> 0 | E109: =SUMPRODUCT(NOT(ISBLANK(E$3:E$103))*(E$3:E$103=$BC$3:$BC$103)) -> 0 | F109: =SUMPRODUCT(NOT(ISBLANK(F$3:F$103))*(F$3:F$103=$BB$3:$BB$103)) -> 0 | G109: =SUMPRODUCT(NOT(ISBLANK(G$3:G$103))*(G$3:G$103=$BC$3:$BC$103)) -> 0 | H109: =SUMPRODUCT(NOT(ISBLANK(H$3:H$103))*(H$3:H$103=$BB$3:$BB$103)) -> 0 | I109: =SUMPRODUCT(NOT(ISBLANK(I$3:I$103))*(I$3:I$103=$BC$3:$BC$103)) -> 0 | J109: =SUMPRODUCT(NOT(ISBLANK(J$3:J$103))*(J$3:J$103=$BB$3:$BB$103)) -> 0 | K109: =SUMPRODUCT(NOT(ISBLANK(K$3:K$103))*(K$3:K$103=$BC$3:$BC$103)) -> 0 | L109: =SUMPRODUCT(NOT(ISBLANK(L$3:L$103))*(L$3:L$103=$BB$3:$BB$103)) -> 0 | M109: =SUMPRODUCT(NOT(ISBLANK(M$3:M$103))*(M$3:M$103=$BC$3:$BC$103)) -> 0 | N109: =SUMPRODUCT(NOT(ISBLANK(N$3:N$103))*(N$3:N$103=$BB$3:$BB$103)) -> 0 | O109: =SUMPRODUCT(NOT(ISBLANK(O$3:O$103))*(O$3:O$103=$BC$3:$BC$103)) -> 0 | P109: =SUMPRODUCT(NOT(ISBLANK(P$3:P$103))*(P$3:P$103=$BB$3:$BB$103)) -> 0 | Q109: =SUMPRODUCT(NOT(ISBLANK(Q$3:Q$103))*(Q$3:Q$103=$BC$3:$BC$103)) -> 0 | R109: =SUMPRODUCT(NOT(ISBLANK(R$3:R$103))*(R$3:R$103=$BB$3:$BB$103)) -> 0 | S109: =SUMPRODUCT(NOT(ISBLANK(S$3:S$103))*(S$3:S$103=$BC$3:$BC$103)) -> 0 | T109: =SUMPRODUCT(NOT(ISBLANK(T$3:T$103))*(T$3:T$103=$BB$3:$BB$103)) -> 0 | U109: =SUMPRODUCT(NOT(ISBLANK(U$3:U$103))*(U$3:U$103=$BC$3:$BC$103)) -> 0 | V109: =SUMPRODUCT(NOT(ISBLANK(V$3:V$103))*(V$3:V$103=$BB$3:$BB$103)) -> 0 | W109: =SUMPRODUCT(NOT(ISBLANK(W$3:W$103))*(W$3:W$103=$BC$3:$BC$103)) -> 0 | X109: =SUMPRODUCT(NOT(ISBLANK(X$3:X$103))*(X$3:X$103=$BB$3:$BB$103)) -> 0 | Y109: =SUMPRODUCT(NOT(ISBLANK(Y$3:Y$103))*(Y$3:Y$103=$BC$3:$BC$103)) -> 0 | Z109: =SUMPRODUCT(NOT(ISBLANK(Z$3:Z$103))*(Z$3:Z$103=$BB$3:$BB$103)) -> 0 | AA109: =SUMPRODUCT(NOT(ISBLANK(AA$3:AA$103))*(AA$3:AA$103=$BC$3:$BC$103)) -> 0 | AB109: =SUMPRODUCT(NOT(ISBLANK(AB$3:AB$103))*(AB$3:AB$103=$BB$3:$BB$103)) -> 0 | AC109: =SUMPRODUCT(NOT(ISBLANK(AC$3:AC$103))*(AC$3:AC$103=$BC$3:$BC$103)) -> 0 | AD109: =SUMPRODUCT(NOT(ISBLANK(AD$3:AD$103))*(AD$3:AD$103=$BB$3:$BB$103)) -> 0 | AE109: =SUMPRODUCT(NOT(ISBLANK(AE$3:AE$103))*(AE$3:AE$103=$BC$3:$BC$103)) -> 0 | AF109: =SUMPRODUCT(NOT(ISBLANK(AF$3:AF$103))*(AF$3:AF$103=$BB$3:$BB$103)) -> 0 | AG109: =SUMPRODUCT(NOT(ISBLANK(AG$3:AG$103))*(AG$3:AG$103=$BC$3:$BC$103)) -> 0 | AH109: =SUMPRODUCT(NOT(ISBLANK(AH$3:AH$103))*(AH$3:AH$103=$BB$3:$BB$103)) -> 0 | AI109: =SUMPRODUCT(NOT(ISBLANK(AI$3:AI$103))*(AI$3:AI$103=$BC$3:$BC$103)) -> 0 | AJ109: =SUMPRODUCT(NOT(ISBLANK(AJ$3:AJ$103))*(AJ$3:AJ$103=$BB$3:$BB$103)) -> 0 | AK109: =SUMPRODUCT(NOT(ISBLANK(AK$3:AK$103))*(AK$3:AK$103=$BC$3:$BC$103)) -> 0 | AL109: =SUMPRODUCT(NOT(ISBLANK(AL$3:AL$103))*(AL$3:AL$103=$BB$3:$BB$103)) -> 0 | AM109: =SUMPRODUCT(NOT(ISBLANK(AM$3:AM$103))*(AM$3:AM$103=$BC$3:$BC$103)) -> 0 | AN109: =SUMPRODUCT(NOT(ISBLANK(AN$3:AN$103))*(AN$3:AN$103=$BB$3:$BB$103)) -> 0 | AO109: =SUMPRODUCT(NOT(ISBLANK(AO$3:AO$103))*(AO$3:AO$103=$BC$3:$BC$103)) -> 0 | AP109: =SUMPRODUCT(NOT(ISBLANK(AP$3:AP$103))*(AP$3:AP$103=$BB$3:$BB$103)) -> 0 | AQ109: =SUMPRODUCT(NOT(ISBLANK(AQ$3:AQ$103))*(AQ$3:AQ$103=$BC$3:$BC$103)) -> 0 | AR109: =SUMPRODUCT(NOT(ISBLANK(AR$3:AR$103))*(AR$3:AR$103=$BB$3:$BB$103)) -> 0 | AS109: =SUMPRODUCT(NOT(ISBLANK(AS$3:AS$103))*(AS$3:AS$103=$BC$3:$BC$103)) -> 0 | AT109: =SUMPRODUCT(NOT(ISBLANK(AT$3:AT$103))*(AT$3:AT$103=$BB$3:$BB$103)) -> 0 | AU109: =SUMPRODUCT(NOT(ISBLANK(AU$3:AU$103))*(AU$3:AU$103=$BC$3:$BC$103)) -> 0 | AV109: =SUMPRODUCT(NOT(ISBLANK(AV$3:AV$103))*(AV$3:AV$103=$BB$3:$BB$103)) -> 0 | AW109: =SUMPRODUCT(NOT(ISBLANK(AW$3:AW$103))*(AW$3:AW$103=$BC$3:$BC$103)) -> 0 | AX109: =SUMPRODUCT(NOT(ISBLANK(AX$3:AX$103))*(AX$3:AX$103=$BB$3:$BB$103)) -> 0 | AY109: =SUMPRODUCT(NOT(ISBLANK(AY$3:AY$103))*(AY$3:AY$103=$BC$3:$BC$103)) -> 0 | AZ109: =SUMPRODUCT(NOT(ISBLANK(AZ$3:AZ$103))*(AZ$3:AZ$103=$BB$3:$BB$103)) -> 0 | BA109: =SUMPRODUCT(NOT(ISBLANK(BA$3:BA$103))*(BA$3:BA$103=$BC$3:$BC$103)) -> 0
A110: BETTER | B110: =SUMPRODUCT(NOT(ISBLANK(B$3:B$103))*(B$3:B$103<$BD$3:$BD$103)) -> 0 | C110: =SUMPRODUCT(NOT(ISBLANK(C$3:C$103))*(C$3:C$103<$BE$3:$BE$103)) -> 0 | D110: =SUMPRODUCT(NOT(ISBLANK(D$3:D$103))*(D$3:D$103<$BD$3:$BD$103)) -> 0 | E110: =SUMPRODUCT(NOT(ISBLANK(E$3:E$103))*(E$3:E$103<$BE$3:$BE$103)) -> 0 | F110: =SUMPRODUCT(NOT(ISBLANK(F$3:F$103))*(F$3:F$103<$BD$3:$BD$103)) -> 0 | G110: =SUMPRODUCT(NOT(ISBLANK(G$3:G$103))*(G$3:G$103<$BE$3:$BE$103)) -> 0 | H110: =SUMPRODUCT(NOT(ISBLANK(H$3:H$103))*(H$3:H$103<$BD$3:$BD$103)) -> 0 | I110: =SUMPRODUCT(NOT(ISBLANK(I$3:I$103))*(I$3:I$103<$BE$3:$BE$103)) -> 0 | J110: =SUMPRODUCT(NOT(ISBLANK(J$3:J$103))*(J$3:J$103<$BD$3:$BD$103)) -> 0 | K110: =SUMPRODUCT(NOT(ISBLANK(K$3:K$103))*(K$3:K$103<$BE$3:$BE$103)) -> 0 | L110: =SUMPRODUCT(NOT(ISBLANK(L$3:L$103))*(L$3:L$103<$BD$3:$BD$103)) -> 0 | M110: =SUMPRODUCT(NOT(ISBLANK(M$3:M$103))*(M$3:M$103<$BE$3:$BE$103)) -> 0 | N110: =SUMPRODUCT(NOT(ISBLANK(N$3:N$103))*(N$3:N$103<$BD$3:$BD$103)) -> 0 | O110: =SUMPRODUCT(NOT(ISBLANK(O$3:O$103))*(O$3:O$103<$BE$3:$BE$103)) -> 0 | P110: =SUMPRODUCT(NOT(ISBLANK(P$3:P$103))*(P$3:P$103<$BD$3:$BD$103)) -> 0 | Q110: =SUMPRODUCT(NOT(ISBLANK(Q$3:Q$103))*(Q$3:Q$103<$BE$3:$BE$103)) -> 0 | R110: =SUMPRODUCT(NOT(ISBLANK(R$3:R$103))*(R$3:R$103<$BD$3:$BD$103)) -> 0 | S110: =SUMPRODUCT(NOT(ISBLANK(S$3:S$103))*(S$3:S$103<$BE$3:$BE$103)) -> 0 | T110: =SUMPRODUCT(NOT(ISBLANK(T$3:T$103))*(T$3:T$103<$BD$3:$BD$103)) -> 0 | U110: =SUMPRODUCT(NOT(ISBLANK(U$3:U$103))*(U$3:U$103<$BE$3:$BE$103)) -> 0 | V110: =SUMPRODUCT(NOT(ISBLANK(V$3:V$103))*(V$3:V$103<$BD$3:$BD$103)) -> 0 | W110: =SUMPRODUCT(NOT(ISBLANK(W$3:W$103))*(W$3:W$103<$BE$3:$BE$103)) -> 0 | X110: =SUMPRODUCT(NOT(ISBLANK(X$3:X$103))*(X$3:X$103<$BD$3:$BD$103)) -> 0 | Y110: =SUMPRODUCT(NOT(ISBLANK(Y$3:Y$103))*(Y$3:Y$103<$BE$3:$BE$103)) -> 0 | Z110: =SUMPRODUCT(NOT(ISBLANK(Z$3:Z$103))*(Z$3:Z$103<$BD$3:$BD$103)) -> 0 | AA110: =SUMPRODUCT(NOT(ISBLANK(AA$3:AA$103))*(AA$3:AA$103<$BE$3:$BE$103)) -> 0 | AB110: =SUMPRODUCT(NOT(ISBLANK(AB$3:AB$103))*(AB$3:AB$103<$BD$3:$BD$103)) -> 0 | AC110: =SUMPRODUCT(NOT(ISBLANK(AC$3:AC$103))*(AC$3:AC$103<$BE$3:$BE$103)) -> 0 | AD110: =SUMPRODUCT(NOT(ISBLANK(AD$3:AD$103))*(AD$3:AD$103<$BD$3:$BD$103)) -> 0 | AE110: =SUMPRODUCT(NOT(ISBLANK(AE$3:AE$103))*(AE$3:AE$103<$BE$3:$BE$103)) -> 0 | AF110: =SUMPRODUCT(NOT(ISBLANK(AF$3:AF$103))*(AF$3:AF$103<$BD$3:$BD$103)) -> 0 | AG110: =SUMPRODUCT(NOT(ISBLANK(AG$3:AG$103))*(AG$3:AG$103<$BE$3:$BE$103)) -> 0 | AH110: =SUMPRODUCT(NOT(ISBLANK(AH$3:AH$103))*(AH$3:AH$103<$BD$3:$BD$103)) -> 0 | AI110: =SUMPRODUCT(NOT(ISBLANK(AI$3:AI$103))*(AI$3:AI$103<$BE$3:$BE$103)) -> 0 | AJ110: =SUMPRODUCT(NOT(ISBLANK(AJ$3:AJ$103))*(AJ$3:AJ$103<$BD$3:$BD$103)) -> 0 | AK110: =SUMPRODUCT(NOT(ISBLANK(AK$3:AK$103))*(AK$3:AK$103<$BE$3:$BE$103)) -> 0 | AL110: =SUMPRODUCT(NOT(ISBLANK(AL$3:AL$103))*(AL$3:AL$103<$BD$3:$BD$103)) -> 0 | AM110: =SUMPRODUCT(NOT(ISBLANK(AM$3:AM$103))*(AM$3:AM$103<$BE$3:$BE$103)) -> 0 | AN110: =SUMPRODUCT(NOT(ISBLANK(AN$3:AN$103))*(AN$3:AN$103<$BD$3:$BD$103)) -> 0 | AO110: =SUMPRODUCT(NOT(ISBLANK(AO$3:AO$103))*(AO$3:AO$103<$BE$3:$BE$103)) -> 0 | AP110: =SUMPRODUCT(NOT(ISBLANK(AP$3:AP$103))*(AP$3:AP$103<$BD$3:$BD$103)) -> 0 | AQ110: =SUMPRODUCT(NOT(ISBLANK(AQ$3:AQ$103))*(AQ$3:AQ$103<$BE$3:$BE$103)) -> 0 | AR110: =SUMPRODUCT(NOT(ISBLANK(AR$3:AR$103))*(AR$3:AR$103<$BD$3:$BD$103)) -> 0 | AS110: =SUMPRODUCT(NOT(ISBLANK(AS$3:AS$103))*(AS$3:AS$103<$BE$3:$BE$103)) -> 0 | AT110: =SUMPRODUCT(NOT(ISBLANK(AT$3:AT$103))*(AT$3:AT$103<$BD$3:$BD$103)) -> 0 | AU110: =SUMPRODUCT(NOT(ISBLANK(AU$3:AU$103))*(AU$3:AU$103<$BE$3:$BE$103)) -> 0 | AV110: =SUMPRODUCT(NOT(ISBLANK(AV$3:AV$103))*(AV$3:AV$103<$BD$3:$BD$103)) -> 0 | AW110: =SUMPRODUCT(NOT(ISBLANK(AW$3:AW$103))*(AW$3:AW$103<$BE$3:$BE$103)) -> 0 | AX110: =SUMPRODUCT(NOT(ISBLANK(AX$3:AX$103))*(AX$3:AX$103<$BD$3:$BD$103)) -> 0 | AY110: =SUMPRODUCT(NOT(ISBLANK(AY$3:AY$103))*(AY$3:AY$103<$BE$3:$BE$103)) -> 0 | AZ110: =SUMPRODUCT(NOT(ISBLANK(AZ$3:AZ$103))*(AZ$3:AZ$103<$BD$3:$BD$103)) -> 0 | BA110: =SUMPRODUCT(NOT(ISBLANK(BA$3:BA$103))*(BA$3:BA$103<$BE$3:$BE$103)) -> 0
A111: WORSE | B111: =SUMPRODUCT((NOT(ISBLANK(B$3:B$103))*(B$3:B$103>$BD$3:$BD$103))+ISBLANK(B$3:B$103)) -> 0 | C111: =SUMPRODUCT((NOT(ISBLANK(C$3:C$103))*(C$3:C$103>$BE$3:$BE$103))+ISBLANK(C$3:C$103)) -> 0 | D111: =SUMPRODUCT((NOT(ISBLANK(D$3:D$103))*(D$3:D$103>$BD$3:$BD$103))+ISBLANK(D$3:D$103)) -> 0 | E111: =SUMPRODUCT((NOT(ISBLANK(E$3:E$103))*(E$3:E$103>$BE$3:$BE$103))+ISBLANK(E$3:E$103)) -> 0 | F111: =SUMPRODUCT((NOT(ISBLANK(F$3:F$103))*(F$3:F$103>$BD$3:$BD$103))+ISBLANK(F$3:F$103)) -> 0 | G111: =SUMPRODUCT((NOT(ISBLANK(G$3:G$103))*(G$3:G$103>$BE$3:$BE$103))+ISBLANK(G$3:G$103)) -> 0 | H111: =SUMPRODUCT((NOT(ISBLANK(H$3:H$103))*(H$3:H$103>$BD$3:$BD$103))+ISBLANK(H$3:H$103)) -> 0 | I111: =SUMPRODUCT((NOT(ISBLANK(I$3:I$103))*(I$3:I$103>$BE$3:$BE$103))+ISBLANK(I$3:I$103)) -> 0 | J111: =SUMPRODUCT((NOT(ISBLANK(J$3:J$103))*(J$3:J$103>$BD$3:$BD$103))+ISBLANK(J$3:J$103)) -> 0 | K111: =SUMPRODUCT((NOT(ISBLANK(K$3:K$103))*(K$3:K$103>$BE$3:$BE$103))+ISBLANK(K$3:K$103)) -> 0 | L111: =SUMPRODUCT((NOT(ISBLANK(L$3:L$103))*(L$3:L$103>$BD$3:$BD$103))+ISBLANK(L$3:L$103)) -> 0 | M111: =SUMPRODUCT((NOT(ISBLANK(M$3:M$103))*(M$3:M$103>$BE$3:$BE$103))+ISBLANK(M$3:M$103)) -> 0 | N111: =SUMPRODUCT((NOT(ISBLANK(N$3:N$103))*(N$3:N$103>$BD$3:$BD$103))+ISBLANK(N$3:N$103)) -> 0 | O111: =SUMPRODUCT((NOT(ISBLANK(O$3:O$103))*(O$3:O$103>$BE$3:$BE$103))+ISBLANK(O$3:O$103)) -> 0 | P111: =SUMPRODUCT((NOT(ISBLANK(P$3:P$103))*(P$3:P$103>$BD$3:$BD$103))+ISBLANK(P$3:P$103)) -> 0 | Q111: =SUMPRODUCT((NOT(ISBLANK(Q$3:Q$103))*(Q$3:Q$103>$BE$3:$BE$103))+ISBLANK(Q$3:Q$103)) -> 0 | R111: =SUMPRODUCT((NOT(ISBLANK(R$3:R$103))*(R$3:R$103>$BD$3:$BD$103))+ISBLANK(R$3:R$103)) -> 0 | S111: =SUMPRODUCT((NOT(ISBLANK(S$3:S$103))*(S$3:S$103>$BE$3:$BE$103))+ISBLANK(S$3:S$103)) -> 0 | T111: =SUMPRODUCT((NOT(ISBLANK(T$3:T$103))*(T$3:T$103>$BD$3:$BD$103))+ISBLANK(T$3:T$103)) -> 0 | U111: =SUMPRODUCT((NOT(ISBLANK(U$3:U$103))*(U$3:U$103>$BE$3:$BE$103))+ISBLANK(U$3:U$103)) -> 0 | V111: =SUMPRODUCT((NOT(ISBLANK(V$3:V$103))*(V$3:V$103>$BD$3:$BD$103))+ISBLANK(V$3:V$103)) -> 0 | W111: =SUMPRODUCT((NOT(ISBLANK(W$3:W$103))*(W$3:W$103>$BE$3:$BE$103))+ISBLANK(W$3:W$103)) -> 0 | X111: =SUMPRODUCT((NOT(ISBLANK(X$3:X$103))*(X$3:X$103>$BD$3:$BD$103))+ISBLANK(X$3:X$103)) -> 0 | Y111: =SUMPRODUCT((NOT(ISBLANK(Y$3:Y$103))*(Y$3:Y$103>$BE$3:$BE$103))+ISBLANK(Y$3:Y$103)) -> 0 | Z111: =SUMPRODUCT((NOT(ISBLANK(Z$3:Z$103))*(Z$3:Z$103>$BD$3:$BD$103))+ISBLANK(Z$3:Z$103)) -> 0 | AA111: =SUMPRODUCT((NOT(ISBLANK(AA$3:AA$103))*(AA$3:AA$103>$BE$3:$BE$103))+ISBLANK(AA$3:AA$103)) -> 0 | AB111: =SUMPRODUCT((NOT(ISBLANK(AB$3:AB$103))*(AB$3:AB$103>$BD$3:$BD$103))+ISBLANK(AB$3:AB$103)) -> 0 | AC111: =SUMPRODUCT((NOT(ISBLANK(AC$3:AC$103))*(AC$3:AC$103>$BE$3:$BE$103))+ISBLANK(AC$3:AC$103)) -> 0 | AD111: =SUMPRODUCT((NOT(ISBLANK(AD$3:AD$103))*(AD$3:AD$103>$BD$3:$BD$103))+ISBLANK(AD$3:AD$103)) -> 0 | AE111: =SUMPRODUCT((NOT(ISBLANK(AE$3:AE$103))*(AE$3:AE$103>$BE$3:$BE$103))+ISBLANK(AE$3:AE$103)) -> 0 | AF111: =SUMPRODUCT((NOT(ISBLANK(AF$3:AF$103))*(AF$3:AF$103>$BD$3:$BD$103))+ISBLANK(AF$3:AF$103)) -> 0 | AG111: =SUMPRODUCT((NOT(ISBLANK(AG$3:AG$103))*(AG$3:AG$103>$BE$3:$BE$103))+ISBLANK(AG$3:AG$103)) -> 0 | AH111: =SUMPRODUCT((NOT(ISBLANK(AH$3:AH$103))*(AH$3:AH$103>$BD$3:$BD$103))+ISBLANK(AH$3:AH$103)) -> 0 | AI111: =SUMPRODUCT((NOT(ISBLANK(AI$3:AI$103))*(AI$3:AI$103>$BE$3:$BE$103))+ISBLANK(AI$3:AI$103)) -> 0 | AJ111: =SUMPRODUCT((NOT(ISBLANK(AJ$3:AJ$103))*(AJ$3:AJ$103>$BD$3:$BD$103))+ISBLANK(AJ$3:AJ$103)) -> 0 | AK111: =SUMPRODUCT((NOT(ISBLANK(AK$3:AK$103))*(AK$3:AK$103>$BE$3:$BE$103))+ISBLANK(AK$3:AK$103)) -> 0 | AL111: =SUMPRODUCT((NOT(ISBLANK(AL$3:AL$103))*(AL$3:AL$103>$BD$3:$BD$103))+ISBLANK(AL$3:AL$103)) -> 0 | AM111: =SUMPRODUCT((NOT(ISBLANK(AM$3:AM$103))*(AM$3:AM$103>$BE$3:$BE$103))+ISBLANK(AM$3:AM$103)) -> 0 | AN111: =SUMPRODUCT((NOT(ISBLANK(AN$3:AN$103))*(AN$3:AN$103>$BD$3:$BD$103))+ISBLANK(AN$3:AN$103)) -> 0 | AO111: =SUMPRODUCT((NOT(ISBLANK(AO$3:AO$103))*(AO$3:AO$103>$BE$3:$BE$103))+ISBLANK(AO$3:AO$103)) -> 0 | AP111: =SUMPRODUCT((NOT(ISBLANK(AP$3:AP$103))*(AP$3:AP$103>$BD$3:$BD$103))+ISBLANK(AP$3:AP$103)) -> 0 | AQ111: =SUMPRODUCT((NOT(ISBLANK(AQ$3:AQ$103))*(AQ$3:AQ$103>$BE$3:$BE$103))+ISBLANK(AQ$3:AQ$103)) -> 0 | AR111: =SUMPRODUCT((NOT(ISBLANK(AR$3:AR$103))*(AR$3:AR$103>$BD$3:$BD$103))+ISBLANK(AR$3:AR$103)) -> 0 | AS111: =SUMPRODUCT((NOT(ISBLANK(AS$3:AS$103))*(AS$3:AS$103>$BE$3:$BE$103))+ISBLANK(AS$3:AS$103)) -> 0 | AT111: =SUMPRODUCT((NOT(ISBLANK(AT$3:AT$103))*(AT$3:AT$103>$BD$3:$BD$103))+ISBLANK(AT$3:AT$103)) -> 0 | AU111: =SUMPRODUCT((NOT(ISBLANK(AU$3:AU$103))*(AU$3:AU$103>$BE$3:$BE$103))+ISBLANK(AU$3:AU$103)) -> 0 | AV111: =SUMPRODUCT((NOT(ISBLANK(AV$3:AV$103))*(AV$3:AV$103>$BD$3:$BD$103))+ISBLANK(AV$3:AV$103)) -> 0 | AW111: =SUMPRODUCT((NOT(ISBLANK(AW$3:AW$103))*(AW$3:AW$103>$BE$3:$BE$103))+ISBLANK(AW$3:AW$103)) -> 0 | AX111: =SUMPRODUCT((NOT(ISBLANK(AX$3:AX$103))*(AX$3:AX$103>$BD$3:$BD$103))+ISBLANK(AX$3:AX$103)) -> 0 | AY111: =SUMPRODUCT((NOT(ISBLANK(AY$3:AY$103))*(AY$3:AY$103>$BE$3:$BE$103))+ISBLANK(AY$3:AY$103)) -> 0 | AZ111: =SUMPRODUCT((NOT(ISBLANK(AZ$3:AZ$103))*(AZ$3:AZ$103>$BD$3:$BD$103))+ISBLANK(AZ$3:AZ$103)) -> 0 | BA111: =SUMPRODUCT((NOT(ISBLANK(BA$3:BA$103))*(BA$3:BA$103>$BE$3:$BE$103))+ISBLANK(BA$3:BA$103)) -> 0
