Workbook

Sheet Instances
B1: coomsuite-1.1.2/incremental-exponential_clingo_1.25 | D1: coomsuite-1.1.2/incremental-exponential_clingo_1.33 | F1: coomsuite-1.1.2/incremental-exponential_clingo_1.5 | H1: coomsuite-1.1.2/incremental-exponential_clingo_1.66 | J1: coomsuite-1.1.2/incremental-exponential_clingo_1.75 | L1: coomsuite-1.1.2/incremental-exponential_clingo_2 | N1: coomsuite-1.1.2/incremental-exponential_clingo_2.25 | P1: coomsuite-1.1.2/incremental-exponential_clingo_2.33 | R1: coomsuite-1.1.2/incremental-exponential_clingo_2.5 | T1: coomsuite-1.1.2/incremental-exponential_clingo_2.66 | V1: coomsuite-1.1.2/incremental-exponential_clingo_2.75 | X1: coomsuite-1.1.2/incremental-exponential_flingo_1.25 | Z1: coomsuite-1.1.2/incremental-exponential_flingo_1.33 | AB1: coomsuite-1.1.2/incremental-exponential_flingo_1.5 | AD1: coomsuite-1.1.2/incremental-exponential_flingo_1.66 | AF1: coomsuite-1.1.2/incremental-exponential_flingo_1.75 | AH1: coomsuite-1.1.2/incremental-exponential_flingo_2 | AJ1: coomsuite-1.1.2/incremental-exponential_flingo_2.25 | AL1: coomsuite-1.1.2/incremental-exponential_flingo_2.33 | AN1: coomsuite-1.1.2/incremental-exponential_flingo_2.5 | AP1: coomsuite-1.1.2/incremental-exponential_flingo_2.66 | AR1: coomsuite-1.1.2/incremental-exponential_flingo_2.75 | AT1: coomsuite-1.1.2/multishot-exponential_1.25 | AV1: coomsuite-1.1.2/multishot-exponential_1.33 | AX1: coomsuite-1.1.2/multishot-exponential_1.5 | AZ1: coomsuite-1.1.2/multishot-exponential_1.66 | BB1: coomsuite-1.1.2/multishot-exponential_1.75 | BD1: coomsuite-1.1.2/multishot-exponential_2 | BF1: coomsuite-1.1.2/multishot-exponential_2.25 | BH1: coomsuite-1.1.2/multishot-exponential_2.33 | BJ1: coomsuite-1.1.2/multishot-exponential_2.5 | BL1: coomsuite-1.1.2/multishot-exponential_2.66 | BN1: coomsuite-1.1.2/multishot-exponential_2.75 | BP1: min | BR1: median | BT1: max
B2: time | C2: timeout | D2: time | E2: timeout | F2: time | G2: timeout | H2: time | I2: timeout | J2: time | K2: timeout | L2: time | M2: timeout | N2: time | O2: timeout | P2: time | Q2: timeout | R2: time | S2: timeout | T2: time | U2: timeout | V2: time | W2: timeout | X2: time | Y2: timeout | Z2: time | AA2: timeout | AB2: time | AC2: timeout | AD2: time | AE2: timeout | AF2: time | AG2: timeout | AH2: time | AI2: timeout | AJ2: time | AK2: timeout | AL2: time | AM2: timeout | AN2: time | AO2: timeout | AP2: time | AQ2: timeout | AR2: time | AS2: timeout | AT2: time | AU2: timeout | AV2: time | AW2: timeout | AX2: time | AY2: timeout | AZ2: time | BA2: timeout | BB2: time | BC2: timeout | BD2: time | BE2: timeout | BF2: time | BG2: timeout | BH2: time | BI2: timeout | BJ2: time | BK2: timeout | BL2: time | BM2: timeout | BN2: time | BO2: timeout | BP2: time | BQ2: timeout | BR2: time | BS2: timeout | BT2: time | BU2: timeout
A3: ./restaurant-1000_user-input-2000 | B3: 61.48 | C3: 0 | D3: 58.23 | E3: 0 | F3: 51.57 | G3: 0 | H3: 600 | I3: 1 | J3: 76.26 | K3: 0 | L3: 70.26 | M3: 0 | N3: 56.63 | O3: 0 | P3: 53.89 | Q3: 0 | R3: 85.85 | S3: 0 | T3: 156.64 | U3: 0 | V3: 59.89 | W3: 0 | X3: 345.86 | Y3: 0 | Z3: 164.17 | AA3: 0 | AB3: 161.96 | AC3: 0 | AD3: 487.56 | AE3: 0 | AF3: 403.53 | AG3: 0 | AH3: 462.17 | AI3: 0 | AJ3: 222.95 | AK3: 0 | AL3: 300.01 | AM3: 0 | AN3: 468.04 | AO3: 0 | AP3: 188.79 | AQ3: 0 | AR3: 316.88 | AS3: 0 | AT3: 600 | AU3: 1 | AV3: 600 | AW3: 1 | AX3: 600 | AY3: 1 | AZ3: 600 | BA3: 1 | BB3: 600 | BC3: 1 | BD3: 600 | BE3: 1 | BF3: 600 | BG3: 1 | BH3: 600 | BI3: 1 | BJ3: 600 | BK3: 1 | BL3: 600 | BM3: 1 | BN3: 600 | BO3: 1 | BP3: =MIN($B3,$D3,$F3,$H3,$J3,$L3,$N3,$P3,$R3,$T3,$V3,$X3,$Z3,$AB3,$AD3,$AF3,$AH3,$AJ3,$AL3,$AN3,$AP3,$AR3,$AT3,$AV3,$AX3,$AZ3,$BB3,$BD3,$BF3,$BH3,$BJ3,$BL3,$BN3) -> 0 | BQ3: =MIN($C3,$E3,$G3,$I3,$K3,$M3,$O3,$Q3,$S3,$U3,$W3,$Y3,$AA3,$AC3,$AE3,$AG3,$AI3,$AK3,$AM3,$AO3,$AQ3,$AS3,$AU3,$AW3,$AY3,$BA3,$BC3,$BE3,$BG3,$BI3,$BK3,$BM3,$BO3) -> 0 | BR3: =MEDIAN($B3,$D3,$F3,$H3,$J3,$L3,$N3,$P3,$R3,$T3,$V3,$X3,$Z3,$AB3,$AD3,$AF3,$AH3,$AJ3,$AL3,$AN3,$AP3,$AR3,$AT3,$AV3,$AX3,$AZ3,$BB3,$BD3,$BF3,$BH3,$BJ3,$BL3,$BN3) -> 0 | BS3: =MEDIAN($C3,$E3,$G3,$I3,$K3,$M3,$O3,$Q3,$S3,$U3,$W3,$Y3,$AA3,$AC3,$AE3,$AG3,$AI3,$AK3,$AM3,$AO3,$AQ3,$AS3,$AU3,$AW3,$AY3,$BA3,$BC3,$BE3,$BG3,$BI3,$BK3,$BM3,$BO3) -> 0 | BT3: =MAX($B3,$D3,$F3,$H3,$J3,$L3,$N3,$P3,$R3,$T3,$V3,$X3,$Z3,$AB3,$AD3,$AF3,$AH3,$AJ3,$AL3,$AN3,$AP3,$AR3,$AT3,$AV3,$AX3,$AZ3,$BB3,$BD3,$BF3,$BH3,$BJ3,$BL3,$BN3) -> 0 | BU3: =MAX($C3,$E3,$G3,$I3,$K3,$M3,$O3,$Q3,$S3,$U3,$W3,$Y3,$AA3,$AC3,$AE3,$AG3,$AI3,$AK3,$AM3,$AO3,$AQ3,$AS3,$AU3,$AW3,$AY3,$BA3,$BC3,$BE3,$BG3,$BI3,$BK3,$BM3,$BO3) -> 0
A4: ./restaurant-1000_user-input-4000 | B4: 386.3 | C4: 0 | D4: 242.88 | E4: 0 | F4: 248.14 | G4: 0 | H4: 496.72 | I4: 0 | J4: 413.61 | K4: 0 | L4: 320.11 | M4: 0 | N4: 306.68 | O4: 0 | P4: 298.94 | Q4: 0 | R4: 296.01 | S4: 0 | T4: 354.49 | U4: 0 | V4: 320.92 | W4: 0 | X4: 600 | Y4: 1 | Z4: 600 | AA4: 1 | AB4: 600 | AC4: 1 | AD4: 600 | AE4: 1 | AF4: 600 | AG4: 1 | AH4: 600 | AI4: 1 | AJ4: 600 | AK4: 1 | AL4: 600 | AM4: 1 | AN4: 600 | AO4: 1 | AP4: 600 | AQ4: 1 | AR4: 600 | AS4: 1 | AT4: 600 | AU4: 1 | AV4: 600 | AW4: 1 | AX4: 600 | AY4: 1 | AZ4: 600 | BA4: 1 | BB4: 600 | BC4: 1 | BD4: 600 | BE4: 1 | BF4: 600 | BG4: 1 | BH4: 600 | BI4: 1 | BJ4: 600 | BK4: 1 | BL4: 600 | BM4: 1 | BN4: 600 | BO4: 1 | BP4: =MIN($B4,$D4,$F4,$H4,$J4,$L4,$N4,$P4,$R4,$T4,$V4,$X4,$Z4,$AB4,$AD4,$AF4,$AH4,$AJ4,$AL4,$AN4,$AP4,$AR4,$AT4,$AV4,$AX4,$AZ4,$BB4,$BD4,$BF4,$BH4,$BJ4,$BL4,$BN4) -> 0 | BQ4: =MIN($C4,$E4,$G4,$I4,$K4,$M4,$O4,$Q4,$S4,$U4,$W4,$Y4,$AA4,$AC4,$AE4,$AG4,$AI4,$AK4,$AM4,$AO4,$AQ4,$AS4,$AU4,$AW4,$AY4,$BA4,$BC4,$BE4,$BG4,$BI4,$BK4,$BM4,$BO4) -> 0 | BR4: =MEDIAN($B4,$D4,$F4,$H4,$J4,$L4,$N4,$P4,$R4,$T4,$V4,$X4,$Z4,$AB4,$AD4,$AF4,$AH4,$AJ4,$AL4,$AN4,$AP4,$AR4,$AT4,$AV4,$AX4,$AZ4,$BB4,$BD4,$BF4,$BH4,$BJ4,$BL4,$BN4) -> 0 | BS4: =MEDIAN($C4,$E4,$G4,$I4,$K4,$M4,$O4,$Q4,$S4,$U4,$W4,$Y4,$AA4,$AC4,$AE4,$AG4,$AI4,$AK4,$AM4,$AO4,$AQ4,$AS4,$AU4,$AW4,$AY4,$BA4,$BC4,$BE4,$BG4,$BI4,$BK4,$BM4,$BO4) -> 0 | BT4: =MAX($B4,$D4,$F4,$H4,$J4,$L4,$N4,$P4,$R4,$T4,$V4,$X4,$Z4,$AB4,$AD4,$AF4,$AH4,$AJ4,$AL4,$AN4,$AP4,$AR4,$AT4,$AV4,$AX4,$AZ4,$BB4,$BD4,$BF4,$BH4,$BJ4,$BL4,$BN4) -> 0 | BU4: =MAX($C4,$E4,$G4,$I4,$K4,$M4,$O4,$Q4,$S4,$U4,$W4,$Y4,$AA4,$AC4,$AE4,$AG4,$AI4,$AK4,$AM4,$AO4,$AQ4,$AS4,$AU4,$AW4,$AY4,$BA4,$BC4,$BE4,$BG4,$BI4,$BK4,$BM4,$BO4) -> 0
A5: ./restaurant-1000_user-input-6000 | B5: 600 | C5: 1 | D5: 597.94 | E5: 0 | F5: 600 | G5: 1 | H5: 600 | I5: 1 | J5: 600 | K5: 1 | L5: 577.88 | M5: 0 | N5: 600 | O5: 1 | P5: 600 | Q5: 1 | R5: 600 | S5: 1 | T5: 600 | U5: 1 | V5: 600 | W5: 1 | X5: 600 | Y5: 1 | Z5: 600 | AA5: 1 | AB5: 600 | AC5: 1 | AD5: 600 | AE5: 1 | AF5: 600 | AG5: 1 | AH5: 600 | AI5: 1 | AJ5: 600 | AK5: 1 | AL5: 600 | AM5: 1 | AN5: 600 | AO5: 1 | AP5: 600 | AQ5: 1 | AR5: 600 | AS5: 1 | AT5: 600 | AU5: 1 | AV5: 600 | AW5: 1 | AX5: 600 | AY5: 1 | AZ5: 600 | BA5: 1 | BB5: 600 | BC5: 1 | BD5: 600 | BE5: 1 | BF5: 600 | BG5: 1 | BH5: 600 | BI5: 1 | BJ5: 600 | BK5: 1 | BL5: 600 | BM5: 1 | BN5: 600 | BO5: 1 | BP5: =MIN($B5,$D5,$F5,$H5,$J5,$L5,$N5,$P5,$R5,$T5,$V5,$X5,$Z5,$AB5,$AD5,$AF5,$AH5,$AJ5,$AL5,$AN5,$AP5,$AR5,$AT5,$AV5,$AX5,$AZ5,$BB5,$BD5,$BF5,$BH5,$BJ5,$BL5,$BN5) -> 0 | BQ5: =MIN($C5,$E5,$G5,$I5,$K5,$M5,$O5,$Q5,$S5,$U5,$W5,$Y5,$AA5,$AC5,$AE5,$AG5,$AI5,$AK5,$AM5,$AO5,$AQ5,$AS5,$AU5,$AW5,$AY5,$BA5,$BC5,$BE5,$BG5,$BI5,$BK5,$BM5,$BO5) -> 0 | BR5: =MEDIAN($B5,$D5,$F5,$H5,$J5,$L5,$N5,$P5,$R5,$T5,$V5,$X5,$Z5,$AB5,$AD5,$AF5,$AH5,$AJ5,$AL5,$AN5,$AP5,$AR5,$AT5,$AV5,$AX5,$AZ5,$BB5,$BD5,$BF5,$BH5,$BJ5,$BL5,$BN5) -> 0 | BS5: =MEDIAN($C5,$E5,$G5,$I5,$K5,$M5,$O5,$Q5,$S5,$U5,$W5,$Y5,$AA5,$AC5,$AE5,$AG5,$AI5,$AK5,$AM5,$AO5,$AQ5,$AS5,$AU5,$AW5,$AY5,$BA5,$BC5,$BE5,$BG5,$BI5,$BK5,$BM5,$BO5) -> 0 | BT5: =MAX($B5,$D5,$F5,$H5,$J5,$L5,$N5,$P5,$R5,$T5,$V5,$X5,$Z5,$AB5,$AD5,$AF5,$AH5,$AJ5,$AL5,$AN5,$AP5,$AR5,$AT5,$AV5,$AX5,$AZ5,$BB5,$BD5,$BF5,$BH5,$BJ5,$BL5,$BN5) -> 0 | BU5: =MAX($C5,$E5,$G5,$I5,$K5,$M5,$O5,$Q5,$S5,$U5,$W5,$Y5,$AA5,$AC5,$AE5,$AG5,$AI5,$AK5,$AM5,$AO5,$AQ5,$AS5,$AU5,$AW5,$AY5,$BA5,$BC5,$BE5,$BG5,$BI5,$BK5,$BM5,$BO5) -> 0
A6: ./restaurant-100_user-input-200 | B6: 1.61 | C6: 0 | D6: 1.55 | E6: 0 | F6: 2.37 | G6: 0 | H6: 1.34 | I6: 0 | J6: 1.5 | K6: 0 | L6: 1.17 | M6: 0 | N6: 1.86 | O6: 0 | P6: 1.37 | Q6: 0 | R6: 1.4 | S6: 0 | T6: 2.04 | U6: 0 | V6: 1.96 | W6: 0 | X6: 6.04 | Y6: 0 | Z6: 5.92 | AA6: 0 | AB6: 6.52 | AC6: 0 | AD6: 4.83 | AE6: 0 | AF6: 6.02 | AG6: 0 | AH6: 5.03 | AI6: 0 | AJ6: 7.54 | AK6: 0 | AL6: 4.98 | AM6: 0 | AN6: 5.04 | AO6: 0 | AP6: 6.23 | AQ6: 0 | AR6: 8.24 | AS6: 0 | AT6: 4.14 | AU6: 0 | AV6: 5.15 | AW6: 0 | AX6: 12.67 | AY6: 0 | AZ6: 4.83 | BA6: 0 | BB6: 4.3 | BC6: 0 | BD6: 3.93 | BE6: 0 | BF6: 15.17 | BG6: 0 | BH6: 4.74 | BI6: 0 | BJ6: 5.88 | BK6: 0 | BL6: 13.41 | BM6: 0 | BN6: 15.4 | BO6: 0 | BP6: =MIN($B6,$D6,$F6,$H6,$J6,$L6,$N6,$P6,$R6,$T6,$V6,$X6,$Z6,$AB6,$AD6,$AF6,$AH6,$AJ6,$AL6,$AN6,$AP6,$AR6,$AT6,$AV6,$AX6,$AZ6,$BB6,$BD6,$BF6,$BH6,$BJ6,$BL6,$BN6) -> 0 | BQ6: =MIN($C6,$E6,$G6,$I6,$K6,$M6,$O6,$Q6,$S6,$U6,$W6,$Y6,$AA6,$AC6,$AE6,$AG6,$AI6,$AK6,$AM6,$AO6,$AQ6,$AS6,$AU6,$AW6,$AY6,$BA6,$BC6,$BE6,$BG6,$BI6,$BK6,$BM6,$BO6) -> 0 | BR6: =MEDIAN($B6,$D6,$F6,$H6,$J6,$L6,$N6,$P6,$R6,$T6,$V6,$X6,$Z6,$AB6,$AD6,$AF6,$AH6,$AJ6,$AL6,$AN6,$AP6,$AR6,$AT6,$AV6,$AX6,$AZ6,$BB6,$BD6,$BF6,$BH6,$BJ6,$BL6,$BN6) -> 0 | BS6: =MEDIAN($C6,$E6,$G6,$I6,$K6,$M6,$O6,$Q6,$S6,$U6,$W6,$Y6,$AA6,$AC6,$AE6,$AG6,$AI6,$AK6,$AM6,$AO6,$AQ6,$AS6,$AU6,$AW6,$AY6,$BA6,$BC6,$BE6,$BG6,$BI6,$BK6,$BM6,$BO6) -> 0 | BT6: =MAX($B6,$D6,$F6,$H6,$J6,$L6,$N6,$P6,$R6,$T6,$V6,$X6,$Z6,$AB6,$AD6,$AF6,$AH6,$AJ6,$AL6,$AN6,$AP6,$AR6,$AT6,$AV6,$AX6,$AZ6,$BB6,$BD6,$BF6,$BH6,$BJ6,$BL6,$BN6) -> 0 | BU6: =MAX($C6,$E6,$G6,$I6,$K6,$M6,$O6,$Q6,$S6,$U6,$W6,$Y6,$AA6,$AC6,$AE6,$AG6,$AI6,$AK6,$AM6,$AO6,$AQ6,$AS6,$AU6,$AW6,$AY6,$BA6,$BC6,$BE6,$BG6,$BI6,$BK6,$BM6,$BO6) -> 0
A7: ./restaurant-100_user-input-400 | B7: 3.71 | C7: 0 | D7: 3.42 | E7: 0 | F7: 2.93 | G7: 0 | H7: 2.77 | I7: 0 | J7: 3.42 | K7: 0 | L7: 2.74 | M7: 0 | N7: 2.32 | O7: 0 | P7: 2.88 | Q7: 0 | R7: 3.63 | S7: 0 | T7: 4.81 | U7: 0 | V7: 2.47 | W7: 0 | X7: 14.64 | Y7: 0 | Z7: 13.72 | AA7: 0 | AB7: 11.94 | AC7: 0 | AD7: 11.99 | AE7: 0 | AF7: 14.04 | AG7: 0 | AH7: 10.7 | AI7: 0 | AJ7: 8.98 | AK7: 0 | AL7: 10.64 | AM7: 0 | AN7: 13.41 | AO7: 0 | AP7: 21.39 | AQ7: 0 | AR7: 10 | AS7: 0 | AT7: 152.68 | AU7: 0 | AV7: 33.36 | AW7: 0 | AX7: 20.95 | AY7: 0 | AZ7: 66.78 | BA7: 0 | BB7: 61.72 | BC7: 0 | BD7: 57.23 | BE7: 0 | BF7: 79.18 | BG7: 0 | BH7: 101.25 | BI7: 0 | BJ7: 75.69 | BK7: 0 | BL7: 256.73 | BM7: 0 | BN7: 37.34 | BO7: 0 | BP7: =MIN($B7,$D7,$F7,$H7,$J7,$L7,$N7,$P7,$R7,$T7,$V7,$X7,$Z7,$AB7,$AD7,$AF7,$AH7,$AJ7,$AL7,$AN7,$AP7,$AR7,$AT7,$AV7,$AX7,$AZ7,$BB7,$BD7,$BF7,$BH7,$BJ7,$BL7,$BN7) -> 0 | BQ7: =MIN($C7,$E7,$G7,$I7,$K7,$M7,$O7,$Q7,$S7,$U7,$W7,$Y7,$AA7,$AC7,$AE7,$AG7,$AI7,$AK7,$AM7,$AO7,$AQ7,$AS7,$AU7,$AW7,$AY7,$BA7,$BC7,$BE7,$BG7,$BI7,$BK7,$BM7,$BO7) -> 0 | BR7: =MEDIAN($B7,$D7,$F7,$H7,$J7,$L7,$N7,$P7,$R7,$T7,$V7,$X7,$Z7,$AB7,$AD7,$AF7,$AH7,$AJ7,$AL7,$AN7,$AP7,$AR7,$AT7,$AV7,$AX7,$AZ7,$BB7,$BD7,$BF7,$BH7,$BJ7,$BL7,$BN7) -> 0 | BS7: =MEDIAN($C7,$E7,$G7,$I7,$K7,$M7,$O7,$Q7,$S7,$U7,$W7,$Y7,$AA7,$AC7,$AE7,$AG7,$AI7,$AK7,$AM7,$AO7,$AQ7,$AS7,$AU7,$AW7,$AY7,$BA7,$BC7,$BE7,$BG7,$BI7,$BK7,$BM7,$BO7) -> 0 | BT7: =MAX($B7,$D7,$F7,$H7,$J7,$L7,$N7,$P7,$R7,$T7,$V7,$X7,$Z7,$AB7,$AD7,$AF7,$AH7,$AJ7,$AL7,$AN7,$AP7,$AR7,$AT7,$AV7,$AX7,$AZ7,$BB7,$BD7,$BF7,$BH7,$BJ7,$BL7,$BN7) -> 0 | BU7: =MAX($C7,$E7,$G7,$I7,$K7,$M7,$O7,$Q7,$S7,$U7,$W7,$Y7,$AA7,$AC7,$AE7,$AG7,$AI7,$AK7,$AM7,$AO7,$AQ7,$AS7,$AU7,$AW7,$AY7,$BA7,$BC7,$BE7,$BG7,$BI7,$BK7,$BM7,$BO7) -> 0
A8: ./restaurant-100_user-input-600 | B8: 6.34 | C8: 0 | D8: 5.95 | E8: 0 | F8: 4.78 | G8: 0 | H8: 5.35 | I8: 0 | J8: 4.32 | K8: 0 | L8: 5.78 | M8: 0 | N8: 5.64 | O8: 0 | P8: 8.21 | Q8: 0 | R8: 5.11 | S8: 0 | T8: 6.12 | U8: 0 | V8: 9.72 | W8: 0 | X8: 23.42 | Y8: 0 | Z8: 22.26 | AA8: 0 | AB8: 22.14 | AC8: 0 | AD8: 21.17 | AE8: 0 | AF8: 17.23 | AG8: 0 | AH8: 24.55 | AI8: 0 | AJ8: 22.25 | AK8: 0 | AL8: 35.17 | AM8: 0 | AN8: 17.22 | AO8: 0 | AP8: 25.46 | AQ8: 0 | AR8: 29.16 | AS8: 0 | AT8: 62.3 | AU8: 0 | AV8: 505.37 | AW8: 0 | AX8: 252.48 | AY8: 0 | AZ8: 543.93 | BA8: 0 | BB8: 484.54 | BC8: 0 | BD8: 583.2 | BE8: 0 | BF8: 490.95 | BG8: 0 | BH8: 445.55 | BI8: 0 | BJ8: 574.4 | BK8: 0 | BL8: 600 | BM8: 1 | BN8: 600 | BO8: 1 | BP8: =MIN($B8,$D8,$F8,$H8,$J8,$L8,$N8,$P8,$R8,$T8,$V8,$X8,$Z8,$AB8,$AD8,$AF8,$AH8,$AJ8,$AL8,$AN8,$AP8,$AR8,$AT8,$AV8,$AX8,$AZ8,$BB8,$BD8,$BF8,$BH8,$BJ8,$BL8,$BN8) -> 0 | BQ8: =MIN($C8,$E8,$G8,$I8,$K8,$M8,$O8,$Q8,$S8,$U8,$W8,$Y8,$AA8,$AC8,$AE8,$AG8,$AI8,$AK8,$AM8,$AO8,$AQ8,$AS8,$AU8,$AW8,$AY8,$BA8,$BC8,$BE8,$BG8,$BI8,$BK8,$BM8,$BO8) -> 0 | BR8: =MEDIAN($B8,$D8,$F8,$H8,$J8,$L8,$N8,$P8,$R8,$T8,$V8,$X8,$Z8,$AB8,$AD8,$AF8,$AH8,$AJ8,$AL8,$AN8,$AP8,$AR8,$AT8,$AV8,$AX8,$AZ8,$BB8,$BD8,$BF8,$BH8,$BJ8,$BL8,$BN8) -> 0 | BS8: =MEDIAN($C8,$E8,$G8,$I8,$K8,$M8,$O8,$Q8,$S8,$U8,$W8,$Y8,$AA8,$AC8,$AE8,$AG8,$AI8,$AK8,$AM8,$AO8,$AQ8,$AS8,$AU8,$AW8,$AY8,$BA8,$BC8,$BE8,$BG8,$BI8,$BK8,$BM8,$BO8) -> 0 | BT8: =MAX($B8,$D8,$F8,$H8,$J8,$L8,$N8,$P8,$R8,$T8,$V8,$X8,$Z8,$AB8,$AD8,$AF8,$AH8,$AJ8,$AL8,$AN8,$AP8,$AR8,$AT8,$AV8,$AX8,$AZ8,$BB8,$BD8,$BF8,$BH8,$BJ8,$BL8,$BN8) -> 0 | BU8: =MAX($C8,$E8,$G8,$I8,$K8,$M8,$O8,$Q8,$S8,$U8,$W8,$Y8,$AA8,$AC8,$AE8,$AG8,$AI8,$AK8,$AM8,$AO8,$AQ8,$AS8,$AU8,$AW8,$AY8,$BA8,$BC8,$BE8,$BG8,$BI8,$BK8,$BM8,$BO8) -> 0
A9: ./restaurant-1500_user-input-3000 | B9: 323.69 | C9: 0 | D9: 200.66 | E9: 0 | F9: 120.59 | G9: 0 | H9: 166.37 | I9: 0 | J9: 131.59 | K9: 0 | L9: 198.48 | M9: 0 | N9: 228.39 | O9: 0 | P9: 173.14 | Q9: 0 | R9: 234.49 | S9: 0 | T9: 288.06 | U9: 0 | V9: 110.34 | W9: 0 | X9: 600 | Y9: 1 | Z9: 600 | AA9: 1 | AB9: 600 | AC9: 1 | AD9: 600 | AE9: 1 | AF9: 600 | AG9: 1 | AH9: 600 | AI9: 1 | AJ9: 600 | AK9: 1 | AL9: 600 | AM9: 1 | AN9: 600 | AO9: 1 | AP9: 600 | AQ9: 1 | AR9: 600 | AS9: 1 | AT9: 600 | AU9: 1 | AV9: 600 | AW9: 1 | AX9: 600 | AY9: 1 | AZ9: 600 | BA9: 1 | BB9: 600 | BC9: 1 | BD9: 600 | BE9: 1 | BF9: 600 | BG9: 1 | BH9: 600 | BI9: 1 | BJ9: 600 | BK9: 1 | BL9: 600 | BM9: 1 | BN9: 600 | BO9: 1 | BP9: =MIN($B9,$D9,$F9,$H9,$J9,$L9,$N9,$P9,$R9,$T9,$V9,$X9,$Z9,$AB9,$AD9,$AF9,$AH9,$AJ9,$AL9,$AN9,$AP9,$AR9,$AT9,$AV9,$AX9,$AZ9,$BB9,$BD9,$BF9,$BH9,$BJ9,$BL9,$BN9) -> 0 | BQ9: =MIN($C9,$E9,$G9,$I9,$K9,$M9,$O9,$Q9,$S9,$U9,$W9,$Y9,$AA9,$AC9,$AE9,$AG9,$AI9,$AK9,$AM9,$AO9,$AQ9,$AS9,$AU9,$AW9,$AY9,$BA9,$BC9,$BE9,$BG9,$BI9,$BK9,$BM9,$BO9) -> 0 | BR9: =MEDIAN($B9,$D9,$F9,$H9,$J9,$L9,$N9,$P9,$R9,$T9,$V9,$X9,$Z9,$AB9,$AD9,$AF9,$AH9,$AJ9,$AL9,$AN9,$AP9,$AR9,$AT9,$AV9,$AX9,$AZ9,$BB9,$BD9,$BF9,$BH9,$BJ9,$BL9,$BN9) -> 0 | BS9: =MEDIAN($C9,$E9,$G9,$I9,$K9,$M9,$O9,$Q9,$S9,$U9,$W9,$Y9,$AA9,$AC9,$AE9,$AG9,$AI9,$AK9,$AM9,$AO9,$AQ9,$AS9,$AU9,$AW9,$AY9,$BA9,$BC9,$BE9,$BG9,$BI9,$BK9,$BM9,$BO9) -> 0 | BT9: =MAX($B9,$D9,$F9,$H9,$J9,$L9,$N9,$P9,$R9,$T9,$V9,$X9,$Z9,$AB9,$AD9,$AF9,$AH9,$AJ9,$AL9,$AN9,$AP9,$AR9,$AT9,$AV9,$AX9,$AZ9,$BB9,$BD9,$BF9,$BH9,$BJ9,$BL9,$BN9) -> 0 | BU9: =MAX($C9,$E9,$G9,$I9,$K9,$M9,$O9,$Q9,$S9,$U9,$W9,$Y9,$AA9,$AC9,$AE9,$AG9,$AI9,$AK9,$AM9,$AO9,$AQ9,$AS9,$AU9,$AW9,$AY9,$BA9,$BC9,$BE9,$BG9,$BI9,$BK9,$BM9,$BO9) -> 0
A10: ./restaurant-1500_user-input-6000 | B10: 600 | C10: 1 | D10: 600 | E10: 1 | F10: 600 | G10: 1 | H10: 600 | I10: 1 | J10: 600 | K10: 1 | L10: 586.25 | M10: 0 | N10: 600 | O10: 1 | P10: 600 | Q10: 1 | R10: 600 | S10: 1 | T10: 600 | U10: 1 | V10: 600 | W10: 1 | X10: 600 | Y10: 1 | Z10: 600 | AA10: 1 | AB10: 600 | AC10: 1 | AD10: 600 | AE10: 1 | AF10: 600 | AG10: 1 | AH10: 600 | AI10: 1 | AJ10: 600 | AK10: 1 | AL10: 600 | AM10: 1 | AN10: 600 | AO10: 1 | AP10: 600 | AQ10: 1 | AR10: 600 | AS10: 1 | AT10: 600 | AU10: 1 | AV10: 600 | AW10: 1 | AX10: 600 | AY10: 1 | AZ10: 600 | BA10: 1 | BB10: 600 | BC10: 1 | BD10: 600 | BE10: 1 | BF10: 600 | BG10: 1 | BH10: 600 | BI10: 1 | BJ10: 600 | BK10: 1 | BL10: 600 | BM10: 1 | BN10: 600 | BO10: 1 | BP10: =MIN($B10,$D10,$F10,$H10,$J10,$L10,$N10,$P10,$R10,$T10,$V10,$X10,$Z10,$AB10,$AD10,$AF10,$AH10,$AJ10,$AL10,$AN10,$AP10,$AR10,$AT10,$AV10,$AX10,$AZ10,$BB10,$BD10,$BF10,$BH10,$BJ10,$BL10,$BN10) -> 0 | BQ10: =MIN($C10,$E10,$G10,$I10,$K10,$M10,$O10,$Q10,$S10,$U10,$W10,$Y10,$AA10,$AC10,$AE10,$AG10,$AI10,$AK10,$AM10,$AO10,$AQ10,$AS10,$AU10,$AW10,$AY10,$BA10,$BC10,$BE10,$BG10,$BI10,$BK10,$BM10,$BO10) -> 0 | BR10: =MEDIAN($B10,$D10,$F10,$H10,$J10,$L10,$N10,$P10,$R10,$T10,$V10,$X10,$Z10,$AB10,$AD10,$AF10,$AH10,$AJ10,$AL10,$AN10,$AP10,$AR10,$AT10,$AV10,$AX10,$AZ10,$BB10,$BD10,$BF10,$BH10,$BJ10,$BL10,$BN10) -> 0 | BS10: =MEDIAN($C10,$E10,$G10,$I10,$K10,$M10,$O10,$Q10,$S10,$U10,$W10,$Y10,$AA10,$AC10,$AE10,$AG10,$AI10,$AK10,$AM10,$AO10,$AQ10,$AS10,$AU10,$AW10,$AY10,$BA10,$BC10,$BE10,$BG10,$BI10,$BK10,$BM10,$BO10) -> 0 | BT10: =MAX($B10,$D10,$F10,$H10,$J10,$L10,$N10,$P10,$R10,$T10,$V10,$X10,$Z10,$AB10,$AD10,$AF10,$AH10,$AJ10,$AL10,$AN10,$AP10,$AR10,$AT10,$AV10,$AX10,$AZ10,$BB10,$BD10,$BF10,$BH10,$BJ10,$BL10,$BN10) -> 0 | BU10: =MAX($C10,$E10,$G10,$I10,$K10,$M10,$O10,$Q10,$S10,$U10,$W10,$Y10,$AA10,$AC10,$AE10,$AG10,$AI10,$AK10,$AM10,$AO10,$AQ10,$AS10,$AU10,$AW10,$AY10,$BA10,$BC10,$BE10,$BG10,$BI10,$BK10,$BM10,$BO10) -> 0
A11: ./restaurant-1500_user-input-9000 | B11: 600 | C11: 1 | D11: 600 | E11: 1 | F11: 600 | G11: 1 | H11: 600 | I11: 1 | J11: 600 | K11: 1 | L11: 600 | M11: 1 | N11: 600 | O11: 1 | P11: 600 | Q11: 1 | R11: 600 | S11: 1 | T11: 600 | U11: 1 | V11: 600 | W11: 1 | X11: 600 | Y11: 1 | Z11: 600 | AA11: 1 | AB11: 600 | AC11: 1 | AD11: 600 | AE11: 1 | AF11: 600 | AG11: 1 | AH11: 600 | AI11: 1 | AJ11: 600 | AK11: 1 | AL11: 600 | AM11: 1 | AN11: 600 | AO11: 1 | AP11: 600 | AQ11: 1 | AR11: 600 | AS11: 1 | AT11: 600 | AU11: 1 | AV11: 600 | AW11: 1 | AX11: 600 | AY11: 1 | AZ11: 600 | BA11: 1 | BB11: 600 | BC11: 1 | BD11: 600 | BE11: 1 | BF11: 600 | BG11: 1 | BH11: 600 | BI11: 1 | BJ11: 600 | BK11: 1 | BL11: 600 | BM11: 1 | BN11: 600 | BO11: 1 | BP11: =MIN($B11,$D11,$F11,$H11,$J11,$L11,$N11,$P11,$R11,$T11,$V11,$X11,$Z11,$AB11,$AD11,$AF11,$AH11,$AJ11,$AL11,$AN11,$AP11,$AR11,$AT11,$AV11,$AX11,$AZ11,$BB11,$BD11,$BF11,$BH11,$BJ11,$BL11,$BN11) -> 0 | BQ11: =MIN($C11,$E11,$G11,$I11,$K11,$M11,$O11,$Q11,$S11,$U11,$W11,$Y11,$AA11,$AC11,$AE11,$AG11,$AI11,$AK11,$AM11,$AO11,$AQ11,$AS11,$AU11,$AW11,$AY11,$BA11,$BC11,$BE11,$BG11,$BI11,$BK11,$BM11,$BO11) -> 0 | BR11: =MEDIAN($B11,$D11,$F11,$H11,$J11,$L11,$N11,$P11,$R11,$T11,$V11,$X11,$Z11,$AB11,$AD11,$AF11,$AH11,$AJ11,$AL11,$AN11,$AP11,$AR11,$AT11,$AV11,$AX11,$AZ11,$BB11,$BD11,$BF11,$BH11,$BJ11,$BL11,$BN11) -> 0 | BS11: =MEDIAN($C11,$E11,$G11,$I11,$K11,$M11,$O11,$Q11,$S11,$U11,$W11,$Y11,$AA11,$AC11,$AE11,$AG11,$AI11,$AK11,$AM11,$AO11,$AQ11,$AS11,$AU11,$AW11,$AY11,$BA11,$BC11,$BE11,$BG11,$BI11,$BK11,$BM11,$BO11) -> 0 | BT11: =MAX($B11,$D11,$F11,$H11,$J11,$L11,$N11,$P11,$R11,$T11,$V11,$X11,$Z11,$AB11,$AD11,$AF11,$AH11,$AJ11,$AL11,$AN11,$AP11,$AR11,$AT11,$AV11,$AX11,$AZ11,$BB11,$BD11,$BF11,$BH11,$BJ11,$BL11,$BN11) -> 0 | BU11: =MAX($C11,$E11,$G11,$I11,$K11,$M11,$O11,$Q11,$S11,$U11,$W11,$Y11,$AA11,$AC11,$AE11,$AG11,$AI11,$AK11,$AM11,$AO11,$AQ11,$AS11,$AU11,$AW11,$AY11,$BA11,$BC11,$BE11,$BG11,$BI11,$BK11,$BM11,$BO11) -> 0
A12: ./restaurant-2000_user-input-12000 | B12: 600 | C12: 1 | D12: 600 | E12: 1 | F12: 600 | G12: 1 | H12: 600 | I12: 1 | J12: 600 | K12: 1 | L12: 600 | M12: 1 | N12: 600 | O12: 1 | P12: 600 | Q12: 1 | R12: 600 | S12: 1 | T12: 600 | U12: 1 | V12: 600 | W12: 1 | X12: 600 | Y12: 1 | Z12: 600 | AA12: 1 | AB12: 600 | AC12: 1 | AD12: 600 | AE12: 1 | AF12: 600 | AG12: 1 | AH12: 600 | AI12: 1 | AJ12: 600 | AK12: 1 | AL12: 600 | AM12: 1 | AN12: 600 | AO12: 1 | AP12: 600 | AQ12: 1 | AR12: 600 | AS12: 1 | AT12: 600 | AU12: 1 | AV12: 600 | AW12: 1 | AX12: 600 | AY12: 1 | AZ12: 600 | BA12: 1 | BB12: 600 | BC12: 1 | BD12: 600 | BE12: 1 | BF12: 600 | BG12: 1 | BH12: 600 | BI12: 1 | BJ12: 600 | BK12: 1 | BL12: 600 | BM12: 1 | BN12: 600 | BO12: 1 | BP12: =MIN($B12,$D12,$F12,$H12,$J12,$L12,$N12,$P12,$R12,$T12,$V12,$X12,$Z12,$AB12,$AD12,$AF12,$AH12,$AJ12,$AL12,$AN12,$AP12,$AR12,$AT12,$AV12,$AX12,$AZ12,$BB12,$BD12,$BF12,$BH12,$BJ12,$BL12,$BN12) -> 0 | BQ12: =MIN($C12,$E12,$G12,$I12,$K12,$M12,$O12,$Q12,$S12,$U12,$W12,$Y12,$AA12,$AC12,$AE12,$AG12,$AI12,$AK12,$AM12,$AO12,$AQ12,$AS12,$AU12,$AW12,$AY12,$BA12,$BC12,$BE12,$BG12,$BI12,$BK12,$BM12,$BO12) -> 0 | BR12: =MEDIAN($B12,$D12,$F12,$H12,$J12,$L12,$N12,$P12,$R12,$T12,$V12,$X12,$Z12,$AB12,$AD12,$AF12,$AH12,$AJ12,$AL12,$AN12,$AP12,$AR12,$AT12,$AV12,$AX12,$AZ12,$BB12,$BD12,$BF12,$BH12,$BJ12,$BL12,$BN12) -> 0 | BS12: =MEDIAN($C12,$E12,$G12,$I12,$K12,$M12,$O12,$Q12,$S12,$U12,$W12,$Y12,$AA12,$AC12,$AE12,$AG12,$AI12,$AK12,$AM12,$AO12,$AQ12,$AS12,$AU12,$AW12,$AY12,$BA12,$BC12,$BE12,$BG12,$BI12,$BK12,$BM12,$BO12) -> 0 | BT12: =MAX($B12,$D12,$F12,$H12,$J12,$L12,$N12,$P12,$R12,$T12,$V12,$X12,$Z12,$AB12,$AD12,$AF12,$AH12,$AJ12,$AL12,$AN12,$AP12,$AR12,$AT12,$AV12,$AX12,$AZ12,$BB12,$BD12,$BF12,$BH12,$BJ12,$BL12,$BN12) -> 0 | BU12: =MAX($C12,$E12,$G12,$I12,$K12,$M12,$O12,$Q12,$S12,$U12,$W12,$Y12,$AA12,$AC12,$AE12,$AG12,$AI12,$AK12,$AM12,$AO12,$AQ12,$AS12,$AU12,$AW12,$AY12,$BA12,$BC12,$BE12,$BG12,$BI12,$BK12,$BM12,$BO12) -> 0
A13: ./restaurant-2000_user-input-4000 | B13: 419.55 | C13: 0 | D13: 280.17 | E13: 0 | F13: 351.77 | G13: 0 | H13: 389.3 | I13: 0 | J13: 404.74 | K13: 0 | L13: 325.32 | M13: 0 | N13: 302.35 | O13: 0 | P13: 319.67 | Q13: 0 | R13: 309.04 | S13: 0 | T13: 342.66 | U13: 0 | V13: 426.14 | W13: 0 | X13: 600 | Y13: 1 | Z13: 600 | AA13: 1 | AB13: 600 | AC13: 1 | AD13: 600 | AE13: 1 | AF13: 600 | AG13: 1 | AH13: 600 | AI13: 1 | AJ13: 600 | AK13: 1 | AL13: 600 | AM13: 1 | AN13: 600 | AO13: 1 | AP13: 600 | AQ13: 1 | AR13: 600 | AS13: 1 | AT13: 600 | AU13: 1 | AV13: 600 | AW13: 1 | AX13: 600 | AY13: 1 | AZ13: 600 | BA13: 1 | BB13: 600 | BC13: 1 | BD13: 600 | BE13: 1 | BF13: 600 | BG13: 1 | BH13: 600 | BI13: 1 | BJ13: 600 | BK13: 1 | BL13: 600 | BM13: 1 | BN13: 600 | BO13: 1 | BP13: =MIN($B13,$D13,$F13,$H13,$J13,$L13,$N13,$P13,$R13,$T13,$V13,$X13,$Z13,$AB13,$AD13,$AF13,$AH13,$AJ13,$AL13,$AN13,$AP13,$AR13,$AT13,$AV13,$AX13,$AZ13,$BB13,$BD13,$BF13,$BH13,$BJ13,$BL13,$BN13) -> 0 | BQ13: =MIN($C13,$E13,$G13,$I13,$K13,$M13,$O13,$Q13,$S13,$U13,$W13,$Y13,$AA13,$AC13,$AE13,$AG13,$AI13,$AK13,$AM13,$AO13,$AQ13,$AS13,$AU13,$AW13,$AY13,$BA13,$BC13,$BE13,$BG13,$BI13,$BK13,$BM13,$BO13) -> 0 | BR13: =MEDIAN($B13,$D13,$F13,$H13,$J13,$L13,$N13,$P13,$R13,$T13,$V13,$X13,$Z13,$AB13,$AD13,$AF13,$AH13,$AJ13,$AL13,$AN13,$AP13,$AR13,$AT13,$AV13,$AX13,$AZ13,$BB13,$BD13,$BF13,$BH13,$BJ13,$BL13,$BN13) -> 0 | BS13: =MEDIAN($C13,$E13,$G13,$I13,$K13,$M13,$O13,$Q13,$S13,$U13,$W13,$Y13,$AA13,$AC13,$AE13,$AG13,$AI13,$AK13,$AM13,$AO13,$AQ13,$AS13,$AU13,$AW13,$AY13,$BA13,$BC13,$BE13,$BG13,$BI13,$BK13,$BM13,$BO13) -> 0 | BT13: =MAX($B13,$D13,$F13,$H13,$J13,$L13,$N13,$P13,$R13,$T13,$V13,$X13,$Z13,$AB13,$AD13,$AF13,$AH13,$AJ13,$AL13,$AN13,$AP13,$AR13,$AT13,$AV13,$AX13,$AZ13,$BB13,$BD13,$BF13,$BH13,$BJ13,$BL13,$BN13) -> 0 | BU13: =MAX($C13,$E13,$G13,$I13,$K13,$M13,$O13,$Q13,$S13,$U13,$W13,$Y13,$AA13,$AC13,$AE13,$AG13,$AI13,$AK13,$AM13,$AO13,$AQ13,$AS13,$AU13,$AW13,$AY13,$BA13,$BC13,$BE13,$BG13,$BI13,$BK13,$BM13,$BO13) -> 0
A14: ./restaurant-2000_user-input-8000 | B14: 600 | C14: 1 | D14: 600 | E14: 1 | F14: 600 | G14: 1 | H14: 600 | I14: 1 | J14: 600 | K14: 1 | L14: 600 | M14: 1 | N14: 600 | O14: 1 | P14: 600 | Q14: 1 | R14: 600 | S14: 1 | T14: 600 | U14: 1 | V14: 600 | W14: 1 | X14: 600 | Y14: 1 | Z14: 600 | AA14: 1 | AB14: 600 | AC14: 1 | AD14: 600 | AE14: 1 | AF14: 600 | AG14: 1 | AH14: 600 | AI14: 1 | AJ14: 600 | AK14: 1 | AL14: 600 | AM14: 1 | AN14: 600 | AO14: 1 | AP14: 600 | AQ14: 1 | AR14: 600 | AS14: 1 | AT14: 600 | AU14: 1 | AV14: 600 | AW14: 1 | AX14: 600 | AY14: 1 | AZ14: 600 | BA14: 1 | BB14: 600 | BC14: 1 | BD14: 600 | BE14: 1 | BF14: 600 | BG14: 1 | BH14: 600 | BI14: 1 | BJ14: 600 | BK14: 1 | BL14: 600 | BM14: 1 | BN14: 600 | BO14: 1 | BP14: =MIN($B14,$D14,$F14,$H14,$J14,$L14,$N14,$P14,$R14,$T14,$V14,$X14,$Z14,$AB14,$AD14,$AF14,$AH14,$AJ14,$AL14,$AN14,$AP14,$AR14,$AT14,$AV14,$AX14,$AZ14,$BB14,$BD14,$BF14,$BH14,$BJ14,$BL14,$BN14) -> 0 | BQ14: =MIN($C14,$E14,$G14,$I14,$K14,$M14,$O14,$Q14,$S14,$U14,$W14,$Y14,$AA14,$AC14,$AE14,$AG14,$AI14,$AK14,$AM14,$AO14,$AQ14,$AS14,$AU14,$AW14,$AY14,$BA14,$BC14,$BE14,$BG14,$BI14,$BK14,$BM14,$BO14) -> 0 | BR14: =MEDIAN($B14,$D14,$F14,$H14,$J14,$L14,$N14,$P14,$R14,$T14,$V14,$X14,$Z14,$AB14,$AD14,$AF14,$AH14,$AJ14,$AL14,$AN14,$AP14,$AR14,$AT14,$AV14,$AX14,$AZ14,$BB14,$BD14,$BF14,$BH14,$BJ14,$BL14,$BN14) -> 0 | BS14: =MEDIAN($C14,$E14,$G14,$I14,$K14,$M14,$O14,$Q14,$S14,$U14,$W14,$Y14,$AA14,$AC14,$AE14,$AG14,$AI14,$AK14,$AM14,$AO14,$AQ14,$AS14,$AU14,$AW14,$AY14,$BA14,$BC14,$BE14,$BG14,$BI14,$BK14,$BM14,$BO14) -> 0 | BT14: =MAX($B14,$D14,$F14,$H14,$J14,$L14,$N14,$P14,$R14,$T14,$V14,$X14,$Z14,$AB14,$AD14,$AF14,$AH14,$AJ14,$AL14,$AN14,$AP14,$AR14,$AT14,$AV14,$AX14,$AZ14,$BB14,$BD14,$BF14,$BH14,$BJ14,$BL14,$BN14) -> 0 | BU14: =MAX($C14,$E14,$G14,$I14,$K14,$M14,$O14,$Q14,$S14,$U14,$W14,$Y14,$AA14,$AC14,$AE14,$AG14,$AI14,$AK14,$AM14,$AO14,$AQ14,$AS14,$AU14,$AW14,$AY14,$BA14,$BC14,$BE14,$BG14,$BI14,$BK14,$BM14,$BO14) -> 0
... A62: ./cargobike-nested-500_user-input-4 | B62: 600 | C62: 1 | D62: 600 | E62: 1 | F62: 600 | G62: 1 | H62: 600 | I62: 1 | J62: 600 | K62: 1 | L62: 600 | M62: 1 | N62: 600 | O62: 1 | P62: 600 | Q62: 1 | R62: 600 | S62: 1 | T62: 600 | U62: 1 | V62: 600 | W62: 1 | X62: 107.08 | Y62: 0 | Z62: 92.17 | AA62: 0 | AB62: 83.97 | AC62: 0 | AD62: 105.8 | AE62: 0 | AF62: 85.81 | AG62: 0 | AH62: 98.02 | AI62: 0 | AJ62: 71.7 | AK62: 0 | AL62: 79.5 | AM62: 0 | AN62: 118.29 | AO62: 0 | AP62: 162.95 | AQ62: 0 | AR62: 220.92 | AS62: 0 | AT62: 21.71 | AU62: 0 | AV62: 23.66 | AW62: 0 | AX62: 13.12 | AY62: 0 | AZ62: 27.19 | BA62: 0 | BB62: 16.75 | BC62: 0 | BD62: 25.91 | BE62: 0 | BF62: 13.85 | BG62: 0 | BH62: 19.79 | BI62: 0 | BJ62: 46.91 | BK62: 0 | BL62: 85.53 | BM62: 0 | BN62: 151.67 | BO62: 0 | BP62: =MIN($B62,$D62,$F62,$H62,$J62,$L62,$N62,$P62,$R62,$T62,$V62,$X62,$Z62,$AB62,$AD62,$AF62,$AH62,$AJ62,$AL62,$AN62,$AP62,$AR62,$AT62,$AV62,$AX62,$AZ62,$BB62,$BD62,$BF62,$BH62,$BJ62,$BL62,$BN62) -> 0 | BQ62: =MIN($C62,$E62,$G62,$I62,$K62,$M62,$O62,$Q62,$S62,$U62,$W62,$Y62,$AA62,$AC62,$AE62,$AG62,$AI62,$AK62,$AM62,$AO62,$AQ62,$AS62,$AU62,$AW62,$AY62,$BA62,$BC62,$BE62,$BG62,$BI62,$BK62,$BM62,$BO62) -> 0 | BR62: =MEDIAN($B62,$D62,$F62,$H62,$J62,$L62,$N62,$P62,$R62,$T62,$V62,$X62,$Z62,$AB62,$AD62,$AF62,$AH62,$AJ62,$AL62,$AN62,$AP62,$AR62,$AT62,$AV62,$AX62,$AZ62,$BB62,$BD62,$BF62,$BH62,$BJ62,$BL62,$BN62) -> 0 | BS62: =MEDIAN($C62,$E62,$G62,$I62,$K62,$M62,$O62,$Q62,$S62,$U62,$W62,$Y62,$AA62,$AC62,$AE62,$AG62,$AI62,$AK62,$AM62,$AO62,$AQ62,$AS62,$AU62,$AW62,$AY62,$BA62,$BC62,$BE62,$BG62,$BI62,$BK62,$BM62,$BO62) -> 0 | BT62: =MAX($B62,$D62,$F62,$H62,$J62,$L62,$N62,$P62,$R62,$T62,$V62,$X62,$Z62,$AB62,$AD62,$AF62,$AH62,$AJ62,$AL62,$AN62,$AP62,$AR62,$AT62,$AV62,$AX62,$AZ62,$BB62,$BD62,$BF62,$BH62,$BJ62,$BL62,$BN62) -> 0 | BU62: =MAX($C62,$E62,$G62,$I62,$K62,$M62,$O62,$Q62,$S62,$U62,$W62,$Y62,$AA62,$AC62,$AE62,$AG62,$AI62,$AK62,$AM62,$AO62,$AQ62,$AS62,$AU62,$AW62,$AY62,$BA62,$BC62,$BE62,$BG62,$BI62,$BK62,$BM62,$BO62) -> 0
A64: SUM | B64: =SUM(B$3:B$62) -> 0 | C64: =SUM(C$3:C$62) -> 0 | D64: =SUM(D$3:D$62) -> 0 | E64: =SUM(E$3:E$62) -> 0 | F64: =SUM(F$3:F$62) -> 0 | G64: =SUM(G$3:G$62) -> 0 | H64: =SUM(H$3:H$62) -> 0 | I64: =SUM(I$3:I$62) -> 0 | ... BU64: =SUM(BU$3:BU$62) -> 0
A65: AVG | B65: =AVERAGE(B$3:B$62) -> 0 | C65: =AVERAGE(C$3:C$62) -> 0 | D65: =AVERAGE(D$3:D$62) -> 0 | E65: =AVERAGE(E$3:E$62) -> 0 | F65: =AVERAGE(F$3:F$62) -> 0 | G65: =AVERAGE(G$3:G$62) -> 0 | H65: =AVERAGE(H$3:H$62) -> 0 | I65: =AVERAGE(I$3:I$62) -> 0 | ... BU65: =AVERAGE(BU$3:BU$62) -> 0
A66: DEV | B66: =STDEV(B$3:B$62) -> 0 | C66: =STDEV(C$3:C$62) -> 0 | D66: =STDEV(D$3:D$62) -> 0 | E66: =STDEV(E$3:E$62) -> 0 | F66: =STDEV(F$3:F$62) -> 0 | G66: =STDEV(G$3:G$62) -> 0 | H66: =STDEV(H$3:H$62) -> 0 | I66: =STDEV(I$3:I$62) -> 0 | ... BU66: =STDEV(BU$3:BU$62) -> 0
A67: DST | B67: =SUMPRODUCT(--(B$3:B$62-$BP$3:$BP$62)^2)^0.5 -> 0 | C67: =SUMPRODUCT(--(C$3:C$62-$BQ$3:$BQ$62)^2)^0.5 -> 0 | D67: =SUMPRODUCT(--(D$3:D$62-$BP$3:$BP$62)^2)^0.5 -> 0 | E67: =SUMPRODUCT(--(E$3:E$62-$BQ$3:$BQ$62)^2)^0.5 -> 0 | F67: =SUMPRODUCT(--(F$3:F$62-$BP$3:$BP$62)^2)^0.5 -> 0 | G67: =SUMPRODUCT(--(G$3:G$62-$BQ$3:$BQ$62)^2)^0.5 -> 0 | H67: =SUMPRODUCT(--(H$3:H$62-$BP$3:$BP$62)^2)^0.5 -> 0 | I67: =SUMPRODUCT(--(I$3:I$62-$BQ$3:$BQ$62)^2)^0.5 -> 0 | J67: =SUMPRODUCT(--(J$3:J$62-$BP$3:$BP$62)^2)^0.5 -> 0 | K67: =SUMPRODUCT(--(K$3:K$62-$BQ$3:$BQ$62)^2)^0.5 -> 0 | L67: =SUMPRODUCT(--(L$3:L$62-$BP$3:$BP$62)^2)^0.5 -> 0 | M67: =SUMPRODUCT(--(M$3:M$62-$BQ$3:$BQ$62)^2)^0.5 -> 0 | N67: =SUMPRODUCT(--(N$3:N$62-$BP$3:$BP$62)^2)^0.5 -> 0 | O67: =SUMPRODUCT(--(O$3:O$62-$BQ$3:$BQ$62)^2)^0.5 -> 0 | P67: =SUMPRODUCT(--(P$3:P$62-$BP$3:$BP$62)^2)^0.5 -> 0 | Q67: =SUMPRODUCT(--(Q$3:Q$62-$BQ$3:$BQ$62)^2)^0.5 -> 0 | R67: =SUMPRODUCT(--(R$3:R$62-$BP$3:$BP$62)^2)^0.5 -> 0 | S67: =SUMPRODUCT(--(S$3:S$62-$BQ$3:$BQ$62)^2)^0.5 -> 0 | T67: =SUMPRODUCT(--(T$3:T$62-$BP$3:$BP$62)^2)^0.5 -> 0 | U67: =SUMPRODUCT(--(U$3:U$62-$BQ$3:$BQ$62)^2)^0.5 -> 0 | V67: =SUMPRODUCT(--(V$3:V$62-$BP$3:$BP$62)^2)^0.5 -> 0 | W67: =SUMPRODUCT(--(W$3:W$62-$BQ$3:$BQ$62)^2)^0.5 -> 0 | X67: =SUMPRODUCT(--(X$3:X$62-$BP$3:$BP$62)^2)^0.5 -> 0 | Y67: =SUMPRODUCT(--(Y$3:Y$62-$BQ$3:$BQ$62)^2)^0.5 -> 0 | Z67: =SUMPRODUCT(--(Z$3:Z$62-$BP$3:$BP$62)^2)^0.5 -> 0 | AA67: =SUMPRODUCT(--(AA$3:AA$62-$BQ$3:$BQ$62)^2)^0.5 -> 0 | AB67: =SUMPRODUCT(--(AB$3:AB$62-$BP$3:$BP$62)^2)^0.5 -> 0 | AC67: =SUMPRODUCT(--(AC$3:AC$62-$BQ$3:$BQ$62)^2)^0.5 -> 0 | AD67: =SUMPRODUCT(--(AD$3:AD$62-$BP$3:$BP$62)^2)^0.5 -> 0 | AE67: =SUMPRODUCT(--(AE$3:AE$62-$BQ$3:$BQ$62)^2)^0.5 -> 0 | AF67: =SUMPRODUCT(--(AF$3:AF$62-$BP$3:$BP$62)^2)^0.5 -> 0 | AG67: =SUMPRODUCT(--(AG$3:AG$62-$BQ$3:$BQ$62)^2)^0.5 -> 0 | AH67: =SUMPRODUCT(--(AH$3:AH$62-$BP$3:$BP$62)^2)^0.5 -> 0 | AI67: =SUMPRODUCT(--(AI$3:AI$62-$BQ$3:$BQ$62)^2)^0.5 -> 0 | AJ67: =SUMPRODUCT(--(AJ$3:AJ$62-$BP$3:$BP$62)^2)^0.5 -> 0 | AK67: =SUMPRODUCT(--(AK$3:AK$62-$BQ$3:$BQ$62)^2)^0.5 -> 0 | AL67: =SUMPRODUCT(--(AL$3:AL$62-$BP$3:$BP$62)^2)^0.5 -> 0 | AM67: =SUMPRODUCT(--(AM$3:AM$62-$BQ$3:$BQ$62)^2)^0.5 -> 0 | AN67: =SUMPRODUCT(--(AN$3:AN$62-$BP$3:$BP$62)^2)^0.5 -> 0 | AO67: =SUMPRODUCT(--(AO$3:AO$62-$BQ$3:$BQ$62)^2)^0.5 -> 0 | AP67: =SUMPRODUCT(--(AP$3:AP$62-$BP$3:$BP$62)^2)^0.5 -> 0 | AQ67: =SUMPRODUCT(--(AQ$3:AQ$62-$BQ$3:$BQ$62)^2)^0.5 -> 0 | AR67: =SUMPRODUCT(--(AR$3:AR$62-$BP$3:$BP$62)^2)^0.5 -> 0 | AS67: =SUMPRODUCT(--(AS$3:AS$62-$BQ$3:$BQ$62)^2)^0.5 -> 0 | AT67: =SUMPRODUCT(--(AT$3:AT$62-$BP$3:$BP$62)^2)^0.5 -> 0 | AU67: =SUMPRODUCT(--(AU$3:AU$62-$BQ$3:$BQ$62)^2)^0.5 -> 0 | AV67: =SUMPRODUCT(--(AV$3:AV$62-$BP$3:$BP$62)^2)^0.5 -> 0 | AW67: =SUMPRODUCT(--(AW$3:AW$62-$BQ$3:$BQ$62)^2)^0.5 -> 0 | AX67: =SUMPRODUCT(--(AX$3:AX$62-$BP$3:$BP$62)^2)^0.5 -> 0 | AY67: =SUMPRODUCT(--(AY$3:AY$62-$BQ$3:$BQ$62)^2)^0.5 -> 0 | AZ67: =SUMPRODUCT(--(AZ$3:AZ$62-$BP$3:$BP$62)^2)^0.5 -> 0 | BA67: =SUMPRODUCT(--(BA$3:BA$62-$BQ$3:$BQ$62)^2)^0.5 -> 0 | BB67: =SUMPRODUCT(--(BB$3:BB$62-$BP$3:$BP$62)^2)^0.5 -> 0 | BC67: =SUMPRODUCT(--(BC$3:BC$62-$BQ$3:$BQ$62)^2)^0.5 -> 0 | BD67: =SUMPRODUCT(--(BD$3:BD$62-$BP$3:$BP$62)^2)^0.5 -> 0 | BE67: =SUMPRODUCT(--(BE$3:BE$62-$BQ$3:$BQ$62)^2)^0.5 -> 0 | BF67: =SUMPRODUCT(--(BF$3:BF$62-$BP$3:$BP$62)^2)^0.5 -> 0 | BG67: =SUMPRODUCT(--(BG$3:BG$62-$BQ$3:$BQ$62)^2)^0.5 -> 0 | BH67: =SUMPRODUCT(--(BH$3:BH$62-$BP$3:$BP$62)^2)^0.5 -> 0 | BI67: =SUMPRODUCT(--(BI$3:BI$62-$BQ$3:$BQ$62)^2)^0.5 -> 0 | BJ67: =SUMPRODUCT(--(BJ$3:BJ$62-$BP$3:$BP$62)^2)^0.5 -> 0 | BK67: =SUMPRODUCT(--(BK$3:BK$62-$BQ$3:$BQ$62)^2)^0.5 -> 0 | BL67: =SUMPRODUCT(--(BL$3:BL$62-$BP$3:$BP$62)^2)^0.5 -> 0 | BM67: =SUMPRODUCT(--(BM$3:BM$62-$BQ$3:$BQ$62)^2)^0.5 -> 0 | BN67: =SUMPRODUCT(--(BN$3:BN$62-$BP$3:$BP$62)^2)^0.5 -> 0 | BO67: =SUMPRODUCT(--(BO$3:BO$62-$BQ$3:$BQ$62)^2)^0.5 -> 0
A68: BEST | B68: =SUMPRODUCT(NOT(ISBLANK(B$3:B$62))*(B$3:B$62=$BP$3:$BP$62)) -> 0 | C68: =SUMPRODUCT(NOT(ISBLANK(C$3:C$62))*(C$3:C$62=$BQ$3:$BQ$62)) -> 0 | D68: =SUMPRODUCT(NOT(ISBLANK(D$3:D$62))*(D$3:D$62=$BP$3:$BP$62)) -> 0 | E68: =SUMPRODUCT(NOT(ISBLANK(E$3:E$62))*(E$3:E$62=$BQ$3:$BQ$62)) -> 0 | F68: =SUMPRODUCT(NOT(ISBLANK(F$3:F$62))*(F$3:F$62=$BP$3:$BP$62)) -> 0 | G68: =SUMPRODUCT(NOT(ISBLANK(G$3:G$62))*(G$3:G$62=$BQ$3:$BQ$62)) -> 0 | H68: =SUMPRODUCT(NOT(ISBLANK(H$3:H$62))*(H$3:H$62=$BP$3:$BP$62)) -> 0 | I68: =SUMPRODUCT(NOT(ISBLANK(I$3:I$62))*(I$3:I$62=$BQ$3:$BQ$62)) -> 0 | J68: =SUMPRODUCT(NOT(ISBLANK(J$3:J$62))*(J$3:J$62=$BP$3:$BP$62)) -> 0 | K68: =SUMPRODUCT(NOT(ISBLANK(K$3:K$62))*(K$3:K$62=$BQ$3:$BQ$62)) -> 0 | L68: =SUMPRODUCT(NOT(ISBLANK(L$3:L$62))*(L$3:L$62=$BP$3:$BP$62)) -> 0 | M68: =SUMPRODUCT(NOT(ISBLANK(M$3:M$62))*(M$3:M$62=$BQ$3:$BQ$62)) -> 0 | N68: =SUMPRODUCT(NOT(ISBLANK(N$3:N$62))*(N$3:N$62=$BP$3:$BP$62)) -> 0 | O68: =SUMPRODUCT(NOT(ISBLANK(O$3:O$62))*(O$3:O$62=$BQ$3:$BQ$62)) -> 0 | P68: =SUMPRODUCT(NOT(ISBLANK(P$3:P$62))*(P$3:P$62=$BP$3:$BP$62)) -> 0 | Q68: =SUMPRODUCT(NOT(ISBLANK(Q$3:Q$62))*(Q$3:Q$62=$BQ$3:$BQ$62)) -> 0 | R68: =SUMPRODUCT(NOT(ISBLANK(R$3:R$62))*(R$3:R$62=$BP$3:$BP$62)) -> 0 | S68: =SUMPRODUCT(NOT(ISBLANK(S$3:S$62))*(S$3:S$62=$BQ$3:$BQ$62)) -> 0 | T68: =SUMPRODUCT(NOT(ISBLANK(T$3:T$62))*(T$3:T$62=$BP$3:$BP$62)) -> 0 | U68: =SUMPRODUCT(NOT(ISBLANK(U$3:U$62))*(U$3:U$62=$BQ$3:$BQ$62)) -> 0 | V68: =SUMPRODUCT(NOT(ISBLANK(V$3:V$62))*(V$3:V$62=$BP$3:$BP$62)) -> 0 | W68: =SUMPRODUCT(NOT(ISBLANK(W$3:W$62))*(W$3:W$62=$BQ$3:$BQ$62)) -> 0 | X68: =SUMPRODUCT(NOT(ISBLANK(X$3:X$62))*(X$3:X$62=$BP$3:$BP$62)) -> 0 | Y68: =SUMPRODUCT(NOT(ISBLANK(Y$3:Y$62))*(Y$3:Y$62=$BQ$3:$BQ$62)) -> 0 | Z68: =SUMPRODUCT(NOT(ISBLANK(Z$3:Z$62))*(Z$3:Z$62=$BP$3:$BP$62)) -> 0 | AA68: =SUMPRODUCT(NOT(ISBLANK(AA$3:AA$62))*(AA$3:AA$62=$BQ$3:$BQ$62)) -> 0 | AB68: =SUMPRODUCT(NOT(ISBLANK(AB$3:AB$62))*(AB$3:AB$62=$BP$3:$BP$62)) -> 0 | AC68: =SUMPRODUCT(NOT(ISBLANK(AC$3:AC$62))*(AC$3:AC$62=$BQ$3:$BQ$62)) -> 0 | AD68: =SUMPRODUCT(NOT(ISBLANK(AD$3:AD$62))*(AD$3:AD$62=$BP$3:$BP$62)) -> 0 | AE68: =SUMPRODUCT(NOT(ISBLANK(AE$3:AE$62))*(AE$3:AE$62=$BQ$3:$BQ$62)) -> 0 | AF68: =SUMPRODUCT(NOT(ISBLANK(AF$3:AF$62))*(AF$3:AF$62=$BP$3:$BP$62)) -> 0 | AG68: =SUMPRODUCT(NOT(ISBLANK(AG$3:AG$62))*(AG$3:AG$62=$BQ$3:$BQ$62)) -> 0 | AH68: =SUMPRODUCT(NOT(ISBLANK(AH$3:AH$62))*(AH$3:AH$62=$BP$3:$BP$62)) -> 0 | AI68: =SUMPRODUCT(NOT(ISBLANK(AI$3:AI$62))*(AI$3:AI$62=$BQ$3:$BQ$62)) -> 0 | AJ68: =SUMPRODUCT(NOT(ISBLANK(AJ$3:AJ$62))*(AJ$3:AJ$62=$BP$3:$BP$62)) -> 0 | AK68: =SUMPRODUCT(NOT(ISBLANK(AK$3:AK$62))*(AK$3:AK$62=$BQ$3:$BQ$62)) -> 0 | AL68: =SUMPRODUCT(NOT(ISBLANK(AL$3:AL$62))*(AL$3:AL$62=$BP$3:$BP$62)) -> 0 | AM68: =SUMPRODUCT(NOT(ISBLANK(AM$3:AM$62))*(AM$3:AM$62=$BQ$3:$BQ$62)) -> 0 | AN68: =SUMPRODUCT(NOT(ISBLANK(AN$3:AN$62))*(AN$3:AN$62=$BP$3:$BP$62)) -> 0 | AO68: =SUMPRODUCT(NOT(ISBLANK(AO$3:AO$62))*(AO$3:AO$62=$BQ$3:$BQ$62)) -> 0 | AP68: =SUMPRODUCT(NOT(ISBLANK(AP$3:AP$62))*(AP$3:AP$62=$BP$3:$BP$62)) -> 0 | AQ68: =SUMPRODUCT(NOT(ISBLANK(AQ$3:AQ$62))*(AQ$3:AQ$62=$BQ$3:$BQ$62)) -> 0 | AR68: =SUMPRODUCT(NOT(ISBLANK(AR$3:AR$62))*(AR$3:AR$62=$BP$3:$BP$62)) -> 0 | AS68: =SUMPRODUCT(NOT(ISBLANK(AS$3:AS$62))*(AS$3:AS$62=$BQ$3:$BQ$62)) -> 0 | AT68: =SUMPRODUCT(NOT(ISBLANK(AT$3:AT$62))*(AT$3:AT$62=$BP$3:$BP$62)) -> 0 | AU68: =SUMPRODUCT(NOT(ISBLANK(AU$3:AU$62))*(AU$3:AU$62=$BQ$3:$BQ$62)) -> 0 | AV68: =SUMPRODUCT(NOT(ISBLANK(AV$3:AV$62))*(AV$3:AV$62=$BP$3:$BP$62)) -> 0 | AW68: =SUMPRODUCT(NOT(ISBLANK(AW$3:AW$62))*(AW$3:AW$62=$BQ$3:$BQ$62)) -> 0 | AX68: =SUMPRODUCT(NOT(ISBLANK(AX$3:AX$62))*(AX$3:AX$62=$BP$3:$BP$62)) -> 0 | AY68: =SUMPRODUCT(NOT(ISBLANK(AY$3:AY$62))*(AY$3:AY$62=$BQ$3:$BQ$62)) -> 0 | AZ68: =SUMPRODUCT(NOT(ISBLANK(AZ$3:AZ$62))*(AZ$3:AZ$62=$BP$3:$BP$62)) -> 0 | BA68: =SUMPRODUCT(NOT(ISBLANK(BA$3:BA$62))*(BA$3:BA$62=$BQ$3:$BQ$62)) -> 0 | BB68: =SUMPRODUCT(NOT(ISBLANK(BB$3:BB$62))*(BB$3:BB$62=$BP$3:$BP$62)) -> 0 | BC68: =SUMPRODUCT(NOT(ISBLANK(BC$3:BC$62))*(BC$3:BC$62=$BQ$3:$BQ$62)) -> 0 | BD68: =SUMPRODUCT(NOT(ISBLANK(BD$3:BD$62))*(BD$3:BD$62=$BP$3:$BP$62)) -> 0 | BE68: =SUMPRODUCT(NOT(ISBLANK(BE$3:BE$62))*(BE$3:BE$62=$BQ$3:$BQ$62)) -> 0 | BF68: =SUMPRODUCT(NOT(ISBLANK(BF$3:BF$62))*(BF$3:BF$62=$BP$3:$BP$62)) -> 0 | BG68: =SUMPRODUCT(NOT(ISBLANK(BG$3:BG$62))*(BG$3:BG$62=$BQ$3:$BQ$62)) -> 0 | BH68: =SUMPRODUCT(NOT(ISBLANK(BH$3:BH$62))*(BH$3:BH$62=$BP$3:$BP$62)) -> 0 | BI68: =SUMPRODUCT(NOT(ISBLANK(BI$3:BI$62))*(BI$3:BI$62=$BQ$3:$BQ$62)) -> 0 | BJ68: =SUMPRODUCT(NOT(ISBLANK(BJ$3:BJ$62))*(BJ$3:BJ$62=$BP$3:$BP$62)) -> 0 | BK68: =SUMPRODUCT(NOT(ISBLANK(BK$3:BK$62))*(BK$3:BK$62=$BQ$3:$BQ$62)) -> 0 | BL68: =SUMPRODUCT(NOT(ISBLANK(BL$3:BL$62))*(BL$3:BL$62=$BP$3:$BP$62)) -> 0 | BM68: =SUMPRODUCT(NOT(ISBLANK(BM$3:BM$62))*(BM$3:BM$62=$BQ$3:$BQ$62)) -> 0 | BN68: =SUMPRODUCT(NOT(ISBLANK(BN$3:BN$62))*(BN$3:BN$62=$BP$3:$BP$62)) -> 0 | BO68: =SUMPRODUCT(NOT(ISBLANK(BO$3:BO$62))*(BO$3:BO$62=$BQ$3:$BQ$62)) -> 0
A69: BETTER | B69: =SUMPRODUCT(NOT(ISBLANK(B$3:B$62))*(B$3:B$62<$BR$3:$BR$62)) -> 0 | C69: =SUMPRODUCT(NOT(ISBLANK(C$3:C$62))*(C$3:C$62<$BS$3:$BS$62)) -> 0 | D69: =SUMPRODUCT(NOT(ISBLANK(D$3:D$62))*(D$3:D$62<$BR$3:$BR$62)) -> 0 | E69: =SUMPRODUCT(NOT(ISBLANK(E$3:E$62))*(E$3:E$62<$BS$3:$BS$62)) -> 0 | F69: =SUMPRODUCT(NOT(ISBLANK(F$3:F$62))*(F$3:F$62<$BR$3:$BR$62)) -> 0 | G69: =SUMPRODUCT(NOT(ISBLANK(G$3:G$62))*(G$3:G$62<$BS$3:$BS$62)) -> 0 | H69: =SUMPRODUCT(NOT(ISBLANK(H$3:H$62))*(H$3:H$62<$BR$3:$BR$62)) -> 0 | I69: =SUMPRODUCT(NOT(ISBLANK(I$3:I$62))*(I$3:I$62<$BS$3:$BS$62)) -> 0 | J69: =SUMPRODUCT(NOT(ISBLANK(J$3:J$62))*(J$3:J$62<$BR$3:$BR$62)) -> 0 | K69: =SUMPRODUCT(NOT(ISBLANK(K$3:K$62))*(K$3:K$62<$BS$3:$BS$62)) -> 0 | L69: =SUMPRODUCT(NOT(ISBLANK(L$3:L$62))*(L$3:L$62<$BR$3:$BR$62)) -> 0 | M69: =SUMPRODUCT(NOT(ISBLANK(M$3:M$62))*(M$3:M$62<$BS$3:$BS$62)) -> 0 | N69: =SUMPRODUCT(NOT(ISBLANK(N$3:N$62))*(N$3:N$62<$BR$3:$BR$62)) -> 0 | O69: =SUMPRODUCT(NOT(ISBLANK(O$3:O$62))*(O$3:O$62<$BS$3:$BS$62)) -> 0 | P69: =SUMPRODUCT(NOT(ISBLANK(P$3:P$62))*(P$3:P$62<$BR$3:$BR$62)) -> 0 | Q69: =SUMPRODUCT(NOT(ISBLANK(Q$3:Q$62))*(Q$3:Q$62<$BS$3:$BS$62)) -> 0 | R69: =SUMPRODUCT(NOT(ISBLANK(R$3:R$62))*(R$3:R$62<$BR$3:$BR$62)) -> 0 | S69: =SUMPRODUCT(NOT(ISBLANK(S$3:S$62))*(S$3:S$62<$BS$3:$BS$62)) -> 0 | T69: =SUMPRODUCT(NOT(ISBLANK(T$3:T$62))*(T$3:T$62<$BR$3:$BR$62)) -> 0 | U69: =SUMPRODUCT(NOT(ISBLANK(U$3:U$62))*(U$3:U$62<$BS$3:$BS$62)) -> 0 | V69: =SUMPRODUCT(NOT(ISBLANK(V$3:V$62))*(V$3:V$62<$BR$3:$BR$62)) -> 0 | W69: =SUMPRODUCT(NOT(ISBLANK(W$3:W$62))*(W$3:W$62<$BS$3:$BS$62)) -> 0 | X69: =SUMPRODUCT(NOT(ISBLANK(X$3:X$62))*(X$3:X$62<$BR$3:$BR$62)) -> 0 | Y69: =SUMPRODUCT(NOT(ISBLANK(Y$3:Y$62))*(Y$3:Y$62<$BS$3:$BS$62)) -> 0 | Z69: =SUMPRODUCT(NOT(ISBLANK(Z$3:Z$62))*(Z$3:Z$62<$BR$3:$BR$62)) -> 0 | AA69: =SUMPRODUCT(NOT(ISBLANK(AA$3:AA$62))*(AA$3:AA$62<$BS$3:$BS$62)) -> 0 | AB69: =SUMPRODUCT(NOT(ISBLANK(AB$3:AB$62))*(AB$3:AB$62<$BR$3:$BR$62)) -> 0 | AC69: =SUMPRODUCT(NOT(ISBLANK(AC$3:AC$62))*(AC$3:AC$62<$BS$3:$BS$62)) -> 0 | AD69: =SUMPRODUCT(NOT(ISBLANK(AD$3:AD$62))*(AD$3:AD$62<$BR$3:$BR$62)) -> 0 | AE69: =SUMPRODUCT(NOT(ISBLANK(AE$3:AE$62))*(AE$3:AE$62<$BS$3:$BS$62)) -> 0 | AF69: =SUMPRODUCT(NOT(ISBLANK(AF$3:AF$62))*(AF$3:AF$62<$BR$3:$BR$62)) -> 0 | AG69: =SUMPRODUCT(NOT(ISBLANK(AG$3:AG$62))*(AG$3:AG$62<$BS$3:$BS$62)) -> 0 | AH69: =SUMPRODUCT(NOT(ISBLANK(AH$3:AH$62))*(AH$3:AH$62<$BR$3:$BR$62)) -> 0 | AI69: =SUMPRODUCT(NOT(ISBLANK(AI$3:AI$62))*(AI$3:AI$62<$BS$3:$BS$62)) -> 0 | AJ69: =SUMPRODUCT(NOT(ISBLANK(AJ$3:AJ$62))*(AJ$3:AJ$62<$BR$3:$BR$62)) -> 0 | AK69: =SUMPRODUCT(NOT(ISBLANK(AK$3:AK$62))*(AK$3:AK$62<$BS$3:$BS$62)) -> 0 | AL69: =SUMPRODUCT(NOT(ISBLANK(AL$3:AL$62))*(AL$3:AL$62<$BR$3:$BR$62)) -> 0 | AM69: =SUMPRODUCT(NOT(ISBLANK(AM$3:AM$62))*(AM$3:AM$62<$BS$3:$BS$62)) -> 0 | AN69: =SUMPRODUCT(NOT(ISBLANK(AN$3:AN$62))*(AN$3:AN$62<$BR$3:$BR$62)) -> 0 | AO69: =SUMPRODUCT(NOT(ISBLANK(AO$3:AO$62))*(AO$3:AO$62<$BS$3:$BS$62)) -> 0 | AP69: =SUMPRODUCT(NOT(ISBLANK(AP$3:AP$62))*(AP$3:AP$62<$BR$3:$BR$62)) -> 0 | AQ69: =SUMPRODUCT(NOT(ISBLANK(AQ$3:AQ$62))*(AQ$3:AQ$62<$BS$3:$BS$62)) -> 0 | AR69: =SUMPRODUCT(NOT(ISBLANK(AR$3:AR$62))*(AR$3:AR$62<$BR$3:$BR$62)) -> 0 | AS69: =SUMPRODUCT(NOT(ISBLANK(AS$3:AS$62))*(AS$3:AS$62<$BS$3:$BS$62)) -> 0 | AT69: =SUMPRODUCT(NOT(ISBLANK(AT$3:AT$62))*(AT$3:AT$62<$BR$3:$BR$62)) -> 0 | AU69: =SUMPRODUCT(NOT(ISBLANK(AU$3:AU$62))*(AU$3:AU$62<$BS$3:$BS$62)) -> 0 | AV69: =SUMPRODUCT(NOT(ISBLANK(AV$3:AV$62))*(AV$3:AV$62<$BR$3:$BR$62)) -> 0 | AW69: =SUMPRODUCT(NOT(ISBLANK(AW$3:AW$62))*(AW$3:AW$62<$BS$3:$BS$62)) -> 0 | AX69: =SUMPRODUCT(NOT(ISBLANK(AX$3:AX$62))*(AX$3:AX$62<$BR$3:$BR$62)) -> 0 | AY69: =SUMPRODUCT(NOT(ISBLANK(AY$3:AY$62))*(AY$3:AY$62<$BS$3:$BS$62)) -> 0 | AZ69: =SUMPRODUCT(NOT(ISBLANK(AZ$3:AZ$62))*(AZ$3:AZ$62<$BR$3:$BR$62)) -> 0 | BA69: =SUMPRODUCT(NOT(ISBLANK(BA$3:BA$62))*(BA$3:BA$62<$BS$3:$BS$62)) -> 0 | BB69: =SUMPRODUCT(NOT(ISBLANK(BB$3:BB$62))*(BB$3:BB$62<$BR$3:$BR$62)) -> 0 | BC69: =SUMPRODUCT(NOT(ISBLANK(BC$3:BC$62))*(BC$3:BC$62<$BS$3:$BS$62)) -> 0 | BD69: =SUMPRODUCT(NOT(ISBLANK(BD$3:BD$62))*(BD$3:BD$62<$BR$3:$BR$62)) -> 0 | BE69: =SUMPRODUCT(NOT(ISBLANK(BE$3:BE$62))*(BE$3:BE$62<$BS$3:$BS$62)) -> 0 | BF69: =SUMPRODUCT(NOT(ISBLANK(BF$3:BF$62))*(BF$3:BF$62<$BR$3:$BR$62)) -> 0 | BG69: =SUMPRODUCT(NOT(ISBLANK(BG$3:BG$62))*(BG$3:BG$62<$BS$3:$BS$62)) -> 0 | BH69: =SUMPRODUCT(NOT(ISBLANK(BH$3:BH$62))*(BH$3:BH$62<$BR$3:$BR$62)) -> 0 | BI69: =SUMPRODUCT(NOT(ISBLANK(BI$3:BI$62))*(BI$3:BI$62<$BS$3:$BS$62)) -> 0 | BJ69: =SUMPRODUCT(NOT(ISBLANK(BJ$3:BJ$62))*(BJ$3:BJ$62<$BR$3:$BR$62)) -> 0 | BK69: =SUMPRODUCT(NOT(ISBLANK(BK$3:BK$62))*(BK$3:BK$62<$BS$3:$BS$62)) -> 0 | BL69: =SUMPRODUCT(NOT(ISBLANK(BL$3:BL$62))*(BL$3:BL$62<$BR$3:$BR$62)) -> 0 | BM69: =SUMPRODUCT(NOT(ISBLANK(BM$3:BM$62))*(BM$3:BM$62<$BS$3:$BS$62)) -> 0 | BN69: =SUMPRODUCT(NOT(ISBLANK(BN$3:BN$62))*(BN$3:BN$62<$BR$3:$BR$62)) -> 0 | BO69: =SUMPRODUCT(NOT(ISBLANK(BO$3:BO$62))*(BO$3:BO$62<$BS$3:$BS$62)) -> 0
A70: WORSE | B70: =SUMPRODUCT((NOT(ISBLANK(B$3:B$62))*(B$3:B$62>$BR$3:$BR$62))+ISBLANK(B$3:B$62)) -> 0 | C70: =SUMPRODUCT((NOT(ISBLANK(C$3:C$62))*(C$3:C$62>$BS$3:$BS$62))+ISBLANK(C$3:C$62)) -> 0 | D70: =SUMPRODUCT((NOT(ISBLANK(D$3:D$62))*(D$3:D$62>$BR$3:$BR$62))+ISBLANK(D$3:D$62)) -> 0 | E70: =SUMPRODUCT((NOT(ISBLANK(E$3:E$62))*(E$3:E$62>$BS$3:$BS$62))+ISBLANK(E$3:E$62)) -> 0 | F70: =SUMPRODUCT((NOT(ISBLANK(F$3:F$62))*(F$3:F$62>$BR$3:$BR$62))+ISBLANK(F$3:F$62)) -> 0 | G70: =SUMPRODUCT((NOT(ISBLANK(G$3:G$62))*(G$3:G$62>$BS$3:$BS$62))+ISBLANK(G$3:G$62)) -> 0 | H70: =SUMPRODUCT((NOT(ISBLANK(H$3:H$62))*(H$3:H$62>$BR$3:$BR$62))+ISBLANK(H$3:H$62)) -> 0 | I70: =SUMPRODUCT((NOT(ISBLANK(I$3:I$62))*(I$3:I$62>$BS$3:$BS$62))+ISBLANK(I$3:I$62)) -> 0 | J70: =SUMPRODUCT((NOT(ISBLANK(J$3:J$62))*(J$3:J$62>$BR$3:$BR$62))+ISBLANK(J$3:J$62)) -> 0 | K70: =SUMPRODUCT((NOT(ISBLANK(K$3:K$62))*(K$3:K$62>$BS$3:$BS$62))+ISBLANK(K$3:K$62)) -> 0 | L70: =SUMPRODUCT((NOT(ISBLANK(L$3:L$62))*(L$3:L$62>$BR$3:$BR$62))+ISBLANK(L$3:L$62)) -> 0 | M70: =SUMPRODUCT((NOT(ISBLANK(M$3:M$62))*(M$3:M$62>$BS$3:$BS$62))+ISBLANK(M$3:M$62)) -> 0 | N70: =SUMPRODUCT((NOT(ISBLANK(N$3:N$62))*(N$3:N$62>$BR$3:$BR$62))+ISBLANK(N$3:N$62)) -> 0 | O70: =SUMPRODUCT((NOT(ISBLANK(O$3:O$62))*(O$3:O$62>$BS$3:$BS$62))+ISBLANK(O$3:O$62)) -> 0 | P70: =SUMPRODUCT((NOT(ISBLANK(P$3:P$62))*(P$3:P$62>$BR$3:$BR$62))+ISBLANK(P$3:P$62)) -> 0 | Q70: =SUMPRODUCT((NOT(ISBLANK(Q$3:Q$62))*(Q$3:Q$62>$BS$3:$BS$62))+ISBLANK(Q$3:Q$62)) -> 0 | R70: =SUMPRODUCT((NOT(ISBLANK(R$3:R$62))*(R$3:R$62>$BR$3:$BR$62))+ISBLANK(R$3:R$62)) -> 0 | S70: =SUMPRODUCT((NOT(ISBLANK(S$3:S$62))*(S$3:S$62>$BS$3:$BS$62))+ISBLANK(S$3:S$62)) -> 0 | T70: =SUMPRODUCT((NOT(ISBLANK(T$3:T$62))*(T$3:T$62>$BR$3:$BR$62))+ISBLANK(T$3:T$62)) -> 0 | U70: =SUMPRODUCT((NOT(ISBLANK(U$3:U$62))*(U$3:U$62>$BS$3:$BS$62))+ISBLANK(U$3:U$62)) -> 0 | V70: =SUMPRODUCT((NOT(ISBLANK(V$3:V$62))*(V$3:V$62>$BR$3:$BR$62))+ISBLANK(V$3:V$62)) -> 0 | W70: =SUMPRODUCT((NOT(ISBLANK(W$3:W$62))*(W$3:W$62>$BS$3:$BS$62))+ISBLANK(W$3:W$62)) -> 0 | X70: =SUMPRODUCT((NOT(ISBLANK(X$3:X$62))*(X$3:X$62>$BR$3:$BR$62))+ISBLANK(X$3:X$62)) -> 0 | Y70: =SUMPRODUCT((NOT(ISBLANK(Y$3:Y$62))*(Y$3:Y$62>$BS$3:$BS$62))+ISBLANK(Y$3:Y$62)) -> 0 | Z70: =SUMPRODUCT((NOT(ISBLANK(Z$3:Z$62))*(Z$3:Z$62>$BR$3:$BR$62))+ISBLANK(Z$3:Z$62)) -> 0 | AA70: =SUMPRODUCT((NOT(ISBLANK(AA$3:AA$62))*(AA$3:AA$62>$BS$3:$BS$62))+ISBLANK(AA$3:AA$62)) -> 0 | AB70: =SUMPRODUCT((NOT(ISBLANK(AB$3:AB$62))*(AB$3:AB$62>$BR$3:$BR$62))+ISBLANK(AB$3:AB$62)) -> 0 | AC70: =SUMPRODUCT((NOT(ISBLANK(AC$3:AC$62))*(AC$3:AC$62>$BS$3:$BS$62))+ISBLANK(AC$3:AC$62)) -> 0 | AD70: =SUMPRODUCT((NOT(ISBLANK(AD$3:AD$62))*(AD$3:AD$62>$BR$3:$BR$62))+ISBLANK(AD$3:AD$62)) -> 0 | AE70: =SUMPRODUCT((NOT(ISBLANK(AE$3:AE$62))*(AE$3:AE$62>$BS$3:$BS$62))+ISBLANK(AE$3:AE$62)) -> 0 | AF70: =SUMPRODUCT((NOT(ISBLANK(AF$3:AF$62))*(AF$3:AF$62>$BR$3:$BR$62))+ISBLANK(AF$3:AF$62)) -> 0 | AG70: =SUMPRODUCT((NOT(ISBLANK(AG$3:AG$62))*(AG$3:AG$62>$BS$3:$BS$62))+ISBLANK(AG$3:AG$62)) -> 0 | AH70: =SUMPRODUCT((NOT(ISBLANK(AH$3:AH$62))*(AH$3:AH$62>$BR$3:$BR$62))+ISBLANK(AH$3:AH$62)) -> 0 | AI70: =SUMPRODUCT((NOT(ISBLANK(AI$3:AI$62))*(AI$3:AI$62>$BS$3:$BS$62))+ISBLANK(AI$3:AI$62)) -> 0 | AJ70: =SUMPRODUCT((NOT(ISBLANK(AJ$3:AJ$62))*(AJ$3:AJ$62>$BR$3:$BR$62))+ISBLANK(AJ$3:AJ$62)) -> 0 | AK70: =SUMPRODUCT((NOT(ISBLANK(AK$3:AK$62))*(AK$3:AK$62>$BS$3:$BS$62))+ISBLANK(AK$3:AK$62)) -> 0 | AL70: =SUMPRODUCT((NOT(ISBLANK(AL$3:AL$62))*(AL$3:AL$62>$BR$3:$BR$62))+ISBLANK(AL$3:AL$62)) -> 0 | AM70: =SUMPRODUCT((NOT(ISBLANK(AM$3:AM$62))*(AM$3:AM$62>$BS$3:$BS$62))+ISBLANK(AM$3:AM$62)) -> 0 | AN70: =SUMPRODUCT((NOT(ISBLANK(AN$3:AN$62))*(AN$3:AN$62>$BR$3:$BR$62))+ISBLANK(AN$3:AN$62)) -> 0 | AO70: =SUMPRODUCT((NOT(ISBLANK(AO$3:AO$62))*(AO$3:AO$62>$BS$3:$BS$62))+ISBLANK(AO$3:AO$62)) -> 0 | AP70: =SUMPRODUCT((NOT(ISBLANK(AP$3:AP$62))*(AP$3:AP$62>$BR$3:$BR$62))+ISBLANK(AP$3:AP$62)) -> 0 | AQ70: =SUMPRODUCT((NOT(ISBLANK(AQ$3:AQ$62))*(AQ$3:AQ$62>$BS$3:$BS$62))+ISBLANK(AQ$3:AQ$62)) -> 0 | AR70: =SUMPRODUCT((NOT(ISBLANK(AR$3:AR$62))*(AR$3:AR$62>$BR$3:$BR$62))+ISBLANK(AR$3:AR$62)) -> 0 | AS70: =SUMPRODUCT((NOT(ISBLANK(AS$3:AS$62))*(AS$3:AS$62>$BS$3:$BS$62))+ISBLANK(AS$3:AS$62)) -> 0 | AT70: =SUMPRODUCT((NOT(ISBLANK(AT$3:AT$62))*(AT$3:AT$62>$BR$3:$BR$62))+ISBLANK(AT$3:AT$62)) -> 0 | AU70: =SUMPRODUCT((NOT(ISBLANK(AU$3:AU$62))*(AU$3:AU$62>$BS$3:$BS$62))+ISBLANK(AU$3:AU$62)) -> 0 | AV70: =SUMPRODUCT((NOT(ISBLANK(AV$3:AV$62))*(AV$3:AV$62>$BR$3:$BR$62))+ISBLANK(AV$3:AV$62)) -> 0 | AW70: =SUMPRODUCT((NOT(ISBLANK(AW$3:AW$62))*(AW$3:AW$62>$BS$3:$BS$62))+ISBLANK(AW$3:AW$62)) -> 0 | AX70: =SUMPRODUCT((NOT(ISBLANK(AX$3:AX$62))*(AX$3:AX$62>$BR$3:$BR$62))+ISBLANK(AX$3:AX$62)) -> 0 | AY70: =SUMPRODUCT((NOT(ISBLANK(AY$3:AY$62))*(AY$3:AY$62>$BS$3:$BS$62))+ISBLANK(AY$3:AY$62)) -> 0 | AZ70: =SUMPRODUCT((NOT(ISBLANK(AZ$3:AZ$62))*(AZ$3:AZ$62>$BR$3:$BR$62))+ISBLANK(AZ$3:AZ$62)) -> 0 | BA70: =SUMPRODUCT((NOT(ISBLANK(BA$3:BA$62))*(BA$3:BA$62>$BS$3:$BS$62))+ISBLANK(BA$3:BA$62)) -> 0 | BB70: =SUMPRODUCT((NOT(ISBLANK(BB$3:BB$62))*(BB$3:BB$62>$BR$3:$BR$62))+ISBLANK(BB$3:BB$62)) -> 0 | BC70: =SUMPRODUCT((NOT(ISBLANK(BC$3:BC$62))*(BC$3:BC$62>$BS$3:$BS$62))+ISBLANK(BC$3:BC$62)) -> 0 | BD70: =SUMPRODUCT((NOT(ISBLANK(BD$3:BD$62))*(BD$3:BD$62>$BR$3:$BR$62))+ISBLANK(BD$3:BD$62)) -> 0 | BE70: =SUMPRODUCT((NOT(ISBLANK(BE$3:BE$62))*(BE$3:BE$62>$BS$3:$BS$62))+ISBLANK(BE$3:BE$62)) -> 0 | BF70: =SUMPRODUCT((NOT(ISBLANK(BF$3:BF$62))*(BF$3:BF$62>$BR$3:$BR$62))+ISBLANK(BF$3:BF$62)) -> 0 | BG70: =SUMPRODUCT((NOT(ISBLANK(BG$3:BG$62))*(BG$3:BG$62>$BS$3:$BS$62))+ISBLANK(BG$3:BG$62)) -> 0 | BH70: =SUMPRODUCT((NOT(ISBLANK(BH$3:BH$62))*(BH$3:BH$62>$BR$3:$BR$62))+ISBLANK(BH$3:BH$62)) -> 0 | BI70: =SUMPRODUCT((NOT(ISBLANK(BI$3:BI$62))*(BI$3:BI$62>$BS$3:$BS$62))+ISBLANK(BI$3:BI$62)) -> 0 | BJ70: =SUMPRODUCT((NOT(ISBLANK(BJ$3:BJ$62))*(BJ$3:BJ$62>$BR$3:$BR$62))+ISBLANK(BJ$3:BJ$62)) -> 0 | BK70: =SUMPRODUCT((NOT(ISBLANK(BK$3:BK$62))*(BK$3:BK$62>$BS$3:$BS$62))+ISBLANK(BK$3:BK$62)) -> 0 | BL70: =SUMPRODUCT((NOT(ISBLANK(BL$3:BL$62))*(BL$3:BL$62>$BR$3:$BR$62))+ISBLANK(BL$3:BL$62)) -> 0 | BM70: =SUMPRODUCT((NOT(ISBLANK(BM$3:BM$62))*(BM$3:BM$62>$BS$3:$BS$62))+ISBLANK(BM$3:BM$62)) -> 0 | BN70: =SUMPRODUCT((NOT(ISBLANK(BN$3:BN$62))*(BN$3:BN$62>$BR$3:$BR$62))+ISBLANK(BN$3:BN$62)) -> 0 | BO70: =SUMPRODUCT((NOT(ISBLANK(BO$3:BO$62))*(BO$3:BO$62>$BS$3:$BS$62))+ISBLANK(BO$3:BO$62)) -> 0
A71: WORST | B71: =SUMPRODUCT((NOT(ISBLANK(B$3:B$62))*(B$3:B$62=$BT$3:$BT$62))+ISBLANK(B$3:B$62)) -> 0 | C71: =SUMPRODUCT((NOT(ISBLANK(C$3:C$62))*(C$3:C$62=$BU$3:$BU$62))+ISBLANK(C$3:C$62)) -> 0 | D71: =SUMPRODUCT((NOT(ISBLANK(D$3:D$62))*(D$3:D$62=$BT$3:$BT$62))+ISBLANK(D$3:D$62)) -> 0 | E71: =SUMPRODUCT((NOT(ISBLANK(E$3:E$62))*(E$3:E$62=$BU$3:$BU$62))+ISBLANK(E$3:E$62)) -> 0 | F71: =SUMPRODUCT((NOT(ISBLANK(F$3:F$62))*(F$3:F$62=$BT$3:$BT$62))+ISBLANK(F$3:F$62)) -> 0 | G71: =SUMPRODUCT((NOT(ISBLANK(G$3:G$62))*(G$3:G$62=$BU$3:$BU$62))+ISBLANK(G$3:G$62)) -> 0 | H71: =SUMPRODUCT((NOT(ISBLANK(H$3:H$62))*(H$3:H$62=$BT$3:$BT$62))+ISBLANK(H$3:H$62)) -> 0 | I71: =SUMPRODUCT((NOT(ISBLANK(I$3:I$62))*(I$3:I$62=$BU$3:$BU$62))+ISBLANK(I$3:I$62)) -> 0 | J71: =SUMPRODUCT((NOT(ISBLANK(J$3:J$62))*(J$3:J$62=$BT$3:$BT$62))+ISBLANK(J$3:J$62)) -> 0 | K71: =SUMPRODUCT((NOT(ISBLANK(K$3:K$62))*(K$3:K$62=$BU$3:$BU$62))+ISBLANK(K$3:K$62)) -> 0 | L71: =SUMPRODUCT((NOT(ISBLANK(L$3:L$62))*(L$3:L$62=$BT$3:$BT$62))+ISBLANK(L$3:L$62)) -> 0 | M71: =SUMPRODUCT((NOT(ISBLANK(M$3:M$62))*(M$3:M$62=$BU$3:$BU$62))+ISBLANK(M$3:M$62)) -> 0 | N71: =SUMPRODUCT((NOT(ISBLANK(N$3:N$62))*(N$3:N$62=$BT$3:$BT$62))+ISBLANK(N$3:N$62)) -> 0 | O71: =SUMPRODUCT((NOT(ISBLANK(O$3:O$62))*(O$3:O$62=$BU$3:$BU$62))+ISBLANK(O$3:O$62)) -> 0 | P71: =SUMPRODUCT((NOT(ISBLANK(P$3:P$62))*(P$3:P$62=$BT$3:$BT$62))+ISBLANK(P$3:P$62)) -> 0 | Q71: =SUMPRODUCT((NOT(ISBLANK(Q$3:Q$62))*(Q$3:Q$62=$BU$3:$BU$62))+ISBLANK(Q$3:Q$62)) -> 0 | R71: =SUMPRODUCT((NOT(ISBLANK(R$3:R$62))*(R$3:R$62=$BT$3:$BT$62))+ISBLANK(R$3:R$62)) -> 0 | S71: =SUMPRODUCT((NOT(ISBLANK(S$3:S$62))*(S$3:S$62=$BU$3:$BU$62))+ISBLANK(S$3:S$62)) -> 0 | T71: =SUMPRODUCT((NOT(ISBLANK(T$3:T$62))*(T$3:T$62=$BT$3:$BT$62))+ISBLANK(T$3:T$62)) -> 0 | U71: =SUMPRODUCT((NOT(ISBLANK(U$3:U$62))*(U$3:U$62=$BU$3:$BU$62))+ISBLANK(U$3:U$62)) -> 0 | V71: =SUMPRODUCT((NOT(ISBLANK(V$3:V$62))*(V$3:V$62=$BT$3:$BT$62))+ISBLANK(V$3:V$62)) -> 0 | W71: =SUMPRODUCT((NOT(ISBLANK(W$3:W$62))*(W$3:W$62=$BU$3:$BU$62))+ISBLANK(W$3:W$62)) -> 0 | X71: =SUMPRODUCT((NOT(ISBLANK(X$3:X$62))*(X$3:X$62=$BT$3:$BT$62))+ISBLANK(X$3:X$62)) -> 0 | Y71: =SUMPRODUCT((NOT(ISBLANK(Y$3:Y$62))*(Y$3:Y$62=$BU$3:$BU$62))+ISBLANK(Y$3:Y$62)) -> 0 | Z71: =SUMPRODUCT((NOT(ISBLANK(Z$3:Z$62))*(Z$3:Z$62=$BT$3:$BT$62))+ISBLANK(Z$3:Z$62)) -> 0 | AA71: =SUMPRODUCT((NOT(ISBLANK(AA$3:AA$62))*(AA$3:AA$62=$BU$3:$BU$62))+ISBLANK(AA$3:AA$62)) -> 0 | AB71: =SUMPRODUCT((NOT(ISBLANK(AB$3:AB$62))*(AB$3:AB$62=$BT$3:$BT$62))+ISBLANK(AB$3:AB$62)) -> 0 | AC71: =SUMPRODUCT((NOT(ISBLANK(AC$3:AC$62))*(AC$3:AC$62=$BU$3:$BU$62))+ISBLANK(AC$3:AC$62)) -> 0 | AD71: =SUMPRODUCT((NOT(ISBLANK(AD$3:AD$62))*(AD$3:AD$62=$BT$3:$BT$62))+ISBLANK(AD$3:AD$62)) -> 0 | AE71: =SUMPRODUCT((NOT(ISBLANK(AE$3:AE$62))*(AE$3:AE$62=$BU$3:$BU$62))+ISBLANK(AE$3:AE$62)) -> 0 | AF71: =SUMPRODUCT((NOT(ISBLANK(AF$3:AF$62))*(AF$3:AF$62=$BT$3:$BT$62))+ISBLANK(AF$3:AF$62)) -> 0 | AG71: =SUMPRODUCT((NOT(ISBLANK(AG$3:AG$62))*(AG$3:AG$62=$BU$3:$BU$62))+ISBLANK(AG$3:AG$62)) -> 0 | AH71: =SUMPRODUCT((NOT(ISBLANK(AH$3:AH$62))*(AH$3:AH$62=$BT$3:$BT$62))+ISBLANK(AH$3:AH$62)) -> 0 | AI71: =SUMPRODUCT((NOT(ISBLANK(AI$3:AI$62))*(AI$3:AI$62=$BU$3:$BU$62))+ISBLANK(AI$3:AI$62)) -> 0 | AJ71: =SUMPRODUCT((NOT(ISBLANK(AJ$3:AJ$62))*(AJ$3:AJ$62=$BT$3:$BT$62))+ISBLANK(AJ$3:AJ$62)) -> 0 | AK71: =SUMPRODUCT((NOT(ISBLANK(AK$3:AK$62))*(AK$3:AK$62=$BU$3:$BU$62))+ISBLANK(AK$3:AK$62)) -> 0 | AL71: =SUMPRODUCT((NOT(ISBLANK(AL$3:AL$62))*(AL$3:AL$62=$BT$3:$BT$62))+ISBLANK(AL$3:AL$62)) -> 0 | AM71: =SUMPRODUCT((NOT(ISBLANK(AM$3:AM$62))*(AM$3:AM$62=$BU$3:$BU$62))+ISBLANK(AM$3:AM$62)) -> 0 | AN71: =SUMPRODUCT((NOT(ISBLANK(AN$3:AN$62))*(AN$3:AN$62=$BT$3:$BT$62))+ISBLANK(AN$3:AN$62)) -> 0 | AO71: =SUMPRODUCT((NOT(ISBLANK(AO$3:AO$62))*(AO$3:AO$62=$BU$3:$BU$62))+ISBLANK(AO$3:AO$62)) -> 0 | AP71: =SUMPRODUCT((NOT(ISBLANK(AP$3:AP$62))*(AP$3:AP$62=$BT$3:$BT$62))+ISBLANK(AP$3:AP$62)) -> 0 | AQ71: =SUMPRODUCT((NOT(ISBLANK(AQ$3:AQ$62))*(AQ$3:AQ$62=$BU$3:$BU$62))+ISBLANK(AQ$3:AQ$62)) -> 0 | AR71: =SUMPRODUCT((NOT(ISBLANK(AR$3:AR$62))*(AR$3:AR$62=$BT$3:$BT$62))+ISBLANK(AR$3:AR$62)) -> 0 | AS71: =SUMPRODUCT((NOT(ISBLANK(AS$3:AS$62))*(AS$3:AS$62=$BU$3:$BU$62))+ISBLANK(AS$3:AS$62)) -> 0 | AT71: =SUMPRODUCT((NOT(ISBLANK(AT$3:AT$62))*(AT$3:AT$62=$BT$3:$BT$62))+ISBLANK(AT$3:AT$62)) -> 0 | AU71: =SUMPRODUCT((NOT(ISBLANK(AU$3:AU$62))*(AU$3:AU$62=$BU$3:$BU$62))+ISBLANK(AU$3:AU$62)) -> 0 | AV71: =SUMPRODUCT((NOT(ISBLANK(AV$3:AV$62))*(AV$3:AV$62=$BT$3:$BT$62))+ISBLANK(AV$3:AV$62)) -> 0 | AW71: =SUMPRODUCT((NOT(ISBLANK(AW$3:AW$62))*(AW$3:AW$62=$BU$3:$BU$62))+ISBLANK(AW$3:AW$62)) -> 0 | AX71: =SUMPRODUCT((NOT(ISBLANK(AX$3:AX$62))*(AX$3:AX$62=$BT$3:$BT$62))+ISBLANK(AX$3:AX$62)) -> 0 | AY71: =SUMPRODUCT((NOT(ISBLANK(AY$3:AY$62))*(AY$3:AY$62=$BU$3:$BU$62))+ISBLANK(AY$3:AY$62)) -> 0 | AZ71: =SUMPRODUCT((NOT(ISBLANK(AZ$3:AZ$62))*(AZ$3:AZ$62=$BT$3:$BT$62))+ISBLANK(AZ$3:AZ$62)) -> 0 | BA71: =SUMPRODUCT((NOT(ISBLANK(BA$3:BA$62))*(BA$3:BA$62=$BU$3:$BU$62))+ISBLANK(BA$3:BA$62)) -> 0 | BB71: =SUMPRODUCT((NOT(ISBLANK(BB$3:BB$62))*(BB$3:BB$62=$BT$3:$BT$62))+ISBLANK(BB$3:BB$62)) -> 0 | BC71: =SUMPRODUCT((NOT(ISBLANK(BC$3:BC$62))*(BC$3:BC$62=$BU$3:$BU$62))+ISBLANK(BC$3:BC$62)) -> 0 | BD71: =SUMPRODUCT((NOT(ISBLANK(BD$3:BD$62))*(BD$3:BD$62=$BT$3:$BT$62))+ISBLANK(BD$3:BD$62)) -> 0 | BE71: =SUMPRODUCT((NOT(ISBLANK(BE$3:BE$62))*(BE$3:BE$62=$BU$3:$BU$62))+ISBLANK(BE$3:BE$62)) -> 0 | BF71: =SUMPRODUCT((NOT(ISBLANK(BF$3:BF$62))*(BF$3:BF$62=$BT$3:$BT$62))+ISBLANK(BF$3:BF$62)) -> 0 | BG71: =SUMPRODUCT((NOT(ISBLANK(BG$3:BG$62))*(BG$3:BG$62=$BU$3:$BU$62))+ISBLANK(BG$3:BG$62)) -> 0 | BH71: =SUMPRODUCT((NOT(ISBLANK(BH$3:BH$62))*(BH$3:BH$62=$BT$3:$BT$62))+ISBLANK(BH$3:BH$62)) -> 0 | BI71: =SUMPRODUCT((NOT(ISBLANK(BI$3:BI$62))*(BI$3:BI$62=$BU$3:$BU$62))+ISBLANK(BI$3:BI$62)) -> 0 | BJ71: =SUMPRODUCT((NOT(ISBLANK(BJ$3:BJ$62))*(BJ$3:BJ$62=$BT$3:$BT$62))+ISBLANK(BJ$3:BJ$62)) -> 0 | BK71: =SUMPRODUCT((NOT(ISBLANK(BK$3:BK$62))*(BK$3:BK$62=$BU$3:$BU$62))+ISBLANK(BK$3:BK$62)) -> 0 | BL71: =SUMPRODUCT((NOT(ISBLANK(BL$3:BL$62))*(BL$3:BL$62=$BT$3:$BT$62))+ISBLANK(BL$3:BL$62)) -> 0 | BM71: =SUMPRODUCT((NOT(ISBLANK(BM$3:BM$62))*(BM$3:BM$62=$BU$3:$BU$62))+ISBLANK(BM$3:BM$62)) -> 0 | BN71: =SUMPRODUCT((NOT(ISBLANK(BN$3:BN$62))*(BN$3:BN$62=$BT$3:$BT$62))+ISBLANK(BN$3:BN$62)) -> 0 | BO71: =SUMPRODUCT((NOT(ISBLANK(BO$3:BO$62))*(BO$3:BO$62=$BU$3:$BU$62))+ISBLANK(BO$3:BO$62)) -> 0

Sheet Merged Runs
A1: Merge criteria: | B1: coomsuite-1.1.2/incremental-exponential_clingo_1.25 | D1: coomsuite-1.1.2/incremental-exponential_clingo_1.33 | F1: coomsuite-1.1.2/incremental-exponential_clingo_1.5 | H1: coomsuite-1.1.2/incremental-exponential_clingo_1.66 | J1: coomsuite-1.1.2/incremental-exponential_clingo_1.75 | L1: coomsuite-1.1.2/incremental-exponential_clingo_2 | N1: coomsuite-1.1.2/incremental-exponential_clingo_2.25 | P1: coomsuite-1.1.2/incremental-exponential_clingo_2.33 | R1: coomsuite-1.1.2/incremental-exponential_clingo_2.5 | T1: coomsuite-1.1.2/incremental-exponential_clingo_2.66 | V1: coomsuite-1.1.2/incremental-exponential_clingo_2.75 | X1: coomsuite-1.1.2/incremental-exponential_flingo_1.25 | Z1: coomsuite-1.1.2/incremental-exponential_flingo_1.33 | AB1: coomsuite-1.1.2/incremental-exponential_flingo_1.5 | AD1: coomsuite-1.1.2/incremental-exponential_flingo_1.66 | AF1: coomsuite-1.1.2/incremental-exponential_flingo_1.75 | AH1: coomsuite-1.1.2/incremental-exponential_flingo_2 | AJ1: coomsuite-1.1.2/incremental-exponential_flingo_2.25 | AL1: coomsuite-1.1.2/incremental-exponential_flingo_2.33 | AN1: coomsuite-1.1.2/incremental-exponential_flingo_2.5 | AP1: coomsuite-1.1.2/incremental-exponential_flingo_2.66 | AR1: coomsuite-1.1.2/incremental-exponential_flingo_2.75 | AT1: coomsuite-1.1.2/multishot-exponential_1.25 | AV1: coomsuite-1.1.2/multishot-exponential_1.33 | AX1: coomsuite-1.1.2/multishot-exponential_1.5 | AZ1: coomsuite-1.1.2/multishot-exponential_1.66 | BB1: coomsuite-1.1.2/multishot-exponential_1.75 | BD1: coomsuite-1.1.2/multishot-exponential_2 | BF1: coomsuite-1.1.2/multishot-exponential_2.25 | BH1: coomsuite-1.1.2/multishot-exponential_2.33 | BJ1: coomsuite-1.1.2/multishot-exponential_2.5 | BL1: coomsuite-1.1.2/multishot-exponential_2.66 | BN1: coomsuite-1.1.2/multishot-exponential_2.75 | BP1: min | BR1: median | BT1: max
A2: median | B2: time | C2: timeout | D2: time | E2: timeout | F2: time | G2: timeout | H2: time | I2: timeout | J2: time | K2: timeout | L2: time | M2: timeout | N2: time | O2: timeout | P2: time | Q2: timeout | R2: time | S2: timeout | T2: time | U2: timeout | V2: time | W2: timeout | X2: time | Y2: timeout | Z2: time | AA2: timeout | AB2: time | AC2: timeout | AD2: time | AE2: timeout | AF2: time | AG2: timeout | AH2: time | AI2: timeout | AJ2: time | AK2: timeout | AL2: time | AM2: timeout | AN2: time | AO2: timeout | AP2: time | AQ2: timeout | AR2: time | AS2: timeout | AT2: time | AU2: timeout | AV2: time | AW2: timeout | AX2: time | AY2: timeout | AZ2: time | BA2: timeout | BB2: time | BC2: timeout | BD2: time | BE2: timeout | BF2: time | BG2: timeout | BH2: time | BI2: timeout | BJ2: time | BK2: timeout | BL2: time | BM2: timeout | BN2: time | BO2: timeout | BP2: time | BQ2: timeout | BR2: time | BS2: timeout | BT2: time | BU2: timeout
