Workbook

Sheet Instances
B1: coomsuite-1.0.0/clingo-base | D1: coomsuite-1.0.0/clingo-bounds-exponential | F1: coomsuite-1.0.0/clingo-bounds-linear | H1: coomsuite-1.0.0/flingo-base | J1: coomsuite-1.0.0/flingo-bounds-exponential | L1: coomsuite-1.0.0/flingo-bounds-linear | N1: coomsuite-1.0.0/multishot-exponential | P1: coomsuite-1.0.0/multishot-linear | R1: min | T1: median | V1: max
B2: time | C2: timeout | D2: time | E2: timeout | F2: time | G2: timeout | H2: time | I2: timeout | J2: time | K2: timeout | L2: time | M2: timeout | N2: time | O2: timeout | P2: time | Q2: timeout | R2: time | S2: timeout | T2: time | U2: timeout | V2: time | W2: timeout
A3: ./citybike-max100_user-input-n100 | B3: 4.37 | C3: 0 | H3: 23.67 | I3: 0 | R3: =MIN($B3,$D3,$F3,$H3,$J3,$L3,$N3,$P3) -> 0 | S3: =MIN($C3,$E3,$G3,$I3,$K3,$M3,$O3,$Q3) -> 0 | T3: =MEDIAN($B3,$D3,$F3,$H3,$J3,$L3,$N3,$P3) -> 0 | U3: =MEDIAN($C3,$E3,$G3,$I3,$K3,$M3,$O3,$Q3) -> 0 | V3: =MAX($B3,$D3,$F3,$H3,$J3,$L3,$N3,$P3) -> 0 | W3: =MAX($C3,$E3,$G3,$I3,$K3,$M3,$O3,$Q3) -> 0
A4: ./citybike-max100_user-input-n25 | B4: 4.29 | C4: 0 | H4: 22.64 | I4: 0 | R4: =MIN($B4,$D4,$F4,$H4,$J4,$L4,$N4,$P4) -> 0 | S4: =MIN($C4,$E4,$G4,$I4,$K4,$M4,$O4,$Q4) -> 0 | T4: =MEDIAN($B4,$D4,$F4,$H4,$J4,$L4,$N4,$P4) -> 0 | U4: =MEDIAN($C4,$E4,$G4,$I4,$K4,$M4,$O4,$Q4) -> 0 | V4: =MAX($B4,$D4,$F4,$H4,$J4,$L4,$N4,$P4) -> 0 | W4: =MAX($C4,$E4,$G4,$I4,$K4,$M4,$O4,$Q4) -> 0
A5: ./citybike-max100_user-input-n33 | B5: 4.32 | C5: 0 | H5: 22.49 | I5: 0 | R5: =MIN($B5,$D5,$F5,$H5,$J5,$L5,$N5,$P5) -> 0 | S5: =MIN($C5,$E5,$G5,$I5,$K5,$M5,$O5,$Q5) -> 0 | T5: =MEDIAN($B5,$D5,$F5,$H5,$J5,$L5,$N5,$P5) -> 0 | U5: =MEDIAN($C5,$E5,$G5,$I5,$K5,$M5,$O5,$Q5) -> 0 | V5: =MAX($B5,$D5,$F5,$H5,$J5,$L5,$N5,$P5) -> 0 | W5: =MAX($C5,$E5,$G5,$I5,$K5,$M5,$O5,$Q5) -> 0
A6: ./citybike-max100_user-input-n50 | B6: 4.41 | C6: 0 | H6: 22.94 | I6: 0 | R6: =MIN($B6,$D6,$F6,$H6,$J6,$L6,$N6,$P6) -> 0 | S6: =MIN($C6,$E6,$G6,$I6,$K6,$M6,$O6,$Q6) -> 0 | T6: =MEDIAN($B6,$D6,$F6,$H6,$J6,$L6,$N6,$P6) -> 0 | U6: =MEDIAN($C6,$E6,$G6,$I6,$K6,$M6,$O6,$Q6) -> 0 | V6: =MAX($B6,$D6,$F6,$H6,$J6,$L6,$N6,$P6) -> 0 | W6: =MAX($C6,$E6,$G6,$I6,$K6,$M6,$O6,$Q6) -> 0
A7: ./citybike-max150_user-input-n150 | B7: 8.63 | C7: 0 | H7: 38.38 | I7: 0 | R7: =MIN($B7,$D7,$F7,$H7,$J7,$L7,$N7,$P7) -> 0 | S7: =MIN($C7,$E7,$G7,$I7,$K7,$M7,$O7,$Q7) -> 0 | T7: =MEDIAN($B7,$D7,$F7,$H7,$J7,$L7,$N7,$P7) -> 0 | U7: =MEDIAN($C7,$E7,$G7,$I7,$K7,$M7,$O7,$Q7) -> 0 | V7: =MAX($B7,$D7,$F7,$H7,$J7,$L7,$N7,$P7) -> 0 | W7: =MAX($C7,$E7,$G7,$I7,$K7,$M7,$O7,$Q7) -> 0
A8: ./citybike-max150_user-input-n37 | B8: 8.55 | C8: 0 | H8: 37.39 | I8: 0 | R8: =MIN($B8,$D8,$F8,$H8,$J8,$L8,$N8,$P8) -> 0 | S8: =MIN($C8,$E8,$G8,$I8,$K8,$M8,$O8,$Q8) -> 0 | T8: =MEDIAN($B8,$D8,$F8,$H8,$J8,$L8,$N8,$P8) -> 0 | U8: =MEDIAN($C8,$E8,$G8,$I8,$K8,$M8,$O8,$Q8) -> 0 | V8: =MAX($B8,$D8,$F8,$H8,$J8,$L8,$N8,$P8) -> 0 | W8: =MAX($C8,$E8,$G8,$I8,$K8,$M8,$O8,$Q8) -> 0
A9: ./citybike-max150_user-input-n50 | B9: 8.72 | C9: 0 | H9: 37.82 | I9: 0 | R9: =MIN($B9,$D9,$F9,$H9,$J9,$L9,$N9,$P9) -> 0 | S9: =MIN($C9,$E9,$G9,$I9,$K9,$M9,$O9,$Q9) -> 0 | T9: =MEDIAN($B9,$D9,$F9,$H9,$J9,$L9,$N9,$P9) -> 0 | U9: =MEDIAN($C9,$E9,$G9,$I9,$K9,$M9,$O9,$Q9) -> 0 | V9: =MAX($B9,$D9,$F9,$H9,$J9,$L9,$N9,$P9) -> 0 | W9: =MAX($C9,$E9,$G9,$I9,$K9,$M9,$O9,$Q9) -> 0
A10: ./citybike-max150_user-input-n75 | B10: 8.67 | C10: 0 | H10: 38.24 | I10: 0 | R10: =MIN($B10,$D10,$F10,$H10,$J10,$L10,$N10,$P10) -> 0 | S10: =MIN($C10,$E10,$G10,$I10,$K10,$M10,$O10,$Q10) -> 0 | T10: =MEDIAN($B10,$D10,$F10,$H10,$J10,$L10,$N10,$P10) -> 0 | U10: =MEDIAN($C10,$E10,$G10,$I10,$K10,$M10,$O10,$Q10) -> 0 | V10: =MAX($B10,$D10,$F10,$H10,$J10,$L10,$N10,$P10) -> 0 | W10: =MAX($C10,$E10,$G10,$I10,$K10,$M10,$O10,$Q10) -> 0
A11: ./citybike-max200_user-input-n100 | B11: 14.57 | C11: 0 | H11: 57.86 | I11: 0 | R11: =MIN($B11,$D11,$F11,$H11,$J11,$L11,$N11,$P11) -> 0 | S11: =MIN($C11,$E11,$G11,$I11,$K11,$M11,$O11,$Q11) -> 0 | T11: =MEDIAN($B11,$D11,$F11,$H11,$J11,$L11,$N11,$P11) -> 0 | U11: =MEDIAN($C11,$E11,$G11,$I11,$K11,$M11,$O11,$Q11) -> 0 | V11: =MAX($B11,$D11,$F11,$H11,$J11,$L11,$N11,$P11) -> 0 | W11: =MAX($C11,$E11,$G11,$I11,$K11,$M11,$O11,$Q11) -> 0
A12: ./citybike-max200_user-input-n200 | B12: 15.85 | C12: 0 | H12: 58.48 | I12: 0 | R12: =MIN($B12,$D12,$F12,$H12,$J12,$L12,$N12,$P12) -> 0 | S12: =MIN($C12,$E12,$G12,$I12,$K12,$M12,$O12,$Q12) -> 0 | T12: =MEDIAN($B12,$D12,$F12,$H12,$J12,$L12,$N12,$P12) -> 0 | U12: =MEDIAN($C12,$E12,$G12,$I12,$K12,$M12,$O12,$Q12) -> 0 | V12: =MAX($B12,$D12,$F12,$H12,$J12,$L12,$N12,$P12) -> 0 | W12: =MAX($C12,$E12,$G12,$I12,$K12,$M12,$O12,$Q12) -> 0
A13: ./citybike-max200_user-input-n50 | B13: 14.56 | C13: 0 | H13: 54.73 | I13: 0 | R13: =MIN($B13,$D13,$F13,$H13,$J13,$L13,$N13,$P13) -> 0 | S13: =MIN($C13,$E13,$G13,$I13,$K13,$M13,$O13,$Q13) -> 0 | T13: =MEDIAN($B13,$D13,$F13,$H13,$J13,$L13,$N13,$P13) -> 0 | U13: =MEDIAN($C13,$E13,$G13,$I13,$K13,$M13,$O13,$Q13) -> 0 | V13: =MAX($B13,$D13,$F13,$H13,$J13,$L13,$N13,$P13) -> 0 | W13: =MAX($C13,$E13,$G13,$I13,$K13,$M13,$O13,$Q13) -> 0
A14: ./citybike-max200_user-input-n66 | B14: 14.38 | C14: 0 | H14: 55.51 | I14: 0 | R14: =MIN($B14,$D14,$F14,$H14,$J14,$L14,$N14,$P14) -> 0 | S14: =MIN($C14,$E14,$G14,$I14,$K14,$M14,$O14,$Q14) -> 0 | T14: =MEDIAN($B14,$D14,$F14,$H14,$J14,$L14,$N14,$P14) -> 0 | U14: =MEDIAN($C14,$E14,$G14,$I14,$K14,$M14,$O14,$Q14) -> 0 | V14: =MAX($B14,$D14,$F14,$H14,$J14,$L14,$N14,$P14) -> 0 | W14: =MAX($C14,$E14,$G14,$I14,$K14,$M14,$O14,$Q14) -> 0
... A73: ./travelbike-max5_user-input-p92-v415 | B73: 28.4 | C73: 0 | H73: 2.32 | I73: 0 | R73: =MIN($B73,$D73,$F73,$H73,$J73,$L73,$N73,$P73) -> 0 | S73: =MIN($C73,$E73,$G73,$I73,$K73,$M73,$O73,$Q73) -> 0 | T73: =MEDIAN($B73,$D73,$F73,$H73,$J73,$L73,$N73,$P73) -> 0 | U73: =MEDIAN($C73,$E73,$G73,$I73,$K73,$M73,$O73,$Q73) -> 0 | V73: =MAX($B73,$D73,$F73,$H73,$J73,$L73,$N73,$P73) -> 0 | W73: =MAX($C73,$E73,$G73,$I73,$K73,$M73,$O73,$Q73) -> 0
A74: ./cargobike-complex-100_user-input-0 | D74: 0.58 | E74: 0 | F74: 0.57 | G74: 0 | J74: 2.11 | K74: 0 | L74: 2.12 | M74: 0 | N74: 0.53 | O74: 0 | P74: 0.73 | Q74: 0 | R74: =MIN($B74,$D74,$F74,$H74,$J74,$L74,$N74,$P74) -> 0 | S74: =MIN($C74,$E74,$G74,$I74,$K74,$M74,$O74,$Q74) -> 0 | T74: =MEDIAN($B74,$D74,$F74,$H74,$J74,$L74,$N74,$P74) -> 0 | U74: =MEDIAN($C74,$E74,$G74,$I74,$K74,$M74,$O74,$Q74) -> 0 | V74: =MAX($B74,$D74,$F74,$H74,$J74,$L74,$N74,$P74) -> 0 | W74: =MAX($C74,$E74,$G74,$I74,$K74,$M74,$O74,$Q74) -> 0
A75: ./cargobike-complex-100_user-input-1 | D75: 0.44 | E75: 0 | F75: 0.44 | G75: 0 | J75: 1.96 | K75: 0 | L75: 1.98 | M75: 0 | N75: 0.45 | O75: 0 | P75: 0.56 | Q75: 0 | R75: =MIN($B75,$D75,$F75,$H75,$J75,$L75,$N75,$P75) -> 0 | S75: =MIN($C75,$E75,$G75,$I75,$K75,$M75,$O75,$Q75) -> 0 | T75: =MEDIAN($B75,$D75,$F75,$H75,$J75,$L75,$N75,$P75) -> 0 | U75: =MEDIAN($C75,$E75,$G75,$I75,$K75,$M75,$O75,$Q75) -> 0 | V75: =MAX($B75,$D75,$F75,$H75,$J75,$L75,$N75,$P75) -> 0 | W75: =MAX($C75,$E75,$G75,$I75,$K75,$M75,$O75,$Q75) -> 0
A76: ./cargobike-complex-100_user-input-10 | D76: 0.65 | E76: 0 | F76: 0.51 | G76: 0 | J76: 5.74 | K76: 0 | L76: 2.91 | M76: 0 | N76: 0.86 | O76: 0 | P76: 0.51 | Q76: 0 | R76: =MIN($B76,$D76,$F76,$H76,$J76,$L76,$N76,$P76) -> 0 | S76: =MIN($C76,$E76,$G76,$I76,$K76,$M76,$O76,$Q76) -> 0 | T76: =MEDIAN($B76,$D76,$F76,$H76,$J76,$L76,$N76,$P76) -> 0 | U76: =MEDIAN($C76,$E76,$G76,$I76,$K76,$M76,$O76,$Q76) -> 0 | V76: =MAX($B76,$D76,$F76,$H76,$J76,$L76,$N76,$P76) -> 0 | W76: =MAX($C76,$E76,$G76,$I76,$K76,$M76,$O76,$Q76) -> 0
A77: ./cargobike-complex-100_user-input-11 | D77: 0.68 | E77: 0 | F77: 0.7 | G77: 0 | J77: 5.61 | K77: 0 | L77: 2.88 | M77: 0 | N77: 0.85 | O77: 0 | P77: 0.5 | Q77: 0 | R77: =MIN($B77,$D77,$F77,$H77,$J77,$L77,$N77,$P77) -> 0 | S77: =MIN($C77,$E77,$G77,$I77,$K77,$M77,$O77,$Q77) -> 0 | T77: =MEDIAN($B77,$D77,$F77,$H77,$J77,$L77,$N77,$P77) -> 0 | U77: =MEDIAN($C77,$E77,$G77,$I77,$K77,$M77,$O77,$Q77) -> 0 | V77: =MAX($B77,$D77,$F77,$H77,$J77,$L77,$N77,$P77) -> 0 | W77: =MAX($C77,$E77,$G77,$I77,$K77,$M77,$O77,$Q77) -> 0
A78: ./cargobike-complex-100_user-input-12 | D78: 0.83 | E78: 0 | F78: 0.75 | G78: 0 | J78: 5.8 | K78: 0 | L78: 4.31 | M78: 0 | N78: 0.85 | O78: 0 | P78: 0.75 | Q78: 0 | R78: =MIN($B78,$D78,$F78,$H78,$J78,$L78,$N78,$P78) -> 0 | S78: =MIN($C78,$E78,$G78,$I78,$K78,$M78,$O78,$Q78) -> 0 | T78: =MEDIAN($B78,$D78,$F78,$H78,$J78,$L78,$N78,$P78) -> 0 | U78: =MEDIAN($C78,$E78,$G78,$I78,$K78,$M78,$O78,$Q78) -> 0 | V78: =MAX($B78,$D78,$F78,$H78,$J78,$L78,$N78,$P78) -> 0 | W78: =MAX($C78,$E78,$G78,$I78,$K78,$M78,$O78,$Q78) -> 0
A79: ./cargobike-complex-100_user-input-13 | D79: 0.8 | E79: 0 | F79: 0.95 | G79: 0 | J79: 5.76 | K79: 0 | L79: 4.19 | M79: 0 | N79: 0.86 | O79: 0 | P79: 0.64 | Q79: 0 | R79: =MIN($B79,$D79,$F79,$H79,$J79,$L79,$N79,$P79) -> 0 | S79: =MIN($C79,$E79,$G79,$I79,$K79,$M79,$O79,$Q79) -> 0 | T79: =MEDIAN($B79,$D79,$F79,$H79,$J79,$L79,$N79,$P79) -> 0 | U79: =MEDIAN($C79,$E79,$G79,$I79,$K79,$M79,$O79,$Q79) -> 0 | V79: =MAX($B79,$D79,$F79,$H79,$J79,$L79,$N79,$P79) -> 0 | W79: =MAX($C79,$E79,$G79,$I79,$K79,$M79,$O79,$Q79) -> 0
A80: ./cargobike-complex-100_user-input-14 | D80: 0.67 | E80: 0 | F80: 0.58 | G80: 0 | J80: 5.68 | K80: 0 | L80: 4.04 | M80: 0 | N80: 0.83 | O80: 0 | P80: 0.63 | Q80: 0 | R80: =MIN($B80,$D80,$F80,$H80,$J80,$L80,$N80,$P80) -> 0 | S80: =MIN($C80,$E80,$G80,$I80,$K80,$M80,$O80,$Q80) -> 0 | T80: =MEDIAN($B80,$D80,$F80,$H80,$J80,$L80,$N80,$P80) -> 0 | U80: =MEDIAN($C80,$E80,$G80,$I80,$K80,$M80,$O80,$Q80) -> 0 | V80: =MAX($B80,$D80,$F80,$H80,$J80,$L80,$N80,$P80) -> 0 | W80: =MAX($C80,$E80,$G80,$I80,$K80,$M80,$O80,$Q80) -> 0
A81: ./cargobike-complex-100_user-input-15 | D81: 0.68 | E81: 0 | F81: 0.6 | G81: 0 | J81: 5.7 | K81: 0 | L81: 4.24 | M81: 0 | N81: 0.87 | O81: 0 | P81: 0.58 | Q81: 0 | R81: =MIN($B81,$D81,$F81,$H81,$J81,$L81,$N81,$P81) -> 0 | S81: =MIN($C81,$E81,$G81,$I81,$K81,$M81,$O81,$Q81) -> 0 | T81: =MEDIAN($B81,$D81,$F81,$H81,$J81,$L81,$N81,$P81) -> 0 | U81: =MEDIAN($C81,$E81,$G81,$I81,$K81,$M81,$O81,$Q81) -> 0 | V81: =MAX($B81,$D81,$F81,$H81,$J81,$L81,$N81,$P81) -> 0 | W81: =MAX($C81,$E81,$G81,$I81,$K81,$M81,$O81,$Q81) -> 0
A82: ./cargobike-complex-100_user-input-16 | D82: 0.73 | E82: 0 | F82: 0.62 | G82: 0 | J82: 5.7 | K82: 0 | L82: 4.21 | M82: 0 | N82: 0.85 | O82: 0 | P82: 0.6 | Q82: 0 | R82: =MIN($B82,$D82,$F82,$H82,$J82,$L82,$N82,$P82) -> 0 | S82: =MIN($C82,$E82,$G82,$I82,$K82,$M82,$O82,$Q82) -> 0 | T82: =MEDIAN($B82,$D82,$F82,$H82,$J82,$L82,$N82,$P82) -> 0 | U82: =MEDIAN($C82,$E82,$G82,$I82,$K82,$M82,$O82,$Q82) -> 0 | V82: =MAX($B82,$D82,$F82,$H82,$J82,$L82,$N82,$P82) -> 0 | W82: =MAX($C82,$E82,$G82,$I82,$K82,$M82,$O82,$Q82) -> 0
A83: ./cargobike-complex-100_user-input-17 | D83: 0.7 | E83: 0 | F83: 0.83 | G83: 0 | J83: 5.78 | K83: 0 | L83: 4.17 | M83: 0 | N83: 0.83 | O83: 0 | P83: 0.83 | Q83: 0 | R83: =MIN($B83,$D83,$F83,$H83,$J83,$L83,$N83,$P83) -> 0 | S83: =MIN($C83,$E83,$G83,$I83,$K83,$M83,$O83,$Q83) -> 0 | T83: =MEDIAN($B83,$D83,$F83,$H83,$J83,$L83,$N83,$P83) -> 0 | U83: =MEDIAN($C83,$E83,$G83,$I83,$K83,$M83,$O83,$Q83) -> 0 | V83: =MAX($B83,$D83,$F83,$H83,$J83,$L83,$N83,$P83) -> 0 | W83: =MAX($C83,$E83,$G83,$I83,$K83,$M83,$O83,$Q83) -> 0
A84: ./cargobike-complex-100_user-input-18 | D84: 0.83 | E84: 0 | F84: 0.75 | G84: 0 | J84: 6.89 | K84: 0 | L84: 4.14 | M84: 0 | N84: 0.87 | O84: 0 | P84: 0.74 | Q84: 0 | R84: =MIN($B84,$D84,$F84,$H84,$J84,$L84,$N84,$P84) -> 0 | S84: =MIN($C84,$E84,$G84,$I84,$K84,$M84,$O84,$Q84) -> 0 | T84: =MEDIAN($B84,$D84,$F84,$H84,$J84,$L84,$N84,$P84) -> 0 | U84: =MEDIAN($C84,$E84,$G84,$I84,$K84,$M84,$O84,$Q84) -> 0 | V84: =MAX($B84,$D84,$F84,$H84,$J84,$L84,$N84,$P84) -> 0 | W84: =MAX($C84,$E84,$G84,$I84,$K84,$M84,$O84,$Q84) -> 0
A85: ./cargobike-complex-100_user-input-19 | D85: 0.81 | E85: 0 | F85: 0.72 | G85: 0 | J85: 5.76 | K85: 0 | L85: 4.13 | M85: 0 | N85: 0.94 | O85: 0 | P85: 0.8 | Q85: 0 | R85: =MIN($B85,$D85,$F85,$H85,$J85,$L85,$N85,$P85) -> 0 | S85: =MIN($C85,$E85,$G85,$I85,$K85,$M85,$O85,$Q85) -> 0 | T85: =MEDIAN($B85,$D85,$F85,$H85,$J85,$L85,$N85,$P85) -> 0 | U85: =MEDIAN($C85,$E85,$G85,$I85,$K85,$M85,$O85,$Q85) -> 0 | V85: =MAX($B85,$D85,$F85,$H85,$J85,$L85,$N85,$P85) -> 0 | W85: =MAX($C85,$E85,$G85,$I85,$K85,$M85,$O85,$Q85) -> 0
... A341: ./travelbike-max5_user-input-p92-v415 | D341: 1200 | E341: 1 | F341: 1200 | G341: 1 | J341: 1200 | K341: 1 | L341: 1200 | M341: 1 | N341: 1200 | O341: 1 | P341: 1200 | Q341: 1 | R341: =MIN($B341,$D341,$F341,$H341,$J341,$L341,$N341,$P341) -> 0 | S341: =MIN($C341,$E341,$G341,$I341,$K341,$M341,$O341,$Q341) -> 0 | T341: =MEDIAN($B341,$D341,$F341,$H341,$J341,$L341,$N341,$P341) -> 0 | U341: =MEDIAN($C341,$E341,$G341,$I341,$K341,$M341,$O341,$Q341) -> 0 | V341: =MAX($B341,$D341,$F341,$H341,$J341,$L341,$N341,$P341) -> 0 | W341: =MAX($C341,$E341,$G341,$I341,$K341,$M341,$O341,$Q341) -> 0
A343: SUM | B343: =SUM(B$3:B$341) -> 0 | C343: =SUM(C$3:C$341) -> 0 | D343: =SUM(D$3:D$341) -> 0 | E343: =SUM(E$3:E$341) -> 0 | F343: =SUM(F$3:F$341) -> 0 | G343: =SUM(G$3:G$341) -> 0 | H343: =SUM(H$3:H$341) -> 0 | I343: =SUM(I$3:I$341) -> 0 | ... W343: =SUM(W$3:W$341) -> 0
A344: AVG | B344: =AVERAGE(B$3:B$341) -> 0 | C344: =AVERAGE(C$3:C$341) -> 0 | D344: =AVERAGE(D$3:D$341) -> 0 | E344: =AVERAGE(E$3:E$341) -> 0 | F344: =AVERAGE(F$3:F$341) -> 0 | G344: =AVERAGE(G$3:G$341) -> 0 | H344: =AVERAGE(H$3:H$341) -> 0 | I344: =AVERAGE(I$3:I$341) -> 0 | ... W344: =AVERAGE(W$3:W$341) -> 0
A345: DEV | B345: =STDEV(B$3:B$341) -> 0 | C345: =STDEV(C$3:C$341) -> 0 | D345: =STDEV(D$3:D$341) -> 0 | E345: =STDEV(E$3:E$341) -> 0 | F345: =STDEV(F$3:F$341) -> 0 | G345: =STDEV(G$3:G$341) -> 0 | H345: =STDEV(H$3:H$341) -> 0 | I345: =STDEV(I$3:I$341) -> 0 | ... W345: =STDEV(W$3:W$341) -> 0
A346: DST | B346: =SUMPRODUCT(--(B$3:B$341-$R$3:$R$341)^2)^0.5 -> 0 | C346: =SUMPRODUCT(--(C$3:C$341-$S$3:$S$341)^2)^0.5 -> 0 | D346: =SUMPRODUCT(--(D$3:D$341-$R$3:$R$341)^2)^0.5 -> 0 | E346: =SUMPRODUCT(--(E$3:E$341-$S$3:$S$341)^2)^0.5 -> 0 | F346: =SUMPRODUCT(--(F$3:F$341-$R$3:$R$341)^2)^0.5 -> 0 | G346: =SUMPRODUCT(--(G$3:G$341-$S$3:$S$341)^2)^0.5 -> 0 | H346: =SUMPRODUCT(--(H$3:H$341-$R$3:$R$341)^2)^0.5 -> 0 | I346: =SUMPRODUCT(--(I$3:I$341-$S$3:$S$341)^2)^0.5 -> 0 | J346: =SUMPRODUCT(--(J$3:J$341-$R$3:$R$341)^2)^0.5 -> 0 | K346: =SUMPRODUCT(--(K$3:K$341-$S$3:$S$341)^2)^0.5 -> 0 | L346: =SUMPRODUCT(--(L$3:L$341-$R$3:$R$341)^2)^0.5 -> 0 | M346: =SUMPRODUCT(--(M$3:M$341-$S$3:$S$341)^2)^0.5 -> 0 | N346: =SUMPRODUCT(--(N$3:N$341-$R$3:$R$341)^2)^0.5 -> 0 | O346: =SUMPRODUCT(--(O$3:O$341-$S$3:$S$341)^2)^0.5 -> 0 | P346: =SUMPRODUCT(--(P$3:P$341-$R$3:$R$341)^2)^0.5 -> 0 | Q346: =SUMPRODUCT(--(Q$3:Q$341-$S$3:$S$341)^2)^0.5 -> 0
A347: BEST | B347: =SUMPRODUCT(NOT(ISBLANK(B$3:B$341))*(B$3:B$341=$R$3:$R$341)) -> 0 | C347: =SUMPRODUCT(NOT(ISBLANK(C$3:C$341))*(C$3:C$341=$S$3:$S$341)) -> 0 | D347: =SUMPRODUCT(NOT(ISBLANK(D$3:D$341))*(D$3:D$341=$R$3:$R$341)) -> 0 | E347: =SUMPRODUCT(NOT(ISBLANK(E$3:E$341))*(E$3:E$341=$S$3:$S$341)) -> 0 | F347: =SUMPRODUCT(NOT(ISBLANK(F$3:F$341))*(F$3:F$341=$R$3:$R$341)) -> 0 | G347: =SUMPRODUCT(NOT(ISBLANK(G$3:G$341))*(G$3:G$341=$S$3:$S$341)) -> 0 | H347: =SUMPRODUCT(NOT(ISBLANK(H$3:H$341))*(H$3:H$341=$R$3:$R$341)) -> 0 | I347: =SUMPRODUCT(NOT(ISBLANK(I$3:I$341))*(I$3:I$341=$S$3:$S$341)) -> 0 | J347: =SUMPRODUCT(NOT(ISBLANK(J$3:J$341))*(J$3:J$341=$R$3:$R$341)) -> 0 | K347: =SUMPRODUCT(NOT(ISBLANK(K$3:K$341))*(K$3:K$341=$S$3:$S$341)) -> 0 | L347: =SUMPRODUCT(NOT(ISBLANK(L$3:L$341))*(L$3:L$341=$R$3:$R$341)) -> 0 | M347: =SUMPRODUCT(NOT(ISBLANK(M$3:M$341))*(M$3:M$341=$S$3:$S$341)) -> 0 | N347: =SUMPRODUCT(NOT(ISBLANK(N$3:N$341))*(N$3:N$341=$R$3:$R$341)) -> 0 | O347: =SUMPRODUCT(NOT(ISBLANK(O$3:O$341))*(O$3:O$341=$S$3:$S$341)) -> 0 | P347: =SUMPRODUCT(NOT(ISBLANK(P$3:P$341))*(P$3:P$341=$R$3:$R$341)) -> 0 | Q347: =SUMPRODUCT(NOT(ISBLANK(Q$3:Q$341))*(Q$3:Q$341=$S$3:$S$341)) -> 0
A348: BETTER | B348: =SUMPRODUCT(NOT(ISBLANK(B$3:B$341))*(B$3:B$341<$T$3:$T$341)) -> 0 | C348: =SUMPRODUCT(NOT(ISBLANK(C$3:C$341))*(C$3:C$341<$U$3:$U$341)) -> 0 | D348: =SUMPRODUCT(NOT(ISBLANK(D$3:D$341))*(D$3:D$341<$T$3:$T$341)) -> 0 | E348: =SUMPRODUCT(NOT(ISBLANK(E$3:E$341))*(E$3:E$341<$U$3:$U$341)) -> 0 | F348: =SUMPRODUCT(NOT(ISBLANK(F$3:F$341))*(F$3:F$341<$T$3:$T$341)) -> 0 | G348: =SUMPRODUCT(NOT(ISBLANK(G$3:G$341))*(G$3:G$341<$U$3:$U$341)) -> 0 | H348: =SUMPRODUCT(NOT(ISBLANK(H$3:H$341))*(H$3:H$341<$T$3:$T$341)) -> 0 | I348: =SUMPRODUCT(NOT(ISBLANK(I$3:I$341))*(I$3:I$341<$U$3:$U$341)) -> 0 | J348: =SUMPRODUCT(NOT(ISBLANK(J$3:J$341))*(J$3:J$341<$T$3:$T$341)) -> 0 | K348: =SUMPRODUCT(NOT(ISBLANK(K$3:K$341))*(K$3:K$341<$U$3:$U$341)) -> 0 | L348: =SUMPRODUCT(NOT(ISBLANK(L$3:L$341))*(L$3:L$341<$T$3:$T$341)) -> 0 | M348: =SUMPRODUCT(NOT(ISBLANK(M$3:M$341))*(M$3:M$341<$U$3:$U$341)) -> 0 | N348: =SUMPRODUCT(NOT(ISBLANK(N$3:N$341))*(N$3:N$341<$T$3:$T$341)) -> 0 | O348: =SUMPRODUCT(NOT(ISBLANK(O$3:O$341))*(O$3:O$341<$U$3:$U$341)) -> 0 | P348: =SUMPRODUCT(NOT(ISBLANK(P$3:P$341))*(P$3:P$341<$T$3:$T$341)) -> 0 | Q348: =SUMPRODUCT(NOT(ISBLANK(Q$3:Q$341))*(Q$3:Q$341<$U$3:$U$341)) -> 0
A349: WORSE | B349: =SUMPRODUCT((NOT(ISBLANK(B$3:B$341))*(B$3:B$341>$T$3:$T$341))+ISBLANK(B$3:B$341)) -> 0 | C349: =SUMPRODUCT((NOT(ISBLANK(C$3:C$341))*(C$3:C$341>$U$3:$U$341))+ISBLANK(C$3:C$341)) -> 0 | D349: =SUMPRODUCT((NOT(ISBLANK(D$3:D$341))*(D$3:D$341>$T$3:$T$341))+ISBLANK(D$3:D$341)) -> 0 | E349: =SUMPRODUCT((NOT(ISBLANK(E$3:E$341))*(E$3:E$341>$U$3:$U$341))+ISBLANK(E$3:E$341)) -> 0 | F349: =SUMPRODUCT((NOT(ISBLANK(F$3:F$341))*(F$3:F$341>$T$3:$T$341))+ISBLANK(F$3:F$341)) -> 0 | G349: =SUMPRODUCT((NOT(ISBLANK(G$3:G$341))*(G$3:G$341>$U$3:$U$341))+ISBLANK(G$3:G$341)) -> 0 | H349: =SUMPRODUCT((NOT(ISBLANK(H$3:H$341))*(H$3:H$341>$T$3:$T$341))+ISBLANK(H$3:H$341)) -> 0 | I349: =SUMPRODUCT((NOT(ISBLANK(I$3:I$341))*(I$3:I$341>$U$3:$U$341))+ISBLANK(I$3:I$341)) -> 0 | J349: =SUMPRODUCT((NOT(ISBLANK(J$3:J$341))*(J$3:J$341>$T$3:$T$341))+ISBLANK(J$3:J$341)) -> 0 | K349: =SUMPRODUCT((NOT(ISBLANK(K$3:K$341))*(K$3:K$341>$U$3:$U$341))+ISBLANK(K$3:K$341)) -> 0 | L349: =SUMPRODUCT((NOT(ISBLANK(L$3:L$341))*(L$3:L$341>$T$3:$T$341))+ISBLANK(L$3:L$341)) -> 0 | M349: =SUMPRODUCT((NOT(ISBLANK(M$3:M$341))*(M$3:M$341>$U$3:$U$341))+ISBLANK(M$3:M$341)) -> 0 | N349: =SUMPRODUCT((NOT(ISBLANK(N$3:N$341))*(N$3:N$341>$T$3:$T$341))+ISBLANK(N$3:N$341)) -> 0 | O349: =SUMPRODUCT((NOT(ISBLANK(O$3:O$341))*(O$3:O$341>$U$3:$U$341))+ISBLANK(O$3:O$341)) -> 0 | P349: =SUMPRODUCT((NOT(ISBLANK(P$3:P$341))*(P$3:P$341>$T$3:$T$341))+ISBLANK(P$3:P$341)) -> 0 | Q349: =SUMPRODUCT((NOT(ISBLANK(Q$3:Q$341))*(Q$3:Q$341>$U$3:$U$341))+ISBLANK(Q$3:Q$341)) -> 0
A350: WORST | B350: =SUMPRODUCT((NOT(ISBLANK(B$3:B$341))*(B$3:B$341=$V$3:$V$341))+ISBLANK(B$3:B$341)) -> 0 | C350: =SUMPRODUCT((NOT(ISBLANK(C$3:C$341))*(C$3:C$341=$W$3:$W$341))+ISBLANK(C$3:C$341)) -> 0 | D350: =SUMPRODUCT((NOT(ISBLANK(D$3:D$341))*(D$3:D$341=$V$3:$V$341))+ISBLANK(D$3:D$341)) -> 0 | E350: =SUMPRODUCT((NOT(ISBLANK(E$3:E$341))*(E$3:E$341=$W$3:$W$341))+ISBLANK(E$3:E$341)) -> 0 | F350: =SUMPRODUCT((NOT(ISBLANK(F$3:F$341))*(F$3:F$341=$V$3:$V$341))+ISBLANK(F$3:F$341)) -> 0 | G350: =SUMPRODUCT((NOT(ISBLANK(G$3:G$341))*(G$3:G$341=$W$3:$W$341))+ISBLANK(G$3:G$341)) -> 0 | H350: =SUMPRODUCT((NOT(ISBLANK(H$3:H$341))*(H$3:H$341=$V$3:$V$341))+ISBLANK(H$3:H$341)) -> 0 | I350: =SUMPRODUCT((NOT(ISBLANK(I$3:I$341))*(I$3:I$341=$W$3:$W$341))+ISBLANK(I$3:I$341)) -> 0 | J350: =SUMPRODUCT((NOT(ISBLANK(J$3:J$341))*(J$3:J$341=$V$3:$V$341))+ISBLANK(J$3:J$341)) -> 0 | K350: =SUMPRODUCT((NOT(ISBLANK(K$3:K$341))*(K$3:K$341=$W$3:$W$341))+ISBLANK(K$3:K$341)) -> 0 | L350: =SUMPRODUCT((NOT(ISBLANK(L$3:L$341))*(L$3:L$341=$V$3:$V$341))+ISBLANK(L$3:L$341)) -> 0 | M350: =SUMPRODUCT((NOT(ISBLANK(M$3:M$341))*(M$3:M$341=$W$3:$W$341))+ISBLANK(M$3:M$341)) -> 0 | N350: =SUMPRODUCT((NOT(ISBLANK(N$3:N$341))*(N$3:N$341=$V$3:$V$341))+ISBLANK(N$3:N$341)) -> 0 | O350: =SUMPRODUCT((NOT(ISBLANK(O$3:O$341))*(O$3:O$341=$W$3:$W$341))+ISBLANK(O$3:O$341)) -> 0 | P350: =SUMPRODUCT((NOT(ISBLANK(P$3:P$341))*(P$3:P$341=$V$3:$V$341))+ISBLANK(P$3:P$341)) -> 0 | Q350: =SUMPRODUCT((NOT(ISBLANK(Q$3:Q$341))*(Q$3:Q$341=$W$3:$W$341))+ISBLANK(Q$3:Q$341)) -> 0

Sheet Merged Runs
A1: Merge criteria: | B1: coomsuite-1.0.0/clingo-base | D1: coomsuite-1.0.0/clingo-bounds-exponential | F1: coomsuite-1.0.0/clingo-bounds-linear | H1: coomsuite-1.0.0/flingo-base | J1: coomsuite-1.0.0/flingo-bounds-exponential | L1: coomsuite-1.0.0/flingo-bounds-linear | N1: coomsuite-1.0.0/multishot-exponential | P1: coomsuite-1.0.0/multishot-linear | R1: min | T1: median | V1: max
A2: median | B2: time | C2: timeout | D2: time | E2: timeout | F2: time | G2: timeout | H2: time | I2: timeout | J2: time | K2: timeout | L2: time | M2: timeout | N2: time | O2: timeout | P2: time | Q2: timeout | R2: time | S2: timeout | T2: time | U2: timeout | V2: time | W2: timeout
A3: ./citybike-max100_user-input-n100 | B3: {=_xlfn.SWITCH($A$2,"average", AVERAGE(Instances!B3:Instances!B3),"median", MEDIAN(Instances!B3:Instances!B3),"min", MIN(Instances!B3:Instances!B3),"max", MAX(Instances!B3:Instances!B3),"diff", MAX(Instances!B3:Instances!B3)-MIN(Instances!B3:Instances!B3))} -> 0 | C3: {=_xlfn.SWITCH($A$2,"average", AVERAGE(Instances!C3:Instances!C3),"median", MEDIAN(Instances!C3:Instances!C3),"min", MIN(Instances!C3:Instances!C3),"max", MAX(Instances!C3:Instances!C3),"diff", MAX(Instances!C3:Instances!C3)-MIN(Instances!C3:Instances!C3))} -> 0 | H3: {=_xlfn.SWITCH($A$2,"average", AVERAGE(Instances!H3:Instances!H3),"median", MEDIAN(Instances!H3:Instances!H3),"min", MIN(Instances!H3:Instances!H3),"max", MAX(Instances!H3:Instances!H3),"diff", MAX(Instances!H3:Instances!H3)-MIN(Instances!H3:Instances!H3))} -> 0 | I3: {=_xlfn.SWITCH($A$2,"average", AVERAGE(Instances!I3:Instances!I3),"median", MEDIAN(Instances!I3:Instances!I3),"min", MIN(Instances!I3:Instances!I3),"max", MAX(Instances!I3:Instances!I3),"diff", MAX(Instances!I3:Instances!I3)-MIN(Instances!I3:Instances!I3))} -> 0 | R3: =MIN($B3,$D3,$F3,$H3,$J3,$L3,$N3,$P3) -> 0 | S3: =MIN($C3,$E3,$G3,$I3,$K3,$M3,$O3,$Q3) -> 0 | T3: =MEDIAN($B3,$D3,$F3,$H3,$J3,$L3,$N3,$P3) -> 0 | U3: =MEDIAN($C3,$E3,$G3,$I3,$K3,$M3,$O3,$Q3) -> 0 | V3: =MAX($B3,$D3,$F3,$H3,$J3,$L3,$N3,$P3) -> 0 | W3: =MAX($C3,$E3,$G3,$I3,$K3,$M3,$O3,$Q3) -> 0
A4: ./citybike-max100_user-input-n25 | B4: {=_xlfn.SWITCH($A$2,"average", AVERAGE(Instances!B4:Instances!B4),"median", MEDIAN(Instances!B4:Instances!B4),"min", MIN(Instances!B4:Instances!B4),"max", MAX(Instances!B4:Instances!B4),"diff", MAX(Instances!B4:Instances!B4)-MIN(Instances!B4:Instances!B4))} -> 0 | C4: {=_xlfn.SWITCH($A$2,"average", AVERAGE(Instances!C4:Instances!C4),"median", MEDIAN(Instances!C4:Instances!C4),"min", MIN(Instances!C4:Instances!C4),"max", MAX(Instances!C4:Instances!C4),"diff", MAX(Instances!C4:Instances!C4)-MIN(Instances!C4:Instances!C4))} -> 0 | H4: {=_xlfn.SWITCH($A$2,"average", AVERAGE(Instances!H4:Instances!H4),"median", MEDIAN(Instances!H4:Instances!H4),"min", MIN(Instances!H4:Instances!H4),"max", MAX(Instances!H4:Instances!H4),"diff", MAX(Instances!H4:Instances!H4)-MIN(Instances!H4:Instances!H4))} -> 0 | I4: {=_xlfn.SWITCH($A$2,"average", AVERAGE(Instances!I4:Instances!I4),"median", MEDIAN(Instances!I4:Instances!I4),"min", MIN(Instances!I4:Instances!I4),"max", MAX(Instances!I4:Instances!I4),"diff", MAX(Instances!I4:Instances!I4)-MIN(Instances!I4:Instances!I4))} -> 0 | R4: =MIN($B4,$D4,$F4,$H4,$J4,$L4,$N4,$P4) -> 0 | S4: =MIN($C4,$E4,$G4,$I4,$K4,$M4,$O4,$Q4) -> 0 | T4: =MEDIAN($B4,$D4,$F4,$H4,$J4,$L4,$N4,$P4) -> 0 | U4: =MEDIAN($C4,$E4,$G4,$I4,$K4,$M4,$O4,$Q4) -> 0 | V4: =MAX($B4,$D4,$F4,$H4,$J4,$L4,$N4,$P4) -> 0 | W4: =MAX($C4,$E4,$G4,$I4,$K4,$M4,$O4,$Q4) -> 0
A5: ./citybike-max100_user-input-n33 | B5: {=_xlfn.SWITCH($A$2,"average", AVERAGE(Instances!B5:Instances!B5),"median", MEDIAN(Instances!B5:Instances!B5),"min", MIN(Instances!B5:Instances!B5),"max", MAX(Instances!B5:Instances!B5),"diff", MAX(Instances!B5:Instances!B5)-MIN(Instances!B5:Instances!B5))} -> 0 | C5: {=_xlfn.SWITCH($A$2,"average", AVERAGE(Instances!C5:Instances!C5),"median", MEDIAN(Instances!C5:Instances!C5),"min", MIN(Instances!C5:Instances!C5),"max", MAX(Instances!C5:Instances!C5),"diff", MAX(Instances!C5:Instances!C5)-MIN(Instances!C5:Instances!C5))} -> 0 | H5: {=_xlfn.SWITCH($A$2,"average", AVERAGE(Instances!H5:Instances!H5),"median", MEDIAN(Instances!H5:Instances!H5),"min", MIN(Instances!H5:Instances!H5),"max", MAX(Instances!H5:Instances!H5),"diff", MAX(Instances!H5:Instances!H5)-MIN(Instances!H5:Instances!H5))} -> 0 | I5: {=_xlfn.SWITCH($A$2,"average", AVERAGE(Instances!I5:Instances!I5),"median", MEDIAN(Instances!I5:Instances!I5),"min", MIN(Instances!I5:Instances!I5),"max", MAX(Instances!I5:Instances!I5),"diff", MAX(Instances!I5:Instances!I5)-MIN(Instances!I5:Instances!I5))} -> 0 | R5: =MIN($B5,$D5,$F5,$H5,$J5,$L5,$N5,$P5) -> 0 | S5: =MIN($C5,$E5,$G5,$I5,$K5,$M5,$O5,$Q5) -> 0 | T5: =MEDIAN($B5,$D5,$F5,$H5,$J5,$L5,$N5,$P5) -> 0 | U5: =MEDIAN($C5,$E5,$G5,$I5,$K5,$M5,$O5,$Q5) -> 0 | V5: =MAX($B5,$D5,$F5,$H5,$J5,$L5,$N5,$P5) -> 0 | W5: =MAX($C5,$E5,$G5,$I5,$K5,$M5,$O5,$Q5) -> 0
A6: ./citybike-max100_user-input-n50 | B6: {=_xlfn.SWITCH($A$2,"average", AVERAGE(Instances!B6:Instances!B6),"median", MEDIAN(Instances!B6:Instances!B6),"min", MIN(Instances!B6:Instances!B6),"max", MAX(Instances!B6:Instances!B6),"diff", MAX(Instances!B6:Instances!B6)-MIN(Instances!B6:Instances!B6))} -> 0 | C6: {=_xlfn.SWITCH($A$2,"average", AVERAGE(Instances!C6:Instances!C6),"median", MEDIAN(Instances!C6:Instances!C6),"min", MIN(Instances!C6:Instances!C6),"max", MAX(Instances!C6:Instances!C6),"diff", MAX(Instances!C6:Instances!C6)-MIN(Instances!C6:Instances!C6))} -> 0 | H6: {=_xlfn.SWITCH($A$2,"average", AVERAGE(Instances!H6:Instances!H6),"median", MEDIAN(Instances!H6:Instances!H6),"min", MIN(Instances!H6:Instances!H6),"max", MAX(Instances!H6:Instances!H6),"diff", MAX(Instances!H6:Instances!H6)-MIN(Instances!H6:Instances!H6))} -> 0 | I6: {=_xlfn.SWITCH($A$2,"average", AVERAGE(Instances!I6:Instances!I6),"median", MEDIAN(Instances!I6:Instances!I6),"min", MIN(Instances!I6:Instances!I6),"max", MAX(Instances!I6:Instances!I6),"diff", MAX(Instances!I6:Instances!I6)-MIN(Instances!I6:Instances!I6))} -> 0 | R6: =MIN($B6,$D6,$F6,$H6,$J6,$L6,$N6,$P6) -> 0 | S6: =MIN($C6,$E6,$G6,$I6,$K6,$M6,$O6,$Q6) -> 0 | T6: =MEDIAN($B6,$D6,$F6,$H6,$J6,$L6,$N6,$P6) -> 0 | U6: =MEDIAN($C6,$E6,$G6,$I6,$K6,$M6,$O6,$Q6) -> 0 | V6: =MAX($B6,$D6,$F6,$H6,$J6,$L6,$N6,$P6) -> 0 | W6: =MAX($C6,$E6,$G6,$I6,$K6,$M6,$O6,$Q6) -> 0
A7: ./citybike-max150_user-input-n150 | B7: {=_xlfn.SWITCH($A$2,"average", AVERAGE(Instances!B7:Instances!B7),"median", MEDIAN(Instances!B7:Instances!B7),"min", MIN(Instances!B7:Instances!B7),"max", MAX(Instances!B7:Instances!B7),"diff", MAX(Instances!B7:Instances!B7)-MIN(Instances!B7:Instances!B7))} -> 0 | C7: {=_xlfn.SWITCH($A$2,"average", AVERAGE(Instances!C7:Instances!C7),"median", MEDIAN(Instances!C7:Instances!C7),"min", MIN(Instances!C7:Instances!C7),"max", MAX(Instances!C7:Instances!C7),"diff", MAX(Instances!C7:Instances!C7)-MIN(Instances!C7:Instances!C7))} -> 0 | H7: {=_xlfn.SWITCH($A$2,"average", AVERAGE(Instances!H7:Instances!H7),"median", MEDIAN(Instances!H7:Instances!H7),"min", MIN(Instances!H7:Instances!H7),"max", MAX(Instances!H7:Instances!H7),"diff", MAX(Instances!H7:Instances!H7)-MIN(Instances!H7:Instances!H7))} -> 0 | I7: {=_xlfn.SWITCH($A$2,"average", AVERAGE(Instances!I7:Instances!I7),"median", MEDIAN(Instances!I7:Instances!I7),"min", MIN(Instances!I7:Instances!I7),"max", MAX(Instances!I7:Instances!I7),"diff", MAX(Instances!I7:Instances!I7)-MIN(Instances!I7:Instances!I7))} -> 0 | R7: =MIN($B7,$D7,$F7,$H7,$J7,$L7,$N7,$P7) -> 0 | S7: =MIN($C7,$E7,$G7,$I7,$K7,$M7,$O7,$Q7) -> 0 | T7: =MEDIAN($B7,$D7,$F7,$H7,$J7,$L7,$N7,$P7) -> 0 | U7: =MEDIAN($C7,$E7,$G7,$I7,$K7,$M7,$O7,$Q7) -> 0 | V7: =MAX($B7,$D7,$F7,$H7,$J7,$L7,$N7,$P7) -> 0 | W7: =MAX($C7,$E7,$G7,$I7,$K7,$M7,$O7,$Q7) -> 0
A8: ./citybike-max150_user-input-n37 | B8: {=_xlfn.SWITCH($A$2,"average", AVERAGE(Instances!B8:Instances!B8),"median", MEDIAN(Instances!B8:Instances!B8),"min", MIN(Instances!B8:Instances!B8),"max", MAX(Instances!B8:Instances!B8),"diff", MAX(Instances!B8:Instances!B8)-MIN(Instances!B8:Instances!B8))} -> 0 | C8: {=_xlfn.SWITCH($A$2,"average", AVERAGE(Instances!C8:Instances!C8),"median", MEDIAN(Instances!C8:Instances!C8),"min", MIN(Instances!C8:Instances!C8),"max", MAX(Instances!C8:Instances!C8),"diff", MAX(Instances!C8:Instances!C8)-MIN(Instances!C8:Instances!C8))} -> 0 | H8: {=_xlfn.SWITCH($A$2,"average", AVERAGE(Instances!H8:Instances!H8),"median", MEDIAN(Instances!H8:Instances!H8),"min", MIN(Instances!H8:Instances!H8),"max", MAX(Instances!H8:Instances!H8),"diff", MAX(Instances!H8:Instances!H8)-MIN(Instances!H8:Instances!H8))} -> 0 | I8: {=_xlfn.SWITCH($A$2,"average", AVERAGE(Instances!I8:Instances!I8),"median", MEDIAN(Instances!I8:Instances!I8),"min", MIN(Instances!I8:Instances!I8),"max", MAX(Instances!I8:Instances!I8),"diff", MAX(Instances!I8:Instances!I8)-MIN(Instances!I8:Instances!I8))} -> 0 | R8: =MIN($B8,$D8,$F8,$H8,$J8,$L8,$N8,$P8) -> 0 | S8: =MIN($C8,$E8,$G8,$I8,$K8,$M8,$O8,$Q8) -> 0 | T8: =MEDIAN($B8,$D8,$F8,$H8,$J8,$L8,$N8,$P8) -> 0 | U8: =MEDIAN($C8,$E8,$G8,$I8,$K8,$M8,$O8,$Q8) -> 0 | V8: =MAX($B8,$D8,$F8,$H8,$J8,$L8,$N8,$P8) -> 0 | W8: =MAX($C8,$E8,$G8,$I8,$K8,$M8,$O8,$Q8) -> 0
A9: ./citybike-max150_user-input-n50 | B9: {=_xlfn.SWITCH($A$2,"average", AVERAGE(Instances!B9:Instances!B9),"median", MEDIAN(Instances!B9:Instances!B9),"min", MIN(Instances!B9:Instances!B9),"max", MAX(Instances!B9:Instances!B9),"diff", MAX(Instances!B9:Instances!B9)-MIN(Instances!B9:Instances!B9))} -> 0 | C9: {=_xlfn.SWITCH($A$2,"average", AVERAGE(Instances!C9:Instances!C9),"median", MEDIAN(Instances!C9:Instances!C9),"min", MIN(Instances!C9:Instances!C9),"max", MAX(Instances!C9:Instances!C9),"diff", MAX(Instances!C9:Instances!C9)-MIN(Instances!C9:Instances!C9))} -> 0 | H9: {=_xlfn.SWITCH($A$2,"average", AVERAGE(Instances!H9:Instances!H9),"median", MEDIAN(Instances!H9:Instances!H9),"min", MIN(Instances!H9:Instances!H9),"max", MAX(Instances!H9:Instances!H9),"diff", MAX(Instances!H9:Instances!H9)-MIN(Instances!H9:Instances!H9))} -> 0 | I9: {=_xlfn.SWITCH($A$2,"average", AVERAGE(Instances!I9:Instances!I9),"median", MEDIAN(Instances!I9:Instances!I9),"min", MIN(Instances!I9:Instances!I9),"max", MAX(Instances!I9:Instances!I9),"diff", MAX(Instances!I9:Instances!I9)-MIN(Instances!I9:Instances!I9))} -> 0 | R9: =MIN($B9,$D9,$F9,$H9,$J9,$L9,$N9,$P9) -> 0 | S9: =MIN($C9,$E9,$G9,$I9,$K9,$M9,$O9,$Q9) -> 0 | T9: =MEDIAN($B9,$D9,$F9,$H9,$J9,$L9,$N9,$P9) -> 0 | U9: =MEDIAN($C9,$E9,$G9,$I9,$K9,$M9,$O9,$Q9) -> 0 | V9: =MAX($B9,$D9,$F9,$H9,$J9,$L9,$N9,$P9) -> 0 | W9: =MAX($C9,$E9,$G9,$I9,$K9,$M9,$O9,$Q9) -> 0
A10: ./citybike-max150_user-input-n75 | B10: {=_xlfn.SWITCH($A$2,"average", AVERAGE(Instances!B10:Instances!B10),"median", MEDIAN(Instances!B10:Instances!B10),"min", MIN(Instances!B10:Instances!B10),"max", MAX(Instances!B10:Instances!B10),"diff", MAX(Instances!B10:Instances!B10)-MIN(Instances!B10:Instances!B10))} -> 0 | C10: {=_xlfn.SWITCH($A$2,"average", AVERAGE(Instances!C10:Instances!C10),"median", MEDIAN(Instances!C10:Instances!C10),"min", MIN(Instances!C10:Instances!C10),"max", MAX(Instances!C10:Instances!C10),"diff", MAX(Instances!C10:Instances!C10)-MIN(Instances!C10:Instances!C10))} -> 0 | H10: {=_xlfn.SWITCH($A$2,"average", AVERAGE(Instances!H10:Instances!H10),"median", MEDIAN(Instances!H10:Instances!H10),"min", MIN(Instances!H10:Instances!H10),"max", MAX(Instances!H10:Instances!H10),"diff", MAX(Instances!H10:Instances!H10)-MIN(Instances!H10:Instances!H10))} -> 0 | I10: {=_xlfn.SWITCH($A$2,"average", AVERAGE(Instances!I10:Instances!I10),"median", MEDIAN(Instances!I10:Instances!I10),"min", MIN(Instances!I10:Instances!I10),"max", MAX(Instances!I10:Instances!I10),"diff", MAX(Instances!I10:Instances!I10)-MIN(Instances!I10:Instances!I10))} -> 0 | R10: =MIN($B10,$D10,$F10,$H10,$J10,$L10,$N10,$P10) -> 0 | S10: =MIN($C10,$E10,$G10,$I10,$K10,$M10,$O10,$Q10) -> 0 | T10: =MEDIAN($B10,$D10,$F10,$H10,$J10,$L10,$N10,$P10) -> 0 | U10: =MEDIAN($C10,$E10,$G10,$I10,$K10,$M10,$O10,$Q10) -> 0 | V10: =MAX($B10,$D10,$F10,$H10,$J10,$L10,$N10,$P10) -> 0 | W10: =MAX($C10,$E10,$G10,$I10,$K10,$M10,$O10,$Q10) -> 0
A11: ./citybike-max200_user-input-n100 | B11: {=_xlfn.SWITCH($A$2,"average", AVERAGE(Instances!B11:Instances!B11),"median", MEDIAN(Instances!B11:Instances!B11),"min", MIN(Instances!B11:Instances!B11),"max", MAX(Instances!B11:Instances!B11),"diff", MAX(Instances!B11:Instances!B11)-MIN(Instances!B11:Instances!B11))} -> 0 | C11: {=_xlfn.SWITCH($A$2,"average", AVERAGE(Instances!C11:Instances!C11),"median", MEDIAN(Instances!C11:Instances!C11),"min", MIN(Instances!C11:Instances!C11),"max", MAX(Instances!C11:Instances!C11),"diff", MAX(Instances!C11:Instances!C11)-MIN(Instances!C11:Instances!C11))} -> 0 | H11: {=_xlfn.SWITCH($A$2,"average", AVERAGE(Instances!H11:Instances!H11),"median", MEDIAN(Instances!H11:Instances!H11),"min", MIN(Instances!H11:Instances!H11),"max", MAX(Instances!H11:Instances!H11),"diff", MAX(Instances!H11:Instances!H11)-MIN(Instances!H11:Instances!H11))} -> 0 | I11: {=_xlfn.SWITCH($A$2,"average", AVERAGE(Instances!I11:Instances!I11),"median", MEDIAN(Instances!I11:Instances!I11),"min", MIN(Instances!I11:Instances!I11),"max", MAX(Instances!I11:Instances!I11),"diff", MAX(Instances!I11:Instances!I11)-MIN(Instances!I11:Instances!I11))} -> 0 | R11: =MIN($B11,$D11,$F11,$H11,$J11,$L11,$N11,$P11) -> 0 | S11: =MIN($C11,$E11,$G11,$I11,$K11,$M11,$O11,$Q11) -> 0 | T11: =MEDIAN($B11,$D11,$F11,$H11,$J11,$L11,$N11,$P11) -> 0 | U11: =MEDIAN($C11,$E11,$G11,$I11,$K11,$M11,$O11,$Q11) -> 0 | V11: =MAX($B11,$D11,$F11,$H11,$J11,$L11,$N11,$P11) -> 0 | W11: =MAX($C11,$E11,$G11,$I11,$K11,$M11,$O11,$Q11) -> 0
A12: ./citybike-max200_user-input-n200 | B12: {=_xlfn.SWITCH($A$2,"average", AVERAGE(Instances!B12:Instances!B12),"median", MEDIAN(Instances!B12:Instances!B12),"min", MIN(Instances!B12:Instances!B12),"max", MAX(Instances!B12:Instances!B12),"diff", MAX(Instances!B12:Instances!B12)-MIN(Instances!B12:Instances!B12))} -> 0 | C12: {=_xlfn.SWITCH($A$2,"average", AVERAGE(Instances!C12:Instances!C12),"median", MEDIAN(Instances!C12:Instances!C12),"min", MIN(Instances!C12:Instances!C12),"max", MAX(Instances!C12:Instances!C12),"diff", MAX(Instances!C12:Instances!C12)-MIN(Instances!C12:Instances!C12))} -> 0 | H12: {=_xlfn.SWITCH($A$2,"average", AVERAGE(Instances!H12:Instances!H12),"median", MEDIAN(Instances!H12:Instances!H12),"min", MIN(Instances!H12:Instances!H12),"max", MAX(Instances!H12:Instances!H12),"diff", MAX(Instances!H12:Instances!H12)-MIN(Instances!H12:Instances!H12))} -> 0 | I12: {=_xlfn.SWITCH($A$2,"average", AVERAGE(Instances!I12:Instances!I12),"median", MEDIAN(Instances!I12:Instances!I12),"min", MIN(Instances!I12:Instances!I12),"max", MAX(Instances!I12:Instances!I12),"diff", MAX(Instances!I12:Instances!I12)-MIN(Instances!I12:Instances!I12))} -> 0 | R12: =MIN($B12,$D12,$F12,$H12,$J12,$L12,$N12,$P12) -> 0 | S12: =MIN($C12,$E12,$G12,$I12,$K12,$M12,$O12,$Q12) -> 0 | T12: =MEDIAN($B12,$D12,$F12,$H12,$J12,$L12,$N12,$P12) -> 0 | U12: =MEDIAN($C12,$E12,$G12,$I12,$K12,$M12,$O12,$Q12) -> 0 | V12: =MAX($B12,$D12,$F12,$H12,$J12,$L12,$N12,$P12) -> 0 | W12: =MAX($C12,$E12,$G12,$I12,$K12,$M12,$O12,$Q12) -> 0
A13: ./citybike-max200_user-input-n50 | B13: {=_xlfn.SWITCH($A$2,"average", AVERAGE(Instances!B13:Instances!B13),"median", MEDIAN(Instances!B13:Instances!B13),"min", MIN(Instances!B13:Instances!B13),"max", MAX(Instances!B13:Instances!B13),"diff", MAX(Instances!B13:Instances!B13)-MIN(Instances!B13:Instances!B13))} -> 0 | C13: {=_xlfn.SWITCH($A$2,"average", AVERAGE(Instances!C13:Instances!C13),"median", MEDIAN(Instances!C13:Instances!C13),"min", MIN(Instances!C13:Instances!C13),"max", MAX(Instances!C13:Instances!C13),"diff", MAX(Instances!C13:Instances!C13)-MIN(Instances!C13:Instances!C13))} -> 0 | H13: {=_xlfn.SWITCH($A$2,"average", AVERAGE(Instances!H13:Instances!H13),"median", MEDIAN(Instances!H13:Instances!H13),"min", MIN(Instances!H13:Instances!H13),"max", MAX(Instances!H13:Instances!H13),"diff", MAX(Instances!H13:Instances!H13)-MIN(Instances!H13:Instances!H13))} -> 0 | I13: {=_xlfn.SWITCH($A$2,"average", AVERAGE(Instances!I13:Instances!I13),"median", MEDIAN(Instances!I13:Instances!I13),"min", MIN(Instances!I13:Instances!I13),"max", MAX(Instances!I13:Instances!I13),"diff", MAX(Instances!I13:Instances!I13)-MIN(Instances!I13:Instances!I13))} -> 0 | R13: =MIN($B13,$D13,$F13,$H13,$J13,$L13,$N13,$P13) -> 0 | S13: =MIN($C13,$E13,$G13,$I13,$K13,$M13,$O13,$Q13) -> 0 | T13: =MEDIAN($B13,$D13,$F13,$H13,$J13,$L13,$N13,$P13) -> 0 | U13: =MEDIAN($C13,$E13,$G13,$I13,$K13,$M13,$O13,$Q13) -> 0 | V13: =MAX($B13,$D13,$F13,$H13,$J13,$L13,$N13,$P13) -> 0 | W13: =MAX($C13,$E13,$G13,$I13,$K13,$M13,$O13,$Q13) -> 0
A14: ./citybike-max200_user-input-n66 | B14: {=_xlfn.SWITCH($A$2,"average", AVERAGE(Instances!B14:Instances!B14),"median", MEDIAN(Instances!B14:Instances!B14),"min", MIN(Instances!B14:Instances!B14),"max", MAX(Instances!B14:Instances!B14),"diff", MAX(Instances!B14:Instances!B14)-MIN(Instances!B14:Instances!B14))} -> 0 | C14: {=_xlfn.SWITCH($A$2,"average", AVERAGE(Instances!C14:Instances!C14),"median", MEDIAN(Instances!C14:Instances!C14),"min", MIN(Instances!C14:Instances!C14),"max", MAX(Instances!C14:Instances!C14),"diff", MAX(Instances!C14:Instances!C14)-MIN(Instances!C14:Instances!C14))} -> 0 | H14: {=_xlfn.SWITCH($A$2,"average", AVERAGE(Instances!H14:Instances!H14),"median", MEDIAN(Instances!H14:Instances!H14),"min", MIN(Instances!H14:Instances!H14),"max", MAX(Instances!H14:Instances!H14),"diff", MAX(Instances!H14:Instances!H14)-MIN(Instances!H14:Instances!H14))} -> 0 | I14: {=_xlfn.SWITCH($A$2,"average", AVERAGE(Instances!I14:Instances!I14),"median", MEDIAN(Instances!I14:Instances!I14),"min", MIN(Instances!I14:Instances!I14),"max", MAX(Instances!I14:Instances!I14),"diff", MAX(Instances!I14:Instances!I14)-MIN(Instances!I14:Instances!I14))} -> 0 | R14: =MIN($B14,$D14,$F14,$H14,$J14,$L14,$N14,$P14) -> 0 | S14: =MIN($C14,$E14,$G14,$I14,$K14,$M14,$O14,$Q14) -> 0 | T14: =MEDIAN($B14,$D14,$F14,$H14,$J14,$L14,$N14,$P14) -> 0 | U14: =MEDIAN($C14,$E14,$G14,$I14,$K14,$M14,$O14,$Q14) -> 0 | V14: =MAX($B14,$D14,$F14,$H14,$J14,$L14,$N14,$P14) -> 0 | W14: =MAX($C14,$E14,$G14,$I14,$K14,$M14,$O14,$Q14) -> 0
... A73: ./travelbike-max5_user-input-p92-v415 | B73: {=_xlfn.SWITCH($A$2,"average", AVERAGE(Instances!B73:Instances!B73),"median", MEDIAN(Instances!B73:Instances!B73),"min", MIN(Instances!B73:Instances!B73),"max", MAX(Instances!B73:Instances!B73),"diff", MAX(Instances!B73:Instances!B73)-MIN(Instances!B73:Instances!B73))} -> 0 | C73: {=_xlfn.SWITCH($A$2,"average", AVERAGE(Instances!C73:Instances!C73),"median", MEDIAN(Instances!C73:Instances!C73),"min", MIN(Instances!C73:Instances!C73),"max", MAX(Instances!C73:Instances!C73),"diff", MAX(Instances!C73:Instances!C73)-MIN(Instances!C73:Instances!C73))} -> 0 | H73: {=_xlfn.SWITCH($A$2,"average", AVERAGE(Instances!H73:Instances!H73),"median", MEDIAN(Instances!H73:Instances!H73),"min", MIN(Instances!H73:Instances!H73),"max", MAX(Instances!H73:Instances!H73),"diff", MAX(Instances!H73:Instances!H73)-MIN(Instances!H73:Instances!H73))} -> 0 | I73: {=_xlfn.SWITCH($A$2,"average", AVERAGE(Instances!I73:Instances!I73),"median", MEDIAN(Instances!I73:Instances!I73),"min", MIN(Instances!I73:Instances!I73),"max", MAX(Instances!I73:Instances!I73),"diff", MAX(Instances!I73:Instances!I73)-MIN(Instances!I73:Instances!I73))} -> 0 | R73: =MIN($B73,$D73,$F73,$H73,$J73,$L73,$N73,$P73) -> 0 | S73: =MIN($C73,$E73,$G73,$I73,$K73,$M73,$O73,$Q73) -> 0 | T73: =MEDIAN($B73,$D73,$F73,$H73,$J73,$L73,$N73,$P73) -> 0 | U73: =MEDIAN($C73,$E73,$G73,$I73,$K73,$M73,$O73,$Q73) -> 0 | V73: =MAX($B73,$D73,$F73,$H73,$J73,$L73,$N73,$P73) -> 0 | W73: =MAX($C73,$E73,$G73,$I73,$K73,$M73,$O73,$Q73) -> 0
A74: ./cargobike-complex-100_user-input-0 | D74: {=_xlfn.SWITCH($A$2,"average", AVERAGE(Instances!D74:Instances!D74),"median", MEDIAN(Instances!D74:Instances!D74),"min", MIN(Instances!D74:Instances!D74),"max", MAX(Instances!D74:Instances!D74),"diff", MAX(Instances!D74:Instances!D74)-MIN(Instances!D74:Instances!D74))} -> 0 | E74: {=_xlfn.SWITCH($A$2,"average", AVERAGE(Instances!E74:Instances!E74),"median", MEDIAN(Instances!E74:Instances!E74),"min", MIN(Instances!E74:Instances!E74),"max", MAX(Instances!E74:Instances!E74),"diff", MAX(Instances!E74:Instances!E74)-MIN(Instances!E74:Instances!E74))} -> 0 | F74: {=_xlfn.SWITCH($A$2,"average", AVERAGE(Instances!F74:Instances!F74),"median", MEDIAN(Instances!F74:Instances!F74),"min", MIN(Instances!F74:Instances!F74),"max", MAX(Instances!F74:Instances!F74),"diff", MAX(Instances!F74:Instances!F74)-MIN(Instances!F74:Instances!F74))} -> 0 | G74: {=_xlfn.SWITCH($A$2,"average", AVERAGE(Instances!G74:Instances!G74),"median", MEDIAN(Instances!G74:Instances!G74),"min", MIN(Instances!G74:Instances!G74),"max", MAX(Instances!G74:Instances!G74),"diff", MAX(Instances!G74:Instances!G74)-MIN(Instances!G74:Instances!G74))} -> 0 | J74: {=_xlfn.SWITCH($A$2,"average", AVERAGE(Instances!J74:Instances!J74),"median", MEDIAN(Instances!J74:Instances!J74),"min", MIN(Instances!J74:Instances!J74),"max", MAX(Instances!J74:Instances!J74),"diff", MAX(Instances!J74:Instances!J74)-MIN(Instances!J74:Instances!J74))} -> 0 | K74: {=_xlfn.SWITCH($A$2,"average", AVERAGE(Instances!K74:Instances!K74),"median", MEDIAN(Instances!K74:Instances!K74),"min", MIN(Instances!K74:Instances!K74),"max", MAX(Instances!K74:Instances!K74),"diff", MAX(Instances!K74:Instances!K74)-MIN(Instances!K74:Instances!K74))} -> 0 | L74: {=_xlfn.SWITCH($A$2,"average", AVERAGE(Instances!L74:Instances!L74),"median", MEDIAN(Instances!L74:Instances!L74),"min", MIN(Instances!L74:Instances!L74),"max", MAX(Instances!L74:Instances!L74),"diff", MAX(Instances!L74:Instances!L74)-MIN(Instances!L74:Instances!L74))} -> 0 | M74: {=_xlfn.SWITCH($A$2,"average", AVERAGE(Instances!M74:Instances!M74),"median", MEDIAN(Instances!M74:Instances!M74),"min", MIN(Instances!M74:Instances!M74),"max", MAX(Instances!M74:Instances!M74),"diff", MAX(Instances!M74:Instances!M74)-MIN(Instances!M74:Instances!M74))} -> 0 | N74: {=_xlfn.SWITCH($A$2,"average", AVERAGE(Instances!N74:Instances!N74),"median", MEDIAN(Instances!N74:Instances!N74),"min", MIN(Instances!N74:Instances!N74),"max", MAX(Instances!N74:Instances!N74),"diff", MAX(Instances!N74:Instances!N74)-MIN(Instances!N74:Instances!N74))} -> 0 | O74: {=_xlfn.SWITCH($A$2,"average", AVERAGE(Instances!O74:Instances!O74),"median", MEDIAN(Instances!O74:Instances!O74),"min", MIN(Instances!O74:Instances!O74),"max", MAX(Instances!O74:Instances!O74),"diff", MAX(Instances!O74:Instances!O74)-MIN(Instances!O74:Instances!O74))} -> 0 | P74: {=_xlfn.SWITCH($A$2,"average", AVERAGE(Instances!P74:Instances!P74),"median", MEDIAN(Instances!P74:Instances!P74),"min", MIN(Instances!P74:Instances!P74),"max", MAX(Instances!P74:Instances!P74),"diff", MAX(Instances!P74:Instances!P74)-MIN(Instances!P74:Instances!P74))} -> 0 | Q74: {=_xlfn.SWITCH($A$2,"average", AVERAGE(Instances!Q74:Instances!Q74),"median", MEDIAN(Instances!Q74:Instances!Q74),"min", MIN(Instances!Q74:Instances!Q74),"max", MAX(Instances!Q74:Instances!Q74),"diff", MAX(Instances!Q74:Instances!Q74)-MIN(Instances!Q74:Instances!Q74))} -> 0 | R74: =MIN($B74,$D74,$F74,$H74,$J74,$L74,$N74,$P74) -> 0 | S74: =MIN($C74,$E74,$G74,$I74,$K74,$M74,$O74,$Q74) -> 0 | T74: =MEDIAN($B74,$D74,$F74,$H74,$J74,$L74,$N74,$P74) -> 0 | U74: =MEDIAN($C74,$E74,$G74,$I74,$K74,$M74,$O74,$Q74) -> 0 | V74: =MAX($B74,$D74,$F74,$H74,$J74,$L74,$N74,$P74) -> 0 | W74: =MAX($C74,$E74,$G74,$I74,$K74,$M74,$O74,$Q74) -> 0
A75: ./cargobike-complex-100_user-input-1 | D75: {=_xlfn.SWITCH($A$2,"average", AVERAGE(Instances!D75:Instances!D75),"median", MEDIAN(Instances!D75:Instances!D75),"min", MIN(Instances!D75:Instances!D75),"max", MAX(Instances!D75:Instances!D75),"diff", MAX(Instances!D75:Instances!D75)-MIN(Instances!D75:Instances!D75))} -> 0 | E75: {=_xlfn.SWITCH($A$2,"average", AVERAGE(Instances!E75:Instances!E75),"median", MEDIAN(Instances!E75:Instances!E75),"min", MIN(Instances!E75:Instances!E75),"max", MAX(Instances!E75:Instances!E75),"diff", MAX(Instances!E75:Instances!E75)-MIN(Instances!E75:Instances!E75))} -> 0 | F75: {=_xlfn.SWITCH($A$2,"average", AVERAGE(Instances!F75:Instances!F75),"median", MEDIAN(Instances!F75:Instances!F75),"min", MIN(Instances!F75:Instances!F75),"max", MAX(Instances!F75:Instances!F75),"diff", MAX(Instances!F75:Instances!F75)-MIN(Instances!F75:Instances!F75))} -> 0 | G75: {=_xlfn.SWITCH($A$2,"average", AVERAGE(Instances!G75:Instances!G75),"median", MEDIAN(Instances!G75:Instances!G75),"min", MIN(Instances!G75:Instances!G75),"max", MAX(Instances!G75:Instances!G75),"diff", MAX(Instances!G75:Instances!G75)-MIN(Instances!G75:Instances!G75))} -> 0 | J75: {=_xlfn.SWITCH($A$2,"average", AVERAGE(Instances!J75:Instances!J75),"median", MEDIAN(Instances!J75:Instances!J75),"min", MIN(Instances!J75:Instances!J75),"max", MAX(Instances!J75:Instances!J75),"diff", MAX(Instances!J75:Instances!J75)-MIN(Instances!J75:Instances!J75))} -> 0 | K75: {=_xlfn.SWITCH($A$2,"average", AVERAGE(Instances!K75:Instances!K75),"median", MEDIAN(Instances!K75:Instances!K75),"min", MIN(Instances!K75:Instances!K75),"max", MAX(Instances!K75:Instances!K75),"diff", MAX(Instances!K75:Instances!K75)-MIN(Instances!K75:Instances!K75))} -> 0 | L75: {=_xlfn.SWITCH($A$2,"average", AVERAGE(Instances!L75:Instances!L75),"median", MEDIAN(Instances!L75:Instances!L75),"min", MIN(Instances!L75:Instances!L75),"max", MAX(Instances!L75:Instances!L75),"diff", MAX(Instances!L75:Instances!L75)-MIN(Instances!L75:Instances!L75))} -> 0 | M75: {=_xlfn.SWITCH($A$2,"average", AVERAGE(Instances!M75:Instances!M75),"median", MEDIAN(Instances!M75:Instances!M75),"min", MIN(Instances!M75:Instances!M75),"max", MAX(Instances!M75:Instances!M75),"diff", MAX(Instances!M75:Instances!M75)-MIN(Instances!M75:Instances!M75))} -> 0 | N75: {=_xlfn.SWITCH($A$2,"average", AVERAGE(Instances!N75:Instances!N75),"median", MEDIAN(Instances!N75:Instances!N75),"min", MIN(Instances!N75:Instances!N75),"max", MAX(Instances!N75:Instances!N75),"diff", MAX(Instances!N75:Instances!N75)-MIN(Instances!N75:Instances!N75))} -> 0 | O75: {=_xlfn.SWITCH($A$2,"average", AVERAGE(Instances!O75:Instances!O75),"median", MEDIAN(Instances!O75:Instances!O75),"min", MIN(Instances!O75:Instances!O75),"max", MAX(Instances!O75:Instances!O75),"diff", MAX(Instances!O75:Instances!O75)-MIN(Instances!O75:Instances!O75))} -> 0 | P75: {=_xlfn.SWITCH($A$2,"average", AVERAGE(Instances!P75:Instances!P75),"median", MEDIAN(Instances!P75:Instances!P75),"min", MIN(Instances!P75:Instances!P75),"max", MAX(Instances!P75:Instances!P75),"diff", MAX(Instances!P75:Instances!P75)-MIN(Instances!P75:Instances!P75))} -> 0 | Q75: {=_xlfn.SWITCH($A$2,"average", AVERAGE(Instances!Q75:Instances!Q75),"median", MEDIAN(Instances!Q75:Instances!Q75),"min", MIN(Instances!Q75:Instances!Q75),"max", MAX(Instances!Q75:Instances!Q75),"diff", MAX(Instances!Q75:Instances!Q75)-MIN(Instances!Q75:Instances!Q75))} -> 0 | R75: =MIN($B75,$D75,$F75,$H75,$J75,$L75,$N75,$P75) -> 0 | S75: =MIN($C75,$E75,$G75,$I75,$K75,$M75,$O75,$Q75) -> 0 | T75: =MEDIAN($B75,$D75,$F75,$H75,$J75,$L75,$N75,$P75) -> 0 | U75: =MEDIAN($C75,$E75,$G75,$I75,$K75,$M75,$O75,$Q75) -> 0 | V75: =MAX($B75,$D75,$F75,$H75,$J75,$L75,$N75,$P75) -> 0 | W75: =MAX($C75,$E75,$G75,$I75,$K75,$M75,$O75,$Q75) -> 0
A76: ./cargobike-complex-100_user-input-10 | D76: {=_xlfn.SWITCH($A$2,"average", AVERAGE(Instances!D76:Instances!D76),"median", MEDIAN(Instances!D76:Instances!D76),"min", MIN(Instances!D76:Instances!D76),"max", MAX(Instances!D76:Instances!D76),"diff", MAX(Instances!D76:Instances!D76)-MIN(Instances!D76:Instances!D76))} -> 0 | E76: {=_xlfn.SWITCH($A$2,"average", AVERAGE(Instances!E76:Instances!E76),"median", MEDIAN(Instances!E76:Instances!E76),"min", MIN(Instances!E76:Instances!E76),"max", MAX(Instances!E76:Instances!E76),"diff", MAX(Instances!E76:Instances!E76)-MIN(Instances!E76:Instances!E76))} -> 0 | F76: {=_xlfn.SWITCH($A$2,"average", AVERAGE(Instances!F76:Instances!F76),"median", MEDIAN(Instances!F76:Instances!F76),"min", MIN(Instances!F76:Instances!F76),"max", MAX(Instances!F76:Instances!F76),"diff", MAX(Instances!F76:Instances!F76)-MIN(Instances!F76:Instances!F76))} -> 0 | G76: {=_xlfn.SWITCH($A$2,"average", AVERAGE(Instances!G76:Instances!G76),"median", MEDIAN(Instances!G76:Instances!G76),"min", MIN(Instances!G76:Instances!G76),"max", MAX(Instances!G76:Instances!G76),"diff", MAX(Instances!G76:Instances!G76)-MIN(Instances!G76:Instances!G76))} -> 0 | J76: {=_xlfn.SWITCH($A$2,"average", AVERAGE(Instances!J76:Instances!J76),"median", MEDIAN(Instances!J76:Instances!J76),"min", MIN(Instances!J76:Instances!J76),"max", MAX(Instances!J76:Instances!J76),"diff", MAX(Instances!J76:Instances!J76)-MIN(Instances!J76:Instances!J76))} -> 0 | K76: {=_xlfn.SWITCH($A$2,"average", AVERAGE(Instances!K76:Instances!K76),"median", MEDIAN(Instances!K76:Instances!K76),"min", MIN(Instances!K76:Instances!K76),"max", MAX(Instances!K76:Instances!K76),"diff", MAX(Instances!K76:Instances!K76)-MIN(Instances!K76:Instances!K76))} -> 0 | L76: {=_xlfn.SWITCH($A$2,"average", AVERAGE(Instances!L76:Instances!L76),"median", MEDIAN(Instances!L76:Instances!L76),"min", MIN(Instances!L76:Instances!L76),"max", MAX(Instances!L76:Instances!L76),"diff", MAX(Instances!L76:Instances!L76)-MIN(Instances!L76:Instances!L76))} -> 0 | M76: {=_xlfn.SWITCH($A$2,"average", AVERAGE(Instances!M76:Instances!M76),"median", MEDIAN(Instances!M76:Instances!M76),"min", MIN(Instances!M76:Instances!M76),"max", MAX(Instances!M76:Instances!M76),"diff", MAX(Instances!M76:Instances!M76)-MIN(Instances!M76:Instances!M76))} -> 0 | N76: {=_xlfn.SWITCH($A$2,"average", AVERAGE(Instances!N76:Instances!N76),"median", MEDIAN(Instances!N76:Instances!N76),"min", MIN(Instances!N76:Instances!N76),"max", MAX(Instances!N76:Instances!N76),"diff", MAX(Instances!N76:Instances!N76)-MIN(Instances!N76:Instances!N76))} -> 0 | O76: {=_xlfn.SWITCH($A$2,"average", AVERAGE(Instances!O76:Instances!O76),"median", MEDIAN(Instances!O76:Instances!O76),"min", MIN(Instances!O76:Instances!O76),"max", MAX(Instances!O76:Instances!O76),"diff", MAX(Instances!O76:Instances!O76)-MIN(Instances!O76:Instances!O76))} -> 0 | P76: {=_xlfn.SWITCH($A$2,"average", AVERAGE(Instances!P76:Instances!P76),"median", MEDIAN(Instances!P76:Instances!P76),"min", MIN(Instances!P76:Instances!P76),"max", MAX(Instances!P76:Instances!P76),"diff", MAX(Instances!P76:Instances!P76)-MIN(Instances!P76:Instances!P76))} -> 0 | Q76: {=_xlfn.SWITCH($A$2,"average", AVERAGE(Instances!Q76:Instances!Q76),"median", MEDIAN(Instances!Q76:Instances!Q76),"min", MIN(Instances!Q76:Instances!Q76),"max", MAX(Instances!Q76:Instances!Q76),"diff", MAX(Instances!Q76:Instances!Q76)-MIN(Instances!Q76:Instances!Q76))} -> 0 | R76: =MIN($B76,$D76,$F76,$H76,$J76,$L76,$N76,$P76) -> 0 | S76: =MIN($C76,$E76,$G76,$I76,$K76,$M76,$O76,$Q76) -> 0 | T76: =MEDIAN($B76,$D76,$F76,$H76,$J76,$L76,$N76,$P76) -> 0 | U76: =MEDIAN($C76,$E76,$G76,$I76,$K76,$M76,$O76,$Q76) -> 0 | V76: =MAX($B76,$D76,$F76,$H76,$J76,$L76,$N76,$P76) -> 0 | W76: =MAX($C76,$E76,$G76,$I76,$K76,$M76,$O76,$Q76) -> 0
A77: ./cargobike-complex-100_user-input-11 | D77: {=_xlfn.SWITCH($A$2,"average", AVERAGE(Instances!D77:Instances!D77),"median", MEDIAN(Instances!D77:Instances!D77),"min", MIN(Instances!D77:Instances!D77),"max", MAX(Instances!D77:Instances!D77),"diff", MAX(Instances!D77:Instances!D77)-MIN(Instances!D77:Instances!D77))} -> 0 | E77: {=_xlfn.SWITCH($A$2,"average", AVERAGE(Instances!E77:Instances!E77),"median", MEDIAN(Instances!E77:Instances!E77),"min", MIN(Instances!E77:Instances!E77),"max", MAX(Instances!E77:Instances!E77),"diff", MAX(Instances!E77:Instances!E77)-MIN(Instances!E77:Instances!E77))} -> 0 | F77: {=_xlfn.SWITCH($A$2,"average", AVERAGE(Instances!F77:Instances!F77),"median", MEDIAN(Instances!F77:Instances!F77),"min", MIN(Instances!F77:Instances!F77),"max", MAX(Instances!F77:Instances!F77),"diff", MAX(Instances!F77:Instances!F77)-MIN(Instances!F77:Instances!F77))} -> 0 | G77: {=_xlfn.SWITCH($A$2,"average", AVERAGE(Instances!G77:Instances!G77),"median", MEDIAN(Instances!G77:Instances!G77),"min", MIN(Instances!G77:Instances!G77),"max", MAX(Instances!G77:Instances!G77),"diff", MAX(Instances!G77:Instances!G77)-MIN(Instances!G77:Instances!G77))} -> 0 | J77: {=_xlfn.SWITCH($A$2,"average", AVERAGE(Instances!J77:Instances!J77),"median", MEDIAN(Instances!J77:Instances!J77),"min", MIN(Instances!J77:Instances!J77),"max", MAX(Instances!J77:Instances!J77),"diff", MAX(Instances!J77:Instances!J77)-MIN(Instances!J77:Instances!J77))} -> 0 | K77: {=_xlfn.SWITCH($A$2,"average", AVERAGE(Instances!K77:Instances!K77),"median", MEDIAN(Instances!K77:Instances!K77),"min", MIN(Instances!K77:Instances!K77),"max", MAX(Instances!K77:Instances!K77),"diff", MAX(Instances!K77:Instances!K77)-MIN(Instances!K77:Instances!K77))} -> 0 | L77: {=_xlfn.SWITCH($A$2,"average", AVERAGE(Instances!L77:Instances!L77),"median", MEDIAN(Instances!L77:Instances!L77),"min", MIN(Instances!L77:Instances!L77),"max", MAX(Instances!L77:Instances!L77),"diff", MAX(Instances!L77:Instances!L77)-MIN(Instances!L77:Instances!L77))} -> 0 | M77: {=_xlfn.SWITCH($A$2,"average", AVERAGE(Instances!M77:Instances!M77),"median", MEDIAN(Instances!M77:Instances!M77),"min", MIN(Instances!M77:Instances!M77),"max", MAX(Instances!M77:Instances!M77),"diff", MAX(Instances!M77:Instances!M77)-MIN(Instances!M77:Instances!M77))} -> 0 | N77: {=_xlfn.SWITCH($A$2,"average", AVERAGE(Instances!N77:Instances!N77),"median", MEDIAN(Instances!N77:Instances!N77),"min", MIN(Instances!N77:Instances!N77),"max", MAX(Instances!N77:Instances!N77),"diff", MAX(Instances!N77:Instances!N77)-MIN(Instances!N77:Instances!N77))} -> 0 | O77: {=_xlfn.SWITCH($A$2,"average", AVERAGE(Instances!O77:Instances!O77),"median", MEDIAN(Instances!O77:Instances!O77),"min", MIN(Instances!O77:Instances!O77),"max", MAX(Instances!O77:Instances!O77),"diff", MAX(Instances!O77:Instances!O77)-MIN(Instances!O77:Instances!O77))} -> 0 | P77: {=_xlfn.SWITCH($A$2,"average", AVERAGE(Instances!P77:Instances!P77),"median", MEDIAN(Instances!P77:Instances!P77),"min", MIN(Instances!P77:Instances!P77),"max", MAX(Instances!P77:Instances!P77),"diff", MAX(Instances!P77:Instances!P77)-MIN(Instances!P77:Instances!P77))} -> 0 | Q77: {=_xlfn.SWITCH($A$2,"average", AVERAGE(Instances!Q77:Instances!Q77),"median", MEDIAN(Instances!Q77:Instances!Q77),"min", MIN(Instances!Q77:Instances!Q77),"max", MAX(Instances!Q77:Instances!Q77),"diff", MAX(Instances!Q77:Instances!Q77)-MIN(Instances!Q77:Instances!Q77))} -> 0 | R77: =MIN($B77,$D77,$F77,$H77,$J77,$L77,$N77,$P77) -> 0 | S77: =MIN($C77,$E77,$G77,$I77,$K77,$M77,$O77,$Q77) -> 0 | T77: =MEDIAN($B77,$D77,$F77,$H77,$J77,$L77,$N77,$P77) -> 0 | U77: =MEDIAN($C77,$E77,$G77,$I77,$K77,$M77,$O77,$Q77) -> 0 | V77: =MAX($B77,$D77,$F77,$H77,$J77,$L77,$N77,$P77) -> 0 | W77: =MAX($C77,$E77,$G77,$I77,$K77,$M77,$O77,$Q77) -> 0
A78: ./cargobike-complex-100_user-input-12 | D78: {=_xlfn.SWITCH($A$2,"average", AVERAGE(Instances!D78:Instances!D78),"median", MEDIAN(Instances!D78:Instances!D78),"min", MIN(Instances!D78:Instances!D78),"max", MAX(Instances!D78:Instances!D78),"diff", MAX(Instances!D78:Instances!D78)-MIN(Instances!D78:Instances!D78))} -> 0 | E78: {=_xlfn.SWITCH($A$2,"average", AVERAGE(Instances!E78:Instances!E78),"median", MEDIAN(Instances!E78:Instances!E78),"min", MIN(Instances!E78:Instances!E78),"max", MAX(Instances!E78:Instances!E78),"diff", MAX(Instances!E78:Instances!E78)-MIN(Instances!E78:Instances!E78))} -> 0 | F78: {=_xlfn.SWITCH($A$2,"average", AVERAGE(Instances!F78:Instances!F78),"median", MEDIAN(Instances!F78:Instances!F78),"min", MIN(Instances!F78:Instances!F78),"max", MAX(Instances!F78:Instances!F78),"diff", MAX(Instances!F78:Instances!F78)-MIN(Instances!F78:Instances!F78))} -> 0 | G78: {=_xlfn.SWITCH($A$2,"average", AVERAGE(Instances!G78:Instances!G78),"median", MEDIAN(Instances!G78:Instances!G78),"min", MIN(Instances!G78:Instances!G78),"max", MAX(Instances!G78:Instances!G78),"diff", MAX(Instances!G78:Instances!G78)-MIN(Instances!G78:Instances!G78))} -> 0 | J78: {=_xlfn.SWITCH($A$2,"average", AVERAGE(Instances!J78:Instances!J78),"median", MEDIAN(Instances!J78:Instances!J78),"min", MIN(Instances!J78:Instances!J78),"max", MAX(Instances!J78:Instances!J78),"diff", MAX(Instances!J78:Instances!J78)-MIN(Instances!J78:Instances!J78))} -> 0 | K78: {=_xlfn.SWITCH($A$2,"average", AVERAGE(Instances!K78:Instances!K78),"median", MEDIAN(Instances!K78:Instances!K78),"min", MIN(Instances!K78:Instances!K78),"max", MAX(Instances!K78:Instances!K78),"diff", MAX(Instances!K78:Instances!K78)-MIN(Instances!K78:Instances!K78))} -> 0 | L78: {=_xlfn.SWITCH($A$2,"average", AVERAGE(Instances!L78:Instances!L78),"median", MEDIAN(Instances!L78:Instances!L78),"min", MIN(Instances!L78:Instances!L78),"max", MAX(Instances!L78:Instances!L78),"diff", MAX(Instances!L78:Instances!L78)-MIN(Instances!L78:Instances!L78))} -> 0 | M78: {=_xlfn.SWITCH($A$2,"average", AVERAGE(Instances!M78:Instances!M78),"median", MEDIAN(Instances!M78:Instances!M78),"min", MIN(Instances!M78:Instances!M78),"max", MAX(Instances!M78:Instances!M78),"diff", MAX(Instances!M78:Instances!M78)-MIN(Instances!M78:Instances!M78))} -> 0 | N78: {=_xlfn.SWITCH($A$2,"average", AVERAGE(Instances!N78:Instances!N78),"median", MEDIAN(Instances!N78:Instances!N78),"min", MIN(Instances!N78:Instances!N78),"max", MAX(Instances!N78:Instances!N78),"diff", MAX(Instances!N78:Instances!N78)-MIN(Instances!N78:Instances!N78))} -> 0 | O78: {=_xlfn.SWITCH($A$2,"average", AVERAGE(Instances!O78:Instances!O78),"median", MEDIAN(Instances!O78:Instances!O78),"min", MIN(Instances!O78:Instances!O78),"max", MAX(Instances!O78:Instances!O78),"diff", MAX(Instances!O78:Instances!O78)-MIN(Instances!O78:Instances!O78))} -> 0 | P78: {=_xlfn.SWITCH($A$2,"average", AVERAGE(Instances!P78:Instances!P78),"median", MEDIAN(Instances!P78:Instances!P78),"min", MIN(Instances!P78:Instances!P78),"max", MAX(Instances!P78:Instances!P78),"diff", MAX(Instances!P78:Instances!P78)-MIN(Instances!P78:Instances!P78))} -> 0 | Q78: {=_xlfn.SWITCH($A$2,"average", AVERAGE(Instances!Q78:Instances!Q78),"median", MEDIAN(Instances!Q78:Instances!Q78),"min", MIN(Instances!Q78:Instances!Q78),"max", MAX(Instances!Q78:Instances!Q78),"diff", MAX(Instances!Q78:Instances!Q78)-MIN(Instances!Q78:Instances!Q78))} -> 0 | R78: =MIN($B78,$D78,$F78,$H78,$J78,$L78,$N78,$P78) -> 0 | S78: =MIN($C78,$E78,$G78,$I78,$K78,$M78,$O78,$Q78) -> 0 | T78: =MEDIAN($B78,$D78,$F78,$H78,$J78,$L78,$N78,$P78) -> 0 | U78: =MEDIAN($C78,$E78,$G78,$I78,$K78,$M78,$O78,$Q78) -> 0 | V78: =MAX($B78,$D78,$F78,$H78,$J78,$L78,$N78,$P78) -> 0 | W78: =MAX($C78,$E78,$G78,$I78,$K78,$M78,$O78,$Q78) -> 0
