Workbook

Sheet Instances
B1: coomsuite-1.0.0/clingo-base | D1: coomsuite-1.0.0/clingo-bounds-exponential | F1: coomsuite-1.0.0/clingo-bounds-linear | H1: coomsuite-1.0.0/flingo-base | J1: coomsuite-1.0.0/flingo-bounds-exponential | L1: coomsuite-1.0.0/flingo-bounds-linear | N1: coomsuite-1.0.0/multishot-exponential | P1: coomsuite-1.0.0/multishot-linear | R1: min | T1: median | V1: max
B2: time | C2: timeout | D2: time | E2: timeout | F2: time | G2: timeout | H2: time | I2: timeout | J2: time | K2: timeout | L2: time | M2: timeout | N2: time | O2: timeout | P2: time | Q2: timeout | R2: time | S2: timeout | T2: time | U2: timeout | V2: time | W2: timeout
A3: ./travelbike-max10_user-input-p155-v655 | B3: 1200 | C3: 1 | H3: 1200 | I3: 1 | R3: =MIN($B3,$D3,$F3,$H3,$J3,$L3,$N3,$P3) -> 0 | S3: =MIN($C3,$E3,$G3,$I3,$K3,$M3,$O3,$Q3) -> 0 | T3: =MEDIAN($B3,$D3,$F3,$H3,$J3,$L3,$N3,$P3) -> 0 | U3: =MEDIAN($C3,$E3,$G3,$I3,$K3,$M3,$O3,$Q3) -> 0 | V3: =MAX($B3,$D3,$F3,$H3,$J3,$L3,$N3,$P3) -> 0 | W3: =MAX($C3,$E3,$G3,$I3,$K3,$M3,$O3,$Q3) -> 0
A4: ./travelbike-max10_user-input-p163-v220 | B4: 1200 | C4: 1 | H4: 4.64 | I4: 0 | R4: =MIN($B4,$D4,$F4,$H4,$J4,$L4,$N4,$P4) -> 0 | S4: =MIN($C4,$E4,$G4,$I4,$K4,$M4,$O4,$Q4) -> 0 | T4: =MEDIAN($B4,$D4,$F4,$H4,$J4,$L4,$N4,$P4) -> 0 | U4: =MEDIAN($C4,$E4,$G4,$I4,$K4,$M4,$O4,$Q4) -> 0 | V4: =MAX($B4,$D4,$F4,$H4,$J4,$L4,$N4,$P4) -> 0 | W4: =MAX($C4,$E4,$G4,$I4,$K4,$M4,$O4,$Q4) -> 0
A5: ./travelbike-max10_user-input-p312-v851 | B5: 1200 | C5: 1 | H5: 5.27 | I5: 0 | R5: =MIN($B5,$D5,$F5,$H5,$J5,$L5,$N5,$P5) -> 0 | S5: =MIN($C5,$E5,$G5,$I5,$K5,$M5,$O5,$Q5) -> 0 | T5: =MEDIAN($B5,$D5,$F5,$H5,$J5,$L5,$N5,$P5) -> 0 | U5: =MEDIAN($C5,$E5,$G5,$I5,$K5,$M5,$O5,$Q5) -> 0 | V5: =MAX($B5,$D5,$F5,$H5,$J5,$L5,$N5,$P5) -> 0 | W5: =MAX($C5,$E5,$G5,$I5,$K5,$M5,$O5,$Q5) -> 0
A6: ./travelbike-max10_user-input-p317-v561 | B6: 1200 | C6: 1 | H6: 6.34 | I6: 0 | R6: =MIN($B6,$D6,$F6,$H6,$J6,$L6,$N6,$P6) -> 0 | S6: =MIN($C6,$E6,$G6,$I6,$K6,$M6,$O6,$Q6) -> 0 | T6: =MEDIAN($B6,$D6,$F6,$H6,$J6,$L6,$N6,$P6) -> 0 | U6: =MEDIAN($C6,$E6,$G6,$I6,$K6,$M6,$O6,$Q6) -> 0 | V6: =MAX($B6,$D6,$F6,$H6,$J6,$L6,$N6,$P6) -> 0 | W6: =MAX($C6,$E6,$G6,$I6,$K6,$M6,$O6,$Q6) -> 0
A7: ./travelbike-max10_user-input-p434-v422 | B7: 845.71 | C7: 0 | H7: 5.15 | I7: 0 | R7: =MIN($B7,$D7,$F7,$H7,$J7,$L7,$N7,$P7) -> 0 | S7: =MIN($C7,$E7,$G7,$I7,$K7,$M7,$O7,$Q7) -> 0 | T7: =MEDIAN($B7,$D7,$F7,$H7,$J7,$L7,$N7,$P7) -> 0 | U7: =MEDIAN($C7,$E7,$G7,$I7,$K7,$M7,$O7,$Q7) -> 0 | V7: =MAX($B7,$D7,$F7,$H7,$J7,$L7,$N7,$P7) -> 0 | W7: =MAX($C7,$E7,$G7,$I7,$K7,$M7,$O7,$Q7) -> 0
A8: ./travelbike-max10_user-input-p619-v924 | B8: 594.87 | C8: 0 | H8: 4.69 | I8: 0 | R8: =MIN($B8,$D8,$F8,$H8,$J8,$L8,$N8,$P8) -> 0 | S8: =MIN($C8,$E8,$G8,$I8,$K8,$M8,$O8,$Q8) -> 0 | T8: =MEDIAN($B8,$D8,$F8,$H8,$J8,$L8,$N8,$P8) -> 0 | U8: =MEDIAN($C8,$E8,$G8,$I8,$K8,$M8,$O8,$Q8) -> 0 | V8: =MAX($B8,$D8,$F8,$H8,$J8,$L8,$N8,$P8) -> 0 | W8: =MAX($C8,$E8,$G8,$I8,$K8,$M8,$O8,$Q8) -> 0
A9: ./travelbike-max10_user-input-p847-v390 | B9: 569.38 | C9: 0 | H9: 6.75 | I9: 0 | R9: =MIN($B9,$D9,$F9,$H9,$J9,$L9,$N9,$P9) -> 0 | S9: =MIN($C9,$E9,$G9,$I9,$K9,$M9,$O9,$Q9) -> 0 | T9: =MEDIAN($B9,$D9,$F9,$H9,$J9,$L9,$N9,$P9) -> 0 | U9: =MEDIAN($C9,$E9,$G9,$I9,$K9,$M9,$O9,$Q9) -> 0 | V9: =MAX($B9,$D9,$F9,$H9,$J9,$L9,$N9,$P9) -> 0 | W9: =MAX($C9,$E9,$G9,$I9,$K9,$M9,$O9,$Q9) -> 0
A10: ./travelbike-max10_user-input-p872-v959 | B10: 907.43 | C10: 0 | H10: 10.13 | I10: 0 | R10: =MIN($B10,$D10,$F10,$H10,$J10,$L10,$N10,$P10) -> 0 | S10: =MIN($C10,$E10,$G10,$I10,$K10,$M10,$O10,$Q10) -> 0 | T10: =MEDIAN($B10,$D10,$F10,$H10,$J10,$L10,$N10,$P10) -> 0 | U10: =MEDIAN($C10,$E10,$G10,$I10,$K10,$M10,$O10,$Q10) -> 0 | V10: =MAX($B10,$D10,$F10,$H10,$J10,$L10,$N10,$P10) -> 0 | W10: =MAX($C10,$E10,$G10,$I10,$K10,$M10,$O10,$Q10) -> 0
A11: ./travelbike-max10_user-input-p930-v649 | B11: 517.7 | C11: 0 | H11: 8.6 | I11: 0 | R11: =MIN($B11,$D11,$F11,$H11,$J11,$L11,$N11,$P11) -> 0 | S11: =MIN($C11,$E11,$G11,$I11,$K11,$M11,$O11,$Q11) -> 0 | T11: =MEDIAN($B11,$D11,$F11,$H11,$J11,$L11,$N11,$P11) -> 0 | U11: =MEDIAN($C11,$E11,$G11,$I11,$K11,$M11,$O11,$Q11) -> 0 | V11: =MAX($B11,$D11,$F11,$H11,$J11,$L11,$N11,$P11) -> 0 | W11: =MAX($C11,$E11,$G11,$I11,$K11,$M11,$O11,$Q11) -> 0
A12: ./travelbike-max10_user-input-p991-v163 | B12: 448.01 | C12: 0 | H12: 7.6 | I12: 0 | R12: =MIN($B12,$D12,$F12,$H12,$J12,$L12,$N12,$P12) -> 0 | S12: =MIN($C12,$E12,$G12,$I12,$K12,$M12,$O12,$Q12) -> 0 | T12: =MEDIAN($B12,$D12,$F12,$H12,$J12,$L12,$N12,$P12) -> 0 | U12: =MEDIAN($C12,$E12,$G12,$I12,$K12,$M12,$O12,$Q12) -> 0 | V12: =MAX($B12,$D12,$F12,$H12,$J12,$L12,$N12,$P12) -> 0 | W12: =MAX($C12,$E12,$G12,$I12,$K12,$M12,$O12,$Q12) -> 0
A13: ./travelbike-max15_user-input-p1004-v748 | B13: 1200 | C13: 1 | H13: 13.08 | I13: 0 | R13: =MIN($B13,$D13,$F13,$H13,$J13,$L13,$N13,$P13) -> 0 | S13: =MIN($C13,$E13,$G13,$I13,$K13,$M13,$O13,$Q13) -> 0 | T13: =MEDIAN($B13,$D13,$F13,$H13,$J13,$L13,$N13,$P13) -> 0 | U13: =MEDIAN($C13,$E13,$G13,$I13,$K13,$M13,$O13,$Q13) -> 0 | V13: =MAX($B13,$D13,$F13,$H13,$J13,$L13,$N13,$P13) -> 0 | W13: =MAX($C13,$E13,$G13,$I13,$K13,$M13,$O13,$Q13) -> 0
A14: ./travelbike-max15_user-input-p1038-v167 | B14: 1200 | C14: 1 | H14: 1200 | I14: 1 | R14: =MIN($B14,$D14,$F14,$H14,$J14,$L14,$N14,$P14) -> 0 | S14: =MIN($C14,$E14,$G14,$I14,$K14,$M14,$O14,$Q14) -> 0 | T14: =MEDIAN($B14,$D14,$F14,$H14,$J14,$L14,$N14,$P14) -> 0 | U14: =MEDIAN($C14,$E14,$G14,$I14,$K14,$M14,$O14,$Q14) -> 0 | V14: =MAX($B14,$D14,$F14,$H14,$J14,$L14,$N14,$P14) -> 0 | W14: =MAX($C14,$E14,$G14,$I14,$K14,$M14,$O14,$Q14) -> 0
... A42: ./travelbike-max5_user-input-p82-v294 | B42: 1200 | C42: 1 | H42: 6.51 | I42: 0 | R42: =MIN($B42,$D42,$F42,$H42,$J42,$L42,$N42,$P42) -> 0 | S42: =MIN($C42,$E42,$G42,$I42,$K42,$M42,$O42,$Q42) -> 0 | T42: =MEDIAN($B42,$D42,$F42,$H42,$J42,$L42,$N42,$P42) -> 0 | U42: =MEDIAN($C42,$E42,$G42,$I42,$K42,$M42,$O42,$Q42) -> 0 | V42: =MAX($B42,$D42,$F42,$H42,$J42,$L42,$N42,$P42) -> 0 | W42: =MAX($C42,$E42,$G42,$I42,$K42,$M42,$O42,$Q42) -> 0
A43: ./travelbike-max10_user-input-p155-v655 | D43: 1200 | E43: 1 | F43: 1200 | G43: 1 | J43: 1200 | K43: 1 | L43: 1200 | M43: 1 | N43: 1200 | O43: 1 | P43: 1200 | Q43: 1 | R43: =MIN($B43,$D43,$F43,$H43,$J43,$L43,$N43,$P43) -> 0 | S43: =MIN($C43,$E43,$G43,$I43,$K43,$M43,$O43,$Q43) -> 0 | T43: =MEDIAN($B43,$D43,$F43,$H43,$J43,$L43,$N43,$P43) -> 0 | U43: =MEDIAN($C43,$E43,$G43,$I43,$K43,$M43,$O43,$Q43) -> 0 | V43: =MAX($B43,$D43,$F43,$H43,$J43,$L43,$N43,$P43) -> 0 | W43: =MAX($C43,$E43,$G43,$I43,$K43,$M43,$O43,$Q43) -> 0
A44: ./travelbike-max10_user-input-p163-v220 | D44: 227.35 | E44: 0 | F44: 153.66 | G44: 0 | J44: 5.05 | K44: 0 | L44: 3.2 | M44: 0 | N44: 1.53 | O44: 0 | P44: 1.29 | Q44: 0 | R44: =MIN($B44,$D44,$F44,$H44,$J44,$L44,$N44,$P44) -> 0 | S44: =MIN($C44,$E44,$G44,$I44,$K44,$M44,$O44,$Q44) -> 0 | T44: =MEDIAN($B44,$D44,$F44,$H44,$J44,$L44,$N44,$P44) -> 0 | U44: =MEDIAN($C44,$E44,$G44,$I44,$K44,$M44,$O44,$Q44) -> 0 | V44: =MAX($B44,$D44,$F44,$H44,$J44,$L44,$N44,$P44) -> 0 | W44: =MAX($C44,$E44,$G44,$I44,$K44,$M44,$O44,$Q44) -> 0
A45: ./travelbike-max10_user-input-p312-v851 | D45: 1200 | E45: 1 | F45: 1200 | G45: 1 | J45: 1200 | K45: 1 | L45: 1200 | M45: 1 | N45: 1200 | O45: 1 | P45: 1200 | Q45: 1 | R45: =MIN($B45,$D45,$F45,$H45,$J45,$L45,$N45,$P45) -> 0 | S45: =MIN($C45,$E45,$G45,$I45,$K45,$M45,$O45,$Q45) -> 0 | T45: =MEDIAN($B45,$D45,$F45,$H45,$J45,$L45,$N45,$P45) -> 0 | U45: =MEDIAN($C45,$E45,$G45,$I45,$K45,$M45,$O45,$Q45) -> 0 | V45: =MAX($B45,$D45,$F45,$H45,$J45,$L45,$N45,$P45) -> 0 | W45: =MAX($C45,$E45,$G45,$I45,$K45,$M45,$O45,$Q45) -> 0
A46: ./travelbike-max10_user-input-p317-v561 | D46: 1200 | E46: 1 | F46: 1200 | G46: 1 | J46: 14.3 | K46: 0 | L46: 9.76 | M46: 0 | N46: 1200 | O46: 1 | P46: 1200 | Q46: 1 | R46: =MIN($B46,$D46,$F46,$H46,$J46,$L46,$N46,$P46) -> 0 | S46: =MIN($C46,$E46,$G46,$I46,$K46,$M46,$O46,$Q46) -> 0 | T46: =MEDIAN($B46,$D46,$F46,$H46,$J46,$L46,$N46,$P46) -> 0 | U46: =MEDIAN($C46,$E46,$G46,$I46,$K46,$M46,$O46,$Q46) -> 0 | V46: =MAX($B46,$D46,$F46,$H46,$J46,$L46,$N46,$P46) -> 0 | W46: =MAX($C46,$E46,$G46,$I46,$K46,$M46,$O46,$Q46) -> 0
A47: ./travelbike-max10_user-input-p434-v422 | D47: 1110.63 | E47: 0 | F47: 775.85 | G47: 0 | J47: 14.49 | K47: 0 | L47: 7.69 | M47: 0 | N47: 232.06 | O47: 0 | P47: 215.78 | Q47: 0 | R47: =MIN($B47,$D47,$F47,$H47,$J47,$L47,$N47,$P47) -> 0 | S47: =MIN($C47,$E47,$G47,$I47,$K47,$M47,$O47,$Q47) -> 0 | T47: =MEDIAN($B47,$D47,$F47,$H47,$J47,$L47,$N47,$P47) -> 0 | U47: =MEDIAN($C47,$E47,$G47,$I47,$K47,$M47,$O47,$Q47) -> 0 | V47: =MAX($B47,$D47,$F47,$H47,$J47,$L47,$N47,$P47) -> 0 | W47: =MAX($C47,$E47,$G47,$I47,$K47,$M47,$O47,$Q47) -> 0
A48: ./travelbike-max10_user-input-p619-v924 | D48: 1200 | E48: 1 | F48: 1200 | G48: 1 | J48: 1200 | K48: 1 | L48: 1200 | M48: 1 | N48: 1200 | O48: 1 | P48: 1200 | Q48: 1 | R48: =MIN($B48,$D48,$F48,$H48,$J48,$L48,$N48,$P48) -> 0 | S48: =MIN($C48,$E48,$G48,$I48,$K48,$M48,$O48,$Q48) -> 0 | T48: =MEDIAN($B48,$D48,$F48,$H48,$J48,$L48,$N48,$P48) -> 0 | U48: =MEDIAN($C48,$E48,$G48,$I48,$K48,$M48,$O48,$Q48) -> 0 | V48: =MAX($B48,$D48,$F48,$H48,$J48,$L48,$N48,$P48) -> 0 | W48: =MAX($C48,$E48,$G48,$I48,$K48,$M48,$O48,$Q48) -> 0
A49: ./travelbike-max10_user-input-p847-v390 | D49: 219.1 | E49: 0 | F49: 219.73 | G49: 0 | J49: 5.02 | K49: 0 | L49: 5.23 | M49: 0 | N49: 191.3 | O49: 0 | P49: 184.33 | Q49: 0 | R49: =MIN($B49,$D49,$F49,$H49,$J49,$L49,$N49,$P49) -> 0 | S49: =MIN($C49,$E49,$G49,$I49,$K49,$M49,$O49,$Q49) -> 0 | T49: =MEDIAN($B49,$D49,$F49,$H49,$J49,$L49,$N49,$P49) -> 0 | U49: =MEDIAN($C49,$E49,$G49,$I49,$K49,$M49,$O49,$Q49) -> 0 | V49: =MAX($B49,$D49,$F49,$H49,$J49,$L49,$N49,$P49) -> 0 | W49: =MAX($C49,$E49,$G49,$I49,$K49,$M49,$O49,$Q49) -> 0
A50: ./travelbike-max10_user-input-p872-v959 | D50: 1200 | E50: 1 | F50: 1200 | G50: 1 | J50: 1200 | K50: 1 | L50: 41.18 | M50: 0 | N50: 1200 | O50: 1 | P50: 1200 | Q50: 1 | R50: =MIN($B50,$D50,$F50,$H50,$J50,$L50,$N50,$P50) -> 0 | S50: =MIN($C50,$E50,$G50,$I50,$K50,$M50,$O50,$Q50) -> 0 | T50: =MEDIAN($B50,$D50,$F50,$H50,$J50,$L50,$N50,$P50) -> 0 | U50: =MEDIAN($C50,$E50,$G50,$I50,$K50,$M50,$O50,$Q50) -> 0 | V50: =MAX($B50,$D50,$F50,$H50,$J50,$L50,$N50,$P50) -> 0 | W50: =MAX($C50,$E50,$G50,$I50,$K50,$M50,$O50,$Q50) -> 0
A51: ./travelbike-max10_user-input-p930-v649 | D51: 1200 | E51: 1 | F51: 1200 | G51: 1 | J51: 16.28 | K51: 0 | L51: 14.51 | M51: 0 | N51: 1200 | O51: 1 | P51: 1200 | Q51: 1 | R51: =MIN($B51,$D51,$F51,$H51,$J51,$L51,$N51,$P51) -> 0 | S51: =MIN($C51,$E51,$G51,$I51,$K51,$M51,$O51,$Q51) -> 0 | T51: =MEDIAN($B51,$D51,$F51,$H51,$J51,$L51,$N51,$P51) -> 0 | U51: =MEDIAN($C51,$E51,$G51,$I51,$K51,$M51,$O51,$Q51) -> 0 | V51: =MAX($B51,$D51,$F51,$H51,$J51,$L51,$N51,$P51) -> 0 | W51: =MAX($C51,$E51,$G51,$I51,$K51,$M51,$O51,$Q51) -> 0
A52: ./travelbike-max10_user-input-p991-v163 | D52: 86.38 | E52: 0 | F52: 91.36 | G52: 0 | J52: 1.76 | K52: 0 | L52: 1.81 | M52: 0 | N52: 1.37 | O52: 0 | P52: 1.19 | Q52: 0 | R52: =MIN($B52,$D52,$F52,$H52,$J52,$L52,$N52,$P52) -> 0 | S52: =MIN($C52,$E52,$G52,$I52,$K52,$M52,$O52,$Q52) -> 0 | T52: =MEDIAN($B52,$D52,$F52,$H52,$J52,$L52,$N52,$P52) -> 0 | U52: =MEDIAN($C52,$E52,$G52,$I52,$K52,$M52,$O52,$Q52) -> 0 | V52: =MAX($B52,$D52,$F52,$H52,$J52,$L52,$N52,$P52) -> 0 | W52: =MAX($C52,$E52,$G52,$I52,$K52,$M52,$O52,$Q52) -> 0
A53: ./travelbike-max15_user-input-p1004-v748 | D53: 1200 | E53: 1 | F53: 1200 | G53: 1 | J53: 16.28 | K53: 0 | L53: 21.88 | M53: 0 | N53: 1200 | O53: 1 | P53: 1200 | Q53: 1 | R53: =MIN($B53,$D53,$F53,$H53,$J53,$L53,$N53,$P53) -> 0 | S53: =MIN($C53,$E53,$G53,$I53,$K53,$M53,$O53,$Q53) -> 0 | T53: =MEDIAN($B53,$D53,$F53,$H53,$J53,$L53,$N53,$P53) -> 0 | U53: =MEDIAN($C53,$E53,$G53,$I53,$K53,$M53,$O53,$Q53) -> 0 | V53: =MAX($B53,$D53,$F53,$H53,$J53,$L53,$N53,$P53) -> 0 | W53: =MAX($C53,$E53,$G53,$I53,$K53,$M53,$O53,$Q53) -> 0
A54: ./travelbike-max15_user-input-p1038-v167 | D54: 444.8 | E54: 0 | F54: 398.19 | G54: 0 | J54: 2.44 | K54: 0 | L54: 1.92 | M54: 0 | N54: 1.38 | O54: 0 | P54: 1.39 | Q54: 0 | R54: =MIN($B54,$D54,$F54,$H54,$J54,$L54,$N54,$P54) -> 0 | S54: =MIN($C54,$E54,$G54,$I54,$K54,$M54,$O54,$Q54) -> 0 | T54: =MEDIAN($B54,$D54,$F54,$H54,$J54,$L54,$N54,$P54) -> 0 | U54: =MEDIAN($C54,$E54,$G54,$I54,$K54,$M54,$O54,$Q54) -> 0 | V54: =MAX($B54,$D54,$F54,$H54,$J54,$L54,$N54,$P54) -> 0 | W54: =MAX($C54,$E54,$G54,$I54,$K54,$M54,$O54,$Q54) -> 0
... A82: ./travelbike-max5_user-input-p82-v294 | D82: 1200 | E82: 1 | F82: 1200 | G82: 1 | J82: 1200 | K82: 1 | L82: 1200 | M82: 1 | N82: 1200 | O82: 1 | P82: 1200 | Q82: 1 | R82: =MIN($B82,$D82,$F82,$H82,$J82,$L82,$N82,$P82) -> 0 | S82: =MIN($C82,$E82,$G82,$I82,$K82,$M82,$O82,$Q82) -> 0 | T82: =MEDIAN($B82,$D82,$F82,$H82,$J82,$L82,$N82,$P82) -> 0 | U82: =MEDIAN($C82,$E82,$G82,$I82,$K82,$M82,$O82,$Q82) -> 0 | V82: =MAX($B82,$D82,$F82,$H82,$J82,$L82,$N82,$P82) -> 0 | W82: =MAX($C82,$E82,$G82,$I82,$K82,$M82,$O82,$Q82) -> 0
A84: SUM | B84: =SUM(B$3:B$82) -> 0 | C84: =SUM(C$3:C$82) -> 0 | D84: =SUM(D$3:D$82) -> 0 | E84: =SUM(E$3:E$82) -> 0 | F84: =SUM(F$3:F$82) -> 0 | G84: =SUM(G$3:G$82) -> 0 | H84: =SUM(H$3:H$82) -> 0 | I84: =SUM(I$3:I$82) -> 0 | ... W84: =SUM(W$3:W$82) -> 0
A85: AVG | B85: =AVERAGE(B$3:B$82) -> 0 | C85: =AVERAGE(C$3:C$82) -> 0 | D85: =AVERAGE(D$3:D$82) -> 0 | E85: =AVERAGE(E$3:E$82) -> 0 | F85: =AVERAGE(F$3:F$82) -> 0 | G85: =AVERAGE(G$3:G$82) -> 0 | H85: =AVERAGE(H$3:H$82) -> 0 | I85: =AVERAGE(I$3:I$82) -> 0 | ... W85: =AVERAGE(W$3:W$82) -> 0
A86: DEV | B86: =STDEV(B$3:B$82) -> 0 | C86: =STDEV(C$3:C$82) -> 0 | D86: =STDEV(D$3:D$82) -> 0 | E86: =STDEV(E$3:E$82) -> 0 | F86: =STDEV(F$3:F$82) -> 0 | G86: =STDEV(G$3:G$82) -> 0 | H86: =STDEV(H$3:H$82) -> 0 | I86: =STDEV(I$3:I$82) -> 0 | ... W86: =STDEV(W$3:W$82) -> 0
A87: DST | B87: =SUMPRODUCT(--(B$3:B$82-$R$3:$R$82)^2)^0.5 -> 0 | C87: =SUMPRODUCT(--(C$3:C$82-$S$3:$S$82)^2)^0.5 -> 0 | D87: =SUMPRODUCT(--(D$3:D$82-$R$3:$R$82)^2)^0.5 -> 0 | E87: =SUMPRODUCT(--(E$3:E$82-$S$3:$S$82)^2)^0.5 -> 0 | F87: =SUMPRODUCT(--(F$3:F$82-$R$3:$R$82)^2)^0.5 -> 0 | G87: =SUMPRODUCT(--(G$3:G$82-$S$3:$S$82)^2)^0.5 -> 0 | H87: =SUMPRODUCT(--(H$3:H$82-$R$3:$R$82)^2)^0.5 -> 0 | I87: =SUMPRODUCT(--(I$3:I$82-$S$3:$S$82)^2)^0.5 -> 0 | J87: =SUMPRODUCT(--(J$3:J$82-$R$3:$R$82)^2)^0.5 -> 0 | K87: =SUMPRODUCT(--(K$3:K$82-$S$3:$S$82)^2)^0.5 -> 0 | L87: =SUMPRODUCT(--(L$3:L$82-$R$3:$R$82)^2)^0.5 -> 0 | M87: =SUMPRODUCT(--(M$3:M$82-$S$3:$S$82)^2)^0.5 -> 0 | N87: =SUMPRODUCT(--(N$3:N$82-$R$3:$R$82)^2)^0.5 -> 0 | O87: =SUMPRODUCT(--(O$3:O$82-$S$3:$S$82)^2)^0.5 -> 0 | P87: =SUMPRODUCT(--(P$3:P$82-$R$3:$R$82)^2)^0.5 -> 0 | Q87: =SUMPRODUCT(--(Q$3:Q$82-$S$3:$S$82)^2)^0.5 -> 0
A88: BEST | B88: =SUMPRODUCT(NOT(ISBLANK(B$3:B$82))*(B$3:B$82=$R$3:$R$82)) -> 0 | C88: =SUMPRODUCT(NOT(ISBLANK(C$3:C$82))*(C$3:C$82=$S$3:$S$82)) -> 0 | D88: =SUMPRODUCT(NOT(ISBLANK(D$3:D$82))*(D$3:D$82=$R$3:$R$82)) -> 0 | E88: =SUMPRODUCT(NOT(ISBLANK(E$3:E$82))*(E$3:E$82=$S$3:$S$82)) -> 0 | F88: =SUMPRODUCT(NOT(ISBLANK(F$3:F$82))*(F$3:F$82=$R$3:$R$82)) -> 0 | G88: =SUMPRODUCT(NOT(ISBLANK(G$3:G$82))*(G$3:G$82=$S$3:$S$82)) -> 0 | H88: =SUMPRODUCT(NOT(ISBLANK(H$3:H$82))*(H$3:H$82=$R$3:$R$82)) -> 0 | I88: =SUMPRODUCT(NOT(ISBLANK(I$3:I$82))*(I$3:I$82=$S$3:$S$82)) -> 0 | J88: =SUMPRODUCT(NOT(ISBLANK(J$3:J$82))*(J$3:J$82=$R$3:$R$82)) -> 0 | K88: =SUMPRODUCT(NOT(ISBLANK(K$3:K$82))*(K$3:K$82=$S$3:$S$82)) -> 0 | L88: =SUMPRODUCT(NOT(ISBLANK(L$3:L$82))*(L$3:L$82=$R$3:$R$82)) -> 0 | M88: =SUMPRODUCT(NOT(ISBLANK(M$3:M$82))*(M$3:M$82=$S$3:$S$82)) -> 0 | N88: =SUMPRODUCT(NOT(ISBLANK(N$3:N$82))*(N$3:N$82=$R$3:$R$82)) -> 0 | O88: =SUMPRODUCT(NOT(ISBLANK(O$3:O$82))*(O$3:O$82=$S$3:$S$82)) -> 0 | P88: =SUMPRODUCT(NOT(ISBLANK(P$3:P$82))*(P$3:P$82=$R$3:$R$82)) -> 0 | Q88: =SUMPRODUCT(NOT(ISBLANK(Q$3:Q$82))*(Q$3:Q$82=$S$3:$S$82)) -> 0
A89: BETTER | B89: =SUMPRODUCT(NOT(ISBLANK(B$3:B$82))*(B$3:B$82<$T$3:$T$82)) -> 0 | C89: =SUMPRODUCT(NOT(ISBLANK(C$3:C$82))*(C$3:C$82<$U$3:$U$82)) -> 0 | D89: =SUMPRODUCT(NOT(ISBLANK(D$3:D$82))*(D$3:D$82<$T$3:$T$82)) -> 0 | E89: =SUMPRODUCT(NOT(ISBLANK(E$3:E$82))*(E$3:E$82<$U$3:$U$82)) -> 0 | F89: =SUMPRODUCT(NOT(ISBLANK(F$3:F$82))*(F$3:F$82<$T$3:$T$82)) -> 0 | G89: =SUMPRODUCT(NOT(ISBLANK(G$3:G$82))*(G$3:G$82<$U$3:$U$82)) -> 0 | H89: =SUMPRODUCT(NOT(ISBLANK(H$3:H$82))*(H$3:H$82<$T$3:$T$82)) -> 0 | I89: =SUMPRODUCT(NOT(ISBLANK(I$3:I$82))*(I$3:I$82<$U$3:$U$82)) -> 0 | J89: =SUMPRODUCT(NOT(ISBLANK(J$3:J$82))*(J$3:J$82<$T$3:$T$82)) -> 0 | K89: =SUMPRODUCT(NOT(ISBLANK(K$3:K$82))*(K$3:K$82<$U$3:$U$82)) -> 0 | L89: =SUMPRODUCT(NOT(ISBLANK(L$3:L$82))*(L$3:L$82<$T$3:$T$82)) -> 0 | M89: =SUMPRODUCT(NOT(ISBLANK(M$3:M$82))*(M$3:M$82<$U$3:$U$82)) -> 0 | N89: =SUMPRODUCT(NOT(ISBLANK(N$3:N$82))*(N$3:N$82<$T$3:$T$82)) -> 0 | O89: =SUMPRODUCT(NOT(ISBLANK(O$3:O$82))*(O$3:O$82<$U$3:$U$82)) -> 0 | P89: =SUMPRODUCT(NOT(ISBLANK(P$3:P$82))*(P$3:P$82<$T$3:$T$82)) -> 0 | Q89: =SUMPRODUCT(NOT(ISBLANK(Q$3:Q$82))*(Q$3:Q$82<$U$3:$U$82)) -> 0
A90: WORSE | B90: =SUMPRODUCT((NOT(ISBLANK(B$3:B$82))*(B$3:B$82>$T$3:$T$82))+ISBLANK(B$3:B$82)) -> 0 | C90: =SUMPRODUCT((NOT(ISBLANK(C$3:C$82))*(C$3:C$82>$U$3:$U$82))+ISBLANK(C$3:C$82)) -> 0 | D90: =SUMPRODUCT((NOT(ISBLANK(D$3:D$82))*(D$3:D$82>$T$3:$T$82))+ISBLANK(D$3:D$82)) -> 0 | E90: =SUMPRODUCT((NOT(ISBLANK(E$3:E$82))*(E$3:E$82>$U$3:$U$82))+ISBLANK(E$3:E$82)) -> 0 | F90: =SUMPRODUCT((NOT(ISBLANK(F$3:F$82))*(F$3:F$82>$T$3:$T$82))+ISBLANK(F$3:F$82)) -> 0 | G90: =SUMPRODUCT((NOT(ISBLANK(G$3:G$82))*(G$3:G$82>$U$3:$U$82))+ISBLANK(G$3:G$82)) -> 0 | H90: =SUMPRODUCT((NOT(ISBLANK(H$3:H$82))*(H$3:H$82>$T$3:$T$82))+ISBLANK(H$3:H$82)) -> 0 | I90: =SUMPRODUCT((NOT(ISBLANK(I$3:I$82))*(I$3:I$82>$U$3:$U$82))+ISBLANK(I$3:I$82)) -> 0 | J90: =SUMPRODUCT((NOT(ISBLANK(J$3:J$82))*(J$3:J$82>$T$3:$T$82))+ISBLANK(J$3:J$82)) -> 0 | K90: =SUMPRODUCT((NOT(ISBLANK(K$3:K$82))*(K$3:K$82>$U$3:$U$82))+ISBLANK(K$3:K$82)) -> 0 | L90: =SUMPRODUCT((NOT(ISBLANK(L$3:L$82))*(L$3:L$82>$T$3:$T$82))+ISBLANK(L$3:L$82)) -> 0 | M90: =SUMPRODUCT((NOT(ISBLANK(M$3:M$82))*(M$3:M$82>$U$3:$U$82))+ISBLANK(M$3:M$82)) -> 0 | N90: =SUMPRODUCT((NOT(ISBLANK(N$3:N$82))*(N$3:N$82>$T$3:$T$82))+ISBLANK(N$3:N$82)) -> 0 | O90: =SUMPRODUCT((NOT(ISBLANK(O$3:O$82))*(O$3:O$82>$U$3:$U$82))+ISBLANK(O$3:O$82)) -> 0 | P90: =SUMPRODUCT((NOT(ISBLANK(P$3:P$82))*(P$3:P$82>$T$3:$T$82))+ISBLANK(P$3:P$82)) -> 0 | Q90: =SUMPRODUCT((NOT(ISBLANK(Q$3:Q$82))*(Q$3:Q$82>$U$3:$U$82))+ISBLANK(Q$3:Q$82)) -> 0
A91: WORST | B91: =SUMPRODUCT((NOT(ISBLANK(B$3:B$82))*(B$3:B$82=$V$3:$V$82))+ISBLANK(B$3:B$82)) -> 0 | C91: =SUMPRODUCT((NOT(ISBLANK(C$3:C$82))*(C$3:C$82=$W$3:$W$82))+ISBLANK(C$3:C$82)) -> 0 | D91: =SUMPRODUCT((NOT(ISBLANK(D$3:D$82))*(D$3:D$82=$V$3:$V$82))+ISBLANK(D$3:D$82)) -> 0 | E91: =SUMPRODUCT((NOT(ISBLANK(E$3:E$82))*(E$3:E$82=$W$3:$W$82))+ISBLANK(E$3:E$82)) -> 0 | F91: =SUMPRODUCT((NOT(ISBLANK(F$3:F$82))*(F$3:F$82=$V$3:$V$82))+ISBLANK(F$3:F$82)) -> 0 | G91: =SUMPRODUCT((NOT(ISBLANK(G$3:G$82))*(G$3:G$82=$W$3:$W$82))+ISBLANK(G$3:G$82)) -> 0 | H91: =SUMPRODUCT((NOT(ISBLANK(H$3:H$82))*(H$3:H$82=$V$3:$V$82))+ISBLANK(H$3:H$82)) -> 0 | I91: =SUMPRODUCT((NOT(ISBLANK(I$3:I$82))*(I$3:I$82=$W$3:$W$82))+ISBLANK(I$3:I$82)) -> 0 | J91: =SUMPRODUCT((NOT(ISBLANK(J$3:J$82))*(J$3:J$82=$V$3:$V$82))+ISBLANK(J$3:J$82)) -> 0 | K91: =SUMPRODUCT((NOT(ISBLANK(K$3:K$82))*(K$3:K$82=$W$3:$W$82))+ISBLANK(K$3:K$82)) -> 0 | L91: =SUMPRODUCT((NOT(ISBLANK(L$3:L$82))*(L$3:L$82=$V$3:$V$82))+ISBLANK(L$3:L$82)) -> 0 | M91: =SUMPRODUCT((NOT(ISBLANK(M$3:M$82))*(M$3:M$82=$W$3:$W$82))+ISBLANK(M$3:M$82)) -> 0 | N91: =SUMPRODUCT((NOT(ISBLANK(N$3:N$82))*(N$3:N$82=$V$3:$V$82))+ISBLANK(N$3:N$82)) -> 0 | O91: =SUMPRODUCT((NOT(ISBLANK(O$3:O$82))*(O$3:O$82=$W$3:$W$82))+ISBLANK(O$3:O$82)) -> 0 | P91: =SUMPRODUCT((NOT(ISBLANK(P$3:P$82))*(P$3:P$82=$V$3:$V$82))+ISBLANK(P$3:P$82)) -> 0 | Q91: =SUMPRODUCT((NOT(ISBLANK(Q$3:Q$82))*(Q$3:Q$82=$W$3:$W$82))+ISBLANK(Q$3:Q$82)) -> 0

Sheet Merged Runs
A1: Merge criteria: | B1: coomsuite-1.0.0/clingo-base | D1: coomsuite-1.0.0/clingo-bounds-exponential | F1: coomsuite-1.0.0/clingo-bounds-linear | H1: coomsuite-1.0.0/flingo-base | J1: coomsuite-1.0.0/flingo-bounds-exponential | L1: coomsuite-1.0.0/flingo-bounds-linear | N1: coomsuite-1.0.0/multishot-exponential | P1: coomsuite-1.0.0/multishot-linear | R1: min | T1: median | V1: max
A2: median | B2: time | C2: timeout | D2: time | E2: timeout | F2: time | G2: timeout | H2: time | I2: timeout | J2: time | K2: timeout | L2: time | M2: timeout | N2: time | O2: timeout | P2: time | Q2: timeout | R2: time | S2: timeout | T2: time | U2: timeout | V2: time | W2: timeout
A3: ./travelbike-max10_user-input-p155-v655 | B3: {=_xlfn.SWITCH($A$2,"average", AVERAGE(Instances!B3:Instances!B3),"median", MEDIAN(Instances!B3:Instances!B3),"min", MIN(Instances!B3:Instances!B3),"max", MAX(Instances!B3:Instances!B3),"diff", MAX(Instances!B3:Instances!B3)-MIN(Instances!B3:Instances!B3))} -> 0 | C3: {=_xlfn.SWITCH($A$2,"average", AVERAGE(Instances!C3:Instances!C3),"median", MEDIAN(Instances!C3:Instances!C3),"min", MIN(Instances!C3:Instances!C3),"max", MAX(Instances!C3:Instances!C3),"diff", MAX(Instances!C3:Instances!C3)-MIN(Instances!C3:Instances!C3))} -> 0 | H3: {=_xlfn.SWITCH($A$2,"average", AVERAGE(Instances!H3:Instances!H3),"median", MEDIAN(Instances!H3:Instances!H3),"min", MIN(Instances!H3:Instances!H3),"max", MAX(Instances!H3:Instances!H3),"diff", MAX(Instances!H3:Instances!H3)-MIN(Instances!H3:Instances!H3))} -> 0 | I3: {=_xlfn.SWITCH($A$2,"average", AVERAGE(Instances!I3:Instances!I3),"median", MEDIAN(Instances!I3:Instances!I3),"min", MIN(Instances!I3:Instances!I3),"max", MAX(Instances!I3:Instances!I3),"diff", MAX(Instances!I3:Instances!I3)-MIN(Instances!I3:Instances!I3))} -> 0 | R3: =MIN($B3,$D3,$F3,$H3,$J3,$L3,$N3,$P3) -> 0 | S3: =MIN($C3,$E3,$G3,$I3,$K3,$M3,$O3,$Q3) -> 0 | T3: =MEDIAN($B3,$D3,$F3,$H3,$J3,$L3,$N3,$P3) -> 0 | U3: =MEDIAN($C3,$E3,$G3,$I3,$K3,$M3,$O3,$Q3) -> 0 | V3: =MAX($B3,$D3,$F3,$H3,$J3,$L3,$N3,$P3) -> 0 | W3: =MAX($C3,$E3,$G3,$I3,$K3,$M3,$O3,$Q3) -> 0
A4: ./travelbike-max10_user-input-p163-v220 | B4: {=_xlfn.SWITCH($A$2,"average", AVERAGE(Instances!B4:Instances!B4),"median", MEDIAN(Instances!B4:Instances!B4),"min", MIN(Instances!B4:Instances!B4),"max", MAX(Instances!B4:Instances!B4),"diff", MAX(Instances!B4:Instances!B4)-MIN(Instances!B4:Instances!B4))} -> 0 | C4: {=_xlfn.SWITCH($A$2,"average", AVERAGE(Instances!C4:Instances!C4),"median", MEDIAN(Instances!C4:Instances!C4),"min", MIN(Instances!C4:Instances!C4),"max", MAX(Instances!C4:Instances!C4),"diff", MAX(Instances!C4:Instances!C4)-MIN(Instances!C4:Instances!C4))} -> 0 | H4: {=_xlfn.SWITCH($A$2,"average", AVERAGE(Instances!H4:Instances!H4),"median", MEDIAN(Instances!H4:Instances!H4),"min", MIN(Instances!H4:Instances!H4),"max", MAX(Instances!H4:Instances!H4),"diff", MAX(Instances!H4:Instances!H4)-MIN(Instances!H4:Instances!H4))} -> 0 | I4: {=_xlfn.SWITCH($A$2,"average", AVERAGE(Instances!I4:Instances!I4),"median", MEDIAN(Instances!I4:Instances!I4),"min", MIN(Instances!I4:Instances!I4),"max", MAX(Instances!I4:Instances!I4),"diff", MAX(Instances!I4:Instances!I4)-MIN(Instances!I4:Instances!I4))} -> 0 | R4: =MIN($B4,$D4,$F4,$H4,$J4,$L4,$N4,$P4) -> 0 | S4: =MIN($C4,$E4,$G4,$I4,$K4,$M4,$O4,$Q4) -> 0 | T4: =MEDIAN($B4,$D4,$F4,$H4,$J4,$L4,$N4,$P4) -> 0 | U4: =MEDIAN($C4,$E4,$G4,$I4,$K4,$M4,$O4,$Q4) -> 0 | V4: =MAX($B4,$D4,$F4,$H4,$J4,$L4,$N4,$P4) -> 0 | W4: =MAX($C4,$E4,$G4,$I4,$K4,$M4,$O4,$Q4) -> 0
A5: ./travelbike-max10_user-input-p312-v851 | B5: {=_xlfn.SWITCH($A$2,"average", AVERAGE(Instances!B5:Instances!B5),"median", MEDIAN(Instances!B5:Instances!B5),"min", MIN(Instances!B5:Instances!B5),"max", MAX(Instances!B5:Instances!B5),"diff", MAX(Instances!B5:Instances!B5)-MIN(Instances!B5:Instances!B5))} -> 0 | C5: {=_xlfn.SWITCH($A$2,"average", AVERAGE(Instances!C5:Instances!C5),"median", MEDIAN(Instances!C5:Instances!C5),"min", MIN(Instances!C5:Instances!C5),"max", MAX(Instances!C5:Instances!C5),"diff", MAX(Instances!C5:Instances!C5)-MIN(Instances!C5:Instances!C5))} -> 0 | H5: {=_xlfn.SWITCH($A$2,"average", AVERAGE(Instances!H5:Instances!H5),"median", MEDIAN(Instances!H5:Instances!H5),"min", MIN(Instances!H5:Instances!H5),"max", MAX(Instances!H5:Instances!H5),"diff", MAX(Instances!H5:Instances!H5)-MIN(Instances!H5:Instances!H5))} -> 0 | I5: {=_xlfn.SWITCH($A$2,"average", AVERAGE(Instances!I5:Instances!I5),"median", MEDIAN(Instances!I5:Instances!I5),"min", MIN(Instances!I5:Instances!I5),"max", MAX(Instances!I5:Instances!I5),"diff", MAX(Instances!I5:Instances!I5)-MIN(Instances!I5:Instances!I5))} -> 0 | R5: =MIN($B5,$D5,$F5,$H5,$J5,$L5,$N5,$P5) -> 0 | S5: =MIN($C5,$E5,$G5,$I5,$K5,$M5,$O5,$Q5) -> 0 | T5: =MEDIAN($B5,$D5,$F5,$H5,$J5,$L5,$N5,$P5) -> 0 | U5: =MEDIAN($C5,$E5,$G5,$I5,$K5,$M5,$O5,$Q5) -> 0 | V5: =MAX($B5,$D5,$F5,$H5,$J5,$L5,$N5,$P5) -> 0 | W5: =MAX($C5,$E5,$G5,$I5,$K5,$M5,$O5,$Q5) -> 0
A6: ./travelbike-max10_user-input-p317-v561 | B6: {=_xlfn.SWITCH($A$2,"average", AVERAGE(Instances!B6:Instances!B6),"median", MEDIAN(Instances!B6:Instances!B6),"min", MIN(Instances!B6:Instances!B6),"max", MAX(Instances!B6:Instances!B6),"diff", MAX(Instances!B6:Instances!B6)-MIN(Instances!B6:Instances!B6))} -> 0 | C6: {=_xlfn.SWITCH($A$2,"average", AVERAGE(Instances!C6:Instances!C6),"median", MEDIAN(Instances!C6:Instances!C6),"min", MIN(Instances!C6:Instances!C6),"max", MAX(Instances!C6:Instances!C6),"diff", MAX(Instances!C6:Instances!C6)-MIN(Instances!C6:Instances!C6))} -> 0 | H6: {=_xlfn.SWITCH($A$2,"average", AVERAGE(Instances!H6:Instances!H6),"median", MEDIAN(Instances!H6:Instances!H6),"min", MIN(Instances!H6:Instances!H6),"max", MAX(Instances!H6:Instances!H6),"diff", MAX(Instances!H6:Instances!H6)-MIN(Instances!H6:Instances!H6))} -> 0 | I6: {=_xlfn.SWITCH($A$2,"average", AVERAGE(Instances!I6:Instances!I6),"median", MEDIAN(Instances!I6:Instances!I6),"min", MIN(Instances!I6:Instances!I6),"max", MAX(Instances!I6:Instances!I6),"diff", MAX(Instances!I6:Instances!I6)-MIN(Instances!I6:Instances!I6))} -> 0 | R6: =MIN($B6,$D6,$F6,$H6,$J6,$L6,$N6,$P6) -> 0 | S6: =MIN($C6,$E6,$G6,$I6,$K6,$M6,$O6,$Q6) -> 0 | T6: =MEDIAN($B6,$D6,$F6,$H6,$J6,$L6,$N6,$P6) -> 0 | U6: =MEDIAN($C6,$E6,$G6,$I6,$K6,$M6,$O6,$Q6) -> 0 | V6: =MAX($B6,$D6,$F6,$H6,$J6,$L6,$N6,$P6) -> 0 | W6: =MAX($C6,$E6,$G6,$I6,$K6,$M6,$O6,$Q6) -> 0
A7: ./travelbike-max10_user-input-p434-v422 | B7: {=_xlfn.SWITCH($A$2,"average", AVERAGE(Instances!B7:Instances!B7),"median", MEDIAN(Instances!B7:Instances!B7),"min", MIN(Instances!B7:Instances!B7),"max", MAX(Instances!B7:Instances!B7),"diff", MAX(Instances!B7:Instances!B7)-MIN(Instances!B7:Instances!B7))} -> 0 | C7: {=_xlfn.SWITCH($A$2,"average", AVERAGE(Instances!C7:Instances!C7),"median", MEDIAN(Instances!C7:Instances!C7),"min", MIN(Instances!C7:Instances!C7),"max", MAX(Instances!C7:Instances!C7),"diff", MAX(Instances!C7:Instances!C7)-MIN(Instances!C7:Instances!C7))} -> 0 | H7: {=_xlfn.SWITCH($A$2,"average", AVERAGE(Instances!H7:Instances!H7),"median", MEDIAN(Instances!H7:Instances!H7),"min", MIN(Instances!H7:Instances!H7),"max", MAX(Instances!H7:Instances!H7),"diff", MAX(Instances!H7:Instances!H7)-MIN(Instances!H7:Instances!H7))} -> 0 | I7: {=_xlfn.SWITCH($A$2,"average", AVERAGE(Instances!I7:Instances!I7),"median", MEDIAN(Instances!I7:Instances!I7),"min", MIN(Instances!I7:Instances!I7),"max", MAX(Instances!I7:Instances!I7),"diff", MAX(Instances!I7:Instances!I7)-MIN(Instances!I7:Instances!I7))} -> 0 | R7: =MIN($B7,$D7,$F7,$H7,$J7,$L7,$N7,$P7) -> 0 | S7: =MIN($C7,$E7,$G7,$I7,$K7,$M7,$O7,$Q7) -> 0 | T7: =MEDIAN($B7,$D7,$F7,$H7,$J7,$L7,$N7,$P7) -> 0 | U7: =MEDIAN($C7,$E7,$G7,$I7,$K7,$M7,$O7,$Q7) -> 0 | V7: =MAX($B7,$D7,$F7,$H7,$J7,$L7,$N7,$P7) -> 0 | W7: =MAX($C7,$E7,$G7,$I7,$K7,$M7,$O7,$Q7) -> 0
A8: ./travelbike-max10_user-input-p619-v924 | B8: {=_xlfn.SWITCH($A$2,"average", AVERAGE(Instances!B8:Instances!B8),"median", MEDIAN(Instances!B8:Instances!B8),"min", MIN(Instances!B8:Instances!B8),"max", MAX(Instances!B8:Instances!B8),"diff", MAX(Instances!B8:Instances!B8)-MIN(Instances!B8:Instances!B8))} -> 0 | C8: {=_xlfn.SWITCH($A$2,"average", AVERAGE(Instances!C8:Instances!C8),"median", MEDIAN(Instances!C8:Instances!C8),"min", MIN(Instances!C8:Instances!C8),"max", MAX(Instances!C8:Instances!C8),"diff", MAX(Instances!C8:Instances!C8)-MIN(Instances!C8:Instances!C8))} -> 0 | H8: {=_xlfn.SWITCH($A$2,"average", AVERAGE(Instances!H8:Instances!H8),"median", MEDIAN(Instances!H8:Instances!H8),"min", MIN(Instances!H8:Instances!H8),"max", MAX(Instances!H8:Instances!H8),"diff", MAX(Instances!H8:Instances!H8)-MIN(Instances!H8:Instances!H8))} -> 0 | I8: {=_xlfn.SWITCH($A$2,"average", AVERAGE(Instances!I8:Instances!I8),"median", MEDIAN(Instances!I8:Instances!I8),"min", MIN(Instances!I8:Instances!I8),"max", MAX(Instances!I8:Instances!I8),"diff", MAX(Instances!I8:Instances!I8)-MIN(Instances!I8:Instances!I8))} -> 0 | R8: =MIN($B8,$D8,$F8,$H8,$J8,$L8,$N8,$P8) -> 0 | S8: =MIN($C8,$E8,$G8,$I8,$K8,$M8,$O8,$Q8) -> 0 | T8: =MEDIAN($B8,$D8,$F8,$H8,$J8,$L8,$N8,$P8) -> 0 | U8: =MEDIAN($C8,$E8,$G8,$I8,$K8,$M8,$O8,$Q8) -> 0 | V8: =MAX($B8,$D8,$F8,$H8,$J8,$L8,$N8,$P8) -> 0 | W8: =MAX($C8,$E8,$G8,$I8,$K8,$M8,$O8,$Q8) -> 0
A9: ./travelbike-max10_user-input-p847-v390 | B9: {=_xlfn.SWITCH($A$2,"average", AVERAGE(Instances!B9:Instances!B9),"median", MEDIAN(Instances!B9:Instances!B9),"min", MIN(Instances!B9:Instances!B9),"max", MAX(Instances!B9:Instances!B9),"diff", MAX(Instances!B9:Instances!B9)-MIN(Instances!B9:Instances!B9))} -> 0 | C9: {=_xlfn.SWITCH($A$2,"average", AVERAGE(Instances!C9:Instances!C9),"median", MEDIAN(Instances!C9:Instances!C9),"min", MIN(Instances!C9:Instances!C9),"max", MAX(Instances!C9:Instances!C9),"diff", MAX(Instances!C9:Instances!C9)-MIN(Instances!C9:Instances!C9))} -> 0 | H9: {=_xlfn.SWITCH($A$2,"average", AVERAGE(Instances!H9:Instances!H9),"median", MEDIAN(Instances!H9:Instances!H9),"min", MIN(Instances!H9:Instances!H9),"max", MAX(Instances!H9:Instances!H9),"diff", MAX(Instances!H9:Instances!H9)-MIN(Instances!H9:Instances!H9))} -> 0 | I9: {=_xlfn.SWITCH($A$2,"average", AVERAGE(Instances!I9:Instances!I9),"median", MEDIAN(Instances!I9:Instances!I9),"min", MIN(Instances!I9:Instances!I9),"max", MAX(Instances!I9:Instances!I9),"diff", MAX(Instances!I9:Instances!I9)-MIN(Instances!I9:Instances!I9))} -> 0 | R9: =MIN($B9,$D9,$F9,$H9,$J9,$L9,$N9,$P9) -> 0 | S9: =MIN($C9,$E9,$G9,$I9,$K9,$M9,$O9,$Q9) -> 0 | T9: =MEDIAN($B9,$D9,$F9,$H9,$J9,$L9,$N9,$P9) -> 0 | U9: =MEDIAN($C9,$E9,$G9,$I9,$K9,$M9,$O9,$Q9) -> 0 | V9: =MAX($B9,$D9,$F9,$H9,$J9,$L9,$N9,$P9) -> 0 | W9: =MAX($C9,$E9,$G9,$I9,$K9,$M9,$O9,$Q9) -> 0
A10: ./travelbike-max10_user-input-p872-v959 | B10: {=_xlfn.SWITCH($A$2,"average", AVERAGE(Instances!B10:Instances!B10),"median", MEDIAN(Instances!B10:Instances!B10),"min", MIN(Instances!B10:Instances!B10),"max", MAX(Instances!B10:Instances!B10),"diff", MAX(Instances!B10:Instances!B10)-MIN(Instances!B10:Instances!B10))} -> 0 | C10: {=_xlfn.SWITCH($A$2,"average", AVERAGE(Instances!C10:Instances!C10),"median", MEDIAN(Instances!C10:Instances!C10),"min", MIN(Instances!C10:Instances!C10),"max", MAX(Instances!C10:Instances!C10),"diff", MAX(Instances!C10:Instances!C10)-MIN(Instances!C10:Instances!C10))} -> 0 | H10: {=_xlfn.SWITCH($A$2,"average", AVERAGE(Instances!H10:Instances!H10),"median", MEDIAN(Instances!H10:Instances!H10),"min", MIN(Instances!H10:Instances!H10),"max", MAX(Instances!H10:Instances!H10),"diff", MAX(Instances!H10:Instances!H10)-MIN(Instances!H10:Instances!H10))} -> 0 | I10: {=_xlfn.SWITCH($A$2,"average", AVERAGE(Instances!I10:Instances!I10),"median", MEDIAN(Instances!I10:Instances!I10),"min", MIN(Instances!I10:Instances!I10),"max", MAX(Instances!I10:Instances!I10),"diff", MAX(Instances!I10:Instances!I10)-MIN(Instances!I10:Instances!I10))} -> 0 | R10: =MIN($B10,$D10,$F10,$H10,$J10,$L10,$N10,$P10) -> 0 | S10: =MIN($C10,$E10,$G10,$I10,$K10,$M10,$O10,$Q10) -> 0 | T10: =MEDIAN($B10,$D10,$F10,$H10,$J10,$L10,$N10,$P10) -> 0 | U10: =MEDIAN($C10,$E10,$G10,$I10,$K10,$M10,$O10,$Q10) -> 0 | V10: =MAX($B10,$D10,$F10,$H10,$J10,$L10,$N10,$P10) -> 0 | W10: =MAX($C10,$E10,$G10,$I10,$K10,$M10,$O10,$Q10) -> 0
A11: ./travelbike-max10_user-input-p930-v649 | B11: {=_xlfn.SWITCH($A$2,"average", AVERAGE(Instances!B11:Instances!B11),"median", MEDIAN(Instances!B11:Instances!B11),"min", MIN(Instances!B11:Instances!B11),"max", MAX(Instances!B11:Instances!B11),"diff", MAX(Instances!B11:Instances!B11)-MIN(Instances!B11:Instances!B11))} -> 0 | C11: {=_xlfn.SWITCH($A$2,"average", AVERAGE(Instances!C11:Instances!C11),"median", MEDIAN(Instances!C11:Instances!C11),"min", MIN(Instances!C11:Instances!C11),"max", MAX(Instances!C11:Instances!C11),"diff", MAX(Instances!C11:Instances!C11)-MIN(Instances!C11:Instances!C11))} -> 0 | H11: {=_xlfn.SWITCH($A$2,"average", AVERAGE(Instances!H11:Instances!H11),"median", MEDIAN(Instances!H11:Instances!H11),"min", MIN(Instances!H11:Instances!H11),"max", MAX(Instances!H11:Instances!H11),"diff", MAX(Instances!H11:Instances!H11)-MIN(Instances!H11:Instances!H11))} -> 0 | I11: {=_xlfn.SWITCH($A$2,"average", AVERAGE(Instances!I11:Instances!I11),"median", MEDIAN(Instances!I11:Instances!I11),"min", MIN(Instances!I11:Instances!I11),"max", MAX(Instances!I11:Instances!I11),"diff", MAX(Instances!I11:Instances!I11)-MIN(Instances!I11:Instances!I11))} -> 0 | R11: =MIN($B11,$D11,$F11,$H11,$J11,$L11,$N11,$P11) -> 0 | S11: =MIN($C11,$E11,$G11,$I11,$K11,$M11,$O11,$Q11) -> 0 | T11: =MEDIAN($B11,$D11,$F11,$H11,$J11,$L11,$N11,$P11) -> 0 | U11: =MEDIAN($C11,$E11,$G11,$I11,$K11,$M11,$O11,$Q11) -> 0 | V11: =MAX($B11,$D11,$F11,$H11,$J11,$L11,$N11,$P11) -> 0 | W11: =MAX($C11,$E11,$G11,$I11,$K11,$M11,$O11,$Q11) -> 0
A12: ./travelbike-max10_user-input-p991-v163 | B12: {=_xlfn.SWITCH($A$2,"average", AVERAGE(Instances!B12:Instances!B12),"median", MEDIAN(Instances!B12:Instances!B12),"min", MIN(Instances!B12:Instances!B12),"max", MAX(Instances!B12:Instances!B12),"diff", MAX(Instances!B12:Instances!B12)-MIN(Instances!B12:Instances!B12))} -> 0 | C12: {=_xlfn.SWITCH($A$2,"average", AVERAGE(Instances!C12:Instances!C12),"median", MEDIAN(Instances!C12:Instances!C12),"min", MIN(Instances!C12:Instances!C12),"max", MAX(Instances!C12:Instances!C12),"diff", MAX(Instances!C12:Instances!C12)-MIN(Instances!C12:Instances!C12))} -> 0 | H12: {=_xlfn.SWITCH($A$2,"average", AVERAGE(Instances!H12:Instances!H12),"median", MEDIAN(Instances!H12:Instances!H12),"min", MIN(Instances!H12:Instances!H12),"max", MAX(Instances!H12:Instances!H12),"diff", MAX(Instances!H12:Instances!H12)-MIN(Instances!H12:Instances!H12))} -> 0 | I12: {=_xlfn.SWITCH($A$2,"average", AVERAGE(Instances!I12:Instances!I12),"median", MEDIAN(Instances!I12:Instances!I12),"min", MIN(Instances!I12:Instances!I12),"max", MAX(Instances!I12:Instances!I12),"diff", MAX(Instances!I12:Instances!I12)-MIN(Instances!I12:Instances!I12))} -> 0 | R12: =MIN($B12,$D12,$F12,$H12,$J12,$L12,$N12,$P12) -> 0 | S12: =MIN($C12,$E12,$G12,$I12,$K12,$M12,$O12,$Q12) -> 0 | T12: =MEDIAN($B12,$D12,$F12,$H12,$J12,$L12,$N12,$P12) -> 0 | U12: =MEDIAN($C12,$E12,$G12,$I12,$K12,$M12,$O12,$Q12) -> 0 | V12: =MAX($B12,$D12,$F12,$H12,$J12,$L12,$N12,$P12) -> 0 | W12: =MAX($C12,$E12,$G12,$I12,$K12,$M12,$O12,$Q12) -> 0
A13: ./travelbike-max15_user-input-p1004-v748 | B13: {=_xlfn.SWITCH($A$2,"average", AVERAGE(Instances!B13:Instances!B13),"median", MEDIAN(Instances!B13:Instances!B13),"min", MIN(Instances!B13:Instances!B13),"max", MAX(Instances!B13:Instances!B13),"diff", MAX(Instances!B13:Instances!B13)-MIN(Instances!B13:Instances!B13))} -> 0 | C13: {=_xlfn.SWITCH($A$2,"average", AVERAGE(Instances!C13:Instances!C13),"median", MEDIAN(Instances!C13:Instances!C13),"min", MIN(Instances!C13:Instances!C13),"max", MAX(Instances!C13:Instances!C13),"diff", MAX(Instances!C13:Instances!C13)-MIN(Instances!C13:Instances!C13))} -> 0 | H13: {=_xlfn.SWITCH($A$2,"average", AVERAGE(Instances!H13:Instances!H13),"median", MEDIAN(Instances!H13:Instances!H13),"min", MIN(Instances!H13:Instances!H13),"max", MAX(Instances!H13:Instances!H13),"diff", MAX(Instances!H13:Instances!H13)-MIN(Instances!H13:Instances!H13))} -> 0 | I13: {=_xlfn.SWITCH($A$2,"average", AVERAGE(Instances!I13:Instances!I13),"median", MEDIAN(Instances!I13:Instances!I13),"min", MIN(Instances!I13:Instances!I13),"max", MAX(Instances!I13:Instances!I13),"diff", MAX(Instances!I13:Instances!I13)-MIN(Instances!I13:Instances!I13))} -> 0 | R13: =MIN($B13,$D13,$F13,$H13,$J13,$L13,$N13,$P13) -> 0 | S13: =MIN($C13,$E13,$G13,$I13,$K13,$M13,$O13,$Q13) -> 0 | T13: =MEDIAN($B13,$D13,$F13,$H13,$J13,$L13,$N13,$P13) -> 0 | U13: =MEDIAN($C13,$E13,$G13,$I13,$K13,$M13,$O13,$Q13) -> 0 | V13: =MAX($B13,$D13,$F13,$H13,$J13,$L13,$N13,$P13) -> 0 | W13: =MAX($C13,$E13,$G13,$I13,$K13,$M13,$O13,$Q13) -> 0
A14: ./travelbike-max15_user-input-p1038-v167 | B14: {=_xlfn.SWITCH($A$2,"average", AVERAGE(Instances!B14:Instances!B14),"median", MEDIAN(Instances!B14:Instances!B14),"min", MIN(Instances!B14:Instances!B14),"max", MAX(Instances!B14:Instances!B14),"diff", MAX(Instances!B14:Instances!B14)-MIN(Instances!B14:Instances!B14))} -> 0 | C14: {=_xlfn.SWITCH($A$2,"average", AVERAGE(Instances!C14:Instances!C14),"median", MEDIAN(Instances!C14:Instances!C14),"min", MIN(Instances!C14:Instances!C14),"max", MAX(Instances!C14:Instances!C14),"diff", MAX(Instances!C14:Instances!C14)-MIN(Instances!C14:Instances!C14))} -> 0 | H14: {=_xlfn.SWITCH($A$2,"average", AVERAGE(Instances!H14:Instances!H14),"median", MEDIAN(Instances!H14:Instances!H14),"min", MIN(Instances!H14:Instances!H14),"max", MAX(Instances!H14:Instances!H14),"diff", MAX(Instances!H14:Instances!H14)-MIN(Instances!H14:Instances!H14))} -> 0 | I14: {=_xlfn.SWITCH($A$2,"average", AVERAGE(Instances!I14:Instances!I14),"median", MEDIAN(Instances!I14:Instances!I14),"min", MIN(Instances!I14:Instances!I14),"max", MAX(Instances!I14:Instances!I14),"diff", MAX(Instances!I14:Instances!I14)-MIN(Instances!I14:Instances!I14))} -> 0 | R14: =MIN($B14,$D14,$F14,$H14,$J14,$L14,$N14,$P14) -> 0 | S14: =MIN($C14,$E14,$G14,$I14,$K14,$M14,$O14,$Q14) -> 0 | T14: =MEDIAN($B14,$D14,$F14,$H14,$J14,$L14,$N14,$P14) -> 0 | U14: =MEDIAN($C14,$E14,$G14,$I14,$K14,$M14,$O14,$Q14) -> 0 | V14: =MAX($B14,$D14,$F14,$H14,$J14,$L14,$N14,$P14) -> 0 | W14: =MAX($C14,$E14,$G14,$I14,$K14,$M14,$O14,$Q14) -> 0
... A42: ./travelbike-max5_user-input-p82-v294 | B42: {=_xlfn.SWITCH($A$2,"average", AVERAGE(Instances!B42:Instances!B42),"median", MEDIAN(Instances!B42:Instances!B42),"min", MIN(Instances!B42:Instances!B42),"max", MAX(Instances!B42:Instances!B42),"diff", MAX(Instances!B42:Instances!B42)-MIN(Instances!B42:Instances!B42))} -> 0 | C42: {=_xlfn.SWITCH($A$2,"average", AVERAGE(Instances!C42:Instances!C42),"median", MEDIAN(Instances!C42:Instances!C42),"min", MIN(Instances!C42:Instances!C42),"max", MAX(Instances!C42:Instances!C42),"diff", MAX(Instances!C42:Instances!C42)-MIN(Instances!C42:Instances!C42))} -> 0 | H42: {=_xlfn.SWITCH($A$2,"average", AVERAGE(Instances!H42:Instances!H42),"median", MEDIAN(Instances!H42:Instances!H42),"min", MIN(Instances!H42:Instances!H42),"max", MAX(Instances!H42:Instances!H42),"diff", MAX(Instances!H42:Instances!H42)-MIN(Instances!H42:Instances!H42))} -> 0 | I42: {=_xlfn.SWITCH($A$2,"average", AVERAGE(Instances!I42:Instances!I42),"median", MEDIAN(Instances!I42:Instances!I42),"min", MIN(Instances!I42:Instances!I42),"max", MAX(Instances!I42:Instances!I42),"diff", MAX(Instances!I42:Instances!I42)-MIN(Instances!I42:Instances!I42))} -> 0 | R42: =MIN($B42,$D42,$F42,$H42,$J42,$L42,$N42,$P42) -> 0 | S42: =MIN($C42,$E42,$G42,$I42,$K42,$M42,$O42,$Q42) -> 0 | T42: =MEDIAN($B42,$D42,$F42,$H42,$J42,$L42,$N42,$P42) -> 0 | U42: =MEDIAN($C42,$E42,$G42,$I42,$K42,$M42,$O42,$Q42) -> 0 | V42: =MAX($B42,$D42,$F42,$H42,$J42,$L42,$N42,$P42) -> 0 | W42: =MAX($C42,$E42,$G42,$I42,$K42,$M42,$O42,$Q42) -> 0
A43: ./travelbike-max10_user-input-p155-v655 | D43: {=_xlfn.SWITCH($A$2,"average", AVERAGE(Instances!D43:Instances!D43),"median", MEDIAN(Instances!D43:Instances!D43),"min", MIN(Instances!D43:Instances!D43),"max", MAX(Instances!D43:Instances!D43),"diff", MAX(Instances!D43:Instances!D43)-MIN(Instances!D43:Instances!D43))} -> 0 | E43: {=_xlfn.SWITCH($A$2,"average", AVERAGE(Instances!E43:Instances!E43),"median", MEDIAN(Instances!E43:Instances!E43),"min", MIN(Instances!E43:Instances!E43),"max", MAX(Instances!E43:Instances!E43),"diff", MAX(Instances!E43:Instances!E43)-MIN(Instances!E43:Instances!E43))} -> 0 | F43: {=_xlfn.SWITCH($A$2,"average", AVERAGE(Instances!F43:Instances!F43),"median", MEDIAN(Instances!F43:Instances!F43),"min", MIN(Instances!F43:Instances!F43),"max", MAX(Instances!F43:Instances!F43),"diff", MAX(Instances!F43:Instances!F43)-MIN(Instances!F43:Instances!F43))} -> 0 | G43: {=_xlfn.SWITCH($A$2,"average", AVERAGE(Instances!G43:Instances!G43),"median", MEDIAN(Instances!G43:Instances!G43),"min", MIN(Instances!G43:Instances!G43),"max", MAX(Instances!G43:Instances!G43),"diff", MAX(Instances!G43:Instances!G43)-MIN(Instances!G43:Instances!G43))} -> 0 | J43: {=_xlfn.SWITCH($A$2,"average", AVERAGE(Instances!J43:Instances!J43),"median", MEDIAN(Instances!J43:Instances!J43),"min", MIN(Instances!J43:Instances!J43),"max", MAX(Instances!J43:Instances!J43),"diff", MAX(Instances!J43:Instances!J43)-MIN(Instances!J43:Instances!J43))} -> 0 | K43: {=_xlfn.SWITCH($A$2,"average", AVERAGE(Instances!K43:Instances!K43),"median", MEDIAN(Instances!K43:Instances!K43),"min", MIN(Instances!K43:Instances!K43),"max", MAX(Instances!K43:Instances!K43),"diff", MAX(Instances!K43:Instances!K43)-MIN(Instances!K43:Instances!K43))} -> 0 | L43: {=_xlfn.SWITCH($A$2,"average", AVERAGE(Instances!L43:Instances!L43),"median", MEDIAN(Instances!L43:Instances!L43),"min", MIN(Instances!L43:Instances!L43),"max", MAX(Instances!L43:Instances!L43),"diff", MAX(Instances!L43:Instances!L43)-MIN(Instances!L43:Instances!L43))} -> 0 | M43: {=_xlfn.SWITCH($A$2,"average", AVERAGE(Instances!M43:Instances!M43),"median", MEDIAN(Instances!M43:Instances!M43),"min", MIN(Instances!M43:Instances!M43),"max", MAX(Instances!M43:Instances!M43),"diff", MAX(Instances!M43:Instances!M43)-MIN(Instances!M43:Instances!M43))} -> 0 | N43: {=_xlfn.SWITCH($A$2,"average", AVERAGE(Instances!N43:Instances!N43),"median", MEDIAN(Instances!N43:Instances!N43),"min", MIN(Instances!N43:Instances!N43),"max", MAX(Instances!N43:Instances!N43),"diff", MAX(Instances!N43:Instances!N43)-MIN(Instances!N43:Instances!N43))} -> 0 | O43: {=_xlfn.SWITCH($A$2,"average", AVERAGE(Instances!O43:Instances!O43),"median", MEDIAN(Instances!O43:Instances!O43),"min", MIN(Instances!O43:Instances!O43),"max", MAX(Instances!O43:Instances!O43),"diff", MAX(Instances!O43:Instances!O43)-MIN(Instances!O43:Instances!O43))} -> 0 | P43: {=_xlfn.SWITCH($A$2,"average", AVERAGE(Instances!P43:Instances!P43),"median", MEDIAN(Instances!P43:Instances!P43),"min", MIN(Instances!P43:Instances!P43),"max", MAX(Instances!P43:Instances!P43),"diff", MAX(Instances!P43:Instances!P43)-MIN(Instances!P43:Instances!P43))} -> 0 | Q43: {=_xlfn.SWITCH($A$2,"average", AVERAGE(Instances!Q43:Instances!Q43),"median", MEDIAN(Instances!Q43:Instances!Q43),"min", MIN(Instances!Q43:Instances!Q43),"max", MAX(Instances!Q43:Instances!Q43),"diff", MAX(Instances!Q43:Instances!Q43)-MIN(Instances!Q43:Instances!Q43))} -> 0 | R43: =MIN($B43,$D43,$F43,$H43,$J43,$L43,$N43,$P43) -> 0 | S43: =MIN($C43,$E43,$G43,$I43,$K43,$M43,$O43,$Q43) -> 0 | T43: =MEDIAN($B43,$D43,$F43,$H43,$J43,$L43,$N43,$P43) -> 0 | U43: =MEDIAN($C43,$E43,$G43,$I43,$K43,$M43,$O43,$Q43) -> 0 | V43: =MAX($B43,$D43,$F43,$H43,$J43,$L43,$N43,$P43) -> 0 | W43: =MAX($C43,$E43,$G43,$I43,$K43,$M43,$O43,$Q43) -> 0
A44: ./travelbike-max10_user-input-p163-v220 | D44: {=_xlfn.SWITCH($A$2,"average", AVERAGE(Instances!D44:Instances!D44),"median", MEDIAN(Instances!D44:Instances!D44),"min", MIN(Instances!D44:Instances!D44),"max", MAX(Instances!D44:Instances!D44),"diff", MAX(Instances!D44:Instances!D44)-MIN(Instances!D44:Instances!D44))} -> 0 | E44: {=_xlfn.SWITCH($A$2,"average", AVERAGE(Instances!E44:Instances!E44),"median", MEDIAN(Instances!E44:Instances!E44),"min", MIN(Instances!E44:Instances!E44),"max", MAX(Instances!E44:Instances!E44),"diff", MAX(Instances!E44:Instances!E44)-MIN(Instances!E44:Instances!E44))} -> 0 | F44: {=_xlfn.SWITCH($A$2,"average", AVERAGE(Instances!F44:Instances!F44),"median", MEDIAN(Instances!F44:Instances!F44),"min", MIN(Instances!F44:Instances!F44),"max", MAX(Instances!F44:Instances!F44),"diff", MAX(Instances!F44:Instances!F44)-MIN(Instances!F44:Instances!F44))} -> 0 | G44: {=_xlfn.SWITCH($A$2,"average", AVERAGE(Instances!G44:Instances!G44),"median", MEDIAN(Instances!G44:Instances!G44),"min", MIN(Instances!G44:Instances!G44),"max", MAX(Instances!G44:Instances!G44),"diff", MAX(Instances!G44:Instances!G44)-MIN(Instances!G44:Instances!G44))} -> 0 | J44: {=_xlfn.SWITCH($A$2,"average", AVERAGE(Instances!J44:Instances!J44),"median", MEDIAN(Instances!J44:Instances!J44),"min", MIN(Instances!J44:Instances!J44),"max", MAX(Instances!J44:Instances!J44),"diff", MAX(Instances!J44:Instances!J44)-MIN(Instances!J44:Instances!J44))} -> 0 | K44: {=_xlfn.SWITCH($A$2,"average", AVERAGE(Instances!K44:Instances!K44),"median", MEDIAN(Instances!K44:Instances!K44),"min", MIN(Instances!K44:Instances!K44),"max", MAX(Instances!K44:Instances!K44),"diff", MAX(Instances!K44:Instances!K44)-MIN(Instances!K44:Instances!K44))} -> 0 | L44: {=_xlfn.SWITCH($A$2,"average", AVERAGE(Instances!L44:Instances!L44),"median", MEDIAN(Instances!L44:Instances!L44),"min", MIN(Instances!L44:Instances!L44),"max", MAX(Instances!L44:Instances!L44),"diff", MAX(Instances!L44:Instances!L44)-MIN(Instances!L44:Instances!L44))} -> 0 | M44: {=_xlfn.SWITCH($A$2,"average", AVERAGE(Instances!M44:Instances!M44),"median", MEDIAN(Instances!M44:Instances!M44),"min", MIN(Instances!M44:Instances!M44),"max", MAX(Instances!M44:Instances!M44),"diff", MAX(Instances!M44:Instances!M44)-MIN(Instances!M44:Instances!M44))} -> 0 | N44: {=_xlfn.SWITCH($A$2,"average", AVERAGE(Instances!N44:Instances!N44),"median", MEDIAN(Instances!N44:Instances!N44),"min", MIN(Instances!N44:Instances!N44),"max", MAX(Instances!N44:Instances!N44),"diff", MAX(Instances!N44:Instances!N44)-MIN(Instances!N44:Instances!N44))} -> 0 | O44: {=_xlfn.SWITCH($A$2,"average", AVERAGE(Instances!O44:Instances!O44),"median", MEDIAN(Instances!O44:Instances!O44),"min", MIN(Instances!O44:Instances!O44),"max", MAX(Instances!O44:Instances!O44),"diff", MAX(Instances!O44:Instances!O44)-MIN(Instances!O44:Instances!O44))} -> 0 | P44: {=_xlfn.SWITCH($A$2,"average", AVERAGE(Instances!P44:Instances!P44),"median", MEDIAN(Instances!P44:Instances!P44),"min", MIN(Instances!P44:Instances!P44),"max", MAX(Instances!P44:Instances!P44),"diff", MAX(Instances!P44:Instances!P44)-MIN(Instances!P44:Instances!P44))} -> 0 | Q44: {=_xlfn.SWITCH($A$2,"average", AVERAGE(Instances!Q44:Instances!Q44),"median", MEDIAN(Instances!Q44:Instances!Q44),"min", MIN(Instances!Q44:Instances!Q44),"max", MAX(Instances!Q44:Instances!Q44),"diff", MAX(Instances!Q44:Instances!Q44)-MIN(Instances!Q44:Instances!Q44))} -> 0 | R44: =MIN($B44,$D44,$F44,$H44,$J44,$L44,$N44,$P44) -> 0 | S44: =MIN($C44,$E44,$G44,$I44,$K44,$M44,$O44,$Q44) -> 0 | T44: =MEDIAN($B44,$D44,$F44,$H44,$J44,$L44,$N44,$P44) -> 0 | U44: =MEDIAN($C44,$E44,$G44,$I44,$K44,$M44,$O44,$Q44) -> 0 | V44: =MAX($B44,$D44,$F44,$H44,$J44,$L44,$N44,$P44) -> 0 | W44: =MAX($C44,$E44,$G44,$I44,$K44,$M44,$O44,$Q44) -> 0
A45: ./travelbike-max10_user-input-p312-v851 | D45: {=_xlfn.SWITCH($A$2,"average", AVERAGE(Instances!D45:Instances!D45),"median", MEDIAN(Instances!D45:Instances!D45),"min", MIN(Instances!D45:Instances!D45),"max", MAX(Instances!D45:Instances!D45),"diff", MAX(Instances!D45:Instances!D45)-MIN(Instances!D45:Instances!D45))} -> 0 | E45: {=_xlfn.SWITCH($A$2,"average", AVERAGE(Instances!E45:Instances!E45),"median", MEDIAN(Instances!E45:Instances!E45),"min", MIN(Instances!E45:Instances!E45),"max", MAX(Instances!E45:Instances!E45),"diff", MAX(Instances!E45:Instances!E45)-MIN(Instances!E45:Instances!E45))} -> 0 | F45: {=_xlfn.SWITCH($A$2,"average", AVERAGE(Instances!F45:Instances!F45),"median", MEDIAN(Instances!F45:Instances!F45),"min", MIN(Instances!F45:Instances!F45),"max", MAX(Instances!F45:Instances!F45),"diff", MAX(Instances!F45:Instances!F45)-MIN(Instances!F45:Instances!F45))} -> 0 | G45: {=_xlfn.SWITCH($A$2,"average", AVERAGE(Instances!G45:Instances!G45),"median", MEDIAN(Instances!G45:Instances!G45),"min", MIN(Instances!G45:Instances!G45),"max", MAX(Instances!G45:Instances!G45),"diff", MAX(Instances!G45:Instances!G45)-MIN(Instances!G45:Instances!G45))} -> 0 | J45: {=_xlfn.SWITCH($A$2,"average", AVERAGE(Instances!J45:Instances!J45),"median", MEDIAN(Instances!J45:Instances!J45),"min", MIN(Instances!J45:Instances!J45),"max", MAX(Instances!J45:Instances!J45),"diff", MAX(Instances!J45:Instances!J45)-MIN(Instances!J45:Instances!J45))} -> 0 | K45: {=_xlfn.SWITCH($A$2,"average", AVERAGE(Instances!K45:Instances!K45),"median", MEDIAN(Instances!K45:Instances!K45),"min", MIN(Instances!K45:Instances!K45),"max", MAX(Instances!K45:Instances!K45),"diff", MAX(Instances!K45:Instances!K45)-MIN(Instances!K45:Instances!K45))} -> 0 | L45: {=_xlfn.SWITCH($A$2,"average", AVERAGE(Instances!L45:Instances!L45),"median", MEDIAN(Instances!L45:Instances!L45),"min", MIN(Instances!L45:Instances!L45),"max", MAX(Instances!L45:Instances!L45),"diff", MAX(Instances!L45:Instances!L45)-MIN(Instances!L45:Instances!L45))} -> 0 | M45: {=_xlfn.SWITCH($A$2,"average", AVERAGE(Instances!M45:Instances!M45),"median", MEDIAN(Instances!M45:Instances!M45),"min", MIN(Instances!M45:Instances!M45),"max", MAX(Instances!M45:Instances!M45),"diff", MAX(Instances!M45:Instances!M45)-MIN(Instances!M45:Instances!M45))} -> 0 | N45: {=_xlfn.SWITCH($A$2,"average", AVERAGE(Instances!N45:Instances!N45),"median", MEDIAN(Instances!N45:Instances!N45),"min", MIN(Instances!N45:Instances!N45),"max", MAX(Instances!N45:Instances!N45),"diff", MAX(Instances!N45:Instances!N45)-MIN(Instances!N45:Instances!N45))} -> 0 | O45: {=_xlfn.SWITCH($A$2,"average", AVERAGE(Instances!O45:Instances!O45),"median", MEDIAN(Instances!O45:Instances!O45),"min", MIN(Instances!O45:Instances!O45),"max", MAX(Instances!O45:Instances!O45),"diff", MAX(Instances!O45:Instances!O45)-MIN(Instances!O45:Instances!O45))} -> 0 | P45: {=_xlfn.SWITCH($A$2,"average", AVERAGE(Instances!P45:Instances!P45),"median", MEDIAN(Instances!P45:Instances!P45),"min", MIN(Instances!P45:Instances!P45),"max", MAX(Instances!P45:Instances!P45),"diff", MAX(Instances!P45:Instances!P45)-MIN(Instances!P45:Instances!P45))} -> 0 | Q45: {=_xlfn.SWITCH($A$2,"average", AVERAGE(Instances!Q45:Instances!Q45),"median", MEDIAN(Instances!Q45:Instances!Q45),"min", MIN(Instances!Q45:Instances!Q45),"max", MAX(Instances!Q45:Instances!Q45),"diff", MAX(Instances!Q45:Instances!Q45)-MIN(Instances!Q45:Instances!Q45))} -> 0 | R45: =MIN($B45,$D45,$F45,$H45,$J45,$L45,$N45,$P45) -> 0 | S45: =MIN($C45,$E45,$G45,$I45,$K45,$M45,$O45,$Q45) -> 0 | T45: =MEDIAN($B45,$D45,$F45,$H45,$J45,$L45,$N45,$P45) -> 0 | U45: =MEDIAN($C45,$E45,$G45,$I45,$K45,$M45,$O45,$Q45) -> 0 | V45: =MAX($B45,$D45,$F45,$H45,$J45,$L45,$N45,$P45) -> 0 | W45: =MAX($C45,$E45,$G45,$I45,$K45,$M45,$O45,$Q45) -> 0
A46: ./travelbike-max10_user-input-p317-v561 | D46: {=_xlfn.SWITCH($A$2,"average", AVERAGE(Instances!D46:Instances!D46),"median", MEDIAN(Instances!D46:Instances!D46),"min", MIN(Instances!D46:Instances!D46),"max", MAX(Instances!D46:Instances!D46),"diff", MAX(Instances!D46:Instances!D46)-MIN(Instances!D46:Instances!D46))} -> 0 | E46: {=_xlfn.SWITCH($A$2,"average", AVERAGE(Instances!E46:Instances!E46),"median", MEDIAN(Instances!E46:Instances!E46),"min", MIN(Instances!E46:Instances!E46),"max", MAX(Instances!E46:Instances!E46),"diff", MAX(Instances!E46:Instances!E46)-MIN(Instances!E46:Instances!E46))} -> 0 | F46: {=_xlfn.SWITCH($A$2,"average", AVERAGE(Instances!F46:Instances!F46),"median", MEDIAN(Instances!F46:Instances!F46),"min", MIN(Instances!F46:Instances!F46),"max", MAX(Instances!F46:Instances!F46),"diff", MAX(Instances!F46:Instances!F46)-MIN(Instances!F46:Instances!F46))} -> 0 | G46: {=_xlfn.SWITCH($A$2,"average", AVERAGE(Instances!G46:Instances!G46),"median", MEDIAN(Instances!G46:Instances!G46),"min", MIN(Instances!G46:Instances!G46),"max", MAX(Instances!G46:Instances!G46),"diff", MAX(Instances!G46:Instances!G46)-MIN(Instances!G46:Instances!G46))} -> 0 | J46: {=_xlfn.SWITCH($A$2,"average", AVERAGE(Instances!J46:Instances!J46),"median", MEDIAN(Instances!J46:Instances!J46),"min", MIN(Instances!J46:Instances!J46),"max", MAX(Instances!J46:Instances!J46),"diff", MAX(Instances!J46:Instances!J46)-MIN(Instances!J46:Instances!J46))} -> 0 | K46: {=_xlfn.SWITCH($A$2,"average", AVERAGE(Instances!K46:Instances!K46),"median", MEDIAN(Instances!K46:Instances!K46),"min", MIN(Instances!K46:Instances!K46),"max", MAX(Instances!K46:Instances!K46),"diff", MAX(Instances!K46:Instances!K46)-MIN(Instances!K46:Instances!K46))} -> 0 | L46: {=_xlfn.SWITCH($A$2,"average", AVERAGE(Instances!L46:Instances!L46),"median", MEDIAN(Instances!L46:Instances!L46),"min", MIN(Instances!L46:Instances!L46),"max", MAX(Instances!L46:Instances!L46),"diff", MAX(Instances!L46:Instances!L46)-MIN(Instances!L46:Instances!L46))} -> 0 | M46: {=_xlfn.SWITCH($A$2,"average", AVERAGE(Instances!M46:Instances!M46),"median", MEDIAN(Instances!M46:Instances!M46),"min", MIN(Instances!M46:Instances!M46),"max", MAX(Instances!M46:Instances!M46),"diff", MAX(Instances!M46:Instances!M46)-MIN(Instances!M46:Instances!M46))} -> 0 | N46: {=_xlfn.SWITCH($A$2,"average", AVERAGE(Instances!N46:Instances!N46),"median", MEDIAN(Instances!N46:Instances!N46),"min", MIN(Instances!N46:Instances!N46),"max", MAX(Instances!N46:Instances!N46),"diff", MAX(Instances!N46:Instances!N46)-MIN(Instances!N46:Instances!N46))} -> 0 | O46: {=_xlfn.SWITCH($A$2,"average", AVERAGE(Instances!O46:Instances!O46),"median", MEDIAN(Instances!O46:Instances!O46),"min", MIN(Instances!O46:Instances!O46),"max", MAX(Instances!O46:Instances!O46),"diff", MAX(Instances!O46:Instances!O46)-MIN(Instances!O46:Instances!O46))} -> 0 | P46: {=_xlfn.SWITCH($A$2,"average", AVERAGE(Instances!P46:Instances!P46),"median", MEDIAN(Instances!P46:Instances!P46),"min", MIN(Instances!P46:Instances!P46),"max", MAX(Instances!P46:Instances!P46),"diff", MAX(Instances!P46:Instances!P46)-MIN(Instances!P46:Instances!P46))} -> 0 | Q46: {=_xlfn.SWITCH($A$2,"average", AVERAGE(Instances!Q46:Instances!Q46),"median", MEDIAN(Instances!Q46:Instances!Q46),"min", MIN(Instances!Q46:Instances!Q46),"max", MAX(Instances!Q46:Instances!Q46),"diff", MAX(Instances!Q46:Instances!Q46)-MIN(Instances!Q46:Instances!Q46))} -> 0 | R46: =MIN($B46,$D46,$F46,$H46,$J46,$L46,$N46,$P46) -> 0 | S46: =MIN($C46,$E46,$G46,$I46,$K46,$M46,$O46,$Q46) -> 0 | T46: =MEDIAN($B46,$D46,$F46,$H46,$J46,$L46,$N46,$P46) -> 0 | U46: =MEDIAN($C46,$E46,$G46,$I46,$K46,$M46,$O46,$Q46) -> 0 | V46: =MAX($B46,$D46,$F46,$H46,$J46,$L46,$N46,$P46) -> 0 | W46: =MAX($C46,$E46,$G46,$I46,$K46,$M46,$O46,$Q46) -> 0
A47: ./travelbike-max10_user-input-p434-v422 | D47: {=_xlfn.SWITCH($A$2,"average", AVERAGE(Instances!D47:Instances!D47),"median", MEDIAN(Instances!D47:Instances!D47),"min", MIN(Instances!D47:Instances!D47),"max", MAX(Instances!D47:Instances!D47),"diff", MAX(Instances!D47:Instances!D47)-MIN(Instances!D47:Instances!D47))} -> 0 | E47: {=_xlfn.SWITCH($A$2,"average", AVERAGE(Instances!E47:Instances!E47),"median", MEDIAN(Instances!E47:Instances!E47),"min", MIN(Instances!E47:Instances!E47),"max", MAX(Instances!E47:Instances!E47),"diff", MAX(Instances!E47:Instances!E47)-MIN(Instances!E47:Instances!E47))} -> 0 | F47: {=_xlfn.SWITCH($A$2,"average", AVERAGE(Instances!F47:Instances!F47),"median", MEDIAN(Instances!F47:Instances!F47),"min", MIN(Instances!F47:Instances!F47),"max", MAX(Instances!F47:Instances!F47),"diff", MAX(Instances!F47:Instances!F47)-MIN(Instances!F47:Instances!F47))} -> 0 | G47: {=_xlfn.SWITCH($A$2,"average", AVERAGE(Instances!G47:Instances!G47),"median", MEDIAN(Instances!G47:Instances!G47),"min", MIN(Instances!G47:Instances!G47),"max", MAX(Instances!G47:Instances!G47),"diff", MAX(Instances!G47:Instances!G47)-MIN(Instances!G47:Instances!G47))} -> 0 | J47: {=_xlfn.SWITCH($A$2,"average", AVERAGE(Instances!J47:Instances!J47),"median", MEDIAN(Instances!J47:Instances!J47),"min", MIN(Instances!J47:Instances!J47),"max", MAX(Instances!J47:Instances!J47),"diff", MAX(Instances!J47:Instances!J47)-MIN(Instances!J47:Instances!J47))} -> 0 | K47: {=_xlfn.SWITCH($A$2,"average", AVERAGE(Instances!K47:Instances!K47),"median", MEDIAN(Instances!K47:Instances!K47),"min", MIN(Instances!K47:Instances!K47),"max", MAX(Instances!K47:Instances!K47),"diff", MAX(Instances!K47:Instances!K47)-MIN(Instances!K47:Instances!K47))} -> 0 | L47: {=_xlfn.SWITCH($A$2,"average", AVERAGE(Instances!L47:Instances!L47),"median", MEDIAN(Instances!L47:Instances!L47),"min", MIN(Instances!L47:Instances!L47),"max", MAX(Instances!L47:Instances!L47),"diff", MAX(Instances!L47:Instances!L47)-MIN(Instances!L47:Instances!L47))} -> 0 | M47: {=_xlfn.SWITCH($A$2,"average", AVERAGE(Instances!M47:Instances!M47),"median", MEDIAN(Instances!M47:Instances!M47),"min", MIN(Instances!M47:Instances!M47),"max", MAX(Instances!M47:Instances!M47),"diff", MAX(Instances!M47:Instances!M47)-MIN(Instances!M47:Instances!M47))} -> 0 | N47: {=_xlfn.SWITCH($A$2,"average", AVERAGE(Instances!N47:Instances!N47),"median", MEDIAN(Instances!N47:Instances!N47),"min", MIN(Instances!N47:Instances!N47),"max", MAX(Instances!N47:Instances!N47),"diff", MAX(Instances!N47:Instances!N47)-MIN(Instances!N47:Instances!N47))} -> 0 | O47: {=_xlfn.SWITCH($A$2,"average", AVERAGE(Instances!O47:Instances!O47),"median", MEDIAN(Instances!O47:Instances!O47),"min", MIN(Instances!O47:Instances!O47),"max", MAX(Instances!O47:Instances!O47),"diff", MAX(Instances!O47:Instances!O47)-MIN(Instances!O47:Instances!O47))} -> 0 | P47: {=_xlfn.SWITCH($A$2,"average", AVERAGE(Instances!P47:Instances!P47),"median", MEDIAN(Instances!P47:Instances!P47),"min", MIN(Instances!P47:Instances!P47),"max", MAX(Instances!P47:Instances!P47),"diff", MAX(Instances!P47:Instances!P47)-MIN(Instances!P47:Instances!P47))} -> 0 | Q47: {=_xlfn.SWITCH($A$2,"average", AVERAGE(Instances!Q47:Instances!Q47),"median", MEDIAN(Instances!Q47:Instances!Q47),"min", MIN(Instances!Q47:Instances!Q47),"max", MAX(Instances!Q47:Instances!Q47),"diff", MAX(Instances!Q47:Instances!Q47)-MIN(Instances!Q47:Instances!Q47))} -> 0 | R47: =MIN($B47,$D47,$F47,$H47,$J47,$L47,$N47,$P47) -> 0 | S47: =MIN($C47,$E47,$G47,$I47,$K47,$M47,$O47,$Q47) -> 0 | T47: =MEDIAN($B47,$D47,$F47,$H47,$J47,$L47,$N47,$P47) -> 0 | U47: =MEDIAN($C47,$E47,$G47,$I47,$K47,$M47,$O47,$Q47) -> 0 | V47: =MAX($B47,$D47,$F47,$H47,$J47,$L47,$N47,$P47) -> 0 | W47: =MAX($C47,$E47,$G47,$I47,$K47,$M47,$O47,$Q47) -> 0
